Workbook

Sheet rubros_id_opex
A1: nombre | B1: id
A2: ENERGIA | B2: 1
A3: HABILITACIONES Y CERT | B3: 2
A4: HIGIENE Y SEGURIDAD | B4: 3
A5: IMPUESTOS | B5: 4
A6: INSUMOS | B6: 5
A7: INVERSION | B7: 6
A8: LOGISTICA | B8: 7
A9: M.PRIMAS | B9: 8
A10: MANTENIMIENTO PREVENTIVO | B10: 9
A11: PERSONAL | B11: 10
A12: REPARACIONES | B12: 11
A13: REPOSICION | B13: 12
A14: SERVICIOS | B14: 12

Sheet fer_gral
C29: DEUDA
C30: FARO | D30: UNI
C31: M23 WORMS | D31: UNI
C32: M23 BROKER WORLD | D32: UNI
C33: SOUTHCROSS | D33: UNI
C34: RAUL BRINGAS | D34: UNI
C35: MOLLINS | D35: UNI
C36: NICOLAS AVELLINO | D36: UNI
C37: JORGE FERNANDEZ | D37: UNI
C38: CARBO | D38: UNI
C39: GARANTIZAR | D39: UNI
C40: CIRCULO CERRADO | D40: UNI
C41: SANTIAGO BORSONE | D41: UNI
... C48: CRISTIAN AMEGHINI | D48: UNI

Sheet fer_expo
B2: RUBRO + GASTO | C2: UM | D2: Q | E2: MONEDA | F2: P | G2: TOTAL
B3: ENERGIA
B4: NAFTA | C4: LTS
B5: ENERGIA ELECTRICA | C5: KW/H
B6: GASOIL G2 | C6: LTS
B7: GASOIL G3 | C7: LTS
B8: FULL OIL | C8: KG
B10: HABILITACION & CERT
B11: ISCC | C11: UNI
B12: AMBIENTAL | C12: UNI
B13: MUNICIPAL | C13: UNI
B15: HIGIENE & SEGURIDAD
B16: EPP | C16: UNI
B17: HONORARIOS SERVICIOS | C17: UNI
B19: INSUMO
B20: PRESINTOS ISO TANUQE | C20: UNI
B21: BOBINA PAPEL | C21: UNI
B23: LOGISTICA
B24: FOB | C24: TN
B25: FSA | C25: TN
B26: CIF | C26: TN
B28: MATERIA PRIMA
B29: AFE (S) | C29: TN
B30: AFE (G) | C30: TN
B31: AFE (SG) | C31: TN
B32: TSO | C32: TN
B33: AFE (AL) | C33: TN
B34: ARE (V) - A | C34: TN
B35: ARE (V) - B | C35: TN
B36: AG - A | C36: TN
B37: AG - B | C37: TN
B38: AG - C | C38: TN
B40: MANTENIMIENTO
B41: LIMPIEZA | C41: UNI
B44: RR.HH
B45: SUPERVISOR | C45: UNI
B46: COORDINADOR | C46: UNI
B47: OPERARIO | C47: UNI
B49: REPARACIONES
B50: BIENES DE USO + PARTES | C50: UNI | D50: 51
...

Sheet rrrhh_nuevo
A1: Fecha de Factura/Recibo | B1: Nombre de la empresa a mostrar en la factura | C1: Número | D1: Total | E1: Líneas de factura/Etiqueta | F1: Líneas de factura/Precio unitario | G1: Líneas de factura/Unidad de medida | H1: Líneas de factura/Producto | I1: Concepto | J1: # LEGAJO | K1: CCO - SECTOR | L1: Total con signo | M1: LEG. | N1: CUIL | O1: Tipo de Gasto 1 | P1: Tipo de Gasto 2 | Q1: Líneas de factura/Cantidad
A2: 46112 | B2: RRHH WORMS (NUEVO) | C2: ABAD, GONZALO | D2: 6630.4348 | E2: ADMINISTRACION | F2: 6630.4348 | G2: # RRHH | H2: PERSONAL | I2: OPEX | J2: 1005 | K2: CC15 | L2: -6630,4348 | M2: 1005 | N2: 20437193941 | O2: FIJO | P2: DIRECTO | Q2: 1
A3: 46112 | B3: RRHH WORMS (NUEVO) | C3: AGUSTIN ALBERTO LOPEZ | D3: 813389.76 | E3: PORTERIA | F3: 813389.76 | G3: # RRHH | H3: PERSONAL | I3: OPEX | J3: 158 | K3: CC22 | L3: -813389,7595 | M3: 158 | N3: 20418603039 | O3: FIJO | P3: DIRECTO | Q3: 1
A4: 46112 | B4: RRHH WORMS (NUEVO) | C4: ALEJANDRO FABIAN ALVAREZ | D4: 1022001 | E4: PILETAS + BACHAS | F4: 1022001 | G4: # RRHH | H4: PERSONAL | I4: OPEX | J4: 252 | K4: CC21 | L4: -1022000,9986 | M4: 252 | N4: 20324334255 | O4: FIJO | P4: DIRECTO | Q4: 1
A5: 46112 | B5: RRHH WORMS (NUEVO) | C5: ALEJO NAHUEL MARTINEZ | D5: 815631.39 | E5: REACTOR | F5: 815631.39 | G5: # RRHH | H5: PERSONAL | I5: OPEX | J5: 260 | K5: CC5 | L5: -815631,3884 | M5: 260 | N5: 20431280524 | O5: FIJO | P5: DIRECTO | Q5: 1
A6: 46112 | B6: RRHH WORMS (NUEVO) | C6: ANA CIELO SANTA CRUZ | D6: 826212.77 | E6: LABORATORIO | F6: 826212.77 | G6: # RRHH | H6: PERSONAL | I6: OPEX | J6: 213 | K6: CC17 | L6: -826212,7679 | M6: 213 | N6: 27320730835 | O6: FIJO | P6: DIRECTO | Q6: 1
A7: 46112 | B7: RRHH WORMS (NUEVO) | C7: ANDREA ANALI DI PAOLO | D7: 1098479.4 | E7: ADMINISTRACION | F7: 1098479.4 | G7: # RRHH | H7: PERSONAL | I7: OPEX | J7: 235 | K7: CC15 | L7: -1098479,3891 | M7: 235 | N7: 27326483791 | O7: FIJO | P7: INDIRECTO | Q7: 1
A8: 46112 | B8: RRHH WORMS (NUEVO) | C8: ANDRES CULOTA | D8: 3357574.7 | E8: ADMINISTRACION | F8: 3357574.7 | G8: # RRHH | H8: PERSONAL | I8: OPEX | J8: 219 | K8: CC15 | L8: -3357574,6753 | M8: 219 | N8: 20244797513 | O8: FIJO | P8: INDIRECTO | Q8: 1
A9: 46112 | B9: RRHH WORMS (NUEVO) | C9: ANDRES HONORES | D9: 1404307 | E9: REACTOR | F9: 1404307 | G9: # RRHH | H9: PERSONAL | I9: OPEX | J9: 43 | K9: CC5 | L9: -1404307,017 | M9: 43 | N9: 20372612615 | O9: FIJO | P9: DIRECTO | Q9: 1
A10: 46112 | B10: RRHH WORMS (NUEVO) | C10: AXEL MARCOS AREVALO | D10: 827089.77 | E10: TALLER MECANICO | F10: 827089.77 | G10: # RRHH | H10: PERSONAL | I10: OPEX | J10: 251 | K10: CC23 | L10: -827089,7725 | M10: 251 | N10: 20456381023 | O10: FIJO | P10: DIRECTO | Q10: 1
A11: 46112 | B11: RRHH WORMS (NUEVO) | C11: AYRTON RODRIGUEZ | D11: 939543.46 | E11: DISPOSICIÓN FINAL RESIDUOS LIQUIDOS + EXPORTACION | F11: 939543.46 | G11: # RRHH | H11: PERSONAL | I11: OPEX | J11: 196 | K11: CC25 | L11: -939543,4613 | M11: 196 | N11: 20402767139 | O11: FIJO | P11: DIRECTO | Q11: 1
A12: 46112 | B12: RRHH WORMS (NUEVO) | C12: BELTRAMO, ANDRES | D12: 0 | E12: DISPOSICIÓN FINAL RESIDUOS SOLIDOS | F12: 0 | G12: # RRHH | H12: PERSONAL | I12: OPEX | J12: 999 | K12: CC2 | L12: 0 | M12: 999 | N12: 20259420696 | O12: FIJO | P12: DIRECTO | Q12: 1
A13: 46112 | B13: RRHH WORMS (NUEVO) | C13: BRIAN EZEQUIEL GROSSO | D13: 1080740.6 | E13: VIGILANCIA | F13: 1080740.6 | G13: # RRHH | H13: PERSONAL | I13: OPEX | J13: 191 | K13: CC29 | L13: -1080740,6139 | M13: 191 | N13: 20398270070 | O13: FIJO | P13: INDIRECTO | Q13: 1
... A93: 46112 | B93: RRHH WORMS (NUEVO) | C93: VAZQUEZ MATIAS EMANUEL | D93: 893215.88 | E93: PILETAS + BACHAS | F93: 893215.88 | G93: # RRHH | H93: PERSONAL | I93: OPEX | J93: 180 | K93: CC21 | L93: -893215,8764 | M93: 180 | N93: 20395675673 | O93: FIJO | P93: DIRECTO | Q93: 1

Sheet sectores_id
A1: Sector | B1: id_sector | G1: SECTOR | H1: id_sector
A2: Bachas | B2: 1 | G2: BACHAS | H2: 1
A3: Cereal & Polvillo | B3: 2 | G3: CEREAL & POLVILLO | H3: 2
A4: COMPOST & FERTILIZANTES | B4: 10 | G4: COMPOST & FERTILIZANTES | H4: 10
A5: Disp. Final Residuos Líquidos | B5: 3 | G5: DISP. FINAL RESIDUOS LÍQUIDOS | H5: 3
A6: Disp. Final Residuos Sólidos | B6: 4 | G6: DISP. FINAL RESIDUOS SÓLIDOS | H6: 4
A7: DISPOSICIÓN FINAL RESIDUOS LIQUIDOS | B7: 3 | G7: EXPORTACION | H7: 5
A8: DISPOSICIÓN FINAL RESIDUOS SOLIDOS | B8: 4 | G8: NFU | H8: 6
A9: EXPORTACION | B9: 5 | G9: PILETAS | H9: 7
A10: Exportación | B10: 5 | G10: REACTORES | H10: 8
A11: General | B11: 0 | G11: TIERRAS FILTRANTES | H11: 9
A12: NFU | B12: 6 | G12: SALES | H12: 20
A13: PILETAS | B13: 7 | G13: TOTAL | H13: >=0
A14: Piletas / AG | B14: 7
A15: Reactores | B15: 8
A16: TIERRAS FILTRANTES | B16: 9
A17: COMPOST_Y_FERTILIZANTES | B17: 10
A18: DISP FINAL RESIDUOS SOLIDOS | B18: 4
A19: CEREAL & POLVILLO | B19: 2
A20: DISP FINAL RESIDUOS LIQUIDOS | B20: 3
A21: BACHAS | B21: 1
A22: REACTORES | B22: 8
A23: Reactor | B23: 8
A24: Piletas | B24: 7
A25: DISPOSICION FINAL DE R. LIQUIDOS | B25: 3
... A34: TEIRRAS FILTRANTES | B34: 9

Sheet Vista_nueva
A2: id | D2: =_xlfn.XLOOKUP(D3,sectores_id!$G$2:$G$13,sectores_id!$H$2:$H$13) -> >=0 | G2: id | H2: 3 | K2: id | L2: 7 | O2: id | P2: 8
D3: TOTAL
D4: OPEX DIRECTO | F4: =SUM(F5:F17) -> 2.8801021e+09
A5: 1 | B5: OPEX DIRECTO | D5: =F5/$F$4 -> 0.026866489 | E5: =_xlfn.XLOOKUP($A5,'rubros_id_opex (2)'!$B:$B,'rubros_id_opex (2)'!$A:$A) -> ENERGIA | F5: =SUMIFS('bbdd.5.final'!$Y:$Y,'bbdd.5.final'!$AA:$AA,Vista_nueva!A5,'bbdd.5.final'!$Z:$Z,$D$2,'bbdd.5.final'!$J:$J,"Opex",'bbdd.5.final'!$L:$L,"DIRECTO") -> 77378232 | G5: 1
A6: 2 | B6: OPEX DIRECTO | D6: =F6/$F$4 -> 0.00049824623 | E6: =_xlfn.XLOOKUP($A6,'rubros_id_opex (2)'!$B:$B,'rubros_id_opex (2)'!$A:$A) -> HABILITACIONES Y CERT | F6: =SUMIFS('bbdd.5.final'!$Y:$Y,'bbdd.5.final'!$AA:$AA,Vista_nueva!A6,'bbdd.5.final'!$Z:$Z,$D$2,'bbdd.5.final'!$J:$J,"Opex",'bbdd.5.final'!$L:$L,"DIRECTO") -> 1435000 | G6: =G5+1 -> 2
A7: 3 | B7: OPEX DIRECTO | D7: =F7/$F$4 -> 0.00083543398 | E7: =_xlfn.XLOOKUP($A7,'rubros_id_opex (2)'!$B:$B,'rubros_id_opex (2)'!$A:$A) -> HIGIENE Y SEGURIDAD | F7: =SUMIFS('bbdd.5.final'!$Y:$Y,'bbdd.5.final'!$AA:$AA,Vista_nueva!A7,'bbdd.5.final'!$Z:$Z,$D$2,'bbdd.5.final'!$J:$J,"Opex",'bbdd.5.final'!$L:$L,"DIRECTO") -> 2406135.1 | G7: =G6+1 -> 3
A8: 5 | B8: OPEX DIRECTO | D8: =F8/$F$4 -> 0.033931015 | E8: =_xlfn.XLOOKUP($A8,'rubros_id_opex (2)'!$B:$B,'rubros_id_opex (2)'!$A:$A) -> INSUMOS | F8: =SUMIFS('bbdd.5.final'!$Y:$Y,'bbdd.5.final'!$AA:$AA,Vista_nueva!A8,'bbdd.5.final'!$Z:$Z,$D$2,'bbdd.5.final'!$J:$J,"Opex",'bbdd.5.final'!$L:$L,"DIRECTO") -> 97724788 | G8: =#REF!+1 -> #REF!
A9: 6 | B9: OPEX DIRECTO | D9: =F9/$F$4 -> 0 | E9: =_xlfn.XLOOKUP($A9,'rubros_id_opex (2)'!$B:$B,'rubros_id_opex (2)'!$A:$A) -> INVERSION | F9: =SUMIFS('bbdd.5.final'!$Y:$Y,'bbdd.5.final'!$AA:$AA,Vista_nueva!A9,'bbdd.5.final'!$Z:$Z,$D$2,'bbdd.5.final'!$J:$J,"Opex",'bbdd.5.final'!$L:$L,"DIRECTO") -> 0 | G9: =G8+1 -> #REF!
A10: 7 | B10: OPEX DIRECTO | D10: =F10/$F$4 -> 0.014737544 | E10: =_xlfn.XLOOKUP($A10,'rubros_id_opex (2)'!$B:$B,'rubros_id_opex (2)'!$A:$A) -> LOGISTICA | F10: =SUMIFS('bbdd.5.final'!$Y:$Y,'bbdd.5.final'!$AA:$AA,Vista_nueva!A10,'bbdd.5.final'!$Z:$Z,$D$2,'bbdd.5.final'!$J:$J,"Opex",'bbdd.5.final'!$L:$L,"DIRECTO") -> 42445632 | G10: =G9+1 -> #REF!
A11: 8 | B11: OPEX DIRECTO | D11: =F11/$F$4 -> 0.88918031 | E11: =_xlfn.XLOOKUP($A11,'rubros_id_opex (2)'!$B:$B,'rubros_id_opex (2)'!$A:$A) -> M.PRIMAS | F11: =SUMIFS('bbdd.5.final'!$Y:$Y,'bbdd.5.final'!$AA:$AA,Vista_nueva!A11,'bbdd.5.final'!$Z:$Z,$D$2,'bbdd.5.final'!$J:$J,"Opex",'bbdd.5.final'!$L:$L,"DIRECTO") -> 2.5609301e+09 | G11: =G10+1 -> #REF!
A12: 9 | B12: OPEX DIRECTO | D12: =F12/$F$4 -> 0.00022510244 | E12: =_xlfn.XLOOKUP($A12,'rubros_id_opex (2)'!$B:$B,'rubros_id_opex (2)'!$A:$A) -> MANTENIMIENTO PREVENTIVO | F12: =SUMIFS('bbdd.5.final'!$Y:$Y,'bbdd.5.final'!$AA:$AA,Vista_nueva!A12,'bbdd.5.final'!$Z:$Z,$D$2,'bbdd.5.final'!$J:$J,"Opex",'bbdd.5.final'!$L:$L,"DIRECTO") -> 648318 | G12: =G11+1 -> #REF!
A13: 10 | B13: OPEX DIRECTO | D13: =F13/$F$4 -> 0.02385739 | E13: =_xlfn.XLOOKUP($A13,'rubros_id_opex (2)'!$B:$B,'rubros_id_opex (2)'!$A:$A) -> PERSONAL | F13: =SUMIFS('bbdd.5.final'!$Y:$Y,'bbdd.5.final'!$AA:$AA,Vista_nueva!A13,'bbdd.5.final'!$Z:$Z,$D$2,'bbdd.5.final'!$J:$J,"Opex",'bbdd.5.final'!$L:$L,"DIRECTO") -> 68711718 | G13: =G12+1 -> #REF!
A14: 11 | B14: OPEX DIRECTO | D14: =F14/$F$4 -> 0.00075358332 | E14: =_xlfn.XLOOKUP($A14,'rubros_id_opex (2)'!$B:$B,'rubros_id_opex (2)'!$A:$A) -> REPARACIONES | F14: =SUMIFS('bbdd.5.final'!$Y:$Y,'bbdd.5.final'!$AA:$AA,Vista_nueva!A14,'bbdd.5.final'!$Z:$Z,$D$2,'bbdd.5.final'!$J:$J,"Opex",'bbdd.5.final'!$L:$L,"DIRECTO") -> 2170396.9 | G14: =G13+1 -> #REF!
A15: 12 | B15: OPEX DIRECTO | D15: =F15/$F$4 -> 0.00036062735 | E15: =_xlfn.XLOOKUP($A15,'rubros_id_opex (2)'!$B:$B,'rubros_id_opex (2)'!$A:$A) -> REPOSICION | F15: =SUMIFS('bbdd.5.final'!$Y:$Y,'bbdd.5.final'!$AA:$AA,Vista_nueva!A15,'bbdd.5.final'!$Z:$Z,$D$2,'bbdd.5.final'!$J:$J,"Opex",'bbdd.5.final'!$L:$L,"DIRECTO") -> 1038643.6 | G15: =G14+1 -> #REF!
A16: 13 | B16: OPEX DIRECTO | D16: =F16/$F$4 -> 0.0085841958 | E16: =_xlfn.XLOOKUP($A16,'rubros_id_opex (2)'!$B:$B,'rubros_id_opex (2)'!$A:$A) -> SERVICIOS | F16: =SUMIFS('bbdd.5.final'!$Y:$Y,'bbdd.5.final'!$AA:$AA,Vista_nueva!A16,'bbdd.5.final'!$Z:$Z,$D$2,'bbdd.5.final'!$J:$J,"Opex",'bbdd.5.final'!$L:$L,"DIRECTO") -> 24723360 | G16: =G15+1 -> #REF!
A17: 14 | B17: OPEX DIRECTO | D17: =F17/$F$4 -> 0.00017006341 | E17: =_xlfn.XLOOKUP($A17,'rubros_id_opex (2)'!$B:$B,'rubros_id_opex (2)'!$A:$A) -> COMERCIAL | F17: =SUMIFS('bbdd.5.final'!$Y:$Y,'bbdd.5.final'!$AA:$AA,Vista_nueva!A17,'bbdd.5.final'!$Z:$Z,$D$2,'bbdd.5.final'!$J:$J,"Opex",'bbdd.5.final'!$L:$L,"DIRECTO") -> 489799.99 | G17: =G16+1 -> #REF!
D19: VENTAS | F19: =SUMIFS(BBDD_INGRESOS_FINAL!$O:$O,BBDD_INGRESOS_FINAL!$R:$R,Vista_nueva!$D$2) -> 3.453388e+09
D21: RESULTADO 1 (EBIT 1) | F21: =F19-F4 -> 5.732859e+08
D23: OPEX INDIRECTO | F23: =SUM(F24:F36) -> 89367666
A24: 1 | B24: OPEX INDIRECTO | D24: =F24/$F$4 -> 0 | E24: =_xlfn.XLOOKUP($A24,'rubros_id_opex (2)'!$B:$B,'rubros_id_opex (2)'!$A:$A) -> ENERGIA | F24: =SUMIFS('bbdd.5.final'!$Y:$Y,'bbdd.5.final'!$AA:$AA,Vista_nueva!A24,'bbdd.5.final'!$Z:$Z,$D$2,'bbdd.5.final'!$J:$J,"Opex",'bbdd.5.final'!$L:$L,"INDIRECTO") -> 0
A25: 2 | B25: OPEX INDIRECTO | D25: =F25/$F$4 -> 0.00050171832 | E25: =_xlfn.XLOOKUP($A25,'rubros_id_opex (2)'!$B:$B,'rubros_id_opex (2)'!$A:$A) -> HABILITACIONES Y CERT | F25: =SUMIFS('bbdd.5.final'!$Y:$Y,'bbdd.5.final'!$AA:$AA,Vista_nueva!A25,'bbdd.5.final'!$Z:$Z,$D$2,'bbdd.5.final'!$J:$J,"Opex",'bbdd.5.final'!$L:$L,"INDIRECTO") -> 1445000
A26: 3 | B26: OPEX INDIRECTO | D26: =F26/$F$4 -> 0 | E26: =_xlfn.XLOOKUP($A26,'rubros_id_opex (2)'!$B:$B,'rubros_id_opex (2)'!$A:$A) -> HIGIENE Y SEGURIDAD | F26: =SUMIFS('bbdd.5.final'!$Y:$Y,'bbdd.5.final'!$AA:$AA,Vista_nueva!A26,'bbdd.5.final'!$Z:$Z,$D$2,'bbdd.5.final'!$J:$J,"Opex",'bbdd.5.final'!$L:$L,"INDIRECTO") -> 0
A27: 5 | B27: OPEX INDIRECTO | D27: =F27/$F$4 -> 0.00077282931 | E27: =_xlfn.XLOOKUP($A27,'rubros_id_opex (2)'!$B:$B,'rubros_id_opex (2)'!$A:$A) -> INSUMOS | F27: =SUMIFS('bbdd.5.final'!$Y:$Y,'bbdd.5.final'!$AA:$AA,Vista_nueva!A27,'bbdd.5.final'!$Z:$Z,$D$2,'bbdd.5.final'!$J:$J,"Opex",'bbdd.5.final'!$L:$L,"INDIRECTO") -> 2225827.3
A28: 6 | B28: OPEX INDIRECTO | D28: =F28/$F$4 -> 0 | E28: =_xlfn.XLOOKUP($A28,'rubros_id_opex (2)'!$B:$B,'rubros_id_opex (2)'!$A:$A) -> INVERSION | F28: =SUMIFS('bbdd.5.final'!$Y:$Y,'bbdd.5.final'!$AA:$AA,Vista_nueva!A28,'bbdd.5.final'!$Z:$Z,$D$2,'bbdd.5.final'!$J:$J,"Opex",'bbdd.5.final'!$L:$L,"INDIRECTO") -> 0
A29: 7 | B29: OPEX INDIRECTO | D29: =F29/$F$4 -> 0 | E29: =_xlfn.XLOOKUP($A29,'rubros_id_opex (2)'!$B:$B,'rubros_id_opex (2)'!$A:$A) -> LOGISTICA | F29: =SUMIFS('bbdd.5.final'!$Y:$Y,'bbdd.5.final'!$AA:$AA,Vista_nueva!A29,'bbdd.5.final'!$Z:$Z,$D$2,'bbdd.5.final'!$J:$J,"Opex",'bbdd.5.final'!$L:$L,"INDIRECTO") -> 0
A30: 8 | B30: OPEX INDIRECTO | D30: =F30/$F$4 -> 0 | E30: =_xlfn.XLOOKUP($A30,'rubros_id_opex (2)'!$B:$B,'rubros_id_opex (2)'!$A:$A) -> M.PRIMAS | F30: =SUMIFS('bbdd.5.final'!$Y:$Y,'bbdd.5.final'!$AA:$AA,Vista_nueva!A30,'bbdd.5.final'!$Z:$Z,$D$2,'bbdd.5.final'!$J:$J,"Opex",'bbdd.5.final'!$L:$L,"INDIRECTO") -> 0
A31: 9 | B31: OPEX INDIRECTO | D31: =F31/$F$4 -> 0.00032567254 | E31: =_xlfn.XLOOKUP($A31,'rubros_id_opex (2)'!$B:$B,'rubros_id_opex (2)'!$A:$A) -> MANTENIMIENTO PREVENTIVO | F31: =SUMIFS('bbdd.5.final'!$Y:$Y,'bbdd.5.final'!$AA:$AA,Vista_nueva!A31,'bbdd.5.final'!$Z:$Z,$D$2,'bbdd.5.final'!$J:$J,"Opex",'bbdd.5.final'!$L:$L,"INDIRECTO") -> 937970.18
A32: 10 | B32: OPEX INDIRECTO | D32: =F32/$F$4 -> 0.010184318 | E32: =_xlfn.XLOOKUP($A32,'rubros_id_opex (2)'!$B:$B,'rubros_id_opex (2)'!$A:$A) -> PERSONAL | F32: =SUMIFS('bbdd.5.final'!$Y:$Y,'bbdd.5.final'!$AA:$AA,Vista_nueva!A32,'bbdd.5.final'!$Z:$Z,$D$2,'bbdd.5.final'!$J:$J,"Opex",'bbdd.5.final'!$L:$L,"INDIRECTO") -> 29331876
A33: 11 | B33: OPEX INDIRECTO | D33: =F33/$F$4 -> 0.0018696265 | E33: =_xlfn.XLOOKUP($A33,'rubros_id_opex (2)'!$B:$B,'rubros_id_opex (2)'!$A:$A) -> REPARACIONES | F33: =SUMIFS('bbdd.5.final'!$Y:$Y,'bbdd.5.final'!$AA:$AA,Vista_nueva!A33,'bbdd.5.final'!$Z:$Z,$D$2,'bbdd.5.final'!$J:$J,"Opex",'bbdd.5.final'!$L:$L,"INDIRECTO") -> 5384715.1
A34: 12 | B34: OPEX INDIRECTO | D34: =F34/$F$4 -> 0.0008588358 | E34: =_xlfn.XLOOKUP($A34,'rubros_id_opex (2)'!$B:$B,'rubros_id_opex (2)'!$A:$A) -> REPOSICION | F34: =SUMIFS('bbdd.5.final'!$Y:$Y,'bbdd.5.final'!$AA:$AA,Vista_nueva!A34,'bbdd.5.final'!$Z:$Z,$D$2,'bbdd.5.final'!$J:$J,"Opex",'bbdd.5.final'!$L:$L,"INDIRECTO") -> 2473534.8
A35: 13 | B35: OPEX INDIRECTO | D35: =F35/$F$4 -> 0.016516339 | E35: =_xlfn.XLOOKUP($A35,'rubros_id_opex (2)'!$B:$B,'rubros_id_opex (2)'!$A:$A) -> SERVICIOS | F35: =SUMIFS('bbdd.5.final'!$Y:$Y,'bbdd.5.final'!$AA:$AA,Vista_nueva!A35,'bbdd.5.final'!$Z:$Z,$D$2,'bbdd.5.final'!$J:$J,"Opex",'bbdd.5.final'!$L:$L,"INDIRECTO") -> 47568743
A36: 14 | B36: OPEX INDIRECTO | D36: =F36/$F$4 -> 0 | E36: =_xlfn.XLOOKUP($A36,'rubros_id_opex (2)'!$B:$B,'rubros_id_opex (2)'!$A:$A) -> COMERCIAL | F36: =SUMIFS('bbdd.5.final'!$Y:$Y,'bbdd.5.final'!$AA:$AA,Vista_nueva!A36,'bbdd.5.final'!$Z:$Z,$D$2,'bbdd.5.final'!$J:$J,"Opex",'bbdd.5.final'!$L:$L,"INDIRECTO") -> 0
D38: RESULTADO 2 (EBIT 2) | F38: =F21-F23 -> 4.8391824e+08
A39: 4 | D39: IMPUESTOS DIRECTOS | E39: =_xlfn.XLOOKUP(A39,'rubros_id_opex (2)'!$B:$B,'rubros_id_opex (2)'!$A:$A) -> IMPUESTOS | F39: =SUMIFS('bbdd.5.final'!$Y:$Y,'bbdd.5.final'!$AA:$AA,A39,'bbdd.5.final'!$Z:$Z,$D$2,'bbdd.5.final'!$J:$J,"Opex",'bbdd.5.final'!$L:$L,"DIRECTO") -> 1412535.2
A40: 4 | D40: IMPUESTOS INDIRECTOS | E40: =_xlfn.XLOOKUP($A40,'rubros_id_opex (2)'!$B:$B,'rubros_id_opex (2)'!$A:$A) -> IMPUESTOS | F40: =SUMIFS('bbdd.5.final'!$Y:$Y,'bbdd.5.final'!$AA:$AA,Vista_nueva!A40,'bbdd.5.final'!$Z:$Z,$D$2,'bbdd.5.final'!$J:$J,"Opex",'bbdd.5.final'!$L:$L,"INDIRECTO") -> 7040238.6
D42: IMPUESTOS TOTALES DEL SECTOR | F42: =SUM(F39:F40) -> 8452773.8
A44: CAPEX | D44: CAPEX DIRECTO | E44: CAPEX | F44: =SUMIFS('bbdd.5.final'!$Y:$Y,'bbdd.5.final'!$AA:$AA,Vista_nueva!A44,'bbdd.5.final'!$Z:$Z,$D$2,'bbdd.5.final'!$L:$L,"DIRECTO") -> 1.127357e+08
A45: CAPEX | D45: CAPEX INDIRECTO | E45: CAPEX | F45: =SUMIFS('bbdd.5.final'!$Y:$Y,'bbdd.5.final'!$AA:$AA,Vista_nueva!A45,'bbdd.5.final'!$Z:$Z,$D$2,'bbdd.5.final'!$L:$L,"INDIRECTO") -> 1.4250062e+08
D46: CAPEX TOTAL DEL SECTOR | F46: =F44+F45 -> 2.5523632e+08
D48: RESULTADO 3 | F48: =F38-F42-F46 -> 2.2022915e+08
...

Sheet Vista
B2: WORMS
B5: TOTALES | F5: FIJO/VARIABLE | J5: DIRECTO/INDERECTO
B6: VENTAS | C6: =SUM(BBDD_INGRESOS_FINAL!$O:$O) -> 3.453388e+09 | F6: VENTAS | G6: =SUM(BBDD_INGRESOS_FINAL!$O:$O) -> 3.453388e+09 | J6: VENTAS | K6: =SUM(BBDD_INGRESOS_FINAL!$O:$O) -> 3.453388e+09
B7: OPEX | C7: =SUMIFS('bbdd.5.final'!$Y:$Y,'bbdd.5.final'!$J:$J,Vista!B7) -> 2.9779225e+09 | F7: Fijo | G7: =SUMIFS(BBDD_GASTOS!$H:$H,BBDD_GASTOS!$J:$J,Vista!F7) -> 1.0332095e+08 | J7: DIRECTO | K7: =SUMIFS('bbdd.5.final'!$Y:$Y,'bbdd.5.final'!$L:$L,$J$7) -> 2.9942503e+09
B8: UTILIDAD | C8: =C6-C7 -> 4.7546546e+08 | F8: Variable | G8: =SUMIFS(BBDD_GASTOS!$H:$H,BBDD_GASTOS!$J:$J,Vista!F8) -> 4.6635073e+09 | J8: INDIRECTO | K8: =SUMIFS('bbdd.5.final'!$Y:$Y,'bbdd.5.final'!$L:$L,$J$8) -> 2.3890852e+08
B9: CAPEX | C9: =SUMIFS('bbdd.5.final'!$Y:$Y,'bbdd.5.final'!$J:$J,Vista!B9) -> 2.5523632e+08
B10: DEUDA | C10: =SUMIFS('bbdd.5.final'!$Y:$Y,'bbdd.5.final'!$J:$J,Vista!B10) -> 0
B11: Flujo de Caja al Accionista | C11: =C6-C7-C9-C10 -> 2.2022915e+08 | F11: Flujo de Caja al Accionista | G11: =G6-G7-G8 -> -1.3134403e+09 | J11: Flujo de Caja al Accionista | K11: =K6-K7-K8 -> 2.2022915e+08
A13: id | B13: 4 | E13: id | F13: 3 | I13: id | J13: 7 | M13: id | N13: 8
B14: DISPOSICIÓN FINAL RESIDUOS SOLIDOS | F14: DISPOSICIÓN FINAL RESIDUOS LIQUIDOS | J14: PILETAS | N14: REACTORES
B15: OPEX | D15: =SUM(D16:D29) -> 9091744.7 | F15: OPEX | H15: =SUM(H16:H29) -> 37569201 | J15: OPEX | L15: =SUM(L16:L28) -> 23546614 | M15: 1 | N15: OPEX | P15: =SUM(P16:P29) -> 1.946207e+08
A16: 1 | B16: =D16/$D$15 -> 0.0062786192 | C16: =_xlfn.XLOOKUP($A16,'rubros_id_opex (2)'!$B:$B,'rubros_id_opex (2)'!$A:$A) -> ENERGIA | D16: =SUMIFS('bbdd.5.final'!$Y:$Y,'bbdd.5.final'!$AA:$AA,Vista!A16,'bbdd.5.final'!$Z:$Z,$B$13,'bbdd.5.final'!$J:$J,"Opex") -> 57083.603 | E16: 1 | F16: =H16/$H$15 -> 0.078263435 | G16: =_xlfn.XLOOKUP($E16,'rubros_id_opex (2)'!$B:$B,'rubros_id_opex (2)'!$A:$A) -> ENERGIA | H16: =SUMIFS('bbdd.5.final'!$Y:$Y,'bbdd.5.final'!$AA:$AA,Vista!E16,'bbdd.5.final'!$Z:$Z,$F$13,'bbdd.5.final'!$J:$J,"Opex") -> 2940294.7 | I16: 1 | J16: =L16/$L$15 -> 0.21684449 | K16: =_xlfn.XLOOKUP($I16,'rubros_id_opex (2)'!$B:$B,'rubros_id_opex (2)'!$A:$A) -> ENERGIA | L16: =SUMIFS('bbdd.5.final'!$Y:$Y,'bbdd.5.final'!$AA:$AA,Vista!I16,'bbdd.5.final'!$Z:$Z,$J$13,'bbdd.5.final'!$J:$J,"Opex") -> 5105953.5 | M16: 1 | N16: =P16/$P$15 -> 0.19133692 | O16: =_xlfn.XLOOKUP($M16,'rubros_id_opex (2)'!$B:$B,'rubros_id_opex (2)'!$A:$A) -> ENERGIA | P16: =SUMIFS('bbdd.5.final'!$Y:$Y,'bbdd.5.final'!$AA:$AA,Vista!M16,'bbdd.5.final'!$Z:$Z,$N$13,'bbdd.5.final'!$J:$J,"Opex") -> 37238125
A17: =A16+1 -> 2 | B17: =D17/$D$15 -> 0.00077462129 | C17: =_xlfn.XLOOKUP($A17,'rubros_id_opex (2)'!$B:$B,'rubros_id_opex (2)'!$A:$A) -> HABILITACIONES Y CERT | D17: =SUMIFS('bbdd.5.final'!$Y:$Y,'bbdd.5.final'!$AA:$AA,Vista!A17,'bbdd.5.final'!$Z:$Z,$B$13,'bbdd.5.final'!$J:$J,"Opex") -> 7042.659 | E17: =E16+1 -> 2 | F17: =H17/$H$15 -> 0.0022997058 | G17: =_xlfn.XLOOKUP($E17,'rubros_id_opex (2)'!$B:$B,'rubros_id_opex (2)'!$A:$A) -> HABILITACIONES Y CERT | H17: =SUMIFS('bbdd.5.final'!$Y:$Y,'bbdd.5.final'!$AA:$AA,Vista!E17,'bbdd.5.final'!$Z:$Z,$F$13,'bbdd.5.final'!$J:$J,"Opex") -> 86398.108 | I17: =I16+1 -> 2 | J17: =L17/$L$15 -> 0.0066031776 | K17: =_xlfn.XLOOKUP($I17,'rubros_id_opex (2)'!$B:$B,'rubros_id_opex (2)'!$A:$A) -> HABILITACIONES Y CERT | L17: =SUMIFS('bbdd.5.final'!$Y:$Y,'bbdd.5.final'!$AA:$AA,Vista!I17,'bbdd.5.final'!$Z:$Z,$J$13,'bbdd.5.final'!$J:$J,"Opex") -> 155482.48 | M17: =M16+1 -> 2 | N17: =P17/$P$15 -> 0.00029457803 | O17: =_xlfn.XLOOKUP($M17,'rubros_id_opex (2)'!$B:$B,'rubros_id_opex (2)'!$A:$A) -> HABILITACIONES Y CERT | P17: =SUMIFS('bbdd.5.final'!$Y:$Y,'bbdd.5.final'!$AA:$AA,Vista!M17,'bbdd.5.final'!$Z:$Z,$N$13,'bbdd.5.final'!$J:$J,"Opex") -> 57330.982
A18: =A17+1 -> 3 | B18: =D18/$D$15 -> 0.0012898571 | C18: =_xlfn.XLOOKUP($A18,'rubros_id_opex (2)'!$B:$B,'rubros_id_opex (2)'!$A:$A) -> HIGIENE Y SEGURIDAD | D18: =SUMIFS('bbdd.5.final'!$Y:$Y,'bbdd.5.final'!$AA:$AA,Vista!A18,'bbdd.5.final'!$Z:$Z,$B$13,'bbdd.5.final'!$J:$J,"Opex") -> 11727.051 | E18: =E17+1 -> 3 | F18: =H18/$H$15 -> 0.0038293446 | G18: =_xlfn.XLOOKUP($E18,'rubros_id_opex (2)'!$B:$B,'rubros_id_opex (2)'!$A:$A) -> HIGIENE Y SEGURIDAD | H18: =SUMIFS('bbdd.5.final'!$Y:$Y,'bbdd.5.final'!$AA:$AA,Vista!E18,'bbdd.5.final'!$Z:$Z,$F$13,'bbdd.5.final'!$J:$J,"Opex") -> 143865.42 | I18: =I17+1 -> 3 | J18: =L18/$L$15 -> 0.010995251 | K18: =_xlfn.XLOOKUP($I18,'rubros_id_opex (2)'!$B:$B,'rubros_id_opex (2)'!$A:$A) -> HIGIENE Y SEGURIDAD | L18: =SUMIFS('bbdd.5.final'!$Y:$Y,'bbdd.5.final'!$AA:$AA,Vista!I18,'bbdd.5.final'!$Z:$Z,$J$13,'bbdd.5.final'!$J:$J,"Opex") -> 258900.93 | M18: =M17+1 -> 3 | N18: =P18/$P$15 -> 0.00049051526 | O18: =_xlfn.XLOOKUP($M18,'rubros_id_opex (2)'!$B:$B,'rubros_id_opex (2)'!$A:$A) -> HIGIENE Y SEGURIDAD | P18: =SUMIFS('bbdd.5.final'!$Y:$Y,'bbdd.5.final'!$AA:$AA,Vista!M18,'bbdd.5.final'!$Z:$Z,$N$13,'bbdd.5.final'!$J:$J,"Opex") -> 95464.423
A19: =A18+1 -> 4 | B19: =D19/$D$15 -> 0.0027586388 | C19: =_xlfn.XLOOKUP($A19,'rubros_id_opex (2)'!$B:$B,'rubros_id_opex (2)'!$A:$A) -> IMPUESTOS | D19: =SUMIFS('bbdd.5.final'!$Y:$Y,'bbdd.5.final'!$AA:$AA,Vista!A19,'bbdd.5.final'!$Z:$Z,$B$13,'bbdd.5.final'!$J:$J,"Opex") -> 25080.84 | E19: =E18+1 -> 4 | F19: =H19/$H$15 -> 0.026134634 | G19: =_xlfn.XLOOKUP($E19,'rubros_id_opex (2)'!$B:$B,'rubros_id_opex (2)'!$A:$A) -> IMPUESTOS | H19: =SUMIFS('bbdd.5.final'!$Y:$Y,'bbdd.5.final'!$AA:$AA,Vista!E19,'bbdd.5.final'!$Z:$Z,$F$13,'bbdd.5.final'!$J:$J,"Opex") -> 981857.3 | I19: =I18+1 -> 4 | J19: =L19/$L$15 -> 0.035171393 | K19: =_xlfn.XLOOKUP($I19,'rubros_id_opex (2)'!$B:$B,'rubros_id_opex (2)'!$A:$A) -> IMPUESTOS | L19: =SUMIFS('bbdd.5.final'!$Y:$Y,'bbdd.5.final'!$AA:$AA,Vista!I19,'bbdd.5.final'!$Z:$Z,$J$13,'bbdd.5.final'!$J:$J,"Opex") -> 828167.22 | M19: =M18+1 -> 4 | N19: =P19/$P$15 -> 0.0010490731 | O19: =_xlfn.XLOOKUP($M19,'rubros_id_opex (2)'!$B:$B,'rubros_id_opex (2)'!$A:$A) -> IMPUESTOS | P19: =SUMIFS('bbdd.5.final'!$Y:$Y,'bbdd.5.final'!$AA:$AA,Vista!M19,'bbdd.5.final'!$Z:$Z,$N$13,'bbdd.5.final'!$J:$J,"Opex") -> 204171.35
A20: =A19+1 -> 5 | B20: =D20/$D$15 -> 0.0010196387 | C20: =_xlfn.XLOOKUP($A20,'rubros_id_opex (2)'!$B:$B,'rubros_id_opex (2)'!$A:$A) -> INSUMOS | D20: =SUMIFS('bbdd.5.final'!$Y:$Y,'bbdd.5.final'!$AA:$AA,Vista!A20,'bbdd.5.final'!$Z:$Z,$B$13,'bbdd.5.final'!$J:$J,"Opex") -> 9270.2951 | E20: =E19+1 -> 5 | F20: =H20/$H$15 -> 0.0030271168 | G20: =_xlfn.XLOOKUP($E20,'rubros_id_opex (2)'!$B:$B,'rubros_id_opex (2)'!$A:$A) -> INSUMOS | H20: =SUMIFS('bbdd.5.final'!$Y:$Y,'bbdd.5.final'!$AA:$AA,Vista!E20,'bbdd.5.final'!$Z:$Z,$F$13,'bbdd.5.final'!$J:$J,"Opex") -> 113726.36 | I20: =I19+1 -> 5 | J20: =L20/$L$15 -> 0.0086918031 | K20: =_xlfn.XLOOKUP($I20,'rubros_id_opex (2)'!$B:$B,'rubros_id_opex (2)'!$A:$A) -> INSUMOS | L20: =SUMIFS('bbdd.5.final'!$Y:$Y,'bbdd.5.final'!$AA:$AA,Vista!I20,'bbdd.5.final'!$Z:$Z,$J$13,'bbdd.5.final'!$J:$J,"Opex") -> 204662.53 | M20: =M19+1 -> 5 | N20: =P20/$P$15 -> 0.47965492 | O20: =_xlfn.XLOOKUP($M20,'rubros_id_opex (2)'!$B:$B,'rubros_id_opex (2)'!$A:$A) -> INSUMOS | P20: =SUMIFS('bbdd.5.final'!$Y:$Y,'bbdd.5.final'!$AA:$AA,Vista!M20,'bbdd.5.final'!$Z:$Z,$N$13,'bbdd.5.final'!$J:$J,"Opex") -> 93350777
A21: =A20+1 -> 6 | B21: =D21/$D$15 -> 0 | C21: =_xlfn.XLOOKUP($A21,'rubros_id_opex (2)'!$B:$B,'rubros_id_opex (2)'!$A:$A) -> INVERSION | D21: =SUMIFS('bbdd.5.final'!$Y:$Y,'bbdd.5.final'!$AA:$AA,Vista!A21,'bbdd.5.final'!$Z:$Z,$B$13,'bbdd.5.final'!$J:$J,"Opex") -> 0 | E21: =E20+1 -> 6 | F21: =H21/$H$15 -> 0 | G21: =_xlfn.XLOOKUP($E21,'rubros_id_opex (2)'!$B:$B,'rubros_id_opex (2)'!$A:$A) -> INVERSION | H21: =SUMIFS('bbdd.5.final'!$Y:$Y,'bbdd.5.final'!$AA:$AA,Vista!E21,'bbdd.5.final'!$Z:$Z,$F$13,'bbdd.5.final'!$J:$J,"Opex") -> 0 | I21: =I20+1 -> 6 | J21: =L21/$L$15 -> 0 | K21: =_xlfn.XLOOKUP($I21,'rubros_id_opex (2)'!$B:$B,'rubros_id_opex (2)'!$A:$A) -> INVERSION | L21: =SUMIFS('bbdd.5.final'!$Y:$Y,'bbdd.5.final'!$AA:$AA,Vista!I21,'bbdd.5.final'!$Z:$Z,$J$13,'bbdd.5.final'!$J:$J,"Opex") -> 0 | M21: =M20+1 -> 6 | N21: =P21/$P$15 -> 0 | O21: =_xlfn.XLOOKUP($M21,'rubros_id_opex (2)'!$B:$B,'rubros_id_opex (2)'!$A:$A) -> INVERSION | P21: =SUMIFS('bbdd.5.final'!$Y:$Y,'bbdd.5.final'!$AA:$AA,Vista!M21,'bbdd.5.final'!$Z:$Z,$N$13,'bbdd.5.final'!$J:$J,"Opex") -> 0
A22: =A21+1 -> 7 | B22: =D22/$D$15 -> 0 | C22: =_xlfn.XLOOKUP($A22,'rubros_id_opex (2)'!$B:$B,'rubros_id_opex (2)'!$A:$A) -> LOGISTICA | D22: =SUMIFS('bbdd.5.final'!$Y:$Y,'bbdd.5.final'!$AA:$AA,Vista!A22,'bbdd.5.final'!$Z:$Z,$B$13,'bbdd.5.final'!$J:$J,"Opex") -> 0 | E22: =E21+1 -> 7 | F22: =H22/$H$15 -> 0 | G22: =_xlfn.XLOOKUP($E22,'rubros_id_opex (2)'!$B:$B,'rubros_id_opex (2)'!$A:$A) -> LOGISTICA | H22: =SUMIFS('bbdd.5.final'!$Y:$Y,'bbdd.5.final'!$AA:$AA,Vista!E22,'bbdd.5.final'!$Z:$Z,$F$13,'bbdd.5.final'!$J:$J,"Opex") -> 0 | I22: =I21+1 -> 7 | J22: =L22/$L$15 -> 0 | K22: =_xlfn.XLOOKUP($I22,'rubros_id_opex (2)'!$B:$B,'rubros_id_opex (2)'!$A:$A) -> LOGISTICA | L22: =SUMIFS('bbdd.5.final'!$Y:$Y,'bbdd.5.final'!$AA:$AA,Vista!I22,'bbdd.5.final'!$Z:$Z,$J$13,'bbdd.5.final'!$J:$J,"Opex") -> 0 | M22: =M21+1 -> 7 | N22: =P22/$P$15 -> 0.003873329 | O22: =_xlfn.XLOOKUP($M22,'rubros_id_opex (2)'!$B:$B,'rubros_id_opex (2)'!$A:$A) -> LOGISTICA | P22: =SUMIFS('bbdd.5.final'!$Y:$Y,'bbdd.5.final'!$AA:$AA,Vista!M22,'bbdd.5.final'!$Z:$Z,$N$13,'bbdd.5.final'!$J:$J,"Opex") -> 753830
A23: =A22+1 -> 8 | B23: =D23/$D$15 -> 0.096249174 | C23: =_xlfn.XLOOKUP($A23,'rubros_id_opex (2)'!$B:$B,'rubros_id_opex (2)'!$A:$A) -> M.PRIMAS | D23: =SUMIFS('bbdd.5.final'!$Y:$Y,'bbdd.5.final'!$AA:$AA,Vista!A23,'bbdd.5.final'!$Z:$Z,$B$13,'bbdd.5.final'!$J:$J,"Opex") -> 875072.92 | E23: =E22+1 -> 8 | F23: =H23/$H$15 -> 0 | G23: =_xlfn.XLOOKUP($E23,'rubros_id_opex (2)'!$B:$B,'rubros_id_opex (2)'!$A:$A) -> M.PRIMAS | H23: =SUMIFS('bbdd.5.final'!$Y:$Y,'bbdd.5.final'!$AA:$AA,Vista!E23,'bbdd.5.final'!$Z:$Z,$F$13,'bbdd.5.final'!$J:$J,"Opex") -> 0 | I23: =I22+1 -> 8 | J23: =L23/$L$15 -> 0 | K23: =_xlfn.XLOOKUP($I23,'rubros_id_opex (2)'!$B:$B,'rubros_id_opex (2)'!$A:$A) -> M.PRIMAS | L23: =SUMIFS('bbdd.5.final'!$Y:$Y,'bbdd.5.final'!$AA:$AA,Vista!I23,'bbdd.5.final'!$Z:$Z,$J$13,'bbdd.5.final'!$J:$J,"Opex") -> 0 | M23: =M22+1 -> 8 | N23: =P23/$P$15 -> 0.23278621 | O23: =_xlfn.XLOOKUP($M23,'rubros_id_opex (2)'!$B:$B,'rubros_id_opex (2)'!$A:$A) -> M.PRIMAS | P23: =SUMIFS('bbdd.5.final'!$Y:$Y,'bbdd.5.final'!$AA:$AA,Vista!M23,'bbdd.5.final'!$Z:$Z,$N$13,'bbdd.5.final'!$J:$J,"Opex") -> 45305016
A24: =A23+1 -> 9 | B24: =D24/$D$15 -> 0.00072738971 | C24: =_xlfn.XLOOKUP($A24,'rubros_id_opex (2)'!$B:$B,'rubros_id_opex (2)'!$A:$A) -> MANTENIMIENTO PREVENTIVO | D24: =SUMIFS('bbdd.5.final'!$Y:$Y,'bbdd.5.final'!$AA:$AA,Vista!A24,'bbdd.5.final'!$Z:$Z,$B$13,'bbdd.5.final'!$J:$J,"Opex") -> 6613.2415 | E24: =E23+1 -> 9 | F24: =H24/$H$15 -> 0.002159484 | G24: =_xlfn.XLOOKUP($E24,'rubros_id_opex (2)'!$B:$B,'rubros_id_opex (2)'!$A:$A) -> MANTENIMIENTO PREVENTIVO | H24: =SUMIFS('bbdd.5.final'!$Y:$Y,'bbdd.5.final'!$AA:$AA,Vista!E24,'bbdd.5.final'!$Z:$Z,$F$13,'bbdd.5.final'!$J:$J,"Opex") -> 81130.09 | I24: =I23+1 -> 9 | J24: =L24/$L$15 -> 0.006200557 | K24: =_xlfn.XLOOKUP($I24,'rubros_id_opex (2)'!$B:$B,'rubros_id_opex (2)'!$A:$A) -> MANTENIMIENTO PREVENTIVO | L24: =SUMIFS('bbdd.5.final'!$Y:$Y,'bbdd.5.final'!$AA:$AA,Vista!I24,'bbdd.5.final'!$Z:$Z,$J$13,'bbdd.5.final'!$J:$J,"Opex") -> 146002.12 | M24: =M23+1 -> 9 | N24: =P24/$P$15 -> 0.00027661649 | O24: =_xlfn.XLOOKUP($M24,'rubros_id_opex (2)'!$B:$B,'rubros_id_opex (2)'!$A:$A) -> MANTENIMIENTO PREVENTIVO | P24: =SUMIFS('bbdd.5.final'!$Y:$Y,'bbdd.5.final'!$AA:$AA,Vista!M24,'bbdd.5.final'!$Z:$Z,$N$13,'bbdd.5.final'!$J:$J,"Opex") -> 53835.296
A25: =A24+1 -> 10 | B25: =D25/$D$15 -> 0.87293138 | C25: =_xlfn.XLOOKUP($A25,'rubros_id_opex (2)'!$B:$B,'rubros_id_opex (2)'!$A:$A) -> PERSONAL | D25: =SUMIFS('bbdd.5.final'!$Y:$Y,'bbdd.5.final'!$AA:$AA,Vista!A25,'bbdd.5.final'!$Z:$Z,$B$13,'bbdd.5.final'!$J:$J,"Opex") -> 7936469.3 | E25: =E24+1 -> 10 | F25: =H25/$H$15 -> 0.28405587 | G25: =_xlfn.XLOOKUP($E25,'rubros_id_opex (2)'!$B:$B,'rubros_id_opex (2)'!$A:$A) -> PERSONAL | H25: =SUMIFS('bbdd.5.final'!$Y:$Y,'bbdd.5.final'!$AA:$AA,Vista!E25,'bbdd.5.final'!$Z:$Z,$F$13,'bbdd.5.final'!$J:$J,"Opex") -> 10671752 | I25: =I24+1 -> 10 | J25: =L25/$L$15 -> 0.56134057 | K25: =_xlfn.XLOOKUP($I25,'rubros_id_opex (2)'!$B:$B,'rubros_id_opex (2)'!$A:$A) -> PERSONAL | L25: =SUMIFS('bbdd.5.final'!$Y:$Y,'bbdd.5.final'!$AA:$AA,Vista!I25,'bbdd.5.final'!$Z:$Z,$J$13,'bbdd.5.final'!$J:$J,"Opex") -> 13217670 | M25: =M24+1 -> 10 | N25: =P25/$P$15 -> 0.075384612 | O25: =_xlfn.XLOOKUP($M25,'rubros_id_opex (2)'!$B:$B,'rubros_id_opex (2)'!$A:$A) -> PERSONAL | P25: =SUMIFS('bbdd.5.final'!$Y:$Y,'bbdd.5.final'!$AA:$AA,Vista!M25,'bbdd.5.final'!$Z:$Z,$N$13,'bbdd.5.final'!$J:$J,"Opex") -> 14671406
A26: =A25+1 -> 11 | B26: =D26/$D$15 -> 0.0035443052 | C26: =_xlfn.XLOOKUP($A26,'rubros_id_opex (2)'!$B:$B,'rubros_id_opex (2)'!$A:$A) -> REPARACIONES | D26: =SUMIFS('bbdd.5.final'!$Y:$Y,'bbdd.5.final'!$AA:$AA,Vista!A26,'bbdd.5.final'!$Z:$Z,$B$13,'bbdd.5.final'!$J:$J,"Opex") -> 32223.918 | E26: =E25+1 -> 11 | F26: =H26/$H$15 -> 0.01052238 | G26: =_xlfn.XLOOKUP($E26,'rubros_id_opex (2)'!$B:$B,'rubros_id_opex (2)'!$A:$A) -> REPARACIONES | H26: =SUMIFS('bbdd.5.final'!$Y:$Y,'bbdd.5.final'!$AA:$AA,Vista!E26,'bbdd.5.final'!$Z:$Z,$F$13,'bbdd.5.final'!$J:$J,"Opex") -> 395317.39 | I26: =I25+1 -> 11 | J26: =L26/$L$15 -> 0.030213057 | K26: =_xlfn.XLOOKUP($I26,'rubros_id_opex (2)'!$B:$B,'rubros_id_opex (2)'!$A:$A) -> REPARACIONES | L26: =SUMIFS('bbdd.5.final'!$Y:$Y,'bbdd.5.final'!$AA:$AA,Vista!I26,'bbdd.5.final'!$Z:$Z,$J$13,'bbdd.5.final'!$J:$J,"Opex") -> 711415.19 | M26: =M25+1 -> 11 | N26: =P26/$P$15 -> 0.0021699634 | O26: =_xlfn.XLOOKUP($M26,'rubros_id_opex (2)'!$B:$B,'rubros_id_opex (2)'!$A:$A) -> REPARACIONES | P26: =SUMIFS('bbdd.5.final'!$Y:$Y,'bbdd.5.final'!$AA:$AA,Vista!M26,'bbdd.5.final'!$Z:$Z,$N$13,'bbdd.5.final'!$J:$J,"Opex") -> 422319.8
A27: =A26+1 -> 12 | B27: =D27/$D$15 -> 0.00073784449 | C27: =_xlfn.XLOOKUP($A27,'rubros_id_opex (2)'!$B:$B,'rubros_id_opex (2)'!$A:$A) -> REPOSICION | D27: =SUMIFS('bbdd.5.final'!$Y:$Y,'bbdd.5.final'!$AA:$AA,Vista!A27,'bbdd.5.final'!$Z:$Z,$B$13,'bbdd.5.final'!$J:$J,"Opex") -> 6708.2937 | E27: =E26+1 -> 12 | F27: =H27/$H$15 -> 0.0021905223 | G27: =_xlfn.XLOOKUP($E27,'rubros_id_opex (2)'!$B:$B,'rubros_id_opex (2)'!$A:$A) -> REPOSICION | H27: =SUMIFS('bbdd.5.final'!$Y:$Y,'bbdd.5.final'!$AA:$AA,Vista!E27,'bbdd.5.final'!$Z:$Z,$F$13,'bbdd.5.final'!$J:$J,"Opex") -> 82296.174 | I27: =I26+1 -> 12 | J27: =L27/$L$15 -> 0.0094914743 | K27: =_xlfn.XLOOKUP($I27,'rubros_id_opex (2)'!$B:$B,'rubros_id_opex (2)'!$A:$A) -> REPOSICION | L27: =SUMIFS('bbdd.5.final'!$Y:$Y,'bbdd.5.final'!$AA:$AA,Vista!I27,'bbdd.5.final'!$Z:$Z,$J$13,'bbdd.5.final'!$J:$J,"Opex") -> 223492.08 | M27: =M26+1 -> 12 | N27: =P27/$P$15 -> 0.0074776906 | O27: =_xlfn.XLOOKUP($M27,'rubros_id_opex (2)'!$B:$B,'rubros_id_opex (2)'!$A:$A) -> REPOSICION | P27: =SUMIFS('bbdd.5.final'!$Y:$Y,'bbdd.5.final'!$AA:$AA,Vista!M27,'bbdd.5.final'!$Z:$Z,$N$13,'bbdd.5.final'!$J:$J,"Opex") -> 1455313.4
A28: =A27+1 -> 13 | B28: =D28/$D$15 -> 0.013425965 | C28: =_xlfn.XLOOKUP($A28,'rubros_id_opex (2)'!$B:$B,'rubros_id_opex (2)'!$A:$A) -> SERVICIOS | D28: =SUMIFS('bbdd.5.final'!$Y:$Y,'bbdd.5.final'!$AA:$AA,Vista!A28,'bbdd.5.final'!$Z:$Z,$B$13,'bbdd.5.final'!$J:$J,"Opex") -> 122065.45 | E28: =E27+1 -> 13 | F28: =H28/$H$15 -> 0.58673799 | G28: =_xlfn.XLOOKUP($E28,'rubros_id_opex (2)'!$B:$B,'rubros_id_opex (2)'!$A:$A) -> SERVICIOS | H28: =SUMIFS('bbdd.5.final'!$Y:$Y,'bbdd.5.final'!$AA:$AA,Vista!E28,'bbdd.5.final'!$Z:$Z,$F$13,'bbdd.5.final'!$J:$J,"Opex") -> 22043278 | I28: =I27+1 -> 13 | J28: =L28/$L$15 -> 0.11444823 | K28: =_xlfn.XLOOKUP($I28,'rubros_id_opex (2)'!$B:$B,'rubros_id_opex (2)'!$A:$A) -> SERVICIOS | L28: =SUMIFS('bbdd.5.final'!$Y:$Y,'bbdd.5.final'!$AA:$AA,Vista!I28,'bbdd.5.final'!$Z:$Z,$J$13,'bbdd.5.final'!$J:$J,"Opex") -> 2694868.3 | M28: =M27+1 -> 13 | N28: =P28/$P$15 -> 0.0051057135 | O28: =_xlfn.XLOOKUP($M28,'rubros_id_opex (2)'!$B:$B,'rubros_id_opex (2)'!$A:$A) -> SERVICIOS | P28: =SUMIFS('bbdd.5.final'!$Y:$Y,'bbdd.5.final'!$AA:$AA,Vista!M28,'bbdd.5.final'!$Z:$Z,$N$13,'bbdd.5.final'!$J:$J,"Opex") -> 993677.54
A29: =A28+1 -> 14 | B29: =D29/$D$15 -> 0.00026256713 | C29: =_xlfn.XLOOKUP($A29,'rubros_id_opex (2)'!$B:$B,'rubros_id_opex (2)'!$A:$A) -> COMERCIAL | D29: =SUMIFS('bbdd.5.final'!$Y:$Y,'bbdd.5.final'!$AA:$AA,Vista!A29,'bbdd.5.final'!$Z:$Z,$B$13,'bbdd.5.final'!$J:$J,"Opex") -> 2387.1933 | E29: =E28+1 -> 14 | F29: =H29/$H$15 -> 0.00077951271 | G29: =_xlfn.XLOOKUP($E29,'rubros_id_opex (2)'!$B:$B,'rubros_id_opex (2)'!$A:$A) -> COMERCIAL | H29: =SUMIFS('bbdd.5.final'!$Y:$Y,'bbdd.5.final'!$AA:$AA,Vista!E29,'bbdd.5.final'!$Z:$Z,$F$13,'bbdd.5.final'!$J:$J,"Opex") -> 29285.67 | I29: =I28+1 -> 14 | J29: =L29/$L$15 -> 0.0022382258 | K29: =_xlfn.XLOOKUP($I29,'rubros_id_opex (2)'!$B:$B,'rubros_id_opex (2)'!$A:$A) -> COMERCIAL | L29: =SUMIFS('bbdd.5.final'!$Y:$Y,'bbdd.5.final'!$AA:$AA,Vista!I29,'bbdd.5.final'!$Z:$Z,$J$13,'bbdd.5.final'!$J:$J,"Opex") -> 52702.64 | M29: =M28+1 -> 14 | N29: =P29/$P$15 -> 9.9850737e-05 | O29: =_xlfn.XLOOKUP($M29,'rubros_id_opex (2)'!$B:$B,'rubros_id_opex (2)'!$A:$A) -> COMERCIAL | P29: =SUMIFS('bbdd.5.final'!$Y:$Y,'bbdd.5.final'!$AA:$AA,Vista!M29,'bbdd.5.final'!$Z:$Z,$N$13,'bbdd.5.final'!$J:$J,"Opex") -> 19433.02
B31: VENTAS | D31: =SUMIFS(BBDD_INGRESOS_FINAL!$O:$O,BBDD_INGRESOS_FINAL!$D:$D,B14) -> 5365216.3 | F31: VENTAS | H31: =SUMIFS(BBDD_INGRESOS_FINAL!$O:$O,BBDD_INGRESOS_FINAL!$D:$D,F14) -> 1.712503e+08 | J31: VENTAS | L31: =SUMIFS(BBDD_INGRESOS_FINAL!$O:$O,BBDD_INGRESOS_FINAL!$D:$D,J14) -> 253547470 | N31: VENTAS | P31: =SUMIFS(BBDD_INGRESOS_FINAL!$O:$O,BBDD_INGRESOS_FINAL!$D:$D,N14) -> 2.1218758e+08
B33: UTILDAD | D33: =D31-D15 -> -3726528.4 | F33: UTILDAD | H33: =H31-H15 -> 1.336811e+08 | J33: UTILDAD | L33: =L31-L15 -> 2.3000086e+08 | N33: UTILDAD | P33: =P31-P15 -> 17566880
B35: CAPEX | D35: =SUMIFS('bbdd.5.final'!$Y:$Y,'bbdd.5.final'!$J:$J,"Capex",'bbdd.5.final'!$Z:$Z,$B$13) -> 10596.047 | F35: CAPEX | H35: =SUMIFS('bbdd.5.final'!$Y:$Y,'bbdd.5.final'!$J:$J,"Capex",'bbdd.5.final'!$Z:$Z,$F$13) -> 1.8221133e+08 | J35: CAPEX | L35: =SUMIFS('bbdd.5.final'!$Y:$Y,'bbdd.5.final'!$J:$J,"Capex",'bbdd.5.final'!$Z:$Z,$J$13) -> 314945.75 | N35: CAPEX | P35: =SUMIFS('bbdd.5.final'!$Y:$Y,'bbdd.5.final'!$J:$J,"Capex",'bbdd.5.final'!$Z:$Z,$N$13) -> 13258557
B37: DEUDA | D37: =SUMIFS('bbdd.5.final'!$Y:$Y,'bbdd.5.final'!$J:$J,"Deuda",'bbdd.5.final'!$V:$V,B14) -> 0 | F37: DEUDA | H37: =SUMIFS('bbdd.5.final'!$Y:$Y,'bbdd.5.final'!$J:$J,"Deuda",'bbdd.5.final'!$V:$V,F14) -> 0 | J37: DEUDA | L37: =SUMIFS('bbdd.5.final'!$Y:$Y,'bbdd.5.final'!$J:$J,"deuda",'bbdd.5.final'!$V:$V,J14) -> 0 | N37: DEUDA | P37: =SUMIFS('bbdd.5.final'!$Y:$Y,'bbdd.5.final'!$J:$J,"deuda",'bbdd.5.final'!$V:$V,N14) -> 0
B39: Flujo de Caja al Accionista | D39: =D33-D37-D35 -> -3737124.5 | F39: Flujo de Caja al Accionista | H39: =H33-H37-H35 -> -48530232 | J39: Flujo de Caja al Accionista | L39: =L33-L37-L35 -> 2.2968591e+08 | N39: Flujo de Caja al Accionista | P39: =P33-P37-P35 -> 4308322.7
A41: id | B41: 1 | E41: id | F41: 6 | I41: id | J41: 10 | M41: id | N41: 2
B42: BACHAS | F42: NFU | J42: COMPOST & FERTILIZANTES | N42: CEREAL & POLVILLO
B43: OPEX | D43: =SUM(D44:D57) -> 1.0830115e+08 | F43: OPEX | H43: =SUM(H44:H57) -> 31513345 | J43: OPEX | L43: =SUM(L44:L57) -> 5032274.4 | N43: OPEX | P43: =SUM(P44:P57) -> 5360775.9
A44: 1 | B44: =D44/$D$43 -> 0.057430276 | C44: =_xlfn.XLOOKUP($A44,'rubros_id_opex (2)'!$B:$B,'rubros_id_opex (2)'!$A:$A) -> ENERGIA | D44: =SUMIFS('bbdd.5.final'!$Y:$Y,'bbdd.5.final'!$AA:$AA,Vista!A44,'bbdd.5.final'!$Z:$Z,$B$41,'bbdd.5.final'!$J:$J,"Opex") -> 6219764.7 | E44: 1 | F44: =H44/$H$43 -> 0.45344772 | G44: =_xlfn.XLOOKUP($A44,'rubros_id_opex (2)'!$B:$B,'rubros_id_opex (2)'!$A:$A) -> ENERGIA | H44: =SUMIFS('bbdd.5.final'!$Y:$Y,'bbdd.5.final'!$AA:$AA,Vista!E44,'bbdd.5.final'!$Z:$Z,$F$41,'bbdd.5.final'!$J:$J,"Opex") -> 14289655 | I44: 1 | J44: =L44/$L$43 -> 0.0011912217 | K44: =_xlfn.XLOOKUP($A44,'rubros_id_opex (2)'!$B:$B,'rubros_id_opex (2)'!$A:$A) -> ENERGIA | L44: =SUMIFS('bbdd.5.final'!$Y:$Y,'bbdd.5.final'!$AA:$AA,Vista!I44,'bbdd.5.final'!$Z:$Z,$J$41,'bbdd.5.final'!$J:$J,"Opex") -> 5994.5544 | M44: 1 | N44: =P44/$P$43 -> 0.018836213 | O44: =_xlfn.XLOOKUP($A44,'rubros_id_opex (2)'!$B:$B,'rubros_id_opex (2)'!$A:$A) -> ENERGIA | P44: =SUMIFS('bbdd.5.final'!$Y:$Y,'bbdd.5.final'!$AA:$AA,Vista!M44,'bbdd.5.final'!$Z:$Z,$N$41,'bbdd.5.final'!$J:$J,"Opex") -> 100976.72
A45: =A44+1 -> 2 | B45: =D45/$D$43 -> 0.00043252458 | C45: =_xlfn.XLOOKUP($A45,'rubros_id_opex (2)'!$B:$B,'rubros_id_opex (2)'!$A:$A) -> HABILITACIONES Y CERT | D45: =SUMIFS('bbdd.5.final'!$Y:$Y,'bbdd.5.final'!$AA:$AA,Vista!A45,'bbdd.5.final'!$Z:$Z,$B$41,'bbdd.5.final'!$J:$J,"Opex") -> 46842.907 | E45: =E44+1 -> 2 | F45: =H45/$H$43 -> 0.00064494846 | G45: =_xlfn.XLOOKUP($A45,'rubros_id_opex (2)'!$B:$B,'rubros_id_opex (2)'!$A:$A) -> HABILITACIONES Y CERT | H45: =SUMIFS('bbdd.5.final'!$Y:$Y,'bbdd.5.final'!$AA:$AA,Vista!E45,'bbdd.5.final'!$Z:$Z,$F$41,'bbdd.5.final'!$J:$J,"Opex") -> 20324.484 | I45: =I44+1 -> 2 | J45: =L45/$L$43 -> 0.00011673438 | K45: =_xlfn.XLOOKUP($A45,'rubros_id_opex (2)'!$B:$B,'rubros_id_opex (2)'!$A:$A) -> HABILITACIONES Y CERT | L45: =SUMIFS('bbdd.5.final'!$Y:$Y,'bbdd.5.final'!$AA:$AA,Vista!I45,'bbdd.5.final'!$Z:$Z,$J$41,'bbdd.5.final'!$J:$J,"Opex") -> 587.43945 | M45: =M44+1 -> 2 | N45: =P45/$P$43 -> 0.0019029499 | O45: =_xlfn.XLOOKUP($A45,'rubros_id_opex (2)'!$B:$B,'rubros_id_opex (2)'!$A:$A) -> HABILITACIONES Y CERT | P45: =SUMIFS('bbdd.5.final'!$Y:$Y,'bbdd.5.final'!$AA:$AA,Vista!M45,'bbdd.5.final'!$Z:$Z,$N$41,'bbdd.5.final'!$J:$J,"Opex") -> 10201.288
A46: =A45+1 -> 3 | B46: =D46/$D$43 -> 0.00072021632 | C46: =_xlfn.XLOOKUP($A46,'rubros_id_opex (2)'!$B:$B,'rubros_id_opex (2)'!$A:$A) -> HIGIENE Y SEGURIDAD | D46: =SUMIFS('bbdd.5.final'!$Y:$Y,'bbdd.5.final'!$AA:$AA,Vista!A46,'bbdd.5.final'!$Z:$Z,$B$41,'bbdd.5.final'!$J:$J,"Opex") -> 78000.253 | E46: =E45+1 -> 3 | F46: =H46/$H$43 -> 0.001073933 | G46: =_xlfn.XLOOKUP($A46,'rubros_id_opex (2)'!$B:$B,'rubros_id_opex (2)'!$A:$A) -> HIGIENE Y SEGURIDAD | H46: =SUMIFS('bbdd.5.final'!$Y:$Y,'bbdd.5.final'!$AA:$AA,Vista!E46,'bbdd.5.final'!$Z:$Z,$F$41,'bbdd.5.final'!$J:$J,"Opex") -> 33843.221 | I46: =I45+1 -> 3 | J46: =L46/$L$43 -> 0.00019437973 | K46: =_xlfn.XLOOKUP($A46,'rubros_id_opex (2)'!$B:$B,'rubros_id_opex (2)'!$A:$A) -> HIGIENE Y SEGURIDAD | L46: =SUMIFS('bbdd.5.final'!$Y:$Y,'bbdd.5.final'!$AA:$AA,Vista!I46,'bbdd.5.final'!$Z:$Z,$J$41,'bbdd.5.final'!$J:$J,"Opex") -> 978.17212 | M46: =M45+1 -> 3 | N46: =P46/$P$43 -> 0.0031686884 | O46: =_xlfn.XLOOKUP($A46,'rubros_id_opex (2)'!$B:$B,'rubros_id_opex (2)'!$A:$A) -> HIGIENE Y SEGURIDAD | P46: =SUMIFS('bbdd.5.final'!$Y:$Y,'bbdd.5.final'!$AA:$AA,Vista!M46,'bbdd.5.final'!$Z:$Z,$N$41,'bbdd.5.final'!$J:$J,"Opex") -> 16986.628
A47: =A46+1 -> 4 | B47: =D47/$D$43 -> 0.0015403386 | C47: =_xlfn.XLOOKUP($A47,'rubros_id_opex (2)'!$B:$B,'rubros_id_opex (2)'!$A:$A) -> IMPUESTOS | D47: =SUMIFS('bbdd.5.final'!$Y:$Y,'bbdd.5.final'!$AA:$AA,Vista!A47,'bbdd.5.final'!$Z:$Z,$B$41,'bbdd.5.final'!$J:$J,"Opex") -> 166820.44 | E47: =E46+1 -> 4 | F47: =H47/$H$43 -> 0.029369377 | G47: =_xlfn.XLOOKUP($A47,'rubros_id_opex (2)'!$B:$B,'rubros_id_opex (2)'!$A:$A) -> IMPUESTOS | H47: =SUMIFS('bbdd.5.final'!$Y:$Y,'bbdd.5.final'!$AA:$AA,Vista!E47,'bbdd.5.final'!$Z:$Z,$F$41,'bbdd.5.final'!$J:$J,"Opex") -> 925527.33 | I47: =I46+1 -> 4 | J47: =L47/$L$43 -> 0.033488186 | K47: =_xlfn.XLOOKUP($A47,'rubros_id_opex (2)'!$B:$B,'rubros_id_opex (2)'!$A:$A) -> IMPUESTOS | L47: =SUMIFS('bbdd.5.final'!$Y:$Y,'bbdd.5.final'!$AA:$AA,Vista!I47,'bbdd.5.final'!$Z:$Z,$J$41,'bbdd.5.final'!$J:$J,"Opex") -> 168521.74 | M47: =M46+1 -> 4 | N47: =P47/$P$43 -> 0.0067769265 | O47: =_xlfn.XLOOKUP($A47,'rubros_id_opex (2)'!$B:$B,'rubros_id_opex (2)'!$A:$A) -> IMPUESTOS | P47: =SUMIFS('bbdd.5.final'!$Y:$Y,'bbdd.5.final'!$AA:$AA,Vista!M47,'bbdd.5.final'!$Z:$Z,$N$41,'bbdd.5.final'!$J:$J,"Opex") -> 36329.584
A48: =A47+1 -> 5 | B48: =D48/$D$43 -> 0.044643114 | C48: =_xlfn.XLOOKUP($A48,'rubros_id_opex (2)'!$B:$B,'rubros_id_opex (2)'!$A:$A) -> INSUMOS | D48: =SUMIFS('bbdd.5.final'!$Y:$Y,'bbdd.5.final'!$AA:$AA,Vista!A48,'bbdd.5.final'!$Z:$Z,$B$41,'bbdd.5.final'!$J:$J,"Opex") -> 4834900.4 | E48: =E47+1 -> 5 | F48: =H48/$H$43 -> 0.0008489496 | G48: =_xlfn.XLOOKUP($A48,'rubros_id_opex (2)'!$B:$B,'rubros_id_opex (2)'!$A:$A) -> INSUMOS | H48: =SUMIFS('bbdd.5.final'!$Y:$Y,'bbdd.5.final'!$AA:$AA,Vista!E48,'bbdd.5.final'!$Z:$Z,$F$41,'bbdd.5.final'!$J:$J,"Opex") -> 26753.242 | I48: =I47+1 -> 5 | J48: =L48/$L$43 -> 0.00015365818 | K48: =_xlfn.XLOOKUP($A48,'rubros_id_opex (2)'!$B:$B,'rubros_id_opex (2)'!$A:$A) -> INSUMOS | L48: =SUMIFS('bbdd.5.final'!$Y:$Y,'bbdd.5.final'!$AA:$AA,Vista!I48,'bbdd.5.final'!$Z:$Z,$J$41,'bbdd.5.final'!$J:$J,"Opex") -> 773.25014 | M48: =M47+1 -> 5 | N48: =P48/$P$43 -> 0.0025048646 | O48: =_xlfn.XLOOKUP($A48,'rubros_id_opex (2)'!$B:$B,'rubros_id_opex (2)'!$A:$A) -> INSUMOS | P48: =SUMIFS('bbdd.5.final'!$Y:$Y,'bbdd.5.final'!$AA:$AA,Vista!M48,'bbdd.5.final'!$Z:$Z,$N$41,'bbdd.5.final'!$J:$J,"Opex") -> 13428.018
A49: =A48+1 -> 6 | B49: =D49/$D$43 -> 0 | C49: =_xlfn.XLOOKUP($A49,'rubros_id_opex (2)'!$B:$B,'rubros_id_opex (2)'!$A:$A) -> INVERSION | D49: =SUMIFS('bbdd.5.final'!$Y:$Y,'bbdd.5.final'!$AA:$AA,Vista!A49,'bbdd.5.final'!$Z:$Z,$B$41,'bbdd.5.final'!$J:$J,"Opex") -> 0 | E49: =E48+1 -> 6 | F49: =H49/$H$43 -> 0 | G49: =_xlfn.XLOOKUP($A49,'rubros_id_opex (2)'!$B:$B,'rubros_id_opex (2)'!$A:$A) -> INVERSION | H49: =SUMIFS('bbdd.5.final'!$Y:$Y,'bbdd.5.final'!$AA:$AA,Vista!E49,'bbdd.5.final'!$Z:$Z,$F$41,'bbdd.5.final'!$J:$J,"Opex") -> 0 | I49: =I48+1 -> 6 | J49: =L49/$L$43 -> 0 | K49: =_xlfn.XLOOKUP($A49,'rubros_id_opex (2)'!$B:$B,'rubros_id_opex (2)'!$A:$A) -> INVERSION | L49: =SUMIFS('bbdd.5.final'!$Y:$Y,'bbdd.5.final'!$AA:$AA,Vista!I49,'bbdd.5.final'!$Z:$Z,$J$41,'bbdd.5.final'!$J:$J,"Opex") -> 0 | M49: =M48+1 -> 6 | N49: =P49/$P$43 -> 0 | O49: =_xlfn.XLOOKUP($A49,'rubros_id_opex (2)'!$B:$B,'rubros_id_opex (2)'!$A:$A) -> INVERSION | P49: =SUMIFS('bbdd.5.final'!$Y:$Y,'bbdd.5.final'!$AA:$AA,Vista!M49,'bbdd.5.final'!$Z:$Z,$N$41,'bbdd.5.final'!$J:$J,"Opex") -> 0
A50: =A49+1 -> 7 | B50: =D50/$D$43 -> 0 | C50: =_xlfn.XLOOKUP($A50,'rubros_id_opex (2)'!$B:$B,'rubros_id_opex (2)'!$A:$A) -> LOGISTICA | D50: =SUMIFS('bbdd.5.final'!$Y:$Y,'bbdd.5.final'!$AA:$AA,Vista!A50,'bbdd.5.final'!$Z:$Z,$B$41,'bbdd.5.final'!$J:$J,"Opex") -> 0 | E50: =E49+1 -> 7 | F50: =H50/$H$43 -> 9.2151435e-05 | G50: =_xlfn.XLOOKUP($A50,'rubros_id_opex (2)'!$B:$B,'rubros_id_opex (2)'!$A:$A) -> LOGISTICA | H50: =SUMIFS('bbdd.5.final'!$Y:$Y,'bbdd.5.final'!$AA:$AA,Vista!E50,'bbdd.5.final'!$Z:$Z,$F$41,'bbdd.5.final'!$J:$J,"Opex") -> 2904 | I50: =I49+1 -> 7 | J50: =L50/$L$43 -> 0 | K50: =_xlfn.XLOOKUP($A50,'rubros_id_opex (2)'!$B:$B,'rubros_id_opex (2)'!$A:$A) -> LOGISTICA | L50: =SUMIFS('bbdd.5.final'!$Y:$Y,'bbdd.5.final'!$AA:$AA,Vista!I50,'bbdd.5.final'!$Z:$Z,$J$41,'bbdd.5.final'!$J:$J,"Opex") -> 0 | M50: =M49+1 -> 7 | N50: =P50/$P$43 -> 0.077973788 | O50: =_xlfn.XLOOKUP($A50,'rubros_id_opex (2)'!$B:$B,'rubros_id_opex (2)'!$A:$A) -> LOGISTICA | P50: =SUMIFS('bbdd.5.final'!$Y:$Y,'bbdd.5.final'!$AA:$AA,Vista!M50,'bbdd.5.final'!$Z:$Z,$N$41,'bbdd.5.final'!$J:$J,"Opex") -> 418000
...

Sheet val1
A1: VENTAS
A2: CEREAL & POLVILLO | B2: =Vista!P59 -> 25207646
A3: DISPOSICIÓN FINAL RESIDUOS SOLIDOS | B3: =Vista!D31 -> 5365216.3 | E3: Row Labels | F3: Sum of TOTAL
A4: DISPOSICIÓN FINAL RESIDUOS LIQUIDOS | B4: =Vista!$H$31 -> 1.712503e+08 | E4: BACHAS | F4: 1.151894e+08
A5: =Vista!J14 -> PILETAS | B5: =Vista!$L$31 -> 253547470 | E5: CEREAL & POLVILLO | F5: 25207646
A6: =Vista!N14 -> REACTORES | B6: =Vista!$P$31 -> 2.1218758e+08 | E6: DISPOSICIÓN FINAL RESIDUOS LIQUIDOS | F6: 1.712503e+08
A7: =Vista!B42 -> BACHAS | B7: =Vista!D59 -> 1.151894e+08 | E7: DISPOSICIÓN FINAL RESIDUOS SOLIDOS | F7: 5365216.3
A8: =Vista!F42 -> NFU | B8: =Vista!H59 -> 36666425 | E8: EXPORTACION | F8: 2.633974e+09
A9: =Vista!J42 -> COMPOST & FERTILIZANTES | B9: =Vista!L59 -> 0 | E9: NFU | F9: 36666425
A10: =Vista!#REF! -> #REF! | B10: =Vista!#REF! -> #REF! | E10: PILETAS | F10: 253547470
A11: =Vista!B70 -> EXPORTACION | B11: =Vista!D88 -> 2.633974e+09 | E11: REACTORES | F11: 2.1218758e+08
A12: SALES | B12: =GETPIVOTDATA("TOTAL",$E$3,"SECTOR","SALES") -> #REF! | E12: (blank)
A13: SUB-TOTAL | B13: =SUM(B2:B12) -> #REF! | E13: Grand Total | F13: 3.453388e+09
A15: TOTAL | B15: =GETPIVOTDATA("TOTAL",$E$3) -> 3.453388e+09
B18: =B15=B13 -> #REF!

Sheet Vista_R_sin_expo
B2: SIN EXPORTACIÓN
B3: TOTAL
B4: OPEX | D4: =SUM(D5:D18) -> 4.150885e+08
A5: 1 | B5: =D5/$D$4 -> 0.15890069 | C5: =_xlfn.XLOOKUP($A5,'rubros_id_opex (2)'!$B:$B,'rubros_id_opex (2)'!$A:$A) -> ENERGIA | D5: =SUMIFS('bbdd.5.final'!$Y:$Y,'bbdd.5.final'!$AA:$AA,A5,'bbdd.5.final'!$J:$J,"Opex",'bbdd.5.final'!$Z:$Z,"<>5") -> 65957848
A6: =A5+1 -> 2 | B6: =D6/$D$4 -> 0.00092561066 | C6: =_xlfn.XLOOKUP($A6,'rubros_id_opex (2)'!$B:$B,'rubros_id_opex (2)'!$A:$A) -> HABILITACIONES Y CERT | D6: =SUMIFS('bbdd.5.final'!$Y:$Y,'bbdd.5.final'!$AA:$AA,A6,'bbdd.5.final'!$J:$J,"Opex",'bbdd.5.final'!$Z:$Z,"<>5") -> 384210.34
A7: =A6+1 -> 3 | B7: =D7/$D$4 -> 0.0015412764 | C7: =_xlfn.XLOOKUP($A7,'rubros_id_opex (2)'!$B:$B,'rubros_id_opex (2)'!$A:$A) -> HIGIENE Y SEGURIDAD | D7: =SUMIFS('bbdd.5.final'!$Y:$Y,'bbdd.5.final'!$AA:$AA,A7,'bbdd.5.final'!$J:$J,"Opex",'bbdd.5.final'!$Z:$Z,"<>5") -> 639766.1
A8: =A7+1 -> 4 | B8: =D8/$D$4 -> 0.0080379865 | C8: =_xlfn.XLOOKUP($A8,'rubros_id_opex (2)'!$B:$B,'rubros_id_opex (2)'!$A:$A) -> IMPUESTOS | D8: =SUMIFS('bbdd.5.final'!$Y:$Y,'bbdd.5.final'!$AA:$AA,A8,'bbdd.5.final'!$J:$J,"Opex",'bbdd.5.final'!$Z:$Z,"<>5") -> 3336475.8
A9: =A8+1 -> 5 | B9: =D9/$D$4 -> 0.23742958 | C9: =_xlfn.XLOOKUP($A9,'rubros_id_opex (2)'!$B:$B,'rubros_id_opex (2)'!$A:$A) -> INSUMOS | D9: =SUMIFS('bbdd.5.final'!$Y:$Y,'bbdd.5.final'!$AA:$AA,A9,'bbdd.5.final'!$J:$J,"Opex",'bbdd.5.final'!$Z:$Z,"<>5") -> 98554291
A10: =A9+1 -> 6 | B10: =D10/$D$4 -> 0 | C10: =_xlfn.XLOOKUP($A10,'rubros_id_opex (2)'!$B:$B,'rubros_id_opex (2)'!$A:$A) -> INVERSION | D10: =SUMIFS('bbdd.5.final'!$Y:$Y,'bbdd.5.final'!$AA:$AA,A10,'bbdd.5.final'!$J:$J,"Opex",'bbdd.5.final'!$Z:$Z,"<>5") -> 0
A11: =A10+1 -> 7 | B11: =D11/$D$4 -> 0.0028300808 | C11: =_xlfn.XLOOKUP($A11,'rubros_id_opex (2)'!$B:$B,'rubros_id_opex (2)'!$A:$A) -> LOGISTICA | D11: =SUMIFS('bbdd.5.final'!$Y:$Y,'bbdd.5.final'!$AA:$AA,A11,'bbdd.5.final'!$J:$J,"Opex",'bbdd.5.final'!$Z:$Z,"<>5") -> 1174734
A12: =A11+1 -> 8 | B12: =D12/$D$4 -> 0.32214452 | C12: =_xlfn.XLOOKUP($A12,'rubros_id_opex (2)'!$B:$B,'rubros_id_opex (2)'!$A:$A) -> M.PRIMAS | D12: =SUMIFS('bbdd.5.final'!$Y:$Y,'bbdd.5.final'!$AA:$AA,A12,'bbdd.5.final'!$J:$J,"Opex",'bbdd.5.final'!$Z:$Z,"<>5") -> 1.3371849e+08
A13: =A12+1 -> 9 | B13: =D13/$D$4 -> 0.0014218145 | C13: =_xlfn.XLOOKUP($A13,'rubros_id_opex (2)'!$B:$B,'rubros_id_opex (2)'!$A:$A) -> MANTENIMIENTO PREVENTIVO | D13: =SUMIFS('bbdd.5.final'!$Y:$Y,'bbdd.5.final'!$AA:$AA,A13,'bbdd.5.final'!$J:$J,"Opex",'bbdd.5.final'!$Z:$Z,"<>5") -> 590178.87
A14: =A13+1 -> 10 | B14: =D14/$D$4 -> 0.18566161 | C14: =_xlfn.XLOOKUP($A14,'rubros_id_opex (2)'!$B:$B,'rubros_id_opex (2)'!$A:$A) -> PERSONAL | D14: =SUMIFS('bbdd.5.final'!$Y:$Y,'bbdd.5.final'!$AA:$AA,A14,'bbdd.5.final'!$J:$J,"Opex",'bbdd.5.final'!$Z:$Z,"<>5") -> 77065999
A15: =A14+1 -> 11 | B15: =D15/$D$4 -> 0.004620622 | C15: =_xlfn.XLOOKUP($A15,'rubros_id_opex (2)'!$B:$B,'rubros_id_opex (2)'!$A:$A) -> REPARACIONES | D15: =SUMIFS('bbdd.5.final'!$Y:$Y,'bbdd.5.final'!$AA:$AA,A15,'bbdd.5.final'!$J:$J,"Opex",'bbdd.5.final'!$Z:$Z,"<>5") -> 1917967.1
A16: =A15+1 -> 12 | B16: =D16/$D$4 -> 0.0045105285 | C16: =_xlfn.XLOOKUP($A16,'rubros_id_opex (2)'!$B:$B,'rubros_id_opex (2)'!$A:$A) -> REPOSICION | D16: =SUMIFS('bbdd.5.final'!$Y:$Y,'bbdd.5.final'!$AA:$AA,A16,'bbdd.5.final'!$J:$J,"Opex",'bbdd.5.final'!$Z:$Z,"<>5") -> 1872268.5
A17: =A16+1 -> 13 | B17: =D17/$D$4 -> 0.07166194 | C17: =_xlfn.XLOOKUP($A17,'rubros_id_opex (2)'!$B:$B,'rubros_id_opex (2)'!$A:$A) -> SERVICIOS | D17: =SUMIFS('bbdd.5.final'!$Y:$Y,'bbdd.5.final'!$AA:$AA,A17,'bbdd.5.final'!$J:$J,"Opex",'bbdd.5.final'!$Z:$Z,"<>5") -> 29746047
A18: =A17+1 -> 14 | B18: =D18/$D$4 -> 0.00031374678 | C18: =_xlfn.XLOOKUP($A18,'rubros_id_opex (2)'!$B:$B,'rubros_id_opex (2)'!$A:$A) -> COMERCIAL | D18: =SUMIFS('bbdd.5.final'!$Y:$Y,'bbdd.5.final'!$AA:$AA,A18,'bbdd.5.final'!$J:$J,"Opex",'bbdd.5.final'!$Z:$Z,"<>5") -> 130232.68
B20: VENTAS | D20: =SUMIFS(BBDD_INGRESOS_FINAL!$O:$O,BBDD_INGRESOS_FINAL!$R:$R,"<>5") -> 8.1941405e+08
B22: UTILDAD | D22: =D20-D4 -> 4.0432554e+08
B24: CAPEX | D24: =SUMIFS('bbdd.5.final'!$Y:$Y,'bbdd.5.final'!$J:$J,"Capex",'bbdd.5.final'!$Z:$Z,"<>5") -> 2.304253e+08
B26: DEUDA | D26: =SUMIFS('bbdd.5.final'!$Y:$Y,'bbdd.5.final'!$J:$J,"Deuda",'bbdd.5.final'!$Z:$Z,"<>5") -> 0
B28: Flujo de Caja al Accionista | D28: =D22-D24-D26 -> 1.7390024e+08
B31: VENTAS
B32: Row Labels | C32: Sum of TOTAL | D32: prc
B33: PILETAS | C33: 253547470 | D33: =C33/$C$40 -> 0.30942534
B34: REACTORES | C34: 2.1218758e+08 | D34: =C34/$C$40 -> 0.25895038
B35: DISPOSICIÓN FINAL RESIDUOS LIQUIDOS | C35: 1.712503e+08 | D35: =C35/$C$40 -> 0.20899118
B36: BACHAS | C36: 1.151894e+08 | D36: =C36/$C$40 -> 0.14057533
B37: NFU | C37: 36666425 | D37: =C37/$C$40 -> 0.044747128
B38: CEREAL & POLVILLO | C38: 25207646 | D38: =C38/$C$40 -> 0.030763014
B39: DISPOSICIÓN FINAL RESIDUOS SOLIDOS | C39: 5365216.3 | D39: =C39/$C$40 -> 0.0065476255
B40: Grand Total | C40: 8.1941405e+08
B44: COSTOS
B45: Row Labels | C45: Sum of MONTO_FINAL
B46: DISP. FINAL RESIDUOS LÍQUIDOS | C46: 2.5542369e+08 | D46: =C46/$C$54 -> 0.27538052
B47: REACTORES | C47: 2.5465884e+08 | D47: =C47/$C$54 -> 0.27455591
B48: BACHAS | C48: 1.30417e+08 | D48: =C48/$C$54 -> 0.14060678
B49: NFU | C49: 1.2746245e+08 | D49: =C49/$C$54 -> 0.13742138
B50: PILETAS | C50: 73655932 | D50: =C50/$C$54 -> 0.079410836
B51: DISP. FINAL RESIDUOS SÓLIDOS | C51: 46252965 | D51: =C51/$C$54 -> 0.049866813
...

Sheet Vista_RUBRO
B2: CON EXPORTACIÓN INCLUÍDA
B3: TOTAL
B4: OPEX | D4: =SUM(D5:D18) -> 2.9779225e+09
A5: 1 | B5: =D5/$D$4 -> 0.025983964 | C5: =_xlfn.XLOOKUP($A5,'rubros_id_opex (2)'!$B:$B,'rubros_id_opex (2)'!$A:$A) -> ENERGIA | D5: =SUMIFS('bbdd.5.final'!$Y:$Y,'bbdd.5.final'!$AA:$AA,A5,'bbdd.5.final'!$J:$J,"Opex") -> 77378232
A6: =A5+1 -> 2 | B6: =D6/$D$4 -> 0.00096711716 | C6: =_xlfn.XLOOKUP($A6,'rubros_id_opex (2)'!$B:$B,'rubros_id_opex (2)'!$A:$A) -> HABILITACIONES Y CERT | D6: =SUMIFS('bbdd.5.final'!$Y:$Y,'bbdd.5.final'!$AA:$AA,A6,'bbdd.5.final'!$J:$J,"Opex") -> 2880000
A7: =A6+1 -> 3 | B7: =D7/$D$4 -> 0.00080799118 | C7: =_xlfn.XLOOKUP($A7,'rubros_id_opex (2)'!$B:$B,'rubros_id_opex (2)'!$A:$A) -> HIGIENE Y SEGURIDAD | D7: =SUMIFS('bbdd.5.final'!$Y:$Y,'bbdd.5.final'!$AA:$AA,A7,'bbdd.5.final'!$J:$J,"Opex") -> 2406135.1
A8: =A7+1 -> 4 | B8: =D8/$D$4 -> 0.0028384801 | C8: =_xlfn.XLOOKUP($A8,'rubros_id_opex (2)'!$B:$B,'rubros_id_opex (2)'!$A:$A) -> IMPUESTOS | D8: =SUMIFS('bbdd.5.final'!$Y:$Y,'bbdd.5.final'!$AA:$AA,A8,'bbdd.5.final'!$J:$J,"Opex") -> 8452773.8
A9: =A8+1 -> 5 | B9: =D9/$D$4 -> 0.033563873 | C9: =_xlfn.XLOOKUP($A9,'rubros_id_opex (2)'!$B:$B,'rubros_id_opex (2)'!$A:$A) -> INSUMOS | D9: =SUMIFS('bbdd.5.final'!$Y:$Y,'bbdd.5.final'!$AA:$AA,A9,'bbdd.5.final'!$J:$J,"Opex") -> 99950615
A10: =A9+1 -> 6 | B10: =D10/$D$4 -> 0 | C10: =_xlfn.XLOOKUP($A10,'rubros_id_opex (2)'!$B:$B,'rubros_id_opex (2)'!$A:$A) -> INVERSION | D10: =SUMIFS('bbdd.5.final'!$Y:$Y,'bbdd.5.final'!$AA:$AA,A10,'bbdd.5.final'!$J:$J,"Opex") -> 0
A11: =A10+1 -> 7 | B11: =D11/$D$4 -> 0.014253437 | C11: =_xlfn.XLOOKUP($A11,'rubros_id_opex (2)'!$B:$B,'rubros_id_opex (2)'!$A:$A) -> LOGISTICA | D11: =SUMIFS('bbdd.5.final'!$Y:$Y,'bbdd.5.final'!$AA:$AA,A11,'bbdd.5.final'!$J:$J,"Opex") -> 42445632
A12: =A11+1 -> 8 | B12: =D12/$D$4 -> 0.85997202 | C12: =_xlfn.XLOOKUP($A12,'rubros_id_opex (2)'!$B:$B,'rubros_id_opex (2)'!$A:$A) -> M.PRIMAS | D12: =SUMIFS('bbdd.5.final'!$Y:$Y,'bbdd.5.final'!$AA:$AA,A12,'bbdd.5.final'!$J:$J,"Opex") -> 2.5609301e+09
A13: =A12+1 -> 9 | B13: =D13/$D$4 -> 0.00053268282 | C13: =_xlfn.XLOOKUP($A13,'rubros_id_opex (2)'!$B:$B,'rubros_id_opex (2)'!$A:$A) -> MANTENIMIENTO PREVENTIVO | D13: =SUMIFS('bbdd.5.final'!$Y:$Y,'bbdd.5.final'!$AA:$AA,A13,'bbdd.5.final'!$J:$J,"Opex") -> 1586288.2
A14: =A13+1 -> 10 | B14: =D14/$D$4 -> 0.032923487 | C14: =_xlfn.XLOOKUP($A14,'rubros_id_opex (2)'!$B:$B,'rubros_id_opex (2)'!$A:$A) -> PERSONAL | D14: =SUMIFS('bbdd.5.final'!$Y:$Y,'bbdd.5.final'!$AA:$AA,A14,'bbdd.5.final'!$J:$J,"Opex") -> 98043594
A15: =A14+1 -> 11 | B15: =D15/$D$4 -> 0.0025370412 | C15: =_xlfn.XLOOKUP($A15,'rubros_id_opex (2)'!$B:$B,'rubros_id_opex (2)'!$A:$A) -> REPARACIONES | D15: =SUMIFS('bbdd.5.final'!$Y:$Y,'bbdd.5.final'!$AA:$AA,A15,'bbdd.5.final'!$J:$J,"Opex") -> 7555112
A16: =A15+1 -> 12 | B16: =D16/$D$4 -> 0.0011794056 | C16: =_xlfn.XLOOKUP($A16,'rubros_id_opex (2)'!$B:$B,'rubros_id_opex (2)'!$A:$A) -> REPOSICION | D16: =SUMIFS('bbdd.5.final'!$Y:$Y,'bbdd.5.final'!$AA:$AA,A16,'bbdd.5.final'!$J:$J,"Opex") -> 3512178.4
A17: =A16+1 -> 13 | B17: =D17/$D$4 -> 0.024276019 | C17: =_xlfn.XLOOKUP($A17,'rubros_id_opex (2)'!$B:$B,'rubros_id_opex (2)'!$A:$A) -> SERVICIOS | D17: =SUMIFS('bbdd.5.final'!$Y:$Y,'bbdd.5.final'!$AA:$AA,A17,'bbdd.5.final'!$J:$J,"Opex") -> 72292103
A18: =A17+1 -> 14 | B18: =D18/$D$4 -> 0.00016447708 | C18: =_xlfn.XLOOKUP($A18,'rubros_id_opex (2)'!$B:$B,'rubros_id_opex (2)'!$A:$A) -> COMERCIAL | D18: =SUMIFS('bbdd.5.final'!$Y:$Y,'bbdd.5.final'!$AA:$AA,A18,'bbdd.5.final'!$J:$J,"Opex") -> 489799.99
B20: VENTAS | D20: =SUM(BBDD_INGRESOS_FINAL!$O:$O) -> 3.453388e+09
B22: UTILDAD | D22: =D20-D4 -> 4.7546546e+08
B24: CAPEX | D24: =SUMIFS('bbdd.5.final'!$Y:$Y,'bbdd.5.final'!$J:$J,"Capex") -> 2.5523632e+08
B26: DEUDA | D26: =SUMIFS('bbdd.5.final'!$Y:$Y,'bbdd.5.final'!$J:$J,"Deuda") -> 0
B28: Flujo de Caja al Accionista | D28: =D22-D24-D26 -> 2.2022915e+08
B31: VENTAS
B32: Row Labels | C32: sectores_id.id_sector_2 | D32: Sum of TOTAL
B33: EXPORTACION | C33: 5 | D33: 2.633974e+09
B34: PILETAS | C34: 7 | D34: 253547470
B35: REACTORES | C35: 8 | D35: 2.1218758e+08
B36: DISPOSICIÓN FINAL RESIDUOS LIQUIDOS | C36: 3 | D36: 1.712503e+08
B37: BACHAS | C37: 1 | D37: 1.151894e+08
B38: NFU | C38: 6 | D38: 36666425
B39: CEREAL & POLVILLO | C39: 2 | D39: 25207646
B40: DISPOSICIÓN FINAL RESIDUOS SOLIDOS | C40: 4 | D40: 5365216.3
B41: Grand Total | C41: 8 | D41: 3.453388e+09
B43: Concepto | C43: OPEX
B44: COSTOS_OPEX
B45: Row Labels | C45: Max of id_sector | D45: Sum of monto_final2
B46: EXPORTACION | C46: 5 | D46: 2.6512766e+09
B47: REACTORES | C47: 8 | D47: 2.4140028e+08
B48: BACHAS | C48: 1 | D48: 1.3034652e+08
B49: NFU | C49: 6 | D49: 92849602
...

Sheet RRHH
C1: TOTAL 1+2 | D1: COMPONENTE
A2: ADMINISTRACION | B2: =_xlfn.CONCAT("RRHH-",A2) -> RRHH-ADMINISTRACION | C2: 67124149 | D2: 100% ADMINISTRACION - 100% DIRECTOR | E2: CC1
A3: INTENDENCIA | B3: =_xlfn.CONCAT("RRHH-",A3) -> RRHH-INTENDENCIA | C3: 9375237.7 | D3: 100% INTENDENCIA - 6,67% PRODUCCION | E3: CC1
A4: LABORATORIO | B4: =_xlfn.CONCAT("RRHH-",A4) -> RRHH-LABORATORIO | C4: 12249966 | D4: 100% LABORATORIO - 6,67% PRODUCCION | E4: CC1
A5: LOGISTICA | B5: =_xlfn.CONCAT("RRHH-",A5) -> RRHH-LOGISTICA | C5: 6459899.7 | D5: 75% LOGISTICA - 6,67% PRODUCCION | E5: CC1
A6: MANTENIMIENTO | B6: =_xlfn.CONCAT("RRHH-",A6) -> RRHH-MANTENIMIENTO | C6: 7742399.7 | D6: 100% MANTENIMIENTO - 6,67% PRODUCCION | E6: CC1
A7: NFU | B7: =_xlfn.CONCAT("RRHH-",A7) -> RRHH-NFU | C7: 29572095 | D7: 25% LOGISTICA - 100% CAT - 100% EXTERNO NFU - 6,67% PRODUCCION - 95% NFU | E7: CC7
A8: PORTERIA | B8: =_xlfn.CONCAT("RRHH-",A8) -> RRHH-PORTERIA | C8: 10797311 | D8: 100% PORTERIA - 6,67% PRODUCCION | E8: CC1
A9: COMPOST Y FERTILIZANTES | B9: =_xlfn.CONCAT("RRHH-",A9) -> RRHH-COMPOST Y FERTILIZANTES | C9: 1833599.1 | D9: 60% COMPOST Y FERTILIZANTES - 6,67% PRODUCCION | E9: CC14
A10: CEREAL Y POLVILLO | B10: =_xlfn.CONCAT("RRHH-",A10) -> RRHH-CEREAL Y POLVILLO | C10: 0 | D10: 0% CEREAL Y POLVILLO - 0% PRODUCCION | E10: NO
A11: TALLER MECANICO | B11: =_xlfn.CONCAT("RRHH-",A11) -> RRHH-TALLER MECANICO | C11: 6300478.7 | D11: 100% TALLER MECANICO - 6,67% PRODUCCION | E11: CC1
A12: TIERRAS FILTRANTES | B12: =_xlfn.CONCAT("RRHH-",A12) -> RRHH-TIERRAS FILTRANTES | C12: 0 | D12: 0% TIERRAS FILTRANTES - 0% PRODUCCION | E12: NO
A13: VIGILANCIA | B13: =_xlfn.CONCAT("RRHH-",A13) -> RRHH-VIGILANCIA | C13: 6294101.7 | D13: 100% VIGILANCIA - 6,67% PRODUCCION | E13: CC1
... A21: SALES | B21: =_xlfn.CONCAT("RRHH-",A21) -> RRHH-SALES | C21: 0 | D21: 0% SALES - 0% PRODUCCION | E21: NO

Sheet ref_rrhh
A1: Sector | B1: f/v | C1: d/i
A2: ADMINISTRACION | B2: Fijo | C2: Indirecto
A3: INTENDENCIA | B3: Fijo | C3: Indirecto
A4: REACTOR | B4: Variable | C4: Directo
A5: NFU | B5: Variable | C5: Directo
A6: DISPOSICION FINAL DE R. LIQUIDOS | B6: Variable | C6: Directo
A7: DIRECTOR | B7: Fijo | C7: Indirecto
A8: TALLER MECANICO | B8: Fijo | C8: Indirecto
A9: PRODUCCION | B9: Variable | C9: Directo
A10: CAT | B10: Variable | C10: Directo
A11: MANTENIMIENTO | B11: Fijo | C11: Indirecto
A12: PORTERIA | B12: Fijo | C12: Indirecto
... A17: COMPOST Y FERTILIZANTES | B17: Variable | C17: Directo

Sheet gastos_unificado.p0
A1: Fecha de Factura/Recibo | B1: Nombre de la empresa a mostrar en la factura | C1: Número | D1: Total con signo | E1: Líneas de factura/Etiqueta | F1: Líneas de factura/Cantidad | G1: Líneas de factura/Precio unitario | H1: Líneas de factura/Unidad de medida | I1: Líneas de factura/Producto | J1: Concepto | K1: Tipo de Gasto 1 | L1: Tipo de Gasto 2 | M1: CCO EMPRESA | N1: CCO - SECTOR | O1: Origen | P1: USD | Q1: SECTOR | R1: SUBRUBRO | S1: TC | T1: Total | U1: # LEGAJO | V1: LEG. | W1: CUIL
A2: 46111 | B2: WORMS 2 | C2: prod17 | D2: -2.0810686e+09 | E2: AFE (S) | F2: 1541.07 | G2: 945 | H2: TN | I2: MATERIA PRIMA | J2: OPEX | K2: VARIABLE | L2: DIRECTO | N2: CC11 | O2: gastos_produccion | P2: 1429 | Q2: EXPORTACION | R2: AFE (S)
A3: 46111 | B3: WORMS 2 | C3: prod15 | D3: -1.2849682e+08 | E3: AFE (G) | F3: 97.74 | G3: 920 | H3: TN | I3: MATERIA PRIMA | J3: OPEX | K3: VARIABLE | L3: DIRECTO | N3: CC11 | O3: gastos_produccion | P3: 1429 | Q3: EXPORTACION | R3: AFE (G)
A4: 46111 | B4: WORMS 2 | C4: prod23 | D4: -89426820 | E4: AG- C | F4: 83.44 | G4: 750 | H4: TN | I4: MATERIA PRIMA | J4: OPEX | K4: VARIABLE | L4: DIRECTO | N4: CC11 | O4: gastos_produccion | P4: 1429 | Q4: EXPORTACION | R4: AG- C
