Workbook
Name precios_internos: precios_mp!$A$1:$H$1

Sheet facturas_ventas
A1: FACTURACION | B1: Cantidades | C1: kg_promedio | D1: Precio promedio | E1: Final +IVA | F1: Subtotal | G1: fecha
A2: CAPON | B2: 1399 | C2: 121.2 | D2: 2446.4866 | E2: 2626.3033 | F2: =B2*C2*E2 -> 4.4531284e+08 | G2: 46173
A3: CHANCHA | B3: 15 | C3: 240.4 | D3: 1575 | E3: 1690.76 | F3: =B3*C3*E3 -> 6096880.6 | G3: 46173

Sheet facturas_gastos
A1: Número | B1: Total con signo | C1: Líneas de factura/Etiqueta | D1: Líneas de factura/Cantidad | E1: Líneas de factura/Precio unitario | F1: Líneas de factura/Unidad de medida | G1: Líneas de factura/Producto | H1: Concepto | I1: Tipo de Gasto 1 | J1: Tipo de Gasto 2 | K1: CCO - SECTOR
A2: nico_1 | B2: -25737688 | C2: fason_calculo_alimentos_1 | D2: 502900 | E2: 47 | F2: KG | G2: Nutrición | H2: OPEX | I2: VARIABLE | J2: DIRECTO
A3: nico_2 | B3: -205058386 | C3: calculo_alimentos_total | D3: 510925 | E3: 395.28866 | F3: KG | G3: Nutrición | H3: OPEX | I3: VARIABLE | J3: DIRECTO
A4: nico_3 | B4: -463680 | C4: embolsado_calculo_alimentos_3 | D4: 14210 | E4: 28.8 | F4: KG | G4: Nutrición | H4: OPEX | I4: OPEX | J4: VARIABLE
A5: remu | B5: -48937777 | C5: nueva_planilla_rrhh | D5: 20 | E5: 48937777 | F5: #RRHH | G5: Personal | H5: OPEX | I5: OPEX | J5: FIJO

Sheet precios_mp
A1: ID | B1: campo | C1: Descripción | D1: UM | E1: ARS | F1: USD | G1: Proveedor | H1: ult_actualizacion | I1: Comentario | J1: RUBRO | K1: IVA
A2: I1 | B2: DÓLAR BNA VENTA | D2: ARS | E2: 1500 | G2: BNA | H2: 46203 | I2: Cot dólar bna momento de factura de Vetifarma | J2: NUTRICION
A3: I2 | B3: Nutran Fason | D3: KG | E3: 47 | G3: Nutran | H3: =H2 -> 46203 | J3: NUTRICION | K3: 0.105
A4: I3 | B4: Nutran Embolsado | D4: KG | E4: 28.8 | G4: Nutran | H4: =H3 -> 46203 | J4: NUTRICION | K4: 0.21
A5: I4 | B5: Maíz | D5: KG | E5: 265 | G5: FOA | H5: =H4 -> 46203 | J5: NUTRICION | K5: 0
A6: I5 | B6: Expeller de soja | D6: KG | E6: 427.5 | G6: CERSA | H6: =H5 -> 46203 | J6: NUTRICION | K6: 0
A7: I6 | B7: Afrechillo de trigo | D7: KG | E7: 220 | G7: Nutran | H7: =H6 -> 46203 | J7: NUTRICION | K7: 0
A8: I7 | B8: Arveja | D8: KG | E8: 265 | G8: Nutran | H8: =H7 -> 46203 | J8: NUTRICION | K8: 0
A9: EXT1 | B9: MAXIMIX CERDAS REP. 2020 | D9: KG | F9: 0.93 | G9: Vetifarma | H9: =H8 -> 46203 | J9: NUTRICION | K9: 0.21
A10: EXT2 | B10: SECUESTRANTE | D10: KG | F10: 5.9 | G10: Vetifarma | H10: =H9 -> 46203 | J10: NUTRICION | K10: 0.21
A11: EXT3 | B11: Starfeed 15% 2020 + iva | D11: KG | F11: 1.84 | G11: Vetifarma | H11: =H10 -> 46203 | J11: NUTRICION | K11: 0.21
A12: EXT4 | B12: Starfeed 6% 2020 + iva | D12: KG | F12: 2.34 | G12: Vetifarma | H12: =H11 -> 46203 | J12: NUTRICION | K12: 0.21
A13: EXT5 | B13: Starfeed Desarrollo 2023 + iva | D13: KG | F13: 1.51 | G13: Vetifarma | H13: =H12 -> 46203 | J13: NUTRICION | K13: 0.21
A14: EXT6 | B14: Starfeed Repro Lactancia 4% | D14: KG | F14: 1.64 | G14: Vetifarma | H14: =H13 -> 46203 | J14: NUTRICION | K14: 0.21
A15: EXT7 | B15: Starfeed Terminación 2023 | D15: KG | F15: 1.26 | G15: Vetifarma | H15: =H14 -> 46203 | J15: NUTRICION | K15: 0.21
A16: E3 | B16: fase_0 | D16: KG | F16: 1.46 | G16: Vetifarma | H16: =H15 -> 46203 | J16: NUTRICION | K16: 0.21
A17: E6 | B17: fase_1_med | D17: KG | F17: 1.44 | G17: Vetifarma | H17: =H16 -> 46203 | J17: NUTRICION | K17: 0.21
A18: E7 | B18: fase_2_med | D18: KG | F18: 1.16 | G18: Vetifarma | H18: =H17 -> 46203 | J18: NUTRICION | K18: 0.21
A19: G1 | B19: Semen | D19: UN | E19: $18.242,82 | H19: =H18 -> 46203 | I19: Esta en facturas | J19: GENETICA | K19: 0

Sheet formulas
A1: ID | B1: m_prima | C1: prc | D1: formula | E1: version | F1: activo | G1: ultima_actualizacion | H1: proveedor | I1: ID_MAT | J1: formula_activa | K1: precios_ars | L1: precio_mp | M1: precio_ac
A2: 7 | B2: EXPELLER | C2: 0.325 | D2: cachorras | E2: v1 | F2: TRUE | G2: 46053 | H2: CERSA | I2: I5 | J2: ="OK" -> OK | K2: =_xlfn.XLOOKUP(formulas_internas[[#This Row],[ID_MAT]],precios_mp_ac!A:A,precios_mp_ac!N:N) -> 427.5 | L2: =formulas_internas[[#This Row],[precios_ars]]*formulas_internas[[#This Row],[prc]] -> 138.9375 | M2: =SUMIFS(L:L,D:D,formulas_internas[[#This Row],[formula]]) -> 361.92395
A3: 6 | B3: MAIZ | C3: 0.644 | D3: cachorras | E3: v1 | F3: TRUE | G3: 46053 | H3: FOA | I3: I4 | J3: ="OK" -> OK | K3: =_xlfn.XLOOKUP(formulas_internas[[#This Row],[ID_MAT]],precios_mp_ac!A:A,precios_mp_ac!N:N) -> 265 | L3: =formulas_internas[[#This Row],[precios_ars]]*formulas_internas[[#This Row],[prc]] -> 170.66 | M3: =SUMIFS(L:L,D:D,formulas_internas[[#This Row],[formula]]) -> 361.92395
A4: 8 | B4: MAXIMIX CERDAS REP. 2020 | C4: 0.031 | D4: cachorras | E4: v1 | F4: TRUE | G4: 46053 | H4: Vetifarma | I4: EXT1 | J4: ="OK" -> OK | K4: =_xlfn.XLOOKUP(formulas_internas[[#This Row],[ID_MAT]],precios_mp_ac!A:A,precios_mp_ac!N:N) -> 1687.95 | L4: =formulas_internas[[#This Row],[precios_ars]]*formulas_internas[[#This Row],[prc]] -> 52.32645 | M4: =SUMIFS(L:L,D:D,formulas_internas[[#This Row],[formula]]) -> 361.92395
A5: 11 | B5: EXPELLER | C5: 0.35722 | D5: desarrollo_1 | E5: v1 | F5: TRUE | G5: 46053 | H5: CERSA | I5: I5 | J5: ="OK" -> OK | K5: =_xlfn.XLOOKUP(formulas_internas[[#This Row],[ID_MAT]],precios_mp_ac!A:A,precios_mp_ac!N:N) -> 427.5 | L5: =formulas_internas[[#This Row],[precios_ars]]*formulas_internas[[#This Row],[prc]] -> 152.71155 | M5: =SUMIFS(L:L,D:D,formulas_internas[[#This Row],[formula]]) -> 397.31775
A6: 10 | B6: MAIZ | C6: 0.61278 | D6: desarrollo_1 | E6: v1 | F6: TRUE | G6: 46053 | H6: FOA | I6: I4 | J6: ="OK" -> OK | K6: =_xlfn.XLOOKUP(formulas_internas[[#This Row],[ID_MAT]],precios_mp_ac!A:A,precios_mp_ac!N:N) -> 265 | L6: =formulas_internas[[#This Row],[precios_ars]]*formulas_internas[[#This Row],[prc]] -> 162.3867 | M6: =SUMIFS(L:L,D:D,formulas_internas[[#This Row],[formula]]) -> 397.31775
A7: 12 | B7: Starfeed Desarrollo 2023 + iva | C7: 0.03 | D7: desarrollo_1 | E7: v1 | F7: TRUE | G7: 46053 | H7: Vetifarma | I7: EXT5 | J7: ="OK" -> OK | K7: =_xlfn.XLOOKUP(formulas_internas[[#This Row],[ID_MAT]],precios_mp_ac!A:A,precios_mp_ac!N:N) -> 2740.65 | L7: =formulas_internas[[#This Row],[precios_ars]]*formulas_internas[[#This Row],[prc]] -> 82.2195 | M7: =SUMIFS(L:L,D:D,formulas_internas[[#This Row],[formula]]) -> 397.31775
A8: 14 | B8: EXPELLER | C8: 0.36768359 | D8: desarrollo_2 | E8: v1 | F8: TRUE | G8: 46053 | H8: CERSA | I8: I5 | J8: ="OK" -> OK | K8: =_xlfn.XLOOKUP(formulas_internas[[#This Row],[ID_MAT]],precios_mp_ac!A:A,precios_mp_ac!N:N) -> 427.5 | L8: =formulas_internas[[#This Row],[precios_ars]]*formulas_internas[[#This Row],[prc]] -> 157.18473 | M8: =SUMIFS(L:L,D:D,formulas_internas[[#This Row],[formula]]) -> 399.01808
A9: 13 | B9: MAIZ | C9: 0.60231641 | D9: desarrollo_2 | E9: v1 | F9: TRUE | G9: 46053 | H9: FOA | I9: I4 | J9: ="OK" -> OK | K9: =_xlfn.XLOOKUP(formulas_internas[[#This Row],[ID_MAT]],precios_mp_ac!A:A,precios_mp_ac!N:N) -> 265 | L9: =formulas_internas[[#This Row],[precios_ars]]*formulas_internas[[#This Row],[prc]] -> 159.61385 | M9: =SUMIFS(L:L,D:D,formulas_internas[[#This Row],[formula]]) -> 399.01808
A10: 15 | B10: Starfeed Desarrollo 2023 + iva | C10: 0.03 | D10: desarrollo_2 | E10: v1 | F10: TRUE | G10: 46053 | H10: Vetifarma | I10: EXT5 | J10: ="OK" -> OK | K10: =_xlfn.XLOOKUP(formulas_internas[[#This Row],[ID_MAT]],precios_mp_ac!A:A,precios_mp_ac!N:N) -> 2740.65 | L10: =formulas_internas[[#This Row],[precios_ars]]*formulas_internas[[#This Row],[prc]] -> 82.2195 | M10: =SUMIFS(L:L,D:D,formulas_internas[[#This Row],[formula]]) -> 399.01808
A11: 22 | B11: ARVEJA | C11: 0.1 | D11: desarrollo_c_arveja | E11: v1 | F11: TRUE | G11: 46053 | H11: Nutran | I11: I7 | J11: ="OK" -> OK | K11: =_xlfn.XLOOKUP(formulas_internas[[#This Row],[ID_MAT]],precios_mp_ac!A:A,precios_mp_ac!N:N) -> 265 | L11: =formulas_internas[[#This Row],[precios_ars]]*formulas_internas[[#This Row],[prc]] -> 26.5 | M11: =SUMIFS(L:L,D:D,formulas_internas[[#This Row],[formula]]) -> 389.157
A12: 20 | B12: MAIZ | C12: 0.563 | D12: desarrollo_c_arveja | E12: v1 | F12: TRUE | G12: 46053 | H12: FOA | I12: I4 | J12: ="OK" -> OK | K12: =_xlfn.XLOOKUP(formulas_internas[[#This Row],[ID_MAT]],precios_mp_ac!A:A,precios_mp_ac!N:N) -> 265 | L12: =formulas_internas[[#This Row],[precios_ars]]*formulas_internas[[#This Row],[prc]] -> 149.195 | M12: =SUMIFS(L:L,D:D,formulas_internas[[#This Row],[formula]]) -> 389.157
A13: 23 | B13: Starfeed Desarrollo 2023 + iva | C13: 0.03 | D13: desarrollo_c_arveja | E13: v1 | F13: TRUE | G13: 46053 | H13: Vetifarma | I13: EXT5 | J13: ="OK" -> OK | K13: =_xlfn.XLOOKUP(formulas_internas[[#This Row],[ID_MAT]],precios_mp_ac!A:A,precios_mp_ac!N:N) -> 2740.65 | L13: =formulas_internas[[#This Row],[precios_ars]]*formulas_internas[[#This Row],[prc]] -> 82.2195 | M13: =SUMIFS(L:L,D:D,formulas_internas[[#This Row],[formula]]) -> 389.157
... A53: 55 | B53: Starfeed Terminación 2023 | C53: 0.02 | D53: terminador_c_arveja_2b | E53: v1 | F53: TRUE | G53: 46053 | H53: Vetifarma | I53: EXT7 | J53: ="OK" -> OK | K53: =_xlfn.XLOOKUP(formulas_internas[[#This Row],[ID_MAT]],precios_mp_ac!A:A,precios_mp_ac!N:N) -> 2286.9 | L53: =formulas_internas[[#This Row],[precios_ars]]*formulas_internas[[#This Row],[prc]] -> 45.738 | M53: =SUMIFS(L:L,D:D,formulas_internas[[#This Row],[formula]]) -> 331.9255

Sheet precios_mp_ac
A1: ID | B1: campo | C1: Descripción | D1: UM | E1: ARS | F1: USD | G1: Proveedor | H1: ult_actualizacion | I1: Comentario | J1: RUBRO | K1: IVA | L1: dolar | M1: precio_ars | N1: precio_final
A2: I1 | B2: DÓLAR BNA VENTA | D2: ARS | E2: =precios_mp!E2 -> 1500 | G2: BNA | H2: =precios_mp!H2 -> 46203 | I2: Cot dólar bna momento de factura de Vetifarma | J2: NUTRICION | L2: =_xlfn.XLOOKUP($B$2,B:B,E:E) -> 1500 | M2: =IF(ISBLANK(precios_mp__2[[#This Row],[ARS]]),F2*L2,precios_mp__2[[#This Row],[ARS]]) -> 1500 | N2: =precios_mp__2[[#This Row],[precio_ars]]*(1+precios_mp__2[[#This Row],[IVA]]) -> 1500
A3: I2 | B3: Nutran Fason | D3: KG | E3: =precios_mp!E3 -> 47 | G3: Nutran | H3: =precios_mp!H3 -> 46203 | J3: NUTRICION | K3: 0.105 | L3: =_xlfn.XLOOKUP($B$2,B:B,E:E) -> 1500 | M3: =IF(ISBLANK(precios_mp__2[[#This Row],[ARS]]),F3*L3,precios_mp__2[[#This Row],[ARS]]) -> 47 | N3: =precios_mp__2[[#This Row],[precio_ars]]*(1+precios_mp__2[[#This Row],[IVA]]) -> 51.935
A4: I3 | B4: Nutran Embolsado | D4: KG | E4: =precios_mp!E4 -> 28.8 | G4: Nutran | H4: =precios_mp!H4 -> 46203 | J4: NUTRICION | K4: 0.21 | L4: =_xlfn.XLOOKUP($B$2,B:B,E:E) -> 1500 | M4: =IF(ISBLANK(precios_mp__2[[#This Row],[ARS]]),F4*L4,precios_mp__2[[#This Row],[ARS]]) -> 28.8 | N4: =precios_mp__2[[#This Row],[precio_ars]]*(1+precios_mp__2[[#This Row],[IVA]]) -> 34.848
A5: I4 | B5: Maíz | D5: KG | E5: =precios_mp!E5 -> 265 | G5: FOA | H5: =precios_mp!H5 -> 46203 | J5: NUTRICION | K5: 0 | L5: =_xlfn.XLOOKUP($B$2,B:B,E:E) -> 1500 | M5: =IF(ISBLANK(precios_mp__2[[#This Row],[ARS]]),F5*L5,precios_mp__2[[#This Row],[ARS]]) -> 265 | N5: =precios_mp__2[[#This Row],[precio_ars]]*(1+precios_mp__2[[#This Row],[IVA]]) -> 265
A6: I5 | B6: Expeller de soja | D6: KG | E6: =precios_mp!E6 -> 427.5 | G6: CERSA | H6: =precios_mp!H6 -> 46203 | J6: NUTRICION | K6: 0 | L6: =_xlfn.XLOOKUP($B$2,B:B,E:E) -> 1500 | M6: =IF(ISBLANK(precios_mp__2[[#This Row],[ARS]]),F6*L6,precios_mp__2[[#This Row],[ARS]]) -> 427.5 | N6: =precios_mp__2[[#This Row],[precio_ars]]*(1+precios_mp__2[[#This Row],[IVA]]) -> 427.5
A7: I6 | B7: Afrechillo de trigo | D7: KG | E7: =precios_mp!E7 -> 220 | G7: Nutran | H7: =precios_mp!H7 -> 46203 | J7: NUTRICION | K7: 0 | L7: =_xlfn.XLOOKUP($B$2,B:B,E:E) -> 1500 | M7: =IF(ISBLANK(precios_mp__2[[#This Row],[ARS]]),F7*L7,precios_mp__2[[#This Row],[ARS]]) -> 220 | N7: =precios_mp__2[[#This Row],[precio_ars]]*(1+precios_mp__2[[#This Row],[IVA]]) -> 220
A8: I7 | B8: Arveja | D8: KG | E8: =precios_mp!E8 -> 265 | G8: Nutran | H8: =precios_mp!H8 -> 46203 | J8: NUTRICION | K8: 0 | L8: =_xlfn.XLOOKUP($B$2,B:B,E:E) -> 1500 | M8: =IF(ISBLANK(precios_mp__2[[#This Row],[ARS]]),F8*L8,precios_mp__2[[#This Row],[ARS]]) -> 265 | N8: =precios_mp__2[[#This Row],[precio_ars]]*(1+precios_mp__2[[#This Row],[IVA]]) -> 265
A9: EXT1 | B9: MAXIMIX CERDAS REP. 2020 | D9: KG | F9: =precios_mp!F9 -> 0.93 | G9: Vetifarma | H9: =precios_mp!H9 -> 46203 | J9: NUTRICION | K9: 0.21 | L9: =_xlfn.XLOOKUP($B$2,B:B,E:E) -> 1500 | M9: =IF(ISBLANK(precios_mp__2[[#This Row],[ARS]]),F9*L9,precios_mp__2[[#This Row],[ARS]]) -> 1395 | N9: =precios_mp__2[[#This Row],[precio_ars]]*(1+precios_mp__2[[#This Row],[IVA]]) -> 1687.95
A10: EXT2 | B10: SECUESTRANTE | D10: KG | F10: =precios_mp!F10 -> 5.9 | G10: Vetifarma | H10: =precios_mp!H10 -> 46203 | J10: NUTRICION | K10: 0.21 | L10: =_xlfn.XLOOKUP($B$2,B:B,E:E) -> 1500 | M10: =IF(ISBLANK(precios_mp__2[[#This Row],[ARS]]),F10*L10,precios_mp__2[[#This Row],[ARS]]) -> 8850 | N10: =precios_mp__2[[#This Row],[precio_ars]]*(1+precios_mp__2[[#This Row],[IVA]]) -> 10708.5
A11: EXT3 | B11: Starfeed 15% 2020 + iva | D11: KG | F11: =precios_mp!F11 -> 1.84 | G11: Vetifarma | H11: =precios_mp!H11 -> 46203 | J11: NUTRICION | K11: 0.21 | L11: =_xlfn.XLOOKUP($B$2,B:B,E:E) -> 1500 | M11: =IF(ISBLANK(precios_mp__2[[#This Row],[ARS]]),F11*L11,precios_mp__2[[#This Row],[ARS]]) -> 2760 | N11: =precios_mp__2[[#This Row],[precio_ars]]*(1+precios_mp__2[[#This Row],[IVA]]) -> 3339.6
A12: EXT4 | B12: Starfeed 6% 2020 + iva | D12: KG | F12: =precios_mp!F12 -> 2.34 | G12: Vetifarma | H12: =precios_mp!H12 -> 46203 | J12: NUTRICION | K12: 0.21 | L12: =_xlfn.XLOOKUP($B$2,B:B,E:E) -> 1500 | M12: =IF(ISBLANK(precios_mp__2[[#This Row],[ARS]]),F12*L12,precios_mp__2[[#This Row],[ARS]]) -> 3510 | N12: =precios_mp__2[[#This Row],[precio_ars]]*(1+precios_mp__2[[#This Row],[IVA]]) -> 4247.1
A13: EXT5 | B13: Starfeed Desarrollo 2023 + iva | D13: KG | F13: =precios_mp!F13 -> 1.51 | G13: Vetifarma | H13: =precios_mp!H13 -> 46203 | J13: NUTRICION | K13: 0.21 | L13: =_xlfn.XLOOKUP($B$2,B:B,E:E) -> 1500 | M13: =IF(ISBLANK(precios_mp__2[[#This Row],[ARS]]),F13*L13,precios_mp__2[[#This Row],[ARS]]) -> 2265 | N13: =precios_mp__2[[#This Row],[precio_ars]]*(1+precios_mp__2[[#This Row],[IVA]]) -> 2740.65
A14: EXT6 | B14: Starfeed Repro Lactancia 4% | D14: KG | F14: =precios_mp!F14 -> 1.64 | G14: Vetifarma | H14: =precios_mp!H14 -> 46203 | J14: NUTRICION | K14: 0.21 | L14: =_xlfn.XLOOKUP($B$2,B:B,E:E) -> 1500 | M14: =IF(ISBLANK(precios_mp__2[[#This Row],[ARS]]),F14*L14,precios_mp__2[[#This Row],[ARS]]) -> 2460 | N14: =precios_mp__2[[#This Row],[precio_ars]]*(1+precios_mp__2[[#This Row],[IVA]]) -> 2976.6
A15: EXT7 | B15: Starfeed Terminación 2023 | D15: KG | F15: =precios_mp!F15 -> 1.26 | G15: Vetifarma | H15: =precios_mp!H15 -> 46203 | J15: NUTRICION | K15: 0.21 | L15: =_xlfn.XLOOKUP($B$2,B:B,E:E) -> 1500 | M15: =IF(ISBLANK(precios_mp__2[[#This Row],[ARS]]),F15*L15,precios_mp__2[[#This Row],[ARS]]) -> 1890 | N15: =precios_mp__2[[#This Row],[precio_ars]]*(1+precios_mp__2[[#This Row],[IVA]]) -> 2286.9
A16: E3 | B16: fase_0 | D16: KG | F16: =precios_mp!F16 -> 1.46 | G16: Vetifarma | H16: =precios_mp!H16 -> 46203 | J16: NUTRICION | K16: 0.21 | L16: =_xlfn.XLOOKUP($B$2,B:B,E:E) -> 1500 | M16: =IF(ISBLANK(precios_mp__2[[#This Row],[ARS]]),F16*L16,precios_mp__2[[#This Row],[ARS]]) -> 2190 | N16: =precios_mp__2[[#This Row],[precio_ars]]*(1+precios_mp__2[[#This Row],[IVA]]) -> 2649.9
A17: E6 | B17: fase_1_med | D17: KG | F17: =precios_mp!F17 -> 1.44 | G17: Vetifarma | H17: =precios_mp!H17 -> 46203 | J17: NUTRICION | K17: 0.21 | L17: =_xlfn.XLOOKUP($B$2,B:B,E:E) -> 1500 | M17: =IF(ISBLANK(precios_mp__2[[#This Row],[ARS]]),F17*L17,precios_mp__2[[#This Row],[ARS]]) -> 2160 | N17: =precios_mp__2[[#This Row],[precio_ars]]*(1+precios_mp__2[[#This Row],[IVA]]) -> 2613.6
A18: E7 | B18: fase_2_med | D18: KG | F18: =precios_mp!F18 -> 1.16 | G18: Vetifarma | H18: =precios_mp!H18 -> 46203 | J18: NUTRICION | K18: 0.21 | L18: =_xlfn.XLOOKUP($B$2,B:B,E:E) -> 1500 | M18: =IF(ISBLANK(precios_mp__2[[#This Row],[ARS]]),F18*L18,precios_mp__2[[#This Row],[ARS]]) -> 1740 | N18: =precios_mp__2[[#This Row],[precio_ars]]*(1+precios_mp__2[[#This Row],[IVA]]) -> 2105.4
A19: G1 | B19: Semen | D19: UN | E19: =precios_mp!E19 -> $18.242,82 | H19: =precios_mp!H19 -> 46203 | I19: Esta en facturas | J19: GENETICA | K19: 0 | L19: =_xlfn.XLOOKUP($B$2,B:B,E:E) -> 1500 | M19: =IF(ISBLANK(precios_mp__2[[#This Row],[ARS]]),F19*L19,precios_mp__2[[#This Row],[ARS]]) -> $18.242,82 | N19: =precios_mp__2[[#This Row],[precio_ars]]*(1+precios_mp__2[[#This Row],[IVA]]) -> #VALUE!

Sheet formula_ciclos
A1: etapa | B1: formula | C1: version | D1: fecha | E1: id_ext
A2: GESTACIÓN-{gestacion,cachorra}-{madres} | B2: gestacion_1 | C2: v1 | D2: 46172 | E2: NO
A3: MATERNIDAD-{lactancia}-{madres} | B3: lactancia | C3: v1 | D3: 46172 | E3: NO
A4: MATERNIDAD-{fase0}-{lechones} | B4: NO | C4: NO | D4: 46172 | E4: E3
A5: MATERNIDAD-{fase1}-{lechones} | B5: NO | C5: NO | D5: 46172 | E5: E6
A6: SITIO 2-{fase1}-{lechones} | B6: NO | C6: NO | D6: 46172 | E6: E7
A7: SITIO 2-{fase2}-{lechones} | B7: NO | C7: NO | D7: 46172 | E7: E7
A8: SITIO 2-{fase3}-{lechones} | B8: fase3 | C8: v1 | D8: 46172 | E8: NO
A9: SITIO 2-{fase4}-{lechones} | B9: fase_4 | C9: v1 | D9: 46172 | E9: NO
A10: SITIO 3-{fase4}-{capones} | B10: fase_4 | C10: v1 | D10: 46172 | E10: NO
A11: SITIO 3-{desarrollo}-{capones} | B11: desarrollo_c_arveja | C11: v1 | D11: 46172 | E11: NO
A12: SITIO 3-{t1}-{capones} | B12: terminador_c_arveja_1a | C12: v1 | D12: 46172 | E12: NO
A13: SITIO 3-{t2}-{capones} | B13: terminador_c_arveja_2b | C13: v1 | D13: 46172 | E13: NO

Sheet genetica_nico 
A1: Fecha de Factura/Recibo | B1: Nombre de la empresa a mostrar en la factura | C1: Número | D1: Total con signo | E1: Líneas de factura/Etiqueta | F1: Líneas de factura/Cantidad | G1: Líneas de factura/Precio unitario | H1: Líneas de factura/Unidad de medida | I1: Líneas de factura/Producto | J1: Concepto | K1: precio_por_dosis | L1: q_servicios | M1: dosis_por_madre | N1: q _final | O1: monto_final | P1: id_lote | Q1: tipo_animal
A2: 46173 | B2: GESTACIÓN | C2: 4925 | D2: =K2*N2*-1 -> -2934753.6 | E2: GESTACIÓN | F2: =N2 -> 139.2 | G2: 21083 | H2: unidades | I2: Semen | J2: Opex | K2: =G2 -> 21083 | L2: 58 | M2: 2.4 | N2: =L2*M2 -> 139.2 | O2: =N2*K2 -> 2934753.6 | P2: =C2 -> 4925 | Q2: {madres}
A3: 46173 | B3: GESTACIÓN | C3: 5125 | D3: =K3*N3*-1 -> -3288948 | E3: GESTACIÓN | F3: =N3 -> 156 | G3: 21083 | H3: unidades | I3: Semen | J3: Opex | K3: =G3 -> 21083 | L3: 65 | M3: 2.4 | N3: =L3*M3 -> 156 | O3: =N3*K3 -> 3288948 | P3: =C3 -> 5125 | Q3: {madres}
A4: 46173 | B4: GESTACIÓN | C4: 126 | D4: =K4*N4*-1 -> -3035952 | E4: GESTACIÓN | F4: =N4 -> 144 | G4: 21083 | H4: unidades | I4: Semen | J4: Opex | K4: =G4 -> 21083 | L4: 60 | M4: 2.4 | N4: =L4*M4 -> 144 | O4: =N4*K4 -> 3035952 | P4: =C4 -> 126 | Q4: {madres}

Sheet sanidad_nico
A1: Fecha de Factura/Recibo | B1: Nombre de la empresa a mostrar en la factura | C1: Número | D1: Total con signo | E1: Líneas de factura/Etiqueta | F1: Líneas de factura/Cantidad | G1: Líneas de factura/Precio unitario | H1: Líneas de factura/Unidad de medida | I1: Líneas de factura/Producto | J1: Concepto | K1: q_servicios | L1: q_partos | M1: q_lechones/capones | N1: precio_total_por_animal | O1: q | P1: monto_final | Q1: id_lote | R1: tipo_animal | S1: formula | T1: orden
A2: 46173 | B2: GESTACIÓN | C2: 4925 | D2: =N2*O2*-1 -> -564050.58 | E2: =_xlfn.CONCAT(Q2,"-",H2,"-",R2) -> 4925-q_servicios-{madres} | F2: =O2 -> 58 | G2: 9725.01 | H2: q_servicios | I2: {madres} | J2: Opex | K2: 58 | L2: 0 | N2: 9725.01 | O2: =SUM(K2:M2) -> 58 | P2: =N2*O2 -> 564050.58 | Q2: =C2 -> 4925 | R2: {madres} | S2: VACUNAS | T2: 1
A3: 46173 | B3: MATERNIDAD | C3: =C2 -> 4925 | D3: =N3*O3*-1 -> -221497.2 | E3: =_xlfn.CONCAT(Q3,"-",H3,"-",R3) -> 4925-q_partos-{madres} | F3: =O3 -> 54 | G3: 4101.8 | H3: q_partos | I3: {madres} | J3: Opex | L3: 54 | N3: 4101.8 | O3: =SUM(K3:M3) -> 54 | P3: =N3*O3 -> 221497.2 | Q3: =C3 -> 4925 | R3: {madres} | S3: VACUNAS | T3: 2
A4: 46173 | B4: MATERNIDAD | C4: =C3 -> 4925 | D4: =N4*O4*-1 -> -136143.18 | E4: =_xlfn.CONCAT(Q4,"-",H4,"-",R4) -> 4925-q_lechones/capones-{lechones} | F4: =O4 -> 771 | G4: 176.58 | H4: q_lechones/capones | I4: {lechones} | J4: Opex | M4: 771 | N4: 176.58 | O4: =SUM(K4:M4) -> 771 | P4: =N4*O4 -> 136143.18 | Q4: =C4 -> 4925 | R4: {lechones} | S4: VACUNAS | T4: 3
A5: 46173 | B5: SITIO 2 | C5: =C4 -> 4925 | D5: =N5*O5*-1 -> -3011096.3 | E5: =_xlfn.CONCAT(Q5,"-",H5,"-",R5) -> 4925-q_lechones/capones-{lechones} | F5: =O5 -> 699 | G5: 4307.72 | H5: q_lechones/capones | I5: {lechones} | J5: Opex | M5: 699 | N5: 4307.72 | O5: =SUM(K5:M5) -> 699 | P5: =N5*O5 -> 3011096.3 | Q5: =C5 -> 4925 | R5: {lechones} | S5: VACUNAS | T5: 4
A6: 46173 | B6: GESTACIÓN | C6: 5125 | D6: =N6*O6*-1 -> -632125.65 | E6: =_xlfn.CONCAT(Q6,"-",H6,"-",R6) -> 5125-q_servicios-{madres} | F6: =O6 -> 65 | G6: 9725.01 | H6: q_servicios | I6: {madres} | J6: Opex | K6: 65 | L6: 0 | N6: 9725.01 | O6: =SUM(K6:M6) -> 65 | P6: =N6*O6 -> 632125.65 | Q6: =C6 -> 5125 | R6: {madres} | S6: VACUNAS | T6: 1
A7: 46173 | B7: MATERNIDAD | C7: =C6 -> 5125 | D7: =N7*O7*-1 -> -225599 | E7: =_xlfn.CONCAT(Q7,"-",H7,"-",R7) -> 5125-q_partos-{madres} | F7: =O7 -> 55 | G7: 4101.8 | H7: q_partos | I7: {madres} | J7: Opex | L7: 55 | N7: 4101.8 | O7: =SUM(K7:M7) -> 55 | P7: =N7*O7 -> 225599 | Q7: =C7 -> 5125 | R7: {madres} | S7: VACUNAS | T7: 2
A8: 46173 | B8: MATERNIDAD | C8: =C7 -> 5125 | D8: =N8*O8*-1 -> -144265.86 | E8: =_xlfn.CONCAT(Q8,"-",H8,"-",R8) -> 5125-q_lechones/capones-{lechones} | F8: =O8 -> 817 | G8: 176.58 | H8: q_lechones/capones | I8: {lechones} | J8: Opex | M8: 817 | N8: 176.58 | O8: =SUM(K8:M8) -> 817 | P8: =N8*O8 -> 144265.86 | Q8: =C8 -> 5125 | R8: {lechones} | S8: VACUNAS | T8: 3
A9: 46173 | B9: SITIO 2 | C9: =C8 -> 5125 | D9: =N9*O9*-1 -> -2744017.6 | E9: =_xlfn.CONCAT(Q9,"-",H9,"-",R9) -> 5125-q_lechones/capones-{lechones} | F9: =O9 -> 637 | G9: 4307.72 | H9: q_lechones/capones | I9: {lechones} | J9: Opex | M9: 637 | N9: 4307.72 | O9: =SUM(K9:M9) -> 637 | P9: =N9*O9 -> 2744017.6 | Q9: =C9 -> 5125 | R9: {lechones} | S9: VACUNAS | T9: 4
A10: 46173 | B10: GESTACIÓN | C10: 126 | D10: =N10*O10*-1 -> -583500.6 | E10: =_xlfn.CONCAT(Q10,"-",H10,"-",R10) -> 126-q_servicios-{madres} | F10: =O10 -> 60 | G10: 9725.01 | H10: q_servicios | I10: {madres} | J10: Opex | K10: 60 | L10: 0 | N10: 9725.01 | O10: =SUM(K10:M10) -> 60 | P10: =N10*O10 -> 583500.6 | Q10: =C10 -> 126 | R10: {madres} | S10: VACUNAS | T10: 1
A11: 46173 | B11: MATERNIDAD | C11: =C10 -> 126 | D11: =N11*O11*-1 -> -229700.8 | E11: =_xlfn.CONCAT(Q11,"-",H11,"-",R11) -> 126-q_partos-{madres} | F11: =O11 -> 56 | G11: 4101.8 | H11: q_partos | I11: {madres} | J11: Opex | L11: 56 | N11: 4101.8 | O11: =SUM(K11:M11) -> 56 | P11: =N11*O11 -> 229700.8 | Q11: =C11 -> 126 | R11: {madres} | S11: VACUNAS | T11: 2
A12: 46173 | B12: MATERNIDAD | C12: =C11 -> 126 | D12: =N12*O12*-1 -> -141087.42 | E12: =_xlfn.CONCAT(Q12,"-",H12,"-",R12) -> 126-q_lechones/capones-{lechones} | F12: =O12 -> 799 | G12: 176.58 | H12: q_lechones/capones | I12: {lechones} | J12: Opex | M12: 799 | N12: 176.58 | O12: =SUM(K12:M12) -> 799 | P12: =N12*O12 -> 141087.42 | Q12: =C12 -> 126 | R12: {lechones} | S12: VACUNAS | T12: 3
A13: 46173 | B13: SITIO 2 | C13: =C12 -> 126 | D13: =N13*O13*-1 -> -2976634.5 | E13: =_xlfn.CONCAT(Q13,"-",H13,"-",R13) -> 126-q_lechones/capones-{lechones} | F13: =O13 -> 691 | G13: 4307.72 | H13: q_lechones/capones | I13: {lechones} | J13: Opex | M13: 691 | N13: 4307.72 | O13: =SUM(K13:M13) -> 691 | P13: =N13*O13 -> 2976634.5 | Q13: =C13 -> 126 | R13: {lechones} | S13: VACUNAS | T13: 4

Sheet nutricion_nico
A1: Fecha de Factura/Recibo | B1: Nombre de la empresa a mostrar en la factura | C1: Número | D1: Total con signo | E1: Líneas de factura/Etiqueta | F1: Líneas de factura/Cantidad | G1: Líneas de factura/Precio unitario | H1: Líneas de factura/Unidad de medida | I1: Líneas de factura/Producto | J1: Concepto | K1: id_lote | L1: tipo_animal | M1: orden_sitio | N1: cat_alimento | O1: id_nut | P1: id_nut2 | Q1: formula_ars | R1: precio_final_ars
A2: 46173 | B2: GESTACIÓN | C2: X | D2: =F2*G2*-1 -> -6252400 | E2: =_xlfn.CONCAT(K2,"-",I2,"-",L2) -> 4925-{gestacion,cachorra}-{madres} | F2: 28420 | G2: =R2 -> 220 | H2: Kg. | I2: {gestacion,cachorra} | J2: Opex | K2: 4925 | L2: {madres} | M2: 1 | N2: =_xlfn.CONCAT(B2,"-",I2,"-",L2) -> GESTACIÓN-{gestacion,cachorra}-{madres} | O2: =MID(E2,FIND("-",E2)+1,LEN(E2)) -> {gestacion,cachorra}-{madres} | P2: =_xlfn.CONCAT(B2,"-",O2) -> GESTACIÓN-{gestacion,cachorra}-{madres} | Q2: =IF(_xlfn.XLOOKUP(P2,formula_ciclos!A:A,formula_ciclos!B:B,"")="NO",_xlfn.XLOOKUP(P2,formula_ciclos!A:A,formula_ciclos!E:E),(_xlfn.XLOOKUP(P2,formula_ciclos!A:A,formula_ciclos!B:B,""))) -> gestacion_1 | R2: =_xlfn.XLOOKUP(Q2,formulas!D:D,formulas!K:K,_xlfn.XLOOKUP(Q2,precios_mp_ac!A:A,precios_mp_ac!N:N,"")) -> 220
A3: 46173 | B3: MATERNIDAD | C3: X | D3: =F3*G3*-1 -> -5194125 | E3: =_xlfn.CONCAT(K3,"-",I3,"-",L3) -> 4925-{lactancia}-{madres} | F3: 12150 | G3: =R3 -> 427.5 | H3: Kg. | I3: {lactancia} | J3: Opex | K3: =$K$2 -> 4925 | L3: {madres} | M3: 2 | N3: =_xlfn.CONCAT(B3,"-",I3,"-",L3) -> MATERNIDAD-{lactancia}-{madres} | O3: =MID(E3,FIND("-",E3)+1,LEN(E3)) -> {lactancia}-{madres} | P3: =_xlfn.CONCAT(B3,"-",O3) -> MATERNIDAD-{lactancia}-{madres} | Q3: =IF(_xlfn.XLOOKUP(P3,formula_ciclos!A:A,formula_ciclos!B:B,"")="NO",_xlfn.XLOOKUP(P3,formula_ciclos!A:A,formula_ciclos!E:E),(_xlfn.XLOOKUP(P3,formula_ciclos!A:A,formula_ciclos!B:B,""))) -> lactancia | R3: =_xlfn.XLOOKUP(Q3,formulas!D:D,formulas!K:K,_xlfn.XLOOKUP(Q3,precios_mp_ac!A:A,precios_mp_ac!N:N,"")) -> 427.5
A4: 46173 | B4: MATERNIDAD | C4: X | D4: =F4*G4*-1 -> -510768.23 | E4: =_xlfn.CONCAT(K4,"-",I4,"-",L4) -> 4925-{fase0}-{lechones} | F4: 192.75 | G4: =R4 -> 2649.9 | H4: Kg. | I4: {fase0} | J4: Opex | K4: =$K$2 -> 4925 | L4: {lechones} | M4: 3 | N4: =_xlfn.CONCAT(B4,"-",I4,"-",L4) -> MATERNIDAD-{fase0}-{lechones} | O4: =MID(E4,FIND("-",E4)+1,LEN(E4)) -> {fase0}-{lechones} | P4: =_xlfn.CONCAT(B4,"-",O4) -> MATERNIDAD-{fase0}-{lechones} | Q4: =IF(_xlfn.XLOOKUP(P4,formula_ciclos!A:A,formula_ciclos!B:B,"")="NO",_xlfn.XLOOKUP(P4,formula_ciclos!A:A,formula_ciclos!E:E),(_xlfn.XLOOKUP(P4,formula_ciclos!A:A,formula_ciclos!B:B,""))) -> E3 | R4: =_xlfn.XLOOKUP(Q4,formulas!D:D,formulas!K:K,_xlfn.XLOOKUP(Q4,precios_mp_ac!A:A,precios_mp_ac!N:N,"")) -> 2649.9
A5: 46173 | B5: MATERNIDAD | C5: X | D5: =F5*G5*-1 -> -1007542.8 | E5: =_xlfn.CONCAT(K5,"-",I5,"-",L5) -> 4925-{fase1}-{lechones} | F5: 385.5 | G5: =R5 -> 2613.6 | H5: Kg. | I5: {fase1} | J5: Opex | K5: =$K$2 -> 4925 | L5: {lechones} | M5: 4 | N5: =_xlfn.CONCAT(B5,"-",I5,"-",L5) -> MATERNIDAD-{fase1}-{lechones} | O5: =MID(E5,FIND("-",E5)+1,LEN(E5)) -> {fase1}-{lechones} | P5: =_xlfn.CONCAT(B5,"-",O5) -> MATERNIDAD-{fase1}-{lechones} | Q5: =IF(_xlfn.XLOOKUP(P5,formula_ciclos!A:A,formula_ciclos!B:B,"")="NO",_xlfn.XLOOKUP(P5,formula_ciclos!A:A,formula_ciclos!E:E),(_xlfn.XLOOKUP(P5,formula_ciclos!A:A,formula_ciclos!B:B,""))) -> E6 | R5: =_xlfn.XLOOKUP(Q5,formulas!D:D,formulas!K:K,_xlfn.XLOOKUP(Q5,precios_mp_ac!A:A,precios_mp_ac!N:N,"")) -> 2613.6
A6: 46173 | B6: SITIO 2 | C6: X | D6: =F6*G6*-1 -> -1105335 | E6: =_xlfn.CONCAT(K6,"-",I6,"-",L6) -> 4925-{fase1}-{lechones} | F6: 525 | G6: =R6 -> 2105.4 | H6: Kg. | I6: {fase1} | J6: Opex | K6: =$K$2 -> 4925 | L6: {lechones} | M6: 5 | N6: =_xlfn.CONCAT(B6,"-",I6,"-",L6) -> SITIO 2-{fase1}-{lechones} | O6: =MID(E6,FIND("-",E6)+1,LEN(E6)) -> {fase1}-{lechones} | P6: =_xlfn.CONCAT(B6,"-",O6) -> SITIO 2-{fase1}-{lechones} | Q6: =IF(_xlfn.XLOOKUP(P6,formula_ciclos!A:A,formula_ciclos!B:B,"")="NO",_xlfn.XLOOKUP(P6,formula_ciclos!A:A,formula_ciclos!E:E),(_xlfn.XLOOKUP(P6,formula_ciclos!A:A,formula_ciclos!B:B,""))) -> E7 | R6: =_xlfn.XLOOKUP(Q6,formulas!D:D,formulas!K:K,_xlfn.XLOOKUP(Q6,precios_mp_ac!A:A,precios_mp_ac!N:N,"")) -> 2105.4
A7: 46173 | B7: SITIO 2 | C7: X | D7: =F7*G7*-1 -> -5895120 | E7: =_xlfn.CONCAT(K7,"-",I7,"-",L7) -> 4925-{fase2}-{lechones} | F7: 2800 | G7: =R7 -> 2105.4 | H7: Kg. | I7: {fase2} | J7: Opex | K7: =$K$2 -> 4925 | L7: {lechones} | M7: 6 | N7: =_xlfn.CONCAT(B7,"-",I7,"-",L7) -> SITIO 2-{fase2}-{lechones} | O7: =MID(E7,FIND("-",E7)+1,LEN(E7)) -> {fase2}-{lechones} | P7: =_xlfn.CONCAT(B7,"-",O7) -> SITIO 2-{fase2}-{lechones} | Q7: =IF(_xlfn.XLOOKUP(P7,formula_ciclos!A:A,formula_ciclos!B:B,"")="NO",_xlfn.XLOOKUP(P7,formula_ciclos!A:A,formula_ciclos!E:E),(_xlfn.XLOOKUP(P7,formula_ciclos!A:A,formula_ciclos!B:B,""))) -> E7 | R7: =_xlfn.XLOOKUP(Q7,formulas!D:D,formulas!K:K,_xlfn.XLOOKUP(Q7,precios_mp_ac!A:A,precios_mp_ac!N:N,"")) -> 2105.4
A8: 46173 | B8: SITIO 2 | C8: X | D8: =F8*G8*-1 -> -1581750 | E8: =_xlfn.CONCAT(K8,"-",I8,"-",L8) -> 4925-{fase3}-{lechones} | F8: 3700 | G8: =R8 -> 427.5 | H8: Kg. | I8: {fase3} | J8: Opex | K8: =$K$2 -> 4925 | L8: {lechones} | M8: 7 | N8: =_xlfn.CONCAT(B8,"-",I8,"-",L8) -> SITIO 2-{fase3}-{lechones} | O8: =MID(E8,FIND("-",E8)+1,LEN(E8)) -> {fase3}-{lechones} | P8: =_xlfn.CONCAT(B8,"-",O8) -> SITIO 2-{fase3}-{lechones} | Q8: =IF(_xlfn.XLOOKUP(P8,formula_ciclos!A:A,formula_ciclos!B:B,"")="NO",_xlfn.XLOOKUP(P8,formula_ciclos!A:A,formula_ciclos!E:E),(_xlfn.XLOOKUP(P8,formula_ciclos!A:A,formula_ciclos!B:B,""))) -> fase3 | R8: =_xlfn.XLOOKUP(Q8,formulas!D:D,formulas!K:K,_xlfn.XLOOKUP(Q8,precios_mp_ac!A:A,precios_mp_ac!N:N,"")) -> 427.5
A9: 46173 | B9: SITIO 2 | C9: X | D9: =F9*G9*-1 -> -1590300 | E9: =_xlfn.CONCAT(K9,"-",I9,"-",L9) -> 4925-{fase4}-{lechones} | F9: 3720 | G9: =R9 -> 427.5 | H9: Kg. | I9: {fase4} | J9: Opex | K9: =$K$2 -> 4925 | L9: {lechones} | M9: 8 | N9: =_xlfn.CONCAT(B9,"-",I9,"-",L9) -> SITIO 2-{fase4}-{lechones} | O9: =MID(E9,FIND("-",E9)+1,LEN(E9)) -> {fase4}-{lechones} | P9: =_xlfn.CONCAT(B9,"-",O9) -> SITIO 2-{fase4}-{lechones} | Q9: =IF(_xlfn.XLOOKUP(P9,formula_ciclos!A:A,formula_ciclos!B:B,"")="NO",_xlfn.XLOOKUP(P9,formula_ciclos!A:A,formula_ciclos!E:E),(_xlfn.XLOOKUP(P9,formula_ciclos!A:A,formula_ciclos!B:B,""))) -> fase_4 | R9: =_xlfn.XLOOKUP(Q9,formulas!D:D,formulas!K:K,_xlfn.XLOOKUP(Q9,precios_mp_ac!A:A,precios_mp_ac!N:N,"")) -> 427.5
A10: 46173 | B10: SITIO 3 | C10: X | D10: =F10*G10*-1 -> -8201160 | E10: =_xlfn.CONCAT(K10,"-",I10,"-",L10) -> 4925-{fase4}-{capones} | F10: 19184 | G10: =R10 -> 427.5 | H10: Kg. | I10: {fase4} | J10: Opex | K10: =$K$2 -> 4925 | L10: {capones} | M10: 9 | N10: =_xlfn.CONCAT(B10,"-",I10,"-",L10) -> SITIO 3-{fase4}-{capones} | O10: =MID(E10,FIND("-",E10)+1,LEN(E10)) -> {fase4}-{capones} | P10: =_xlfn.CONCAT(B10,"-",O10) -> SITIO 3-{fase4}-{capones} | Q10: =IF(_xlfn.XLOOKUP(P10,formula_ciclos!A:A,formula_ciclos!B:B,"")="NO",_xlfn.XLOOKUP(P10,formula_ciclos!A:A,formula_ciclos!E:E),(_xlfn.XLOOKUP(P10,formula_ciclos!A:A,formula_ciclos!B:B,""))) -> fase_4 | R10: =_xlfn.XLOOKUP(Q10,formulas!D:D,formulas!K:K,_xlfn.XLOOKUP(Q10,precios_mp_ac!A:A,precios_mp_ac!N:N,"")) -> 427.5
A11: 46173 | B11: SITIO 3 | C11: X | D11: =F11*G11*-1 -> -12370200 | E11: =_xlfn.CONCAT(K11,"-",I11,"-",L11) -> 4925-{desarrollo}-{capones} | F11: 46680 | G11: =R11 -> 265 | H11: Kg. | I11: {desarrollo} | J11: Opex | K11: =$K$2 -> 4925 | L11: {capones} | M11: 10 | N11: =_xlfn.CONCAT(B11,"-",I11,"-",L11) -> SITIO 3-{desarrollo}-{capones} | O11: =MID(E11,FIND("-",E11)+1,LEN(E11)) -> {desarrollo}-{capones} | P11: =_xlfn.CONCAT(B11,"-",O11) -> SITIO 3-{desarrollo}-{capones} | Q11: =IF(_xlfn.XLOOKUP(P11,formula_ciclos!A:A,formula_ciclos!B:B,"")="NO",_xlfn.XLOOKUP(P11,formula_ciclos!A:A,formula_ciclos!E:E),(_xlfn.XLOOKUP(P11,formula_ciclos!A:A,formula_ciclos!B:B,""))) -> desarrollo_c_arveja | R11: =_xlfn.XLOOKUP(Q11,formulas!D:D,formulas!K:K,_xlfn.XLOOKUP(Q11,precios_mp_ac!A:A,precios_mp_ac!N:N,"")) -> 265
A12: 46173 | B12: SITIO 3 | C12: X | D12: =F12*G12*-1 -> -14241100 | E12: =_xlfn.CONCAT(K12,"-",I12,"-",L12) -> 4925-{t1}-{capones} | F12: 53740 | G12: =R12 -> 265 | H12: Kg. | I12: {t1} | J12: Opex | K12: =$K$2 -> 4925 | L12: {capones} | M12: 11 | N12: =_xlfn.CONCAT(B12,"-",I12,"-",L12) -> SITIO 3-{t1}-{capones} | O12: =MID(E12,FIND("-",E12)+1,LEN(E12)) -> {t1}-{capones} | P12: =_xlfn.CONCAT(B12,"-",O12) -> SITIO 3-{t1}-{capones} | Q12: =IF(_xlfn.XLOOKUP(P12,formula_ciclos!A:A,formula_ciclos!B:B,"")="NO",_xlfn.XLOOKUP(P12,formula_ciclos!A:A,formula_ciclos!E:E),(_xlfn.XLOOKUP(P12,formula_ciclos!A:A,formula_ciclos!B:B,""))) -> terminador_c_arveja_1a | R12: =_xlfn.XLOOKUP(Q12,formulas!D:D,formulas!K:K,_xlfn.XLOOKUP(Q12,precios_mp_ac!A:A,precios_mp_ac!N:N,"")) -> 265
A13: 46173 | B13: SITIO 3 | C13: X | D13: =F13*G13*-1 -> -27361710 | E13: =_xlfn.CONCAT(K13,"-",I13,"-",L13) -> 4925-{t2}-{capones} | F13: 64004 | G13: =R13 -> 427.5 | H13: Kg. | I13: {t2} | J13: Opex | K13: =$K$2 -> 4925 | L13: {capones} | M13: 12 | N13: =_xlfn.CONCAT(B13,"-",I13,"-",L13) -> SITIO 3-{t2}-{capones} | O13: =MID(E13,FIND("-",E13)+1,LEN(E13)) -> {t2}-{capones} | P13: =_xlfn.CONCAT(B13,"-",O13) -> SITIO 3-{t2}-{capones} | Q13: =IF(_xlfn.XLOOKUP(P13,formula_ciclos!A:A,formula_ciclos!B:B,"")="NO",_xlfn.XLOOKUP(P13,formula_ciclos!A:A,formula_ciclos!E:E),(_xlfn.XLOOKUP(P13,formula_ciclos!A:A,formula_ciclos!B:B,""))) -> terminador_c_arveja_2b | R13: =_xlfn.XLOOKUP(Q13,formulas!D:D,formulas!K:K,_xlfn.XLOOKUP(Q13,precios_mp_ac!A:A,precios_mp_ac!N:N,"")) -> 427.5
A14: 46173 | B14: GESTACIÓN | C14: X | D14: =F14*G14*-1 -> -7007000 | E14: =_xlfn.CONCAT(K14,"-",I14,"-",L14) -> 5125-{gestacion,cachorra}-{madres} | F14: 31850 | G14: =R14 -> 220 | H14: Kg. | I14: {gestacion,cachorra} | J14: Opex | K14: 5125 | L14: {madres} | M14: 1 | N14: =_xlfn.CONCAT(B14,"-",I14,"-",L14) -> GESTACIÓN-{gestacion,cachorra}-{madres} | O14: =MID(E14,FIND("-",E14)+1,LEN(E14)) -> {gestacion,cachorra}-{madres} | P14: =_xlfn.CONCAT(B14,"-",O14) -> GESTACIÓN-{gestacion,cachorra}-{madres} | Q14: =IF(_xlfn.XLOOKUP(P14,formula_ciclos!A:A,formula_ciclos!B:B,"")="NO",_xlfn.XLOOKUP(P14,formula_ciclos!A:A,formula_ciclos!E:E),(_xlfn.XLOOKUP(P14,formula_ciclos!A:A,formula_ciclos!B:B,""))) -> gestacion_1 | R14: =_xlfn.XLOOKUP(Q14,formulas!D:D,formulas!K:K,_xlfn.XLOOKUP(Q14,precios_mp_ac!A:A,precios_mp_ac!N:N,"")) -> 220
A15: 46173 | B15: MATERNIDAD | C15: X | D15: =F15*G15*-1 -> -5290312.5 | E15: =_xlfn.CONCAT(K15,"-",I15,"-",L15) -> 5125-{lactancia}-{madres} | F15: 12375 | G15: =R15 -> 427.5 | H15: Kg. | I15: {lactancia} | J15: Opex | K15: =$K$14 -> 5125 | L15: {madres} | M15: 2 | N15: =_xlfn.CONCAT(B15,"-",I15,"-",L15) -> MATERNIDAD-{lactancia}-{madres} | O15: =MID(E15,FIND("-",E15)+1,LEN(E15)) -> {lactancia}-{madres} | P15: =_xlfn.CONCAT(B15,"-",O15) -> MATERNIDAD-{lactancia}-{madres} | Q15: =IF(_xlfn.XLOOKUP(P15,formula_ciclos!A:A,formula_ciclos!B:B,"")="NO",_xlfn.XLOOKUP(P15,formula_ciclos!A:A,formula_ciclos!E:E),(_xlfn.XLOOKUP(P15,formula_ciclos!A:A,formula_ciclos!B:B,""))) -> lactancia | R15: =_xlfn.XLOOKUP(Q15,formulas!D:D,formulas!K:K,_xlfn.XLOOKUP(Q15,precios_mp_ac!A:A,precios_mp_ac!N:N,"")) -> 427.5
A16: 46173 | B16: MATERNIDAD | C16: X | D16: =F16*G16*-1 -> -541242.08 | E16: =_xlfn.CONCAT(K16,"-",I16,"-",L16) -> 5125-{fase0}-{lechones} | F16: 204.25 | G16: =R16 -> 2649.9 | H16: Kg. | I16: {fase0} | J16: Opex | K16: =$K$14 -> 5125 | L16: {lechones} | M16: 3 | N16: =_xlfn.CONCAT(B16,"-",I16,"-",L16) -> MATERNIDAD-{fase0}-{lechones} | O16: =MID(E16,FIND("-",E16)+1,LEN(E16)) -> {fase0}-{lechones} | P16: =_xlfn.CONCAT(B16,"-",O16) -> MATERNIDAD-{fase0}-{lechones} | Q16: =IF(_xlfn.XLOOKUP(P16,formula_ciclos!A:A,formula_ciclos!B:B,"")="NO",_xlfn.XLOOKUP(P16,formula_ciclos!A:A,formula_ciclos!E:E),(_xlfn.XLOOKUP(P16,formula_ciclos!A:A,formula_ciclos!B:B,""))) -> E3 | R16: =_xlfn.XLOOKUP(Q16,formulas!D:D,formulas!K:K,_xlfn.XLOOKUP(Q16,precios_mp_ac!A:A,precios_mp_ac!N:N,"")) -> 2649.9
A17: 46173 | B17: MATERNIDAD | C17: X | D17: =F17*G17*-1 -> -1067655.6 | E17: =_xlfn.CONCAT(K17,"-",I17,"-",L17) -> 5125-{fase1}-{lechones} | F17: 408.5 | G17: =R17 -> 2613.6 | H17: Kg. | I17: {fase1} | J17: Opex | K17: =$K$14 -> 5125 | L17: {lechones} | M17: 4 | N17: =_xlfn.CONCAT(B17,"-",I17,"-",L17) -> MATERNIDAD-{fase1}-{lechones} | O17: =MID(E17,FIND("-",E17)+1,LEN(E17)) -> {fase1}-{lechones} | P17: =_xlfn.CONCAT(B17,"-",O17) -> MATERNIDAD-{fase1}-{lechones} | Q17: =IF(_xlfn.XLOOKUP(P17,formula_ciclos!A:A,formula_ciclos!B:B,"")="NO",_xlfn.XLOOKUP(P17,formula_ciclos!A:A,formula_ciclos!E:E),(_xlfn.XLOOKUP(P17,formula_ciclos!A:A,formula_ciclos!B:B,""))) -> E6 | R17: =_xlfn.XLOOKUP(Q17,formulas!D:D,formulas!K:K,_xlfn.XLOOKUP(Q17,precios_mp_ac!A:A,precios_mp_ac!N:N,"")) -> 2613.6
A18: 46173 | B18: SITIO 2 | C18: X | D18: =F18*G18*-1 -> -2158035 | E18: =_xlfn.CONCAT(K18,"-",I18,"-",L18) -> 5125-{fase1}-{lechones} | F18: 1025 | G18: =R18 -> 2105.4 | H18: Kg. | I18: {fase1} | J18: Opex | K18: =$K$14 -> 5125 | L18: {lechones} | M18: 5 | N18: =_xlfn.CONCAT(B18,"-",I18,"-",L18) -> SITIO 2-{fase1}-{lechones} | O18: =MID(E18,FIND("-",E18)+1,LEN(E18)) -> {fase1}-{lechones} | P18: =_xlfn.CONCAT(B18,"-",O18) -> SITIO 2-{fase1}-{lechones} | Q18: =IF(_xlfn.XLOOKUP(P18,formula_ciclos!A:A,formula_ciclos!B:B,"")="NO",_xlfn.XLOOKUP(P18,formula_ciclos!A:A,formula_ciclos!E:E),(_xlfn.XLOOKUP(P18,formula_ciclos!A:A,formula_ciclos!B:B,""))) -> E7 | R18: =_xlfn.XLOOKUP(Q18,formulas!D:D,formulas!K:K,_xlfn.XLOOKUP(Q18,precios_mp_ac!A:A,precios_mp_ac!N:N,"")) -> 2105.4
A19: 46173 | B19: SITIO 2 | C19: X | D19: =F19*G19*-1 -> -5368770 | E19: =_xlfn.CONCAT(K19,"-",I19,"-",L19) -> 5125-{fase2}-{lechones} | F19: 2550 | G19: =R19 -> 2105.4 | H19: Kg. | I19: {fase2} | J19: Opex | K19: =$K$14 -> 5125 | L19: {lechones} | M19: 6 | N19: =_xlfn.CONCAT(B19,"-",I19,"-",L19) -> SITIO 2-{fase2}-{lechones} | O19: =MID(E19,FIND("-",E19)+1,LEN(E19)) -> {fase2}-{lechones} | P19: =_xlfn.CONCAT(B19,"-",O19) -> SITIO 2-{fase2}-{lechones} | Q19: =IF(_xlfn.XLOOKUP(P19,formula_ciclos!A:A,formula_ciclos!B:B,"")="NO",_xlfn.XLOOKUP(P19,formula_ciclos!A:A,formula_ciclos!E:E),(_xlfn.XLOOKUP(P19,formula_ciclos!A:A,formula_ciclos!B:B,""))) -> E7 | R19: =_xlfn.XLOOKUP(Q19,formulas!D:D,formulas!K:K,_xlfn.XLOOKUP(Q19,precios_mp_ac!A:A,precios_mp_ac!N:N,"")) -> 2105.4
A20: 46173 | B20: SITIO 2 | C20: X | D20: =F20*G20*-1 -> -2169562.5 | E20: =_xlfn.CONCAT(K20,"-",I20,"-",L20) -> 5125-{fase3}-{lechones} | F20: 5075 | G20: =R20 -> 427.5 | H20: Kg. | I20: {fase3} | J20: Opex | K20: =$K$14 -> 5125 | L20: {lechones} | M20: 7 | N20: =_xlfn.CONCAT(B20,"-",I20,"-",L20) -> SITIO 2-{fase3}-{lechones} | O20: =MID(E20,FIND("-",E20)+1,LEN(E20)) -> {fase3}-{lechones} | P20: =_xlfn.CONCAT(B20,"-",O20) -> SITIO 2-{fase3}-{lechones} | Q20: =IF(_xlfn.XLOOKUP(P20,formula_ciclos!A:A,formula_ciclos!B:B,"")="NO",_xlfn.XLOOKUP(P20,formula_ciclos!A:A,formula_ciclos!E:E),(_xlfn.XLOOKUP(P20,formula_ciclos!A:A,formula_ciclos!B:B,""))) -> fase3 | R20: =_xlfn.XLOOKUP(Q20,formulas!D:D,formulas!K:K,_xlfn.XLOOKUP(Q20,precios_mp_ac!A:A,precios_mp_ac!N:N,"")) -> 427.5
A21: 46173 | B21: SITIO 2 | C21: X | D21: =F21*G21*-1 -> -1138005 | E21: =_xlfn.CONCAT(K21,"-",I21,"-",L21) -> 5125-{fase4}-{lechones} | F21: 2662 | G21: =R21 -> 427.5 | H21: Kg. | I21: {fase4} | J21: Opex | K21: =$K$14 -> 5125 | L21: {lechones} | M21: 8 | N21: =_xlfn.CONCAT(B21,"-",I21,"-",L21) -> SITIO 2-{fase4}-{lechones} | O21: =MID(E21,FIND("-",E21)+1,LEN(E21)) -> {fase4}-{lechones} | P21: =_xlfn.CONCAT(B21,"-",O21) -> SITIO 2-{fase4}-{lechones} | Q21: =IF(_xlfn.XLOOKUP(P21,formula_ciclos!A:A,formula_ciclos!B:B,"")="NO",_xlfn.XLOOKUP(P21,formula_ciclos!A:A,formula_ciclos!E:E),(_xlfn.XLOOKUP(P21,formula_ciclos!A:A,formula_ciclos!B:B,""))) -> fase_4 | R21: =_xlfn.XLOOKUP(Q21,formulas!D:D,formulas!K:K,_xlfn.XLOOKUP(Q21,precios_mp_ac!A:A,precios_mp_ac!N:N,"")) -> 427.5
A22: 46173 | B22: SITIO 3 | C22: X | D22: =F22*G22*-1 -> -6395400 | E22: =_xlfn.CONCAT(K22,"-",I22,"-",L22) -> 5125-{fase4}-{capones} | F22: 14960 | G22: =R22 -> 427.5 | H22: Kg. | I22: {fase4} | J22: Opex | K22: =$K$14 -> 5125 | L22: {capones} | M22: 9 | N22: =_xlfn.CONCAT(B22,"-",I22,"-",L22) -> SITIO 3-{fase4}-{capones} | O22: =MID(E22,FIND("-",E22)+1,LEN(E22)) -> {fase4}-{capones} | P22: =_xlfn.CONCAT(B22,"-",O22) -> SITIO 3-{fase4}-{capones} | Q22: =IF(_xlfn.XLOOKUP(P22,formula_ciclos!A:A,formula_ciclos!B:B,"")="NO",_xlfn.XLOOKUP(P22,formula_ciclos!A:A,formula_ciclos!E:E),(_xlfn.XLOOKUP(P22,formula_ciclos!A:A,formula_ciclos!B:B,""))) -> fase_4 | R22: =_xlfn.XLOOKUP(Q22,formulas!D:D,formulas!K:K,_xlfn.XLOOKUP(Q22,precios_mp_ac!A:A,precios_mp_ac!N:N,"")) -> 427.5
A23: 46173 | B23: SITIO 3 | C23: X | D23: =F23*G23*-1 -> -11214800 | E23: =_xlfn.CONCAT(K23,"-",I23,"-",L23) -> 5125-{desarrollo}-{capones} | F23: 42320 | G23: =R23 -> 265 | H23: Kg. | I23: {desarrollo} | J23: Opex | K23: =$K$14 -> 5125 | L23: {capones} | M23: 10 | N23: =_xlfn.CONCAT(B23,"-",I23,"-",L23) -> SITIO 3-{desarrollo}-{capones} | O23: =MID(E23,FIND("-",E23)+1,LEN(E23)) -> {desarrollo}-{capones} | P23: =_xlfn.CONCAT(B23,"-",O23) -> SITIO 3-{desarrollo}-{capones} | Q23: =IF(_xlfn.XLOOKUP(P23,formula_ciclos!A:A,formula_ciclos!B:B,"")="NO",_xlfn.XLOOKUP(P23,formula_ciclos!A:A,formula_ciclos!E:E),(_xlfn.XLOOKUP(P23,formula_ciclos!A:A,formula_ciclos!B:B,""))) -> desarrollo_c_arveja | R23: =_xlfn.XLOOKUP(Q23,formulas!D:D,formulas!K:K,_xlfn.XLOOKUP(Q23,precios_mp_ac!A:A,precios_mp_ac!N:N,"")) -> 265
A24: 46173 | B24: SITIO 3 | C24: X | D24: =F24*G24*-1 -> -12854620 | E24: =_xlfn.CONCAT(K24,"-",I24,"-",L24) -> 5125-{t1}-{capones} | F24: 48508 | G24: =R24 -> 265 | H24: Kg. | I24: {t1} | J24: Opex | K24: =$K$14 -> 5125 | L24: {capones} | M24: 11 | N24: =_xlfn.CONCAT(B24,"-",I24,"-",L24) -> SITIO 3-{t1}-{capones} | O24: =MID(E24,FIND("-",E24)+1,LEN(E24)) -> {t1}-{capones} | P24: =_xlfn.CONCAT(B24,"-",O24) -> SITIO 3-{t1}-{capones} | Q24: =IF(_xlfn.XLOOKUP(P24,formula_ciclos!A:A,formula_ciclos!B:B,"")="NO",_xlfn.XLOOKUP(P24,formula_ciclos!A:A,formula_ciclos!E:E),(_xlfn.XLOOKUP(P24,formula_ciclos!A:A,formula_ciclos!B:B,""))) -> terminador_c_arveja_1a | R24: =_xlfn.XLOOKUP(Q24,formulas!D:D,formulas!K:K,_xlfn.XLOOKUP(Q24,precios_mp_ac!A:A,precios_mp_ac!N:N,"")) -> 265
A25: 46173 | B25: SITIO 3 | C25: X | D25: =F25*G25*-1 -> -23609970 | E25: =_xlfn.CONCAT(K25,"-",I25,"-",L25) -> 5125-{t2}-{capones} | F25: 55228 | G25: =R25 -> 427.5 | H25: Kg. | I25: {t2} | J25: Opex | K25: =$K$14 -> 5125 | L25: {capones} | M25: 12 | N25: =_xlfn.CONCAT(B25,"-",I25,"-",L25) -> SITIO 3-{t2}-{capones} | O25: =MID(E25,FIND("-",E25)+1,LEN(E25)) -> {t2}-{capones} | P25: =_xlfn.CONCAT(B25,"-",O25) -> SITIO 3-{t2}-{capones} | Q25: =IF(_xlfn.XLOOKUP(P25,formula_ciclos!A:A,formula_ciclos!B:B,"")="NO",_xlfn.XLOOKUP(P25,formula_ciclos!A:A,formula_ciclos!E:E),(_xlfn.XLOOKUP(P25,formula_ciclos!A:A,formula_ciclos!B:B,""))) -> terminador_c_arveja_2b | R25: =_xlfn.XLOOKUP(Q25,formulas!D:D,formulas!K:K,_xlfn.XLOOKUP(Q25,precios_mp_ac!A:A,precios_mp_ac!N:N,"")) -> 427.5
A26: 46173 | B26: GESTACIÓN | C26: X | D26: =F26*G26*-1 -> -6468000 | E26: =_xlfn.CONCAT(K26,"-",I26,"-",L26) -> 126-{gestacion,cachorra}-{madres} | F26: 29400 | G26: =R26 -> 220 | H26: Kg. | I26: {gestacion,cachorra} | J26: Opex | K26: 126 | L26: {madres} | M26: 1 | N26: =_xlfn.CONCAT(B26,"-",I26,"-",L26) -> GESTACIÓN-{gestacion,cachorra}-{madres} | O26: =MID(E26,FIND("-",E26)+1,LEN(E26)) -> {gestacion,cachorra}-{madres} | P26: =_xlfn.CONCAT(B26,"-",O26) -> GESTACIÓN-{gestacion,cachorra}-{madres} | Q26: =IF(_xlfn.XLOOKUP(P26,formula_ciclos!A:A,formula_ciclos!B:B,"")="NO",_xlfn.XLOOKUP(P26,formula_ciclos!A:A,formula_ciclos!E:E),(_xlfn.XLOOKUP(P26,formula_ciclos!A:A,formula_ciclos!B:B,""))) -> gestacion_1 | R26: =_xlfn.XLOOKUP(Q26,formulas!D:D,formulas!K:K,_xlfn.XLOOKUP(Q26,precios_mp_ac!A:A,precios_mp_ac!N:N,"")) -> 220
A27: 46173 | B27: MATERNIDAD | C27: X | D27: =F27*G27*-1 -> -5386500 | E27: =_xlfn.CONCAT(K27,"-",I27,"-",L27) -> 126-{lactancia}-{madres} | F27: 12600 | G27: =R27 -> 427.5 | H27: Kg. | I27: {lactancia} | J27: Opex | K27: =$K$26 -> 126 | L27: {madres} | M27: 2 | N27: =_xlfn.CONCAT(B27,"-",I27,"-",L27) -> MATERNIDAD-{lactancia}-{madres} | O27: =MID(E27,FIND("-",E27)+1,LEN(E27)) -> {lactancia}-{madres} | P27: =_xlfn.CONCAT(B27,"-",O27) -> MATERNIDAD-{lactancia}-{madres} | Q27: =IF(_xlfn.XLOOKUP(P27,formula_ciclos!A:A,formula_ciclos!B:B,"")="NO",_xlfn.XLOOKUP(P27,formula_ciclos!A:A,formula_ciclos!E:E),(_xlfn.XLOOKUP(P27,formula_ciclos!A:A,formula_ciclos!B:B,""))) -> lactancia | R27: =_xlfn.XLOOKUP(Q27,formulas!D:D,formulas!K:K,_xlfn.XLOOKUP(Q27,precios_mp_ac!A:A,precios_mp_ac!N:N,"")) -> 427.5
A28: 46173 | B28: MATERNIDAD | C28: X | D28: =F28*G28*-1 -> -529317.53 | E28: =_xlfn.CONCAT(K28,"-",I28,"-",L28) -> 126-{fase0}-{lechones} | F28: 199.75 | G28: =R28 -> 2649.9 | H28: Kg. | I28: {fase0} | J28: Opex | K28: =$K$26 -> 126 | L28: {lechones} | M28: 3 | N28: =_xlfn.CONCAT(B28,"-",I28,"-",L28) -> MATERNIDAD-{fase0}-{lechones} | O28: =MID(E28,FIND("-",E28)+1,LEN(E28)) -> {fase0}-{lechones} | P28: =_xlfn.CONCAT(B28,"-",O28) -> MATERNIDAD-{fase0}-{lechones} | Q28: =IF(_xlfn.XLOOKUP(P28,formula_ciclos!A:A,formula_ciclos!B:B,"")="NO",_xlfn.XLOOKUP(P28,formula_ciclos!A:A,formula_ciclos!E:E),(_xlfn.XLOOKUP(P28,formula_ciclos!A:A,formula_ciclos!B:B,""))) -> E3 | R28: =_xlfn.XLOOKUP(Q28,formulas!D:D,formulas!K:K,_xlfn.XLOOKUP(Q28,precios_mp_ac!A:A,precios_mp_ac!N:N,"")) -> 2649.9
A29: 46173 | B29: MATERNIDAD | C29: X | D29: =F29*G29*-1 -> -1044133.2 | E29: =_xlfn.CONCAT(K29,"-",I29,"-",L29) -> 126-{fase1}-{lechones} | F29: 399.5 | G29: =R29 -> 2613.6 | H29: Kg. | I29: {fase1} | J29: Opex | K29: =$K$26 -> 126 | L29: {lechones} | M29: 4 | N29: =_xlfn.CONCAT(B29,"-",I29,"-",L29) -> MATERNIDAD-{fase1}-{lechones} | O29: =MID(E29,FIND("-",E29)+1,LEN(E29)) -> {fase1}-{lechones} | P29: =_xlfn.CONCAT(B29,"-",O29) -> MATERNIDAD-{fase1}-{lechones} | Q29: =IF(_xlfn.XLOOKUP(P29,formula_ciclos!A:A,formula_ciclos!B:B,"")="NO",_xlfn.XLOOKUP(P29,formula_ciclos!A:A,formula_ciclos!E:E),(_xlfn.XLOOKUP(P29,formula_ciclos!A:A,formula_ciclos!B:B,""))) -> E6 | R29: =_xlfn.XLOOKUP(Q29,formulas!D:D,formulas!K:K,_xlfn.XLOOKUP(Q29,precios_mp_ac!A:A,precios_mp_ac!N:N,"")) -> 2613.6
A30: 46173 | B30: SITIO 2 | C30: X | D30: =F30*G30*-1 -> -1842225 | E30: =_xlfn.CONCAT(K30,"-",I30,"-",L30) -> 126-{fase1}-{lechones} | F30: 875 | G30: =R30 -> 2105.4 | H30: Kg. | I30: {fase1} | J30: Opex | K30: =$K$26 -> 126 | L30: {lechones} | M30: 5 | N30: =_xlfn.CONCAT(B30,"-",I30,"-",L30) -> SITIO 2-{fase1}-{lechones} | O30: =MID(E30,FIND("-",E30)+1,LEN(E30)) -> {fase1}-{lechones} | P30: =_xlfn.CONCAT(B30,"-",O30) -> SITIO 2-{fase1}-{lechones} | Q30: =IF(_xlfn.XLOOKUP(P30,formula_ciclos!A:A,formula_ciclos!B:B,"")="NO",_xlfn.XLOOKUP(P30,formula_ciclos!A:A,formula_ciclos!E:E),(_xlfn.XLOOKUP(P30,formula_ciclos!A:A,formula_ciclos!B:B,""))) -> E7 | R30: =_xlfn.XLOOKUP(Q30,formulas!D:D,formulas!K:K,_xlfn.XLOOKUP(Q30,precios_mp_ac!A:A,precios_mp_ac!N:N,"")) -> 2105.4
A31: 46173 | B31: SITIO 2 | C31: X | D31: =F31*G31*-1 -> -5947755 | E31: =_xlfn.CONCAT(K31,"-",I31,"-",L31) -> 126-{fase2}-{lechones} | F31: 2825 | G31: =R31 -> 2105.4 | H31: Kg. | I31: {fase2} | J31: Opex | K31: =$K$26 -> 126 | L31: {lechones} | M31: 6 | N31: =_xlfn.CONCAT(B31,"-",I31,"-",L31) -> SITIO 2-{fase2}-{lechones} | O31: =MID(E31,FIND("-",E31)+1,LEN(E31)) -> {fase2}-{lechones} | P31: =_xlfn.CONCAT(B31,"-",O31) -> SITIO 2-{fase2}-{lechones} | Q31: =IF(_xlfn.XLOOKUP(P31,formula_ciclos!A:A,formula_ciclos!B:B,"")="NO",_xlfn.XLOOKUP(P31,formula_ciclos!A:A,formula_ciclos!E:E),(_xlfn.XLOOKUP(P31,formula_ciclos!A:A,formula_ciclos!B:B,""))) -> E7 | R31: =_xlfn.XLOOKUP(Q31,formulas!D:D,formulas!K:K,_xlfn.XLOOKUP(Q31,precios_mp_ac!A:A,precios_mp_ac!N:N,"")) -> 2105.4
A32: 46173 | B32: SITIO 2 | C32: X | D32: =F32*G32*-1 -> -2351250 | E32: =_xlfn.CONCAT(K32,"-",I32,"-",L32) -> 126-{fase3}-{lechones} | F32: 5500 | G32: =R32 -> 427.5 | H32: Kg. | I32: {fase3} | J32: Opex | K32: =$K$26 -> 126 | L32: {lechones} | M32: 7 | N32: =_xlfn.CONCAT(B32,"-",I32,"-",L32) -> SITIO 2-{fase3}-{lechones} | O32: =MID(E32,FIND("-",E32)+1,LEN(E32)) -> {fase3}-{lechones} | P32: =_xlfn.CONCAT(B32,"-",O32) -> SITIO 2-{fase3}-{lechones} | Q32: =IF(_xlfn.XLOOKUP(P32,formula_ciclos!A:A,formula_ciclos!B:B,"")="NO",_xlfn.XLOOKUP(P32,formula_ciclos!A:A,formula_ciclos!E:E),(_xlfn.XLOOKUP(P32,formula_ciclos!A:A,formula_ciclos!B:B,""))) -> fase3 | R32: =_xlfn.XLOOKUP(Q32,formulas!D:D,formulas!K:K,_xlfn.XLOOKUP(Q32,precios_mp_ac!A:A,precios_mp_ac!N:N,"")) -> 427.5
A33: 46173 | B33: SITIO 2 | C33: X | D33: =F33*G33*-1 -> -153900 | E33: =_xlfn.CONCAT(K33,"-",I33,"-",L33) -> 126-{fase4}-{lechones} | F33: 360 | G33: =R33 -> 427.5 | H33: Kg. | I33: {fase4} | J33: Opex | K33: =$K$26 -> 126 | L33: {lechones} | M33: 8 | N33: =_xlfn.CONCAT(B33,"-",I33,"-",L33) -> SITIO 2-{fase4}-{lechones} | O33: =MID(E33,FIND("-",E33)+1,LEN(E33)) -> {fase4}-{lechones} | P33: =_xlfn.CONCAT(B33,"-",O33) -> SITIO 2-{fase4}-{lechones} | Q33: =IF(_xlfn.XLOOKUP(P33,formula_ciclos!A:A,formula_ciclos!B:B,"")="NO",_xlfn.XLOOKUP(P33,formula_ciclos!A:A,formula_ciclos!E:E),(_xlfn.XLOOKUP(P33,formula_ciclos!A:A,formula_ciclos!B:B,""))) -> fase_4 | R33: =_xlfn.XLOOKUP(Q33,formulas!D:D,formulas!K:K,_xlfn.XLOOKUP(Q33,precios_mp_ac!A:A,precios_mp_ac!N:N,"")) -> 427.5
A34: 46173 | B34: SITIO 3 | C34: X | D34: =F34*G34*-1 -> -7626600 | E34: =_xlfn.CONCAT(K34,"-",I34,"-",L34) -> 126-{fase4}-{capones} | F34: 17840 | G34: =R34 -> 427.5 | H34: Kg. | I34: {fase4} | J34: Opex | K34: =$K$26 -> 126 | L34: {capones} | M34: 9 | N34: =_xlfn.CONCAT(B34,"-",I34,"-",L34) -> SITIO 3-{fase4}-{capones} | O34: =MID(E34,FIND("-",E34)+1,LEN(E34)) -> {fase4}-{capones} | P34: =_xlfn.CONCAT(B34,"-",O34) -> SITIO 3-{fase4}-{capones} | Q34: =IF(_xlfn.XLOOKUP(P34,formula_ciclos!A:A,formula_ciclos!B:B,"")="NO",_xlfn.XLOOKUP(P34,formula_ciclos!A:A,formula_ciclos!E:E),(_xlfn.XLOOKUP(P34,formula_ciclos!A:A,formula_ciclos!B:B,""))) -> fase_4 | R34: =_xlfn.XLOOKUP(Q34,formulas!D:D,formulas!K:K,_xlfn.XLOOKUP(Q34,precios_mp_ac!A:A,precios_mp_ac!N:N,"")) -> 427.5
A35: 46173 | B35: SITIO 3 | C35: X | D35: =F35*G35*-1 -> -15262622 | E35: =_xlfn.CONCAT(K35,"-",I35,"-",L35) -> 126-{desarrollo}-{capones} | F35: 57594.8 | G35: =R35 -> 265 | H35: Kg. | I35: {desarrollo} | J35: Opex | K35: =$K$26 -> 126 | L35: {capones} | M35: 10 | N35: =_xlfn.CONCAT(B35,"-",I35,"-",L35) -> SITIO 3-{desarrollo}-{capones} | O35: =MID(E35,FIND("-",E35)+1,LEN(E35)) -> {desarrollo}-{capones} | P35: =_xlfn.CONCAT(B35,"-",O35) -> SITIO 3-{desarrollo}-{capones} | Q35: =IF(_xlfn.XLOOKUP(P35,formula_ciclos!A:A,formula_ciclos!B:B,"")="NO",_xlfn.XLOOKUP(P35,formula_ciclos!A:A,formula_ciclos!E:E),(_xlfn.XLOOKUP(P35,formula_ciclos!A:A,formula_ciclos!B:B,""))) -> desarrollo_c_arveja | R35: =_xlfn.XLOOKUP(Q35,formulas!D:D,formulas!K:K,_xlfn.XLOOKUP(Q35,precios_mp_ac!A:A,precios_mp_ac!N:N,"")) -> 265
A36: 46173 | B36: SITIO 3 | C36: X | D36: =F36*G36*-1 -> -11671236 | E36: =_xlfn.CONCAT(K36,"-",I36,"-",L36) -> 126-{t1}-{capones} | F36: 44042.4 | G36: =R36 -> 265 | H36: Kg. | I36: {t1} | J36: Opex | K36: =$K$26 -> 126 | L36: {capones} | M36: 11 | N36: =_xlfn.CONCAT(B36,"-",I36,"-",L36) -> SITIO 3-{t1}-{capones} | O36: =MID(E36,FIND("-",E36)+1,LEN(E36)) -> {t1}-{capones} | P36: =_xlfn.CONCAT(B36,"-",O36) -> SITIO 3-{t1}-{capones} | Q36: =IF(_xlfn.XLOOKUP(P36,formula_ciclos!A:A,formula_ciclos!B:B,"")="NO",_xlfn.XLOOKUP(P36,formula_ciclos!A:A,formula_ciclos!E:E),(_xlfn.XLOOKUP(P36,formula_ciclos!A:A,formula_ciclos!B:B,""))) -> terminador_c_arveja_1a | R36: =_xlfn.XLOOKUP(Q36,formulas!D:D,formulas!K:K,_xlfn.XLOOKUP(Q36,precios_mp_ac!A:A,precios_mp_ac!N:N,"")) -> 265
A37: 46173 | B37: SITIO 3 | C37: X | D37: =F37*G37*-1 -> -27457744 | E37: =_xlfn.CONCAT(K37,"-",I37,"-",L37) -> 126-{t2}-{capones} | F37: 64228.64 | G37: =R37 -> 427.5 | H37: Kg. | I37: {t2} | J37: Opex | K37: =$K$26 -> 126 | L37: {capones} | M37: 12 | N37: =_xlfn.CONCAT(B37,"-",I37,"-",L37) -> SITIO 3-{t2}-{capones} | O37: =MID(E37,FIND("-",E37)+1,LEN(E37)) -> {t2}-{capones} | P37: =_xlfn.CONCAT(B37,"-",O37) -> SITIO 3-{t2}-{capones} | Q37: =IF(_xlfn.XLOOKUP(P37,formula_ciclos!A:A,formula_ciclos!B:B,"")="NO",_xlfn.XLOOKUP(P37,formula_ciclos!A:A,formula_ciclos!E:E),(_xlfn.XLOOKUP(P37,formula_ciclos!A:A,formula_ciclos!B:B,""))) -> terminador_c_arveja_2b | R37: =_xlfn.XLOOKUP(Q37,formulas!D:D,formulas!K:K,_xlfn.XLOOKUP(Q37,precios_mp_ac!A:A,precios_mp_ac!N:N,"")) -> 427.5

Sheet produccion
A1: lote | B1: etapa | C1: descripcion | D1: q | E1: kg_prom | F1: precio_ref (c/iva) | G1: mortandad_sitio_3 | H1: monto_final | I1: modalidad_de_venta | J1: fecha
A2: 4925 | B2: MATERNIDAD | D2: 699 | E2: 7.32 | F2: =2250*2.46 -> 5535 | H2: =(D2*E2)*F2 -> 28320824 | J2: 46203
A3: =A2 -> 4925 | B3: SITIO 2 | D3: 690 | E3: 16.78 | F3: =2250*2.1 -> 4725 | H3: =(D3*E3)*F3 -> 54706995 | J3: =$J$2 -> 46203
A4: =A3 -> 4925 | B4: SITIO 3 | D4: 649 | E4: 122.98 | F4: =2250*1.0735 -> 2415.375 | G4: =D4/D3-1 -> -0.05942029 | H4: =(D4*E4)*F4 -> 1.9278079e+08 | J4: =$J$2 -> 46203
A5: =A4 -> 4925 | B5: VENTA DE 1/2 RES | D5: =D4 -> 649 | E5: =E4 -> 122.98 | F5: 2836 | H5: =(D5*E5)*F5 -> 2.2635256e+08 | J5: =$J$2 -> 46203
A6: 5125 | B6: MATERNIDAD | D6: 637 | E6: 6.4 | F6: =2250*2.5 -> 5625 | H6: =(D6*E6)*F6 -> 22932000 | J6: =$J$2 -> 46203
A7: =A6 -> 5125 | B7: SITIO 2 | D7: 630 | E7: 19.81 | F7: =2250*1.94 -> 4365 | H7: =(D7*E7)*F7 -> 54476510 | J7: =$J$2 -> 46203
A8: =A7 -> 5125 | B8: SITIO 3 | D8: 581 | E8: 118.51 | F8: =F4 -> 2415.375 | G8: =D8/D7-1 -> -0.077777778 | H8: =(D8*E8)*F8 -> 1.6630898e+08 | J8: =$J$2 -> 46203
A9: =A8 -> 5125 | B9: VENTA DE 1/2 RES | D9: =D8 -> 581 | E9: =E8 -> 118.51 | F9: =F5 -> 2836 | H9: =(D9*E9)*F9 -> 1.9527082e+08 | J9: =$J$2 -> 46203
A10: 126 | B10: MATERNIDAD | D10: 691 | E10: 7.03 | F10: =2250*2.46 -> 5535 | H10: =(D10*E10)*F10 -> 26887536 | J10: 46177
A11: =A10 -> 126 | B11: SITIO 2 | D11: 686 | E11: 18.22 | F11: =2250*2.02 -> 4545 | H11: =(D11*E11)*F11 -> 56807591 | J11: =$J$2 -> 46203
A12: =A11 -> 126 | B12: SITIO 3 | D12: 645 | E12: 119.2 | F12: =F8 -> 2415.375 | G12: =D12/D11-1 -> -0.059766764 | H12: =(D12*E12)*F12 -> 1.8570369e+08 | J12: =$J$2 -> 46203
A13: =A12 -> 126 | B13: VENTA DE 1/2 RES | D13: =D12 -> 645 | E13: =E12 -> 119.2 | F13: =F9 -> 2836 | H13: =(D13*E13)*F13 -> 218043024 | J13: =$J$2 -> 46203

Sheet ad_hoc
A1: etapa_alimentaria | B1: formula_id | C1: tipo
A2: GESTACIÓN-{gestacion,cachorra}-{madres} | B2: gestacion_1 | C2: internas
A3: MATERNIDAD-{lactancia}-{madres} | B3: lactancia | C3: internas
A4: MATERNIDAD-{fase0}-{lechones} | B4: 3 | C4: externos
A5: MATERNIDAD-{fase1}-{lechones} | B5: 4 | C5: externos
A6: SITIO 2-{fase1}-{lechones} | B6: 6 | C6: externos
A7: SITIO 2-{fase2}-{lechones} | B7: 7 | C7: externos
A8: SITIO 2-{fase3}-{lechones} | B8: fase3 | C8: internas
A9: SITIO 2-{fase4}-{lechones} | B9: fase_4 | C9: internas
A10: SITIO 3-{fase4}-{capones} | B10: fase_4 | C10: internas
A11: SITIO 3-{desarrollo}-{capones} | B11: terminador_c_arveja_1a | C11: internas
A12: SITIO 3-{t1}-{capones} | B12: terminador_c_arveja_1a | C12: internas
A13: SITIO 3-{t2}-{capones} | B13: terminador_c_arveja_2a | C13: internas

Sheet cco_calzim
A1: COD CCO | B1: SECTOR | C1: DCOMUN | D1: prc | E1: IMPUTACION | F1: #SECTORES | G1: Tipo de Gasto 1 | H1: Tipo de Gasto 2 | I1: lista_etapas | J1: etapa_pura | K1: Column1
A2: CC1 | B2: GESTACIÓN | C2: CC1GESTACIÓN | D2: 0.25 | E2: PERSONAL GNRAL ;SANIDAD-INSUMOS;OTROS | F2: 4 | G2: Fijo | H2: Directo | I2: GESTACIÓN , MATERNIDAD, SITIO 2, SITIO 3 | K2: {="{" & _xlfn.TEXTJOIN(",", TRUE, _xlfn.SORTBY( _xlfn._xlws.FILTER(cco_calzim[prc], cco_calzim[COD CCO]=cco_calzim[[#This Row],[COD CCO]]), _xlfn._xlws.FILTER(cco_calzim[SECTOR], cco_calzim[COD CCO]=cco_calzim[[#This Row],[COD CCO]]), 1 ) ) & "}"} -> {0.25,0.25,0.25,0.25}
A3: CC1 | B3: MATERNIDAD | C3: CC1MATERNIDAD | D3: 0.25 | E3: PERSONAL GNRAL | F3: 4 | G3: Fijo | H3: Directo | I3: GESTACIÓN , MATERNIDAD, SITIO 2, SITIO 3 | K3: {="{" & _xlfn.TEXTJOIN(",", TRUE, _xlfn.SORTBY( _xlfn._xlws.FILTER(cco_calzim[prc], cco_calzim[COD CCO]=cco_calzim[[#This Row],[COD CCO]]), _xlfn._xlws.FILTER(cco_calzim[SECTOR], cco_calzim[COD CCO]=cco_calzim[[#This Row],[COD CCO]]), 1 ) ) & "}"} -> {0.25,0.25,0.25,0.25}
A4: CC1 | B4: SITIO 2 | C4: CC1SITIO 2 | D4: 0.25 | E4: PERSONAL GNRAL | F4: 4 | G4: Fijo | H4: Directo | I4: GESTACIÓN , MATERNIDAD, SITIO 2, SITIO 3 | K4: {="{" & _xlfn.TEXTJOIN(",", TRUE, _xlfn.SORTBY( _xlfn._xlws.FILTER(cco_calzim[prc], cco_calzim[COD CCO]=cco_calzim[[#This Row],[COD CCO]]), _xlfn._xlws.FILTER(cco_calzim[SECTOR], cco_calzim[COD CCO]=cco_calzim[[#This Row],[COD CCO]]), 1 ) ) & "}"} -> {0.25,0.25,0.25,0.25}
A5: CC1 | B5: SITIO 3 | C5: CC1SITIO 3 | D5: 0.25 | E5: PERSONAL GNRAL | F5: 4 | G5: Fijo | H5: Directo | I5: GESTACIÓN , MATERNIDAD, SITIO 2, SITIO 3 | K5: {="{" & _xlfn.TEXTJOIN(",", TRUE, _xlfn.SORTBY( _xlfn._xlws.FILTER(cco_calzim[prc], cco_calzim[COD CCO]=cco_calzim[[#This Row],[COD CCO]]), _xlfn._xlws.FILTER(cco_calzim[SECTOR], cco_calzim[COD CCO]=cco_calzim[[#This Row],[COD CCO]]), 1 ) ) & "}"} -> {0.25,0.25,0.25,0.25}
A6: CC2 | B6: GESTACIÓN | C6: CC2GESTACIÓN | D6: 1 | E6: GESTACIÓN PURA/GENETICA | F6: 1 | G6: Variable | H6: Directo | I6: GESTACIÓN | J6: GESTACIÓN | K6: {="{" & _xlfn.TEXTJOIN(",", TRUE, _xlfn.SORTBY( _xlfn._xlws.FILTER(cco_calzim[prc], cco_calzim[COD CCO]=cco_calzim[[#This Row],[COD CCO]]), _xlfn._xlws.FILTER(cco_calzim[SECTOR], cco_calzim[COD CCO]=cco_calzim[[#This Row],[COD CCO]]), 1 ) ) & "}"} -> {1}
A7: CC3 | B7: MATERNIDAD | C7: CC3MATERNIDAD | D7: 1 | E7: MATERNIDAD PURA | F7: 1 | G7: Variable | H7: Directo | I7: MATERNIDAD | J7: MATERNIDAD | K7: {="{" & _xlfn.TEXTJOIN(",", TRUE, _xlfn.SORTBY( _xlfn._xlws.FILTER(cco_calzim[prc], cco_calzim[COD CCO]=cco_calzim[[#This Row],[COD CCO]]), _xlfn._xlws.FILTER(cco_calzim[SECTOR], cco_calzim[COD CCO]=cco_calzim[[#This Row],[COD CCO]]), 1 ) ) & "}"} -> {1}
A8: CC4 | B8: SITIO 2 | C8: CC4SITIO 2 | D8: 1 | E8: SITIO 2 PURA | F8: 1 | G8: Variable | H8: Directo | I8: SITIO 2 | J8: SITIO 2 | K8: {="{" & _xlfn.TEXTJOIN(",", TRUE, _xlfn.SORTBY( _xlfn._xlws.FILTER(cco_calzim[prc], cco_calzim[COD CCO]=cco_calzim[[#This Row],[COD CCO]]), _xlfn._xlws.FILTER(cco_calzim[SECTOR], cco_calzim[COD CCO]=cco_calzim[[#This Row],[COD CCO]]), 1 ) ) & "}"} -> {1}
A9: CC5 | B9: SITIO 3 | C9: CC5SITIO 3 | D9: 1 | E9: SITIO 3 PURA/FLETES | F9: 1 | G9: Variable | H9: Directo | I9: SITIO 3 | J9: SITIO 3 | K9: {="{" & _xlfn.TEXTJOIN(",", TRUE, _xlfn.SORTBY( _xlfn._xlws.FILTER(cco_calzim[prc], cco_calzim[COD CCO]=cco_calzim[[#This Row],[COD CCO]]), _xlfn._xlws.FILTER(cco_calzim[SECTOR], cco_calzim[COD CCO]=cco_calzim[[#This Row],[COD CCO]]), 1 ) ) & "}"} -> {1}
A10: CC6 | B10: GESTACIÓN | C10: CC6GESTACIÓN | D10: 0.53 | E10: SANIDAD-VACUNA | F10: 4 | G10: Variable | H10: Directo | I10: GESTACIÓN , MATERNIDAD, SITIO 2, SITIO 3 | K10: {="{" & _xlfn.TEXTJOIN(",", TRUE, _xlfn.SORTBY( _xlfn._xlws.FILTER(cco_calzim[prc], cco_calzim[COD CCO]=cco_calzim[[#This Row],[COD CCO]]), _xlfn._xlws.FILTER(cco_calzim[SECTOR], cco_calzim[COD CCO]=cco_calzim[[#This Row],[COD CCO]]), 1 ) ) & "}"} -> {0.53,0.23,0.23,0.01}
A11: CC6 | B11: MATERNIDAD | C11: CC6MATERNIDAD | D11: 0.23 | E11: SANIDAD-VACUNA | F11: 4 | G11: Variable | H11: Directo | I11: GESTACIÓN , MATERNIDAD, SITIO 2, SITIO 3 | K11: {="{" & _xlfn.TEXTJOIN(",", TRUE, _xlfn.SORTBY( _xlfn._xlws.FILTER(cco_calzim[prc], cco_calzim[COD CCO]=cco_calzim[[#This Row],[COD CCO]]), _xlfn._xlws.FILTER(cco_calzim[SECTOR], cco_calzim[COD CCO]=cco_calzim[[#This Row],[COD CCO]]), 1 ) ) & "}"} -> {0.53,0.23,0.23,0.01}
A12: CC6 | B12: SITIO 2 | C12: CC6SITIO 2 | D12: 0.23 | E12: SANIDAD-VACUNA | F12: 4 | G12: Variable | H12: Directo | I12: GESTACIÓN , MATERNIDAD, SITIO 2, SITIO 3 | K12: {="{" & _xlfn.TEXTJOIN(",", TRUE, _xlfn.SORTBY( _xlfn._xlws.FILTER(cco_calzim[prc], cco_calzim[COD CCO]=cco_calzim[[#This Row],[COD CCO]]), _xlfn._xlws.FILTER(cco_calzim[SECTOR], cco_calzim[COD CCO]=cco_calzim[[#This Row],[COD CCO]]), 1 ) ) & "}"} -> {0.53,0.23,0.23,0.01}
