Workbook

Sheet costos_ampliados
A1: Actividades | B1: Estado | C1: Estado de pago | D1: Fecha de Factura/Recibo | E1: Fecha de vencimiento | F1: Importe sin impuestos con signo | G1: Nombre de la empresa a mostrar en la factura | H1: Número | I1: Referencia | J1: Total con signo | K1: Total en divisa con signo | L1: Importe adeudado | M1: Líneas de factura/Etiquetas | N1: Líneas de factura/Etiqueta | O1: Líneas de factura/Cantidad | P1: Líneas de factura/Precio unitario | Q1: Líneas de factura/Unidad de medida | R1: Apuntes contables/Líneas analíticas/Cuenta analítica | S1: Origen
B2: Publicado | C2: No pagadas | D2: 45900 | E2: 45907 | F2: -118800 | G2: Barrera, Adrian Jesus | H2: FA-C 00001-00000366 | J2: -118800 | K2: -118800 | L2: 118800 | N2: OC 0001-00001152: Gastos Operativos (C) Bidones de agua de 20 litros | O2: 33 | P2: 3600 | Q2: Unidad(es) | S2: OC 0001-00001152
B4: Publicado | C4: No pagadas | D4: 45900 | E4: 45930 | F4: -140842.95 | G4: Agroceres Pic Argentina S A | H4: FA-A 00008-00137653 | J4: -170419.97 | K4: -170419.97 | L4: 170419.97 | N4: DOSIS AGpic337 Roy | O4: 15 | P4: 9389.53 | Q4: Unidad(es)
B7: Publicado | C7: Pagado | D7: 45898 | E7: 45898 | F7: -2479500 | G7: Sueldos a pagar | H7: OC/2025/0131 | J7: -2479500 | K7: -2479500 | N7: ALBERTENGO GUIDO Pablos (ACUERDO) | O7: 1 | P7: 2479500
B9: Publicado | C9: Pagado | D9: 45898 | E9: 45898 | F9: -2137500 | G9: Sueldos a pagar | H9: OC/2025/0130 | J9: -2137500 | K9: -2137500 | N9: Albertengo Juan Ignacio(ACUERDO) | O9: 1 | P9: 2137500
B11: Publicado | C11: Pagado | D11: 45898 | E11: 45898 | F11: -1754639 | G11: Sueldos a pagar | H11: OC/2025/0129 | J11: -1754639 | K11: -1754639 | N11: Cristian Franco Emiliano Nicolas (ACUERDO) | O11: 1 | P11: 1754639
B13: Publicado | C13: Pagado | D13: 45898 | E13: 45898 | F13: -1459831.4 | G13: Sueldos a pagar | H13: OC/2025/0128 | J13: -1459831.4 | K13: -1459831.4 | N13: Cristian Franco Martin Andrés (ACUERDO) | O13: 1 | P13: 1459831.4
B15: Publicado | C15: Pagado | D15: 45898 | E15: 45898 | F15: -1302502 | G15: Sueldos a pagar | H15: OC/2025/0127 | J15: -1302502 | K15: -1302502 | N15: Cristian Joaquin Duran (ACUERDO) | O15: 1 | P15: 1302502
O16: 1 | P16: 0
B19: Publicado | C19: Pagado | D19: 45898 | E19: 45898 | F19: -200000 | G19: Sueldos a pagar | H19: OC/2025/0126 | J19: -200000 | K19: -200000 | N19: Cristian Leonardo Celaya (ACUERDO) | O19: 1 | P19: 200000
B21: Publicado | C21: No pagadas | D21: 45898 | E21: 45929 | F21: -3627176 | G21: Nutran S.R.L. | H21: FA-A 00002-00009786 | J21: -4388883 | K21: -4388883 | L21: 4388883 | N21: OC 0001-00000960: Fason(C) | O21: 1 | P21: 3627176 | Q21: Unidad(es) | S21: OC 0001-00000960
B24: Publicado | C24: Pagado | D24: 45898 | E24: 45912 | F24: -20774.4 | G24: Comercial Uritorco S. R. L. | H24: FA-A 00001-00006198 | J24: -25137.03 | K24: -25137.03 | N24: ALAMBRE RECOCIDO NEGRO 17=1.42XR ROLLO | O24: 1 | P24: 15580.8 | Q24: Unidad(es)
N25: ALAMBRE RECOCDIO NEGRO17=1.42X R ROLLO= 1KG | O25: 1 | P25: 5193.6 | Q25: Unidad(es)
B29: Publicado | C29: Pagado | D29: 45898 | E29: 45912 | F29: -66531.8 | G29: Comercial Uritorco S. R. L. | H29: FA-A 00001-00006197 | J29: -80503.48 | K29: -80503.48 | N29: AEROSOL AZUL 350ML.USO GENERAL TEK BOND | O29: 1 | P29: 33265.9 | Q29: Unidad(es)
N30: AEROSOL ROJO 350ML.ACRILICA TEK BOND | O30: 1 | P30: 33265.9 | Q30: Unidad(es)
B34: Publicado | C34: Pagado | D34: 45898 | E34: 45898 | F34: -90500.8 | G34: Pascual Materiales S. R. L. | H34: FA-A 00001-00000311 | J34: -109506.01 | K34: -109506.01 | N34: bolsas de cemento (hidroponia) | O34: 12 | P34: 4463.04 | Q34: Unidad(es)
N35: bolsas de cemento(recrea) | O35: 8 | P35: 4463.04 | Q35: Unidad(es)
N36: envió de mercaderia | O36: 1 | P36: 1240 | Q36: Unidad(es)
B41: Publicado | C41: Pagado | D41: 45897 | E41: 45897 | F41: -190449.86 | G41: ARCA | H41: OC/2025/0125 | J41: -190449.86 | K41: -190449.86 | O41: 1 | P41: 190449.86
B43: Publicado | C43: No pagadas | D43: 45897 | E43: 45912 | F43: -4500 | G43: Forconi, Marcos Roman | H43: FA-C 00001-00000305 | J43: -4500 | K43: -4500 | L43: 4500 | N43: diferencia aumento de septiembre | O43: 1 | P43: 4500 | Q43: Unidad(es)
B45: Publicado | C45: No pagadas | D45: 45897 | E45: 45912 | F45: -57999 | G45: Forconi, Marcos Roman | H45: FA-C 00001-00000290 | J45: -57999 | K45: -57999 | L45: 57999 | N45: Servicio mes de septiembre 2025 | O45: 1 | P45: 57999 | Q45: Unidad(es)
B47: Publicado | C47: Pagado | D47: 45897 | E47: 45897 | F47: -11172374 | G47: Topigs Norsvin Argentina S.R.L. | H47: FA-A 00011-00027677 | J47: -12345474 | K47: -12345474 | N47: abuelas cash gps plus genético | O47: 1 | P47: 11172374 | Q47: Unidad(es)
B50: Publicado | C50: Pagado | D50: 45896 | E50: 45896 | F50: -10539.86 | G50: Servicio Nacional De Sanidad Y Calidad Agroalimentaria Senasa | H50: OC/2025/0124 | J50: -10539.86 | K50: -10539.86 | N50: Gastos Operativos (C) | O50: 1 | P50: 10539.86 | Q50: Unidad(es)
B52: Publicado | C52: Pagado | D52: 45896 | E52: 45896 | F52: -1500000 | G52: Sueldos a pagar | H52: OC/2025/0123 | J52: -1500000 | K52: -1500000 | N52: Cristian Leonardo Celaya (ACUERDO) | O52: 1 | P52: 1500000 | S52: OC 0001-00001004
B54: Publicado | C54: Pagado | D54: 45895 | E54: 45895 | F54: -15711.62 | G54: Servicio Nacional De Sanidad Y Calidad Agroalimentaria Senasa | H54: OC/2025/0122 | J54: -15711.62 | K54: -15711.62 | N54: Gastos Operativos (C) | O54: 1 | P54: 15711.62 | Q54: Unidad(es)
B56: Publicado | C56: No pagadas | D56: 45896 | E56: 45958 | F56: -1200 | G56: Esperanza Distribuciones Srl | H56: FA-A 00026-00489583 | J56: -1452 | K56: -1452 | L56: 1452 | N56: gastos adm, de cheques | O56: 1 | P56: 1200 | Q56: Unidad(es)
B59: Publicado | C59: No pagadas | D59: 45896 | E59: 45911 | F59: -3352500 | G59: Arrieta, Fernando Gabriel | H59: FA-A 00003-00000285 | J59: -4056525 | K59: -4056525 | L59: 4056525 | N59: Flete, fecha : 04/08/2025 Calzim / Máximo paz kms:70 tipo: simple DTE: 29964925-29968915-CABEZAS: 85 CHOFER:GARFAGNOLI MATIAS | O59: 1 | P59: 415000 | Q59: Unidad(es)
N60: Flete-Fecha:07/08/2025 ARROYO SECO/MAXIMO PAZ KM: 70 TIPO:SOBLE dte:2199819957-2199820408-Cabezas:0 | O60: 1 | P60: 495000 | Q60: Unidad(es)
N61: Flete: Fceha_21/08/2025 Arroyo Seco /Maximo Paz kms:70 tipo:Simple DTE: 300861393 | O61: 1 | P61: 415000 | Q61: Unidad(es)
N62: LETE-fECHA:05/08/2025 Arroyo SEco /Máximo Paz kms: tipo: simple. Dte_2299721302-2299721426-2299721671 | O62: 1 | P62: 415000 | Q62: Unidad(es)
N63: Flete -Fecha:14/08/2025 Arroyo Seco/Maximo Paz kms: 70 Tipo: Doble DTE:300309143--cABEZAS:0 CHOFER: SCUOTRI OMAR | O63: 1 | P63: 495000 | Q63: Unidad(es)
N64: fLETE-fECHA:19/08/2025 aRROYO sECO/mAXIMO pAZ kms.70 tipo :chasis Dte:300795205 | O64: 1 | P64: 287500 | Q64: Unidad(es)
N65: Flete-Fecha:11/08/2025 Arroyo Seco/Maximo Paz KMs: 70 Tipo : Simple Dte: 2300127943-2300127606 cabezas:0 chofer ; scuotri Omar | O65: 1 | P65: 415000 | Q65: Unidad(es)
N66: Flete: Fecha:18/08/2025 Arroyo Seco/Maximo Paz Kms:70 Tipo: SIMPLEDTE:2300618057-2300617670-CABEZAS:0 CHOFER | O66: 1 | P66: 415000 | Q66: Unidad(es)
B76: Publicado | C76: Pagado | D76: 45896 | E76: 45910 | F76: -21409.9 | G76: Comercial Uritorco S. R. L. | H76: FA-A 00001-00006140 | J76: -25905.98 | K76: -25905.98 | N76: bulon whitwortk 5/16 x 1cincada taco metalico | O76: 1 | P76: 21409.9 | Q76: Unidad(es)
B79: Publicado | C79: Pagado | D79: 45896 | E79: 45910 | F79: -14355.27 | G79: Comercial Uritorco S. R. L. | H79: FA-A 00001-00000639 | J79: -17369.88 | K79: -17369.88 | N79: vaso magnetico hexag, disc diam segmentado(mantenimiento) | O79: 1 | P79: 14355.27 | Q79: Unidad(es)
B82: Publicado | C82: Pagado | D82: 45896 | E82: 45896 | F82: -36323.98 | G82: Pascual Materiales S. R. L. | H82: FA-A 00001-00000309 | J82: -43952.02 | K82: -43952.02 | N82: Cemento AVELLANEDA X 25KG DE MAYORISTA (RECRIA) | O82: 1 | P82: 36323.98 | Q82: Unidad(es)
B85: Publicado | C85: Pagado | D85: 45894 | E85: 45894 | F85: -332727.7 | G85: Administracion Provincial De Impuestos | H85: OC/2025/0119 | J85: -332727.7 | K85: -332727.7 | N85: SERVICIOS (C) | O85: 1 | P85: 332727.7 | Q85: Unidad(es)
B87: Publicado | C87: Pagado | D87: 45895 | E87: 45895 | F87: -266479.34 | G87: Pascual Materiales S. R. L. | H87: FA-A 00001-00000308 | J87: -322440 | K87: -322440 | N87: bolson de arena, piedras 6/19 x bolson, hieroo 10 por barra x 12mts, cemento avellaneda x 25 kg mayorista, servicio grua (hidroponía) | O87: 1 | P87: 266479.34 | Q87: Unidad(es)
B90: Publicado | C90: Pagado | D90: 45894 | E90: 45894 | F90: -12421.99 | G90: Servicio Nacional De Sanidad Y Calidad Agroalimentaria Senasa | H90: OC/2025/0121 | J90: -12421.99 | K90: -12421.99 | N90: Gastos Operativos (C) | O90: 1 | P90: 12421.99 | Q90: Unidad(es) | S90: OC 0001-00000985
...

Sheet facturacion
A1: Asiento | B1: Partner | C1: Provincia de entrega | D1: Fecha de factura | E1: Producto | F1: Apunte contable/Líneas analíticas/Cuenta analítica | G1: Cantidad producto | H1: Precio unitario | I1: Total libre de impuestos | J1: Total (CC)
A2: LCDP-A 00009-00002010 | B2: Gapre S R L | C2: Santa Fe (AR) | D2: 45898 | E2: CERDAS | G2: 2081 | H2: 1330 | I2: 2767730 | J2: 3058341.6
A3: LCDP-A 00009-00002009 | B3: Gapre S R L | C3: Santa Fe (AR) | D3: 45898 | E3: PORCINOS | G3: 3446 | H3: 1822.26 | I3: 6279508 | J3: 6938856.3
A4: LCDP-A 00009-00002008 | B4: Gapre S R L | C4: Santa Fe (AR) | D4: 45897 | E4: PORCINOS | G4: 13142 | H4: 1838.41 | I4: 24160384 | J4: 26697225
A5: LCDP-A 00002-00000172 | B5: Gaspari, Leonardo Sergio | C5: Santa Fe (AR) | D5: 45897 | E5: PORCINOS | G5: 3324 | H5: 1330 | I5: 4420920 | J5: 4885116.6
A6: LCDP-A 00009-00002006 | B6: Gapre S R L | C6: Santa Fe (AR) | D6: 45895 | E6: PORCINOS | G6: 5433 | H6: 1890.56 | I6: 10271412 | J6: 11349911
A7: LCDP-A 00009-00002007 | B7: Gapre S R L | C7: Santa Fe (AR) | D7: 45895 | E7: PORCINOS | G7: 4004 | H7: 1876.27 | I7: 7512585.1 | J7: 8301406.5
A8: LCDP-A 00009-00002003 | B8: Gapre S R L | C8: Santa Fe (AR) | D8: 45894 | E8: PORCINOS | G8: 3358 | H8: 1891.51 | I8: 6351690.6 | J8: 7018618.1
A9: LCDP-A 00009-00002002 | B9: Gapre S R L | C9: Santa Fe (AR) | D9: 45894 | E9: CERDAS | G9: 1079 | H9: 1330 | I9: 1435070 | J9: 1585752.4
A10: LCDP-A 00009-00002001 | B10: Gapre S R L | C10: Santa Fe (AR) | D10: 45894 | E10: CERDAS | G10: 2403 | H10: 1330 | I10: 3195990 | J10: 3531569
A11: LCDP-A 00002-00000169 | B11: Gaspari, Leonardo Sergio | C11: Santa Fe (AR) | D11: 45890 | E11: PORCINOS | G11: 3090 | H11: 1450 | I11: 4480500 | J11: 4950952.5
A12: LCDP-A 00009-00002000 | B12: Gapre S R L | C12: Santa Fe (AR) | D12: 45890 | E12: PORCINOS | G12: 13908 | H12: 1798.36 | I12: 25011591 | J12: 27637808
A13: LCDP-A 00002-00000170 | B13: Gaspari, Leonardo Sergio | C13: Santa Fe (AR) | D13: 45890 | E13: PORCINOS | G13: 3831 | H13: 1550 | I13: 5938050 | J13: 6561545.2
... A32: LCDP-A 00009-00001981 | B32: Gapre S R L | C32: Santa Fe (AR) | D32: 45873 | E32: PORCINOS | G32: 10823 | H32: 1754.26 | I32: 18986356 | J32: 20979923

Sheet Vista_RUBRO
B2: TOTAL CALZIM
B3: VENTAS | C3: =SUM(venta_nico!F:F) -> 3.8425232e+08
B4: OPEX | C4: =D11 -> 3.3910724e+08
B5: UTILIDAD | C5: =C3-C4 -> 45145074
B6: CAPEX | C6: =SUMIFS(union_gastos!$D:$D,union_gastos!$J:$J,B6) -> 0
B7: DEUDA | C7: =SUMIFS(union_gastos!$D:$D,union_gastos!$J:$J,B7)*-1 -> 225721.37
B8: Flujo de Caja al Accionista | C8: =C5-C6-C7 -> 44919352
B11: OPEX | D11: =SUM(D12:D22) -> 3.3910724e+08
B12: 2 | C12: NUTRICIÓN | D12: =SUMIFS(union_gastos!$D:$D,union_gastos!$J:$J,"OPEX",union_gastos!$P:$P,Vista_RUBRO!C12)*-1 -> 2.0105721e+08 | E12: =D12/$D$11 -> 0.59290156
B13: 9 | C13: PERSONAL | D13: =SUMIFS(union_gastos!$D:$D,union_gastos!$J:$J,"OPEX",union_gastos!$P:$P,Vista_RUBRO!C13) -> 49609364 | E13: =D13/$D$11 -> 0.14629403
B14: 1 | C14: SANIDAD | D14: =SUMIFS(union_gastos!$D:$D,union_gastos!$J:$J,"OPEX",union_gastos!$P:$P,Vista_RUBRO!C14)*-1 -> 23353554 | E14: =D14/$D$11 -> 0.068867753
B15: 7 | C15: GENÉTICA | D15: =SUMIFS(union_gastos!$D:$D,union_gastos!$J:$J,"OPEX",union_gastos!$P:$P,Vista_RUBRO!C15)*-1 -> 8511805.7 | E15: =D15/$D$11 -> 0.025100631
B16: 10 | C16: FLETES | D16: =SUMIFS(union_gastos!$D:$D,union_gastos!$J:$J,"OPEX",union_gastos!$P:$P,Vista_RUBRO!C16)*-1 -> 6921200 | E16: =D16/$D$11 -> 0.020410062
B17: 3 | C17: ENERGÍA | D17: =SUMIFS(union_gastos!$D:$D,union_gastos!$J:$J,"OPEX",union_gastos!$P:$P,Vista_RUBRO!C17)*-1 -> 12284042 | E17: =D17/$D$11 -> 0.036224651
B18: 8 | C18: MANTENIMIENTO | D18: =SUMIFS(union_gastos!$D:$D,union_gastos!$J:$J,"OPEX",union_gastos!$P:$P,Vista_RUBRO!C18)*-1 -> 5755846.3 | E18: =D18/$D$11 -> 0.016973528
B19: 6 | C19: GASTOS OPERATIVOS | D19: =SUMIFS(union_gastos!$D:$D,union_gastos!$J:$J,"OPEX",union_gastos!$P:$P,Vista_RUBRO!C19)*-1 -> 23312174 | E19: =D19/$D$11 -> 0.068745728
B20: 5 | C20: IMPUESTOS | D20: =SUMIFS(union_gastos!$D:$D,union_gastos!$J:$J,"OPEX",union_gastos!$P:$P,Vista_RUBRO!C20)*-1 -> 6008871.6 | E20: =D20/$D$11 -> 0.017719679
B21: 11 | C21: HONORARIOS | D21: =SUMIFS(union_gastos!$D:$D,union_gastos!$J:$J,"OPEX",union_gastos!$P:$P,Vista_RUBRO!C21)*-1 -> 2293173.5 | E21: =D21/$D$11 -> 0.0067623844
C22: SERVICIOS | D22: =SUMIFS(union_gastos!$D:$D,union_gastos!$J:$J,"OPEX",union_gastos!$P:$P,Vista_RUBRO!C22)*-1 -> 0 | E22: =D22/$D$11 -> 0
B24: VENTAS POR FACTURAS | D24: =C3 -> 3.8425232e+08
B26: RESULTADO NETO | D26: =D22-D11 -> -3.3910724e+08
B27: MARGEN BRUTO | D27: =D29/D24 -> 0.1174881
B29: UTILDAD OPERATIVA | D29: =D24-D11 -> 45145074
B31: DEUDA | D31: =SUMIFS('BD Gastos_DICIEMBRE'!$V:$V,'BD Gastos_DICIEMBRE'!$Z:$Z,1,'BD Gastos_DICIEMBRE'!A:A,1) -> 0
B32: CAPEX | D32: =SUMIFS('BD Gastos_DICIEMBRE'!$V:$V,'BD Gastos_DICIEMBRE'!$AA:$AA,1,'BD Gastos_DICIEMBRE'!A:A,1) -> 0
B34: Flujo de Caja al Accionista | D34: =D29-D31-D32 -> 45145074

Sheet costos
A1: Asiento | B1: Partner | C1: Provincia de entrega | D1: Fecha de factura | E1: Producto | F1: Cantidad producto | G1: Precio unitario | H1: Total libre de impuestos | I1: Total (CC) | J1: Estado de factura
A2: FA-C 00001-00000366 | B2: Barrera, Adrian Jesus | C2: Santa Fe (AR) | D2: 45900 | E2: Gastos Operativos (C) | F2: -33 | G2: 3600 | H2: -118800 | I2: -118800 | J2: Abierto
A3: FA-A 00008-00137653 | B3: Agroceres Pic Argentina S A | C3: Ciudad Autónoma de Buenos Aires (AR) | D3: 45900 | E3: Genetica (C) | F3: -15 | G3: 9389.53 | H3: -140842.95 | I3: -170419.97 | J3: Abierto
A4: OC/2025/0128 | B4: Sueldos a pagar | D4: 45898 | F4: -1 | G4: 1459831.4 | H4: -1459831.4 | I4: -1459831.4 | J4: Abierto
A5: OC/2025/0130 | B5: Sueldos a pagar | D5: 45898 | F5: -1 | G5: 2137500 | H5: -2137500 | I5: -2137500 | J5: Abierto
A6: OC/2025/0129 | B6: Sueldos a pagar | D6: 45898 | F6: -1 | G6: 1754639 | H6: -1754639 | I6: -1754639 | J6: Abierto
A7: OC/2025/0126 | B7: Sueldos a pagar | D7: 45898 | F7: -1 | G7: 200000 | H7: -200000 | I7: -200000 | J7: Abierto
A8: FA-A 00001-00006197 | B8: Comercial Uritorco S. R. L. | C8: Santa Fe (AR) | D8: 45898 | E8: Reparaciones y repuestos (C) | F8: -1 | G8: 33265.9 | H8: -33265.9 | I8: -40251.74 | J8: Abierto
A9: FA-A 00001-00006197 | B9: Comercial Uritorco S. R. L. | C9: Santa Fe (AR) | D9: 45898 | E9: Reparaciones y repuestos (C) | F9: -1 | G9: 33265.9 | H9: -33265.9 | I9: -40251.74 | J9: Abierto
A10: FA-A 00001-00006198 | B10: Comercial Uritorco S. R. L. | C10: Santa Fe (AR) | D10: 45898 | E10: Reparaciones y repuestos (C) | F10: -1 | G10: 15580.8 | H10: -15580.8 | I10: -18852.77 | J10: Abierto
A11: FA-A 00001-00006198 | B11: Comercial Uritorco S. R. L. | C11: Santa Fe (AR) | D11: 45898 | E11: Reparaciones y repuestos (C) | F11: -1 | G11: 5193.6 | H11: -5193.6 | I11: -6284.26 | J11: Abierto
A12: OC/2025/0127 | B12: Sueldos a pagar | D12: 45898 | F12: -1 | G12: 1302502 | H12: -1302502 | I12: -1302502 | J12: Abierto
A13: FA-A 00001-00000311 | B13: Pascual Materiales S. R. L. | C13: Santa Fe (AR) | D13: 45898 | E13: Mantenimiento (C) | F13: -1 | G13: 1240 | H13: -1240 | I13: -1500.4 | J13: Abierto
A14: FA-A 00001-00000311 | B14: Pascual Materiales S. R. L. | C14: Santa Fe (AR) | D14: 45898 | E14: Mantenimiento (C) | F14: -8 | G14: 4463.04 | H14: -35704.32 | I14: -43202.23 | J14: Abierto
A15: OC/2025/0127 | B15: Sueldos a pagar | D15: 45898 | F15: -1 | J15: Abierto
A16: FA-A 00001-00000311 | B16: Pascual Materiales S. R. L. | C16: Santa Fe (AR) | D16: 45898 | E16: Mantenimiento (C) | F16: -12 | G16: 4463.04 | H16: -53556.48 | I16: -64803.34 | J16: Abierto
A17: OC/2025/0131 | B17: Sueldos a pagar | D17: 45898 | F17: -1 | G17: 2479500 | H17: -2479500 | I17: -2479500 | J17: Abierto
A18: FA-A 00011-00027677 | B18: Topigs Norsvin Argentina S.R.L. | C18: Ciudad Autónoma de Buenos Aires (AR) | D18: 45897 | E18: Genetica (C) | F18: -1 | G18: 11172374 | H18: -11172374 | I18: -12345474 | J18: Abierto
A19: FA-C 00001-00000305 | B19: Forconi, Marcos Roman | C19: Santa Fe (AR) | D19: 45897 | E19: SS de terceros (C) | F19: -1 | G19: 4500 | H19: -4500 | I19: -4500 | J19: Abierto
A20: FA-C 00001-00000290 | B20: Forconi, Marcos Roman | C20: Santa Fe (AR) | D20: 45897 | E20: SS de terceros (C) | F20: -1 | G20: 57999 | H20: -57999 | I20: -57999 | J20: Abierto
A21: OC/2025/0125 | B21: ARCA | D21: 45897 | F21: -1 | G21: 190449.86 | H21: -190449.86 | I21: -190449.86 | J21: Abierto
A22: OC/2025/0124 | B22: Servicio Nacional De Sanidad Y Calidad Agroalimentaria Senasa | C22: Ciudad Autónoma de Buenos Aires (AR) | D22: 45896 | E22: Gastos Operativos (C) | F22: -1 | G22: 10539.86 | H22: -10539.86 | I22: -10539.86 | J22: Abierto
A23: FA-A 00003-00000285 | B23: Arrieta, Fernando Gabriel | C23: Santa Fe (AR) | D23: 45896 | E23: Fletes (C) | F23: -1 | G23: 495000 | H23: -495000 | I23: -598950 | J23: Abierto
A24: FA-A 00003-00000285 | B24: Arrieta, Fernando Gabriel | C24: Santa Fe (AR) | D24: 45896 | E24: Fletes (C) | F24: -1 | G24: 415000 | H24: -415000 | I24: -502150 | J24: Abierto
A25: FA-A 00003-00000285 | B25: Arrieta, Fernando Gabriel | C25: Santa Fe (AR) | D25: 45896 | E25: Fletes (C) | F25: -1 | G25: 415000 | H25: -415000 | I25: -502150 | J25: Abierto
A26: FA-A 00003-00000285 | B26: Arrieta, Fernando Gabriel | C26: Santa Fe (AR) | D26: 45896 | E26: Fletes (C) | F26: -1 | G26: 495000 | H26: -495000 | I26: -598950 | J26: Abierto
A27: FA-A 00003-00000285 | B27: Arrieta, Fernando Gabriel | C27: Santa Fe (AR) | D27: 45896 | E27: Fletes (C) | F27: -1 | G27: 415000 | H27: -415000 | I27: -502150 | J27: Abierto
A28: FA-A 00003-00000285 | B28: Arrieta, Fernando Gabriel | C28: Santa Fe (AR) | D28: 45896 | E28: Fletes (C) | F28: -1 | G28: 415000 | H28: -415000 | I28: -502150 | J28: Abierto
A29: OC/2025/0123 | B29: Sueldos a pagar | D29: 45896 | F29: -1 | G29: 1500000 | H29: -1500000 | I29: -1500000 | J29: Abierto
A30: NC-A 00011-00010896 (Reversión de: FA-A 00011-00050785) | B30: Rosario Agro Industrial Srl | C30: Santa Fe (AR) | D30: 45896 | E30: Mantenimiento (C) | F30: 1 | G30: 72865 | H30: 72865 | I30: 88166.65 | J30: Abierto
A31: FA-A 00001-00000309 | B31: Pascual Materiales S. R. L. | C31: Santa Fe (AR) | D31: 45896 | E31: Mantenimiento (C) | F31: -1 | G31: 36323.98 | H31: -36323.98 | I31: -43952.02 | J31: Abierto
A32: FA-A 00001-00006140 | B32: Comercial Uritorco S. R. L. | C32: Santa Fe (AR) | D32: 45896 | E32: Reparaciones y repuestos (C) | F32: -1 | G32: 21409.9 | H32: -21409.9 | I32: -25905.98 | J32: Abierto
A33: FA-A 00001-00000639 | B33: Comercial Uritorco S. R. L. | C33: Santa Fe (AR) | D33: 45896 | E33: Reparaciones y repuestos (C) | F33: -1 | G33: 14355.27 | H33: -14355.27 | I33: -17369.88 | J33: Abierto
A34: FA-A 00026-00489583 | B34: Esperanza Distribuciones Srl | C34: Santa Fe (AR) | D34: 45896 | E34: Sanidad (C) | F34: -1 | G34: 1200 | H34: -1200 | I34: -1452 | J34: Abierto
A35: FA-A 00003-00000285 | B35: Arrieta, Fernando Gabriel | C35: Santa Fe (AR) | D35: 45896 | E35: Fletes (C) | F35: -1 | G35: 287500 | H35: -287500 | I35: -347875 | J35: Abierto
A36: FA-A 00003-00000285 | B36: Arrieta, Fernando Gabriel | C36: Santa Fe (AR) | D36: 45896 | E36: Fletes (C) | F36: -1 | G36: 415000 | H36: -415000 | I36: -502150 | J36: Abierto
A37: FA-A 00001-00000308 | B37: Pascual Materiales S. R. L. | C37: Santa Fe (AR) | D37: 45895 | E37: Mantenimiento (C) | F37: -1 | G37: 266479.34 | H37: -266479.34 | I37: -322440 | J37: Abierto
A38: OC/2025/0122 | B38: Servicio Nacional De Sanidad Y Calidad Agroalimentaria Senasa | C38: Ciudad Autónoma de Buenos Aires (AR) | D38: 45895 | E38: Gastos Operativos (C) | F38: -1 | G38: 15711.62 | H38: -15711.62 | I38: -15711.62 | J38: Abierto
A39: FA-A 00001-00006079 | B39: Comercial Uritorco S. R. L. | C39: Santa Fe (AR) | D39: 45894 | E39: Reparaciones y repuestos (C) | F39: -1 | G39: 37110.11 | H39: -37110.11 | I39: -44903.23 | J39: Abierto
A40: FA-A 00001-00000306 | B40: Pascual Materiales S. R. L. | C40: Santa Fe (AR) | D40: 45894 | E40: Mantenimiento (C) | F40: -1 | G40: 176269.65 | H40: -176269.65 | I40: -213286.28 | J40: Abierto
...

Sheet BBDD_PROVEEDORES_FINAL
A1: ID | B1: PROVEEDOR | C1: CANAL | D1: CONCEPTO | E1: TIPO 1 (DIRECTO/INDIRECTO) | F1: TIPO 2 (FIJO/VARIABLE) | G1: RUBRO | H1: AREA | I1: UN | J1: CUIT | K1: ESTADO | L1: METODO_DE_PAGO | M1: CUIT2 | N1: Nombre Fantasia | O1: Teléfono | P1: Mail | Q1: Contacto | R1: Direccion | S1: Observaciones | T1: Canal de pago | U1: ESTADO2 | V1: PDP | W1: INTERESES MORATORIO MENSUAL | X1: Total_con_signo_2025 | Y1: Crédito máximo asignado | Z1: Base Aine
A2: 30684082627 | B2: Vetifarma S A | C2: 1 | D2: OPEX | E2: DIRECTO | F2: VARIABLE | H2: PORCINOS | I2: GRAL | J2: 30684082627 | K2: ACTIVO | L2: TRANSF | M2: 30684082627 | N2: Vetifarma S A | O2: +54 9 221 617-6065 | P2: vetifarma@vetifarma.com.ar | T2: 1 | U2: ACTIVO | V2: 2 | W2: 0 | X2: 1.3358374e+09 | Y2: 46900000
A3: 30707140514 | B3: Nutran S.R.L. | C3: 1 | D3: OPEX | E3: DIRECTO | F3: VARIABLE | H3: PORCINOS | I3: GRAL | J3: 30707140514 | K3: ACTIVO | L3: TRANSF | M3: 30707140514 | N3: Nutran S.R.L. | O3: +54 9 3469 69-3367 | P3: nutransrl@gmail.com | T3: 1 | U3: ACTIVO | V3: 2 | W3: 0 | X3: 6.3956659e+08 | Y3: 12400000
A4: 30716107309 | B4: Agroindustrial Cosanic S.R.L. | C4: 1 | D4: OPEX | E4: INDIRECTO | F4: VARIABLE | H4: PORCINOS | I4: GRAL | J4: 30716107309 | K4: ACTIVO | L4: TRANSF | M4: 30716107309 | N4: Agroindustrial Cosanic S.R.L. | O4: +54 9 2266 46-4650 | P4: admin1.agroindustrial@grupocosanic.com | T4: 1 | U4: ACTIVO | V4: 2 | W4: 0 | X4: 5.4080364e+08 | Y4: 54100000
A5: 30586988359 | B5: Drovet S A | C5: 1 | D5: OPEX | E5: DIRECTO | F5: VARIABLE | H5: PORCINOS | I5: GRAL | J5: 30586988359 | K5: ACTIVO | L5: TRANSF | M5: 30586988359 | N5: Drovet S A | O5: +54 9 341 311-8981 | T5: 1 | U5: ACTIVO | V5: 2 | W5: 0 | X5: 4.4233435e+08 | Y5: 4100000
A6: a_000006 | B6: Sueldos a pagar | C6: 1 | D6: OPEX | E6: DIRECTO | F6: FIJO | H6: PORCINOS | I6: GRAL | K6: ACTIVO | L6: TRANSF | N6: Sueldos a pagar | T6: 1 | U6: ACTIVO | V6: 1 | W6: 0 | X6: 4.1250728e+08 | Y6: 11500000
A7: 30663202657 | B7: Agroceres Pic Argentina S A | C7: 1 | D7: OPEX | E7: DIRECTO | F7: VARIABLE | H7: PORCINOS | I7: GRAL | J7: 30663202657 | K7: ACTIVO | L7: TRANSF | M7: 30663202657 | N7: Agroceres Pic Argentina S A | O7: +54 11 6658-6406 | P7: administracion@agroceres.com. | T7: 1 | U7: ACTIVO | V7: 2 | W7: 0 | X7: 2.9507223e+08 | Y7: 3100000
A8: 23175073779 | B8: Arrieta, Fernando Gabriel | C8: 1 | D8: OPEX | E8: DIRECTO | F8: VARIABLE | H8: PORCINOS | I8: GRAL | J8: 23175073779 | K8: ACTIVO | L8: TRANSF | M8: 23175073779 | N8: Arrieta, Fernando Gabriel | O8: +54 9 3402 65-9154 | T8: 1 | U8: ACTIVO | V8: 2 | W8: 0 | X8: 2.6441406e+08 | Y8: 9800000
A9: a_000079 | B9: Sueldos ok | C9: 1 | D9: OPEX | E9: INDIRECTO | F9: FIJO | H9: PORCINOS | I9: GRAL | K9: ACTIVO | L9: TRANSF | N9: Sueldos ok | T9: 1 | U9: ACTIVO | V9: 1 | W9: 0 | X9: 222416675 | Y9: 74100000
A10: 20305330516 | B10: Colella, Santiago Nicolas | C10: 1 | D10: OPEX | E10: INDIRECTO | F10: VARIABLE | H10: PORCINOS | I10: GRAL | J10: 20305330516 | K10: ACTIVO | L10: TRANSF | M10: 20305330516 | N10: Colella, Santiago Nicolas | T10: 1 | U10: ACTIVO | V10: 2 | W10: 0 | X10: 155685895 | Y10: 51900000
A11: 30713986808 | B11: La Quinta Eventos S.R.L. | C11: 1 | D11: OPEX | E11: DIRECTO | F11: VARIABLE | H11: PORCINOS | I11: GRAL | J11: 30713986808 | K11: ACTIVO | L11: TRANSF | M11: 30713986808 | N11: La Quinta Eventos S.R.L. | O11: +54 9 3402 50-5858 | T11: 1 | U11: ACTIVO | V11: 3 | W11: 0 | X11: 1.3675182e+08 | Y11: 6500000
A12: 30714259012 | B12: SAN AGUSTIN CEREALES | C12: 1 | D12: OPEX | E12: DIRECTO | F12: VARIABLE | H12: PORCINOS | I12: GRAL | J12: 30714259012 | K12: ACTIVO | L12: TRANSF | M12: 30714259012 | N12: SAN AGUSTIN CEREALES | T12: 1 | U12: ACTIVO | V12: 2 | W12: 0 | X12: 1.1006013e+08 | Y12: 110100000
A13: 30545788167 | B13: Empresa Provincial De La Energia De Santa Fe | C13: 1 | D13: OPEX | E13: DIRECTO | F13: VARIABLE | H13: PORCINOS | I13: GRAL | J13: 30545788167 | K13: ACTIVO | L13: TRANSF | M13: 30545788167 | N13: Empresa Provincial De La Energia De Santa Fe | T13: 1 | U13: ACTIVO | V13: 2 | W13: 0 | X13: 1.0926222e+08 | Y13: 7300000
A14: 30710882564 | B14: Topigs Norsvin Argentina S.R.L. | C14: 1 | D14: OPEX | E14: DIRECTO | F14: VARIABLE | H14: PORCINOS | I14: GRAL | J14: 30710882564 | K14: ACTIVO | L14: TRANSF | M14: 30710882564 | N14: Topigs Norsvin Argentina S.R.L. | T14: 1 | U14: ACTIVO | V14: 2 | W14: 0 | X14: 99028637 | Y14: 19800000
A15: 30709181714 | B15: Jacycec S.R.L. | C15: 1 | D15: OPEX | E15: INDIRECTO | F15: VARIABLE | H15: PORCINOS | I15: GRAL | J15: 30709181714 | K15: ACTIVO | L15: TRANSF | M15: 30709181714 | N15: Jacycec S.R.L. | T15: 1 | U15: ACTIVO | V15: 2 | W15: 0 | X15: 89096426 | Y15: 17800000
A16: 30708982713 | B16: Los Rolleros S. R. L. | C16: 1 | D16: OPEX | E16: INDIRECTO | F16: VARIABLE | H16: PORCINOS | I16: GRAL | J16: 30708982713 | K16: ACTIVO | L16: TRANSF | M16: 30708982713 | N16: Los Rolleros S. R. L. | T16: 1 | U16: ACTIVO | V16: 2 | W16: 0 | X16: 65096730 | Y16: 13000000
A17: 30619484807 | B17: Esperanza Distribuciones Srl | C17: 1 | D17: OPEX | E17: INDIRECTO | F17: VARIABLE | H17: PORCINOS | I17: GRAL | J17: 30619484807 | K17: ACTIVO | L17: TRANSF | M17: 30619484807 | N17: Esperanza Distribuciones Srl | O17: +54 9 3496 57-7789 | T17: 1 | U17: ACTIVO | V17: 2 | W17: 0 | X17: 54410645 | Y17: 2000000
A18: 20247725238 | B18: Rojas, Juan Manuel | C18: 1 | D18: OPEX | E18: INDIRECTO | F18: VARIABLE | H18: PORCINOS | I18: GRAL | J18: 20247725238 | K18: ACTIVO | L18: TRANSF | M18: 20247725238 | N18: Rojas, Juan Manuel | O18: +54 9 341 687-3022 | T18: 1 | U18: ACTIVO | V18: 2 | W18: 0 | X18: 45556500 | Y18: 4600000
A19: 27059351899 | B19: Sacco, Alicia Iris | C19: 1 | D19: OPEX | E19: INDIRECTO | F19: VARIABLE | H19: PORCINOS | I19: GRAL | J19: 27059351899 | K19: ACTIVO | L19: TRANSF | M19: 27059351899 | N19: Sacco, Alicia Iris | T19: 1 | U19: ACTIVO | V19: 3 | W19: 0 | X19: 42275888 | Y19: 84600000
A20: 30711239991 | B20: Tfin Sa | C20: 1 | D20: OPEX | E20: INDIRECTO | F20: VARIABLE | H20: PORCINOS | I20: GRAL | J20: 30711239991 | K20: ACTIVO | L20: TRANSF | M20: 30711239991 | N20: Tfin Sa | P20: franciscoa@tfinancial.com.ar | T20: 1 | U20: ACTIVO | V20: 1 | W20: 0 | X20: 40384888 | Y20: 3200000
A21: 30622309730 | B21: Rosario Insumos Agropecuarios Sa | C21: 1 | D21: OPEX | E21: INDIRECTO | F21: VARIABLE | H21: PORCINOS | I21: GRAL | J21: 30622309730 | K21: ACTIVO | L21: TRANSF | M21: 30622309730 | N21: Rosario Insumos Agropecuarios Sa | T21: 1 | U21: ACTIVO | V21: 3 | W21: 0 | X21: 36686441 | Y21: 10500000
A22: 30685484303 | B22: Establecimiento Do#A Teresa S R L | C22: 1 | D22: OPEX | E22: INDIRECTO | F22: VARIABLE | H22: PORCINOS | I22: GRAL | J22: 30685484303 | K22: ACTIVO | L22: TRANSF | M22: 30685484303 | N22: Establecimiento Do#A Teresa S R L | T22: 1 | U22: ACTIVO | V22: 3 | W22: 0 | X22: 35956055 | Y22: 6500000
A23: 20241865070 | B23: Eliceche, Adrian Alberto | C23: 1 | D23: OPEX | E23: INDIRECTO | F23: VARIABLE | H23: PORCINOS | I23: GRAL | J23: 20241865070 | K23: ACTIVO | L23: TRANSF | M23: 20241865070 | N23: Eliceche, Adrian Alberto | T23: 1 | U23: ACTIVO | V23: 3 | W23: 0 | X23: 33946281 | Y23: 8500000
A24: 30717713431 | B24: Don Vitto Wa-La S.A.S. | C24: 1 | D24: OPEX | E24: INDIRECTO | F24: VARIABLE | H24: PORCINOS | I24: GRAL | J24: 30717713431 | K24: ACTIVO | L24: TRANSF | M24: 30717713431 | N24: Don Vitto Wa-La S.A.S. | T24: 1 | U24: ACTIVO | V24: 3 | W24: 0 | X24: 31000000 | Y24: 31000000
A25: 20227667592 | B25: D Angela, Sergio | C25: 1 | D25: OPEX | E25: INDIRECTO | F25: VARIABLE | H25: PORCINOS | I25: GRAL | J25: 20227667592 | K25: ACTIVO | L25: TRANSF | M25: 20227667592 | N25: D Angela, Sergio | O25: +54 9 341 505-5497 | T25: 1 | U25: ACTIVO | V25: 3 | W25: 0 | X25: 30748919 | Y25: 7700000
A26: 30718209222 | B26: Grupo Nodo Gestion Ambiental S.R.L. | C26: 1 | D26: OPEX | E26: INDIRECTO | F26: VARIABLE | H26: PORCINOS | I26: GRAL | J26: 30718209222 | K26: ACTIVO | L26: TRANSF | M26: 30718209222 | N26: Grupo Nodo Gestion Ambiental S.R.L. | O26: +54 9 221 643-0789 | T26: 1 | U26: ACTIVO | V26: 3 | W26: 0 | X26: 29678727 | Y26: 3100000
A27: 30716299852 | B27: Special Commodity Srl | C27: 1 | D27: OPEX | E27: INDIRECTO | F27: VARIABLE | H27: PORCINOS | I27: GRAL | J27: 30716299852 | K27: ACTIVO | L27: TRANSF | M27: 30716299852 | N27: Special Commodity Srl | T27: 1 | U27: ACTIVO | V27: 3 | W27: 0 | X27: 28881955 | Y27: 28900000
A28: 30500049460 | B28: Sancor Cooperativa De Seguros Limitada | C28: 1 | D28: OPEX | E28: INDIRECTO | F28: VARIABLE | H28: PORCINOS | I28: GRAL | J28: 30500049460 | K28: ACTIVO | L28: TRANSF | M28: 30500049460 | N28: Sancor Cooperativa De Seguros Limitada | O28: +54 3462 55-5654 | T28: 1 | U28: ACTIVO | V28: 3 | W28: 0 | X28: 26306820 | Y28: 52600000
A29: 30500049460 | B29: Sancor Cooperativa De Seguros Limitada | C29: 1 | D29: OPEX | E29: INDIRECTO | F29: VARIABLE | H29: PORCINOS | I29: GRAL | J29: 30500049460 | K29: ACTIVO | L29: TRANSF | M29: 30500049460 | N29: Sancor Cooperativa De Seguros Limitada | O29: +54 3462 55-5654 | T29: 1 | U29: ACTIVO | V29: 3 | W29: 0 | X29: 26306820 | Y29: 52600000
A30: 33715110909 | B30: Estudio De Profesionales Sa | C30: 1 | D30: OPEX | E30: INDIRECTO | F30: VARIABLE | H30: PORCINOS | I30: GRAL | J30: 33715110909 | K30: ACTIVO | L30: TRANSF | M30: 33715110909 | N30: Estudio De Profesionales Sa | O30: +54 9 341 657-5087 | T30: 1 | U30: ACTIVO | V30: 3 | W30: 0 | X30: 25913438 | Y30: 2100000
A31: a_000020 | B31: ARCA | C31: 1 | D31: OPEX | E31: INDIRECTO | F31: VARIABLE | H31: PORCINOS | I31: GRAL | K31: ACTIVO | L31: TRANSF | N31: ARCA | T31: 1 | U31: ACTIVO | V31: 4 | W31: 0 | X31: 23783407 | Y31: 3000000
A32: 20172586776 | B32: Cesaretti, Fernando Rene | C32: 1 | D32: OPEX | E32: INDIRECTO | F32: VARIABLE | H32: PORCINOS | I32: GRAL | J32: 20172586776 | K32: ACTIVO | L32: TRANSF | M32: 20172586776 | N32: Cesaretti, Fernando Rene | T32: 1 | U32: ACTIVO | V32: 4 | W32: 0 | X32: 22912729 | Y32: 7600000
A33: 30500001735 | B33: Banco De Galicia Y Buenos Aires S A U | C33: 1 | D33: OPEX | E33: INDIRECTO | F33: VARIABLE | H33: PORCINOS | I33: GRAL | J33: 30500001735 | K33: ACTIVO | L33: TRANSF | M33: 30500001735 | N33: Banco De Galicia Y Buenos Aires S A U | T33: 1 | U33: ACTIVO | V33: 4 | W33: 0 | X33: 21264640 | Y33: 21300000
A34: 20287965444 | B34: Perez, Rodrigo Alejandro | C34: 1 | D34: OPEX | E34: INDIRECTO | F34: VARIABLE | H34: PORCINOS | I34: GRAL | J34: 20287965444 | K34: ACTIVO | L34: TRANSF | M34: 20287965444 | N34: Perez, Rodrigo Alejandro | T34: 1 | U34: ACTIVO | V34: 4 | W34: 0 | X34: 20463053 | Y34: 20500000
A35: 20173241985 | B35: Matteo, Marcelo Mario | C35: 1 | D35: OPEX | E35: INDIRECTO | F35: VARIABLE | H35: PORCINOS | I35: GRAL | J35: 20173241985 | K35: ACTIVO | L35: TRANSF | M35: 20173241985 | N35: Matteo, Marcelo Mario | T35: 1 | U35: ACTIVO | V35: 4 | W35: 0 | X35: 18140297 | Y35: 3000000
A36: 33707409369 | B36: Afe Sociedad Civil | C36: 1 | D36: OPEX | E36: INDIRECTO | F36: VARIABLE | H36: PORCINOS | I36: GRAL | J36: 33707409369 | K36: ACTIVO | L36: TRANSF | M36: 33707409369 | N36: Afe Sociedad Civil | O36: +54 9 341 657-5087 | T36: 1 | U36: ACTIVO | V36: 4 | W36: 0 | X36: 16413582 | Y36: 1200000
A37: 20123698372 | B37: Donda, Ruben Estelio | C37: 1 | D37: OPEX | E37: INDIRECTO | F37: VARIABLE | H37: PORCINOS | I37: GRAL | J37: 20123698372 | K37: ACTIVO | L37: TRANSF | M37: 20123698372 | N37: Donda, Ruben Estelio | T37: 1 | U37: ACTIVO | V37: 4 | W37: 0 | X37: 14100000 | Y37: 3100000
A38: 30670799758 | B38: Grantec Sa | C38: 1 | D38: OPEX | E38: INDIRECTO | F38: VARIABLE | H38: PORCINOS | I38: GRAL | J38: 30670799758 | K38: ACTIVO | L38: TRANSF | M38: 30670799758 | N38: Grantec Sa | O38: +54 9 3442 55-3871 | T38: 1 | U38: ACTIVO | V38: 4 | W38: 0 | X38: 13897098 | Y38: 9300000
A39: 20345257595 | B39: Ventura, Agustin | C39: 1 | D39: OPEX | E39: INDIRECTO | F39: VARIABLE | H39: PORCINOS | I39: GRAL | J39: 20345257595 | K39: ACTIVO | L39: TRANSF | M39: 20345257595 | N39: Ventura, Agustin | T39: 1 | U39: ACTIVO | V39: 4 | W39: 0 | X39: 13812500 | Y39: 13800000
A40: 20233291073 | B40: Bieule, Cesar | C40: 1 | D40: OPEX | E40: INDIRECTO | F40: VARIABLE | H40: PORCINOS | I40: GRAL | J40: 20233291073 | K40: ACTIVO | L40: TRANSF | M40: 20233291073 | N40: Bieule, Cesar | T40: 1 | U40: ACTIVO | V40: 4 | W40: 0 | X40: 13310000 | Y40: 6700000
...

Sheet union_gastos
A1: Fecha de Factura/Recibo | B1: Nombre de la empresa a mostrar en la factura | C1: Número | D1: Total con signo | E1: Líneas de factura/Etiqueta | F1: Líneas de factura/Cantidad | G1: Líneas de factura/Precio unitario | H1: Líneas de factura/Unidad de medida | I1: Líneas de factura/Producto | J1: Concepto | K1: Tipo de Gasto 1 | L1: Tipo de Gasto 2 | M1: CCO - SECTOR | N1: origen | O1: rubro_id | P1: rubro_final
A2: 46112 | B2: Alimento | C2: nico_2 | D2: -1.7861696e+08 | E2: calculo_alimentos_total | F2: 432780 | G2: 412.72 | H2: KG | I2: Nutrición | J2: OPEX | K2: VARIABLE | L2: DIRECTO | N2: nutri&rrhh | O2: =_xlfn.XLOOKUP(union_gastos[[#This Row],[Líneas de factura/Producto]],'concepto_id'!A:A,'concepto_id'!B:B) -> 1 | P2: =_xlfn.XLOOKUP(union_gastos[[#This Row],[rubro_id]],rubros!B:B,rubros!A:A) -> NUTRICIÓN
A3: 46112 | B3: Nutran | C3: nico_1 | D3: -21985644 | E3: fason_calculo_alimentos_1 | F3: 423330 | G3: 47 | H3: KG | I3: Nutrición | J3: OPEX | K3: VARIABLE | L3: DIRECTO | N3: nutri&rrhh | O3: =_xlfn.XLOOKUP(union_gastos[[#This Row],[Líneas de factura/Producto]],'concepto_id'!A:A,'concepto_id'!B:B) -> 1 | P3: =_xlfn.XLOOKUP(union_gastos[[#This Row],[rubro_id]],rubros!B:B,rubros!A:A) -> NUTRICIÓN
A4: 46090 | B4: Empresa Provincial De La Energia De Santa Fe | C4: FA-A 00069-00039924 | D4: -12284042 | E4: Energia (C) | F4: 1 | G4: 8313807.3 | H4: Unidad(es) | I4: Energia (C) | J4: OPEX | K4: VARIABLE | L4: DIRECTO | N4: gastos_facturas | O4: =_xlfn.XLOOKUP(union_gastos[[#This Row],[Líneas de factura/Producto]],'concepto_id'!A:A,'concepto_id'!B:B) -> 11 | P4: =_xlfn.XLOOKUP(union_gastos[[#This Row],[rubro_id]],rubros!B:B,rubros!A:A) -> ENERGÍA
A5: 46104 | B5: Trt S.A. | C5: FA-A 00012-00058059 | D5: -4849392.4 | E5: Sanidad (C) IMPROVAC X 125 DS | F5: 20 | G5: 183017.71 | H5: Unidad(es) | I5: Sanidad (C) | J5: OPEX | K5: VARIABLE | L5: DIRECTO | N5: gastos_facturas | O5: =_xlfn.XLOOKUP(union_gastos[[#This Row],[Líneas de factura/Producto]],'concepto_id'!A:A,'concepto_id'!B:B) -> 3 | P5: =_xlfn.XLOOKUP(union_gastos[[#This Row],[rubro_id]],rubros!B:B,rubros!A:A) -> SANIDAD
A6: 46108 | B6: ARCA 931 | C6: OC/2026/0149 | D6: -4772839.3 | E6: IMPUESTO (C) Obra Social Diciembre | F6: 1 | G6: 4772839.3 | H6: Unidad(es) | I6: IMPUESTO (C) | J6: OPEX | K6: VARIABLE | L6: INDIRECTO | N6: gastos_facturas | O6: =_xlfn.XLOOKUP(union_gastos[[#This Row],[Líneas de factura/Producto]],'concepto_id'!A:A,'concepto_id'!B:B) -> 8 | P6: =_xlfn.XLOOKUP(union_gastos[[#This Row],[rubro_id]],rubros!B:B,rubros!A:A) -> IMPUESTOS
A7: 46091 | B7: Establecimiento Do#A Teresa S R L | C7: FA-A 00005-00008597 | D7: -4673960 | E7: Gastos Operativos (C) Gastos Operativos (C) Alquiler mes Marzo Campo Tonfoni | F7: 2000 | G7: 2278.48 | H7: Unidad(es) | I7: Gastos Operativos (C) | J7: OPEX | K7: FIJO | L7: INDIRECTO | N7: gastos_facturas | O7: =_xlfn.XLOOKUP(union_gastos[[#This Row],[Líneas de factura/Producto]],'concepto_id'!A:A,'concepto_id'!B:B) -> 7 | P7: =_xlfn.XLOOKUP(union_gastos[[#This Row],[rubro_id]],rubros!B:B,rubros!A:A) -> GASTOS OPERATIVOS
A8: 46094 | B8: Drovet S A | C8: FA-A 00330-00214077 | D8: -3748727.7 | E8: Sanidad (C) Porcilis pcv | F8: 26 | G8: 65042.2 | H8: Unidad(es) | I8: Sanidad (C) | J8: OPEX | K8: VARIABLE | L8: DIRECTO | N8: gastos_facturas | O8: =_xlfn.XLOOKUP(union_gastos[[#This Row],[Líneas de factura/Producto]],'concepto_id'!A:A,'concepto_id'!B:B) -> 3 | P8: =_xlfn.XLOOKUP(union_gastos[[#This Row],[rubro_id]],rubros!B:B,rubros!A:A) -> SANIDAD
A9: 46083 | B9: Arrieta, Fernando Gabriel | C9: FA-A 00003-00000538 | D9: -3460600 | E9: Fletes (C) DOBLE 02/02 / 09/02 | F9: 2 | G9: 550000 | H9: Unidad(es) | I9: Fletes (C) | J9: OPEX | K9: VARIABLE | L9: INDIRECTO | N9: gastos_facturas | O9: =_xlfn.XLOOKUP(union_gastos[[#This Row],[Líneas de factura/Producto]],'concepto_id'!A:A,'concepto_id'!B:B) -> 5 | P9: =_xlfn.XLOOKUP(union_gastos[[#This Row],[rubro_id]],rubros!B:B,rubros!A:A) -> FLETES
A10: 46092 | B10: Drovet S A | C10: FA-A 00330-00013592 | D10: -3042226.4 | E10: Sanidad (C) coglapix x 50 ds | F10: 44 | G10: 47926 | H10: Unidad(es) | I10: Sanidad (C) | J10: OPEX | K10: VARIABLE | L10: DIRECTO | N10: gastos_facturas | O10: =_xlfn.XLOOKUP(union_gastos[[#This Row],[Líneas de factura/Producto]],'concepto_id'!A:A,'concepto_id'!B:B) -> 3 | P10: =_xlfn.XLOOKUP(union_gastos[[#This Row],[rubro_id]],rubros!B:B,rubros!A:A) -> SANIDAD
A11: 46097 | B11: Trt S.A. | C11: FA-A 00012-00057855 | D11: -3010390.4 | E11: Sanidad (C) HYOGEN | F11: 54 | G11: 45807.7 | H11: Unidad(es) | I11: Sanidad (C) | J11: OPEX | K11: VARIABLE | L11: DIRECTO | N11: gastos_facturas | O11: =_xlfn.XLOOKUP(union_gastos[[#This Row],[Líneas de factura/Producto]],'concepto_id'!A:A,'concepto_id'!B:B) -> 3 | P11: =_xlfn.XLOOKUP(union_gastos[[#This Row],[rubro_id]],rubros!B:B,rubros!A:A) -> SANIDAD
A12: 46092 | B12: Drovet S A | C12: FA-A 00330-00213643 | D12: -2889639 | E12: Sanidad (C) Hypra suis glasser x 50 DS | F12: 54 | G12: 43307.45 | H12: Unidad(es) | I12: Sanidad (C) | J12: OPEX | K12: VARIABLE | L12: DIRECTO | N12: gastos_facturas | O12: =_xlfn.XLOOKUP(union_gastos[[#This Row],[Líneas de factura/Producto]],'concepto_id'!A:A,'concepto_id'!B:B) -> 3 | P12: =_xlfn.XLOOKUP(union_gastos[[#This Row],[rubro_id]],rubros!B:B,rubros!A:A) -> SANIDAD
A13: 46094 | B13: Agroceres Pic Argentina S A | C13: FA-A 00004-00021027 | D13: -2494688.1 | E13: Genetica (C) Royalty lechón destetado macho | F13: 1110 | G13: 1846.73 | H13: Unidad(es) | I13: Genetica (C) | J13: OPEX | K13: VARIABLE | L13: DIRECTO | N13: gastos_facturas | O13: =_xlfn.XLOOKUP(union_gastos[[#This Row],[Líneas de factura/Producto]],'concepto_id'!A:A,'concepto_id'!B:B) -> 4 | P13: =_xlfn.XLOOKUP(union_gastos[[#This Row],[rubro_id]],rubros!B:B,rubros!A:A) -> GENÉTICA
... A110: 46112 | B110: HABERES | C110: remu | D110: 49609364 | E110: planilla de andres | F110: 23 | G110: -2156928.9 | H110: #RRHH | I110: Personal | J110: OPEX | K110: OPEX | L110: FIJO | N110: nutri&rrhh | O110: =_xlfn.XLOOKUP(union_gastos[[#This Row],[Líneas de factura/Producto]],'concepto_id'!A:A,'concepto_id'!B:B) -> 2 | P110: =_xlfn.XLOOKUP(union_gastos[[#This Row],[rubro_id]],rubros!B:B,rubros!A:A) -> PERSONAL

Sheet concepto_id
A1: CONCEPTO | B1: ID | C1: Column3 | D1: Column4 | E1: Column5 | F1: Column6 | G1: Column7 | H1: Column8
A2: Honorarios (C) | B2: 9
A3: IMPUESTO (C) | B3: 8
A4: Genetica (C) | B4: 4
A5: Mantenimiento (C) | B5: 6
A6: Fletes (C) | B6: 5
A7: SERVICIOS (C) | B7: 10
A8: NUTRICION | B8: 1
A9: Sanidad (C) | B9: 3
A10: PERSONAL (C) | B10: 2
A11: rrhh_andy1 | B11: 2
A12: rrhh_andy2 | B12: 2
A13: rrhh_andy3 | B13: 2
... A93: Reparaciones y repuestos (C) | B93: 6

Sheet facturas_ingresos
A1: Actividades | B1: Estado | C1: Estado de pago | D1: Fecha de Factura/Recibo | E1: Fecha de vencimiento | F1: Importe sin impuestos con signo | G1: Nombre de la empresa a mostrar en la factura | H1: Número | I1: Referencia | J1: Total con signo | K1: Total en divisa con signo | L1: Importe adeudado | M1: Líneas de factura/Etiquetas | N1: Líneas de factura/Etiqueta | O1: Líneas de factura/Cantidad | P1: Líneas de factura/Precio unitario | Q1: Líneas de factura/Unidad de medida | R1: Apuntes contables/Líneas analíticas/Cuenta analítica | S1: Origen | T1: Líneas de factura/Producto
B2: Publicado | C2: No pagadas | D2: 46022 | E2: 46028 | F2: 1933516 | G2: Worms Argentina S.A ok | H2: FA-M 00001-00000041 | J2: 2339554.4 | K2: 2339554.4 | L2: 2339554.4 | N2: Efluentes solidos (cama profunda)recibidos durante el mes de diciembre 2025 | O2: 93860 | P2: 20.6 | Q2: Unidad(es) | T2: Efluentes solidos (cama profunda)
B3: Publicado | C3: No pagadas | D3: 46022 | E3: 46028 | F3: 33616589 | G3: Worms Argentina S.A ok | H3: FA-M 00001-00000040 | J3: 40676072 | K3: 40676072 | L3: 40676072 | N3: Efluentes liquidos (biol)recibidos durante el mes de diciembre 2025 | O3: 174080 | P3: 193.11 | Q3: Unidad(es) | T3: Efluentes liquidos (biol)
B4: Publicado | C4: Pagado | D4: 46021 | E4: 46041 | F4: 6313300 | G4: Gaspari, Leonardo Sergio | H4: LCDP-A 00002-00000207 | J4: 6976196.5 | K4: 6976196.5 | N4: PORCINOS | O4: 4354 | P4: 1450 | Q4: kg | S4: OV 0001-00001266 | T4: PORCINOS
B5: Publicado | C5: No pagadas | D5: 46021 | E5: 46052 | F5: 5250055.7 | G5: De La Fuente Florencia | H5: FA-M 00001-00000039 | J5: 5801311.6 | K5: 5801311.6 | L5: 5801311.6 | N5: KG DE CARNE CAPON PORCINOS PORCINOS | O5: 3031 | P5: 1732.12 | Q5: Unidad(es) | S5: OV 0001-00001273 | T5: KG DE CARNE CAPON PORCINOS
B6: Publicado | C6: Revertido | D6: 46020 | E6: 46021 | F6: 1792744.2 | G6: Gonzalez Maximiliano Eduardo | H6: ND-M 00001-00000001 | J6: 1980982.3 | K6: 1980982.3 | N6: KG DE CARNE CAPON PORCINOS PORCINOS | O6: 1035 | P6: 1732.12 | Q6: Unidad(es) | T6: KG DE CARNE CAPON PORCINOS
B7: Publicado | C7: No pagadas | D7: 46020 | E7: 46038 | F7: 5267150 | G7: Gapre S R L | H7: LCDP-A 00009-00002095 | J7: 5820200.8 | K7: 5820200.8 | L7: 5820200.8 | N7: PORCINOS | O7: 3725 | P7: 1414 | Q7: kg | S7: OV 0001-00001148 | T7: PORCINOS
B8: Publicado | C8: Pagado | D8: 46020 | E8: 46039 | F8: 3970891.6 | G8: Pura Raza S.A.S. | H8: FA-M 00001-00000038 | J8: 4387835.3 | K8: 4387835.3 | N8: KG DE CARNE CAPON PORCINOS PORCINOS | O8: 1965 | P8: 2020.81 | Q8: Unidad(es) | S8: OV 0001-00001242 | T8: KG DE CARNE CAPON PORCINOS
B9: Publicado | C9: Pagado | D9: 46020 | E9: 46039 | F9: 7720058.8 | G9: Rovetto, Carlos Alberto | H9: FA-M 00001-00000037 | J9: 8530665 | K9: 8530665 | N9: KG DE CARNE CAPON PORCINOS PORCINOS | O9: 4457 | P9: 1732.12 | Q9: Unidad(es) | S9: OV 0001-00001241 | T9: KG DE CARNE CAPON PORCINOS
B10: Publicado | C10: Revertido | D10: 46020 | E10: 46025 | F10: 1792744.2 | G10: Gonzalez Maximiliano Eduardo | H10: FA-M 00001-00000035 | J10: 1980982.3 | K10: 1980982.3 | N10: KG DE CARNE CAPON PORCINOS PORCINOS | O10: 1035 | P10: 1732.12 | Q10: Unidad(es) | S10: OV 0001-00001239 | T10: KG DE CARNE CAPON PORCINOS
B11: Publicado | C11: Pagado Parcialmente | D11: 46020 | E11: 46041 | F11: 8638082.4 | G11: Rovetto, Carlos Alberto | H11: FA-M 00001-00000034 | J11: 9545081.1 | K11: 9545081.1 | L11: 9361337.8 | N11: KG DE CARNE CAPON PORCINOS PORCINOS | O11: 4987 | P11: 1732.12 | Q11: Unidad(es) | S11: OV 0001-00001237 | T11: KG DE CARNE CAPON PORCINOS
B12: Publicado | C12: Pagado | D12: 46020 | E12: 46039 | F12: 3730415.3 | G12: Pura Raza S.A.S. | H12: FA-M 00001-00000033 | J12: 4122108.9 | K12: 4122108.9 | N12: KG DE CARNE CAPON PORCINOS PORCINOS | O12: 1846 | P12: 2020.81 | Q12: Unidad(es) | S12: OV 0001-00001238 | T12: KG DE CARNE CAPON PORCINOS
B13: Publicado | C13: Pagado | D13: 46018 | E13: 46025 | F13: 788114.6 | G13: RATONE PAOLA | H13: FA-M 00001-00000036 | J13: 870866.63 | K13: 870866.63 | N13: KG DE CARNE CAPON PORCINOS PORCINOS | O13: 455 | P13: 1732.12 | Q13: Unidad(es) | S13: OV 0001-00001240 | T13: KG DE CARNE CAPON PORCINOS
B14: Publicado | C14: No pagadas | D14: 46013 | E14: 46031 | F14: 14205044 | G14: Gapre S R L | H14: LCDP-A 00009-00002094 | J14: 15696574 | K14: 15696574 | L14: 15696574 | N14: PORCINOS | O14: 10046 | P14: 1414 | Q14: kg | S14: OV 0001-00001236 | T14: PORCINOS
B15: Publicado | C15: No pagadas | D15: 46013 | E15: 46031 | F15: 1888538.4 | G15: Gapre S R L | H15: LCDP-A 00009-00002093 | J15: 2086834.9 | K15: 2086834.9 | L15: 2086834.9 | N15: CERDAS | O15: 1908 | P15: 989.8 | Q15: kg | S15: OV 0001-00001235 | T15: CERDAS
B16: Publicado | C16: No pagadas | D16: 46013 | E16: 46031 | F16: 5344920 | G16: Gapre S R L | H16: LCDP-A 00009-00002092 | J16: 5906136.6 | K16: 5906136.6 | L16: 5906136.6 | N16: PORCINOS | O16: 3780 | P16: 1414 | Q16: kg | S16: OV 0001-00001234 | T16: PORCINOS
B17: Publicado | C17: Pagado Parcialmente | D17: 46013 | E17: 46031 | F17: 14654696 | G17: Gapre S R L | H17: LCDP-A 00009-00002091 | J17: 16193439 | K17: 16193439 | L17: 3388083.5 | N17: PORCINOS | O17: 10364 | P17: 1414 | Q17: kg | S17: OV 0001-00001233 | T17: PORCINOS
B18: Publicado | C18: Pagado | D18: 46013 | E18: 46024 | F18: 18181212 | G18: Gapre S R L | H18: LCDP-A 00009-00002090 | J18: 20090239 | K18: 20090239 | N18: PORCINOS | O18: 12858 | P18: 1414 | Q18: kg | S18: OV 0001-00001232 | T18: PORCINOS
B19: Publicado | C19: Pagado | D19: 46013 | E19: 46013 | F19: 6403200 | G19: Gaspari, Leonardo Sergio | H19: LCDP-A 00002-00000205 | J19: 7075536 | K19: 7075536 | N19: PORCINOS | O19: 4416 | P19: 1450 | Q19: kg | S19: OV 0001-00001226 | T19: PORCINOS
B20: Publicado | C20: Pagado | D20: 46009 | E20: 46022 | F20: 935635.03 | G20: DIAMBRI FEDERICO | H20: FA-M 00001-00000032 | J20: 1033876.7 | K20: 1033876.7 | N20: KG DE CARNE CAPON PORCINOS PORCINOS | O20: 463 | P20: 2020.81 | Q20: Unidad(es) | S20: OV 0001-00001217 | T20: KG DE CARNE CAPON PORCINOS
B21: Publicado | C21: Pagado | D21: 46008 | E21: 46036 | F21: 4080015.4 | G21: Pura Raza S.A.S. | H21: FA-M 00001-00000031 | J21: 4508417 | K21: 4508417 | N21: KG DE CARNE CAPON PORCINOS PORCINOS | O21: 2019 | P21: 2020.81 | Q21: Unidad(es) | S21: OV 0001-00001211 | T21: KG DE CARNE CAPON PORCINOS
B22: Publicado | C22: Pagado | D22: 46008 | E22: 46029 | F22: 4077994.6 | G22: Pura Raza S.A.S. | H22: FA-M 00001-00000030 | J22: 4506184 | K22: 4506184 | N22: KG DE CARNE CAPON PORCINOS PORCINOS | O22: 2018 | P22: 2020.81 | Q22: Unidad(es) | S22: OV 0001-00001210 | T22: KG DE CARNE CAPON PORCINOS
B23: Publicado | C23: Pagado | D23: 46008 | E23: 46028 | F23: 8284730 | G23: Rovetto, Carlos Alberto | H23: FA-M 00001-00000029 | J23: 9154626.6 | K23: 9154626.6 | N23: KG DE CARNE CAPON PORCINOS PORCINOS | O23: 4783 | P23: 1732.12 | Q23: Unidad(es) | S23: OV 0001-00001203 | T23: KG DE CARNE CAPON PORCINOS
B24: Publicado | C24: No pagadas | D24: 46008 | E24: 46032 | F24: 4905363.8 | G24: SANVIRO S.A | H24: FA-M 00001-00000028 | J24: 5420427 | K24: 5420427 | L24: 5420427 | N24: KG DE CARNE CAPON PORCINOS PORCINOS | O24: 2832 | P24: 1732.12 | Q24: Unidad(es) | S24: OV 0001-00000999 | T24: KG DE CARNE CAPON PORCINOS
B25: Publicado | C25: Pagado Parcialmente | D25: 46008 | E25: 46025 | F25: 4903631.7 | G25: SANVIRO S.A | H25: FA-M 00001-00000027 | J25: 5418513 | K25: 5418513 | L25: 4947329.1 | N25: KG DE CARNE CAPON PORCINOS PORCINOS | O25: 2831 | P25: 1732.12 | Q25: Unidad(es) | S25: OV 0001-00000998 | T25: KG DE CARNE CAPON PORCINOS
B26: Publicado | C26: Pagado | D26: 46008 | E26: 46018 | F26: 5139200 | G26: SANVIRO S.A | H26: FA-M 00001-00000026 | J26: 5678816 | K26: 5678816 | N26: KG DE CARNE CAPON PORCINOS PORCINOS | O26: 2967 | P26: 1732.12 | Q26: Unidad(es) | S26: OV 0001-00000997 | T26: KG DE CARNE CAPON PORCINOS
B27: Publicado | C27: Pagado | D27: 46007 | E27: 46024 | F27: 10846794 | G27: Gapre S R L | H27: LCDP-A 00009-00002089 | J27: 11985707 | K27: 11985707 | N27: PORCINOS | O27: 7671 | P27: 1414 | Q27: kg | S27: OV 0001-00001231 | T27: PORCINOS
B28: Publicado | C28: Pagado | D28: 46006 | E28: 46024 | F28: 11242714 | G28: Gapre S R L | H28: LCDP-A 00009-00002088 | J28: 12423199 | K28: 12423199 | N28: PORCINOS | O28: 7951 | P28: 1414 | Q28: kg | S28: OV 0001-00001147 | T28: PORCINOS
B29: Publicado | C29: Pagado | D29: 46006 | E29: 46017 | F29: 2577439.2 | G29: Gapre S R L | H29: LCDP-A 00009-00002087 | J29: 2848070.3 | K29: 2848070.3 | N29: CERDAS | O29: 2604 | P29: 989.8 | Q29: kg | S29: OV 0001-00001223 | T29: CERDAS
B30: Publicado | C30: Pagado | D30: 46006 | E30: 46017 | F30: 470155 | G30: Gapre S R L | H30: LCDP-A 00009-00002086 | J30: 519521.28 | K30: 519521.28 | N30: CERDAS | O30: 475 | P30: 989.8 | Q30: kg | S30: OV 0001-00001222 | T30: CERDAS
B31: Publicado | C31: Pagado | D31: 46006 | E31: 46017 | F31: 11234230 | G31: Gapre S R L | H31: LCDP-A 00009-00002085 | J31: 12413824 | K31: 12413824 | N31: PORCINOS | O31: 7945 | P31: 1414 | Q31: kg | S31: OV 0001-00001146 | T31: PORCINOS
B32: Publicado | C32: Pagado | D32: 46004 | E32: 46010 | F32: 4292500 | G32: Livolti, Maria | H32: LCDP-A 00001-00000788 | J32: 4743212.5 | K32: 4743212.5 | N32: PORCINOS | O32: 2125 | P32: 2020 | Q32: kg | S32: OV 0001-00001216 | T32: PORCINOS
B33: Publicado | C33: Pagado | D33: 46003 | E33: 46024 | F33: 8631154 | G33: Rovetto, Carlos Alberto | H33: FA-M 00001-00000025 | J33: 9537425.1 | K33: 9537425.1 | N33: KG DE CARNE CAPON PORCINOS PORCINOS | O33: 4983 | P33: 1732.12 | Q33: Unidad(es) | S33: OV 0001-00001184 | T33: KG DE CARNE CAPON PORCINOS
B34: Publicado | C34: Pagado | D34: 46002 | E34: 46017 | F34: 193920 | G34: Gapre S R L | H34: LCDP-A 00009-00002084 | J34: 214281.6 | K34: 214281.6 | N34: PORCINOS | O34: 160 | P34: 1212 | Q34: kg | S34: OV 0001-00001206 | T34: PORCINOS
B35: Publicado | C35: Pagado | D35: 46000 | E35: 46016 | F35: 16481988 | G35: Gapre S R L | H35: LCDP-A 00009-00002083 | J35: 18212597 | K35: 18212597 | N35: PORCINOS | O35: 13599 | P35: 1212 | Q35: kg | S35: OV 0001-00001205 | T35: PORCINOS
B36: Publicado | C36: No pagadas | D36: 46000 | E36: 46002 | F36: 2081549.4 | G36: Cooperativa Agricola Ganadera Aaron Castellanos Ltda De Esperanza | H36: LCDP-A 00004-00000247 | J36: 2300112.1 | K36: 2300112.1 | L36: 2300112.1 | N36: CERDAS | O36: 2103 | P36: 989.8 | Q36: kg | T36: CERDAS
B37: Publicado | C37: Revertido | D37: 46000 | E37: 46002 | F37: 2973642 | G37: Cooperativa Agricola Ganadera Aaron Castellanos Ltda De Esperanza | H37: LCDP-A 00004-00000245 | J37: 3285874.4 | K37: 3285874.4 | N37: CERDAS | O37: 2103 | P37: 1414 | Q37: kg | T37: CERDAS
B38: Publicado | C38: Pagado | D38: 46000 | E38: 46015 | F38: 3898142.5 | G38: Pura Raza S.A.S. | H38: FA-M 00001-00000024 | J38: 4307447.5 | K38: 4307447.5 | N38: KG DE CARNE CAPON PORCINOS PORCINOS | O38: 1929 | P38: 2020.81 | Q38: Unidad(es) | S38: OV 0001-00001177 | T38: KG DE CARNE CAPON PORCINOS
B39: Publicado | C39: Pagado | D39: 46000 | E39: 46020 | F39: 8535887.4 | G39: Rovetto, Carlos Alberto | H39: FA-M 00001-00000023 | J39: 9432155.5 | K39: 9432155.5 | N39: KG DE CARNE CAPON PORCINOS PORCINOS | O39: 4928 | P39: 1732.12 | Q39: Unidad(es) | S39: OV 0001-00001175 | T39: KG DE CARNE CAPON PORCINOS
B40: Publicado | C40: Pagado | D40: 46000 | E40: 46013 | F40: 2691714.5 | G40: Rovetto, Carlos Alberto | H40: FA-M 00001-00000022 | J40: 2974344.5 | K40: 2974344.5 | N40: KG DE CARNE CAPON PORCINOS PORCINOS | O40: 1554 | P40: 1732.12 | Q40: Unidad(es) | S40: OV 0001-00001174 | T40: KG DE CARNE CAPON PORCINOS
...

Sheet venta_nico
A1: FACTURACION | B1: Cantidades | C1: kg_promedio | D1: Precio promedio | E1: Final +IVA | F1: Subtotal
A2: CAPON | B2: 1280 | C2: 114.36 | D2: 2427.63 | E2: 2592.95 | F2: =B2*C2*E2 -> 3.795581e+08
A3: CHANCHA | B3: 11 | C3: 263.4 | D3: 1510.79 | E3: 1620.15 | F3: =B3*C3*E3 -> 4694222.6

Sheet rubros
A1: RUBRO | B1: ID
A2: NUTRICIÓN | B2: 1
A3: PERSONAL | B3: 2
A4: SANIDAD | B4: 3
A5: GENÉTICA | B5: 4
A6: FLETES | B6: 5
A7: ENERGÍA | B7: 11
A8: MANTENIMIENTO | B8: 6
A9: GASTOS OPERATIVOS | B9: 7
A10: IMPUESTOS | B10: 8
A11: HONORARIOS | B11: 9
A12: SERVICIOS | B12: 10

Sheet nutri&rrhh
A1: Fecha de Factura/Recibo | B1: Nombre de la empresa a mostrar en la factura | C1: Número | D1: Total con signo | E1: Líneas de factura/Etiqueta | F1: Líneas de factura/Cantidad | G1: Líneas de factura/Precio unitario | H1: Líneas de factura/Unidad de medida | I1: Líneas de factura/Producto | J1: Concepto | K1: Tipo de Gasto 1 | L1: Tipo de Gasto 2 | M1: CCO - SECTOR
A2: 46112 | B2: Nutran | C2: nico_1 | D2: -21985644 | E2: fason_calculo_alimentos_1 | F2: 423330 | G2: 47 | H2: KG | I2: Nutrición | J2: OPEX | K2: VARIABLE | L2: DIRECTO
A3: 46112 | B3: Alimento | C3: nico_2 | D3: -1.7861696e+08 | E3: calculo_alimentos_total | F3: 432780 | G3: 412.72 | H3: KG | I3: Nutrición | J3: OPEX | K3: VARIABLE | L3: DIRECTO
A4: 46112 | B4: Nutran | C4: nico_3 | D4: -454608 | E4: embolsado_calculo_alimentos_3 | F4: 15785 | G4: 28.8 | H4: KG | I4: Nutrición | J4: OPEX | K4: OPEX | L4: VARIABLE
A5: 46112 | B5: HABERES | C5: remu | D5: 49609364 | E5: planilla de andres | F5: 23 | G5: -2156928.9 | H5: #RRHH | I5: Personal | J5: OPEX | K5: OPEX | L5: FIJO

Sheet gastos_facturas
A1: Fecha de Factura/Recibo | B1: Nombre de la empresa a mostrar en la factura | C1: Número | D1: Total con signo | E1: Líneas de factura/Etiqueta | F1: Líneas de factura/Cantidad | G1: Líneas de factura/Precio unitario | H1: Líneas de factura/Unidad de medida | I1: Líneas de factura/Producto | J1: Concepto | K1: Tipo de Gasto 1 | L1: Tipo de Gasto 2 | M1: CCO - SECTOR
A2: 46112 | B2: Servicio Nacional De Sanidad Y Calidad Agroalimentaria Senasa | C2: OC/2026/0155 | D2: -21642.72 | E2: IMPUESTO (C) | F2: 1 | G2: 21642.72 | H2: Unidad(es) | I2: IMPUESTO (C) | J2: OPEX | K2: FIJO | L2: DIRECTO
A3: 46112 | B3: Correa, Natalia Erica | C3: OC/2026/0152 | D3: -51343.54 | E3: Honorarios (C) | F3: 1 | G3: 51343.54 | H3: Unidad(es) | I3: Honorarios (C) | J3: OPEX | K3: VARIABLE | L3: INDIRECTO
A4: 46112 | B4: Barrera, Adrian Jesus | C4: FA-C 00001-00000437 | D4: -225600 | E4: Gastos Operativos (C) | F4: 47 | G4: 4800 | H4: Unidad(es) | I4: Gastos Operativos (C) | J4: OPEX | K4: VARIABLE | L4: INDIRECTO
A5: 46112 | B5: Esperanza Distribuciones Srl | C5: FA-A 00026-00530141 | D5: -127060.24 | E5: Sanidad (C) Despadac | F5: 1 | G5: 105008.46 | H5: Unidad(es) | I5: Sanidad (C) | J5: OPEX | K5: VARIABLE | L5: DIRECTO
A6: 46112 | B6: Agroceres Pic Argentina S A | C6: FA-A 00008-00151527 | D6: -913335.72 | E6: Genetica (C) Dosis AGPIC337 IU ROY I | F6: 62 | G6: 10264.94 | H6: Unidad(es) | I6: Genetica (C) | J6: OPEX | K6: VARIABLE | L6: DIRECTO | U6: Genetica (C)
A7: 46112 | B7: Agroceres Pic Argentina S A | C7: FA-A 00008-00015564 | D7: -279170.81 | E7: Genetica (C) DOSIS AG1020 ABUELO VISTA | F7: 3 | G7: 76906.56 | H7: Unidad(es) | I7: Genetica (C) | J7: OPEX | K7: VARIABLE | L7: DIRECTO
A8: 46112 | B8: Comercial Uritorco S. R. L. | C8: FA-A 00001-00009311 | D8: -293208.43 | E8: Mantenimiento (C) Espiga c/rosca, espig.dob., piton cincado, taco universal, teflon , poliet, espiga , aerosol rojo, azul, verde, alambre recocido negro | F8: 1 | G8: 242321.02 | H8: Unidad(es) | I8: Mantenimiento (C) | J8: OPEX | K8: VARIABLE | L8: INDIRECTO
A9: 46111 | B9: Topigs Norsvin Argentina S.R.L. | C9: FA-A 00011-00034214 | D9: -265043.43 | E9: Genetica (C) Semen Linea TLLL Pedido correspondientess del 16 al 22 de marzo | F9: 96 | G9: 2281.71 | H9: Unidad(es) | I9: Genetica (C) | J9: OPEX | K9: VARIABLE | L9: DIRECTO
A10: 46111 | B10: Agroceres Pic Argentina S A | C10: FA-A 00008-00151320 | D10: -513577.89 | E10: Genetica (C) Dosis AGPIC337 IU ROY I | F10: 30 | G10: 10264.94 | H10: Unidad(es) | I10: Genetica (C) | J10: OPEX | K10: VARIABLE | L10: DIRECTO
A11: 46111 | B11: Bca Distribuciones Sa | C11: FA-A 00001-00005944 | D11: -303732.45 | E11: Mantenimiento (C) TEE EPOXI HH 1/2 | F11: 20 | G11: 1520.5179 | H11: Unidad(es) | I11: Mantenimiento (C) | J11: OPEX | K11: VARIABLE | L11: INDIRECTO
A12: 46109 | B12: Trt S.A. | C12: FA-A 00012-00058283 | D12: -839050 | E12: Sanidad (C) cheque nª 57879404 | F12: 1 | G12: 839050 | H12: Unidad(es) | I12: Sanidad (C) | J12: OPEX | K12: VARIABLE | L12: DIRECTO
A13: 46108 | B13: Servicio Nacional De Sanidad Y Calidad Agroalimentaria Senasa | C13: OC/2026/0151 | D13: -22857.09 | E13: IMPUESTO (C) | F13: 1 | G13: 22857.09 | H13: Unidad(es) | I13: IMPUESTO (C) | J13: OPEX | K13: FIJO | L13: DIRECTO
A14: 46108 | B14: Asociacion Empleados De Comercio De Rosario | C14: OC/2026/0150 | D14: -522382.82 | E14: Gastos Operativos (C) Requerimiento | F14: 1 | G14: 522382.82 | H14: Unidad(es) | I14: Gastos Operativos (C) | J14: OPEX | K14: VARIABLE | L14: INDIRECTO
A15: 46108 | B15: ARCA 931 | C15: OC/2026/0149 | D15: -4772839.3 | E15: IMPUESTO (C) Obra Social Diciembre | F15: 1 | G15: 4772839.3 | H15: Unidad(es) | I15: IMPUESTO (C) | J15: OPEX | K15: VARIABLE | L15: INDIRECTO
A16: 46108 | B16: Carrizo, Juan Mario | C16: FA-C 00001-00000217 | D16: -520000 | E16: Mantenimiento (C) reparación de bomba sumergible (Bomba quemada de worms) | F16: 1 | G16: 520000 | H16: Unidad(es) | I16: Mantenimiento (C) | J16: OPEX | K16: VARIABLE | L16: DIRECTO
A17: 46108 | B17: Seproa S.R.L. | C17: FA-A 00004-00006273 | D17: -104544 | E17: Gastos Operativos (C) | F17: 20 | G17: 4320 | H17: Unidad(es) | I17: Gastos Operativos (C) | J17: OPEX | K17: VARIABLE | L17: DIRECTO
A18: 46107 | B18: Servicio Nacional De Sanidad Y Calidad Agroalimentaria Senasa | C18: OC/2026/0148 | D18: -10785.37 | E18: IMPUESTO (C) | F18: 1 | G18: 10785.37 | H18: Unidad(es) | I18: IMPUESTO (C) | J18: OPEX | K18: FIJO | L18: DIRECTO
... A106: 46082 | B106: Pick Sas | C106: FA-A 00002-00027498 | D106: -337305.65 | E106: Gastos Operativos (C) | F106: 1 | G106: 278765 | H106: Unidad(es) | I106: Gastos Operativos (C) | J106: OPEX | K106: FIJO | L106: INDIRECTO

Sheet BD Gastos_DICIEMBRE
A1: VALIDO | B1: id_factura | C1: FECHA CARGA | D1: # ID GASTO | E1: CANAL | F1: CONCEPTO | G1: TIPO 1 (DIRECTO/INDIRECTO) | H1: TIPO 2 (FIJO/VARIABLE) | I1: RUBRO | J1: AREA | K1: UN | L1: PRODUCTO | M1: PROVEEDOR | N1: DESCRIPCION | O1: UM | P1: Q | Q1: P | R1: MONEDA | S1: SUBTOTAL | T1: T.C | U1: IVA | V1: TOTAL | W1: COMENTARIO | X1: id_rubro | Y1: rubro_final | Z1: deuda_ok | AA1: capex_ok | AB1: opex_ok
A2: 1 | B2: nico_1 | C2: 45992 | D2: =B2 -> nico_1 | E2: 1 | F2: OPEX | G2: DIRECTO | H2: VARIABLE | I2: Nutrición | J2: PORCINOS | K2: PORCINOS | M2: Nutran | N2: fason_calculo_alimentos_1 | O2: kg | P2: 502888 | Q2: 35 | R2: ARS | S2: =P2*Q2 -> 17601080 | T2: 1 | U2: 0 | V2: =S2 -> 17601080 | X2: =_xlfn.XLOOKUP(I2,id_rubro!A:A,id_rubro!B:B) -> 2 | Y2: =_xlfn.XLOOKUP(X2,id_rubro!B:B,id_rubro!C:C) -> Nutrición | Z2: =IF(TRIM(F2)="DEUDA",1,0) -> 0 | AA2: =IF(TRIM($F2)="capex",1,0) -> 0 | AB2: =IF(TRIM($F2)="opex",1,0) -> 1
A3: 1 | B3: nico_2 | C3: 45992 | D3: =B3 -> nico_2 | E3: 2 | F3: OPEX | G3: DIRECTO | H3: VARIABLE | I3: Nutrición | J3: PORCINOS | K3: PORCINOS | M3: Alimento | N3: calculo_alimentos_2 | O3: kg | P3: 510488 | Q3: 353.49 | R3: ARS | S3: =P3*Q3 -> 1.804524e+08 | T3: 1 | U3: 0 | V3: =S3 -> 1.804524e+08 | X3: =_xlfn.XLOOKUP(I3,id_rubro!A:A,id_rubro!B:B) -> 2 | Y3: =_xlfn.XLOOKUP(X3,id_rubro!B:B,id_rubro!C:C) -> Nutrición | Z3: =IF(TRIM(F3)="DEUDA",1,0) -> 0 | AA3: =IF(TRIM($F3)="capex",1,0) -> 0 | AB3: =IF(TRIM($F3)="opex",1,0) -> 1
A4: 1 | B4: nico_3 | C4: 45992 | D4: =B4 -> nico_3 | E4: 1 | F4: OPEX | G4: DIRECTO | H4: VARIABLE | I4: Nutrición | M4: Nutran | N4: embolsado_calculo_alimentos_3 | O4: kg | P4: 10355 | Q4: 29 | R4: ARS | S4: =P4*Q4 -> 300295 | T4: 1 | U4: 0 | V4: =S4 -> 300295 | X4: =_xlfn.XLOOKUP(I4,id_rubro!A:A,id_rubro!B:B) -> 2 | Y4: =_xlfn.XLOOKUP(X4,id_rubro!B:B,id_rubro!C:C) -> Nutrición | Z4: =IF(TRIM(F4)="DEUDA",1,0) -> 0 | AA4: =IF(TRIM($F4)="capex",1,0) -> 0 | AB4: =IF(TRIM($F4)="opex",1,0) -> 1
