Workbook

Sheet lote_todos
A1: LOTE | B1: >=0 | C1: Mortandad-SITIO 2 | G1: CALZIM
C2: Mortandad-SITIO 3 | D2: =SUMIFS(produccion!G:G,produccion!$A:$A,B1) -> -0.094058413
B5: TOTALES | F5: FIJO/VARIABLE | J5: DIRECTO/INDERECTO
B6: VENTAS SITIO 3 | C6: =D55 -> 3.0382462e+08 | F6: VENTAS | G6: =C6 -> 3.0382462e+08 | J6: VENTAS | K6: =G6 -> 3.0382462e+08
B7: OPEX | C7: =SUMIFS(BBDD_GASTOS_FINAL!$Z:$Z,BBDD_GASTOS_FINAL!$V:$V,lote_todos!$B$1,BBDD_GASTOS_FINAL!$J:$J,"OPEX")*-1 -> 2.5052749e+08 | F7: Fijo | G7: =SUMIFS(BBDD_GASTOS_FINAL!$Z:$Z,BBDD_GASTOS_FINAL!$V:$V,lote_todos!$B$1,BBDD_GASTOS_FINAL!$J:$J,"OPEX",BBDD_GASTOS_FINAL!$K:$K,lote_todos!F7)*-1 -> 5405487.4 | J7: DIRECTO | K7: =SUMIFS(BBDD_GASTOS_FINAL!$Z:$Z,BBDD_GASTOS_FINAL!$V:$V,lote_todos!$B$1,BBDD_GASTOS_FINAL!$J:$J,"OPEX",BBDD_GASTOS_FINAL!$L:$L,lote_todos!J7)*-1 -> 25488574
B8: UTILIDAD | C8: =C6-C7 -> 53297135 | F8: Variable | G8: =SUMIFS(BBDD_GASTOS_FINAL!$Z:$Z,BBDD_GASTOS_FINAL!$V:$V,lote_todos!$B$1,BBDD_GASTOS_FINAL!$J:$J,"OPEX",BBDD_GASTOS_FINAL!$K:$K,lote_todos!F8)*-1 -> 44585205 | J8: INDIRECTO | K8: =SUMIFS(BBDD_GASTOS_FINAL!$Z:$Z,BBDD_GASTOS_FINAL!$V:$V,lote_todos!$B$1,BBDD_GASTOS_FINAL!$J:$J,"OPEX",BBDD_GASTOS_FINAL!$L:$L,lote_todos!J8)*-1 -> 24502119
B9: CAPEX | C9: =SUMIFS(BBDD_GASTOS_FINAL!$Y:$Y,BBDD_GASTOS_FINAL!$J:$J,lote_todos!B9) -> 0
B10: DEUDA | C10: =SUMIFS(BBDD_GASTOS_FINAL!$Z:$Z,BBDD_GASTOS_FINAL!$J:$J,lote_todos!B10)*-1 -> 221959.33
B11: Flujo de Caja al Accionista | C11: =C6-C7-C9-C10 -> 53075176 | F11: Flujo de Caja al Accionista | G11: =G6-G7-G8 -> 2.5383393e+08 | J11: Flujo de Caja al Accionista | K11: =K6-K7-K8 -> 2.5383393e+08
A13: id | B13: 4 | E13: id | F13: 3 | I13: id | J13: 7 | M13: id
B14: GESTACIÓN | F14: MATERNIDAD | J14: SITIO 2
B15: OPEX | D15: =SUM(D16:D26) -> 47491108 | F15: OPEX | H15: =SUM(H16:H26) -> 36382907 | J15: OPEX | L15: =SUM(L16:L26) -> 36382907 | M15: 1
A16: 1 | B16: =D16/$D$15 -> 0.30685958 | C16: NUTRICIÓN | D16: =SUMIFS(BBDD_GASTOS_FINAL!$Z:$Z,BBDD_GASTOS_FINAL!$V:$V,$B$1,BBDD_GASTOS_FINAL!$W:$W,$B$14,BBDD_GASTOS_FINAL!$AC:$AC,lote_todos!$C16)*-1 -> 14573101 | E16: 1 | F16: =H16/$H$15 -> 0.20759624 | G16: NUTRICIÓN | H16: =SUMIFS(BBDD_GASTOS_FINAL!$Z:$Z,BBDD_GASTOS_FINAL!$V:$V,$B$1,BBDD_GASTOS_FINAL!$W:$W,$F$14,BBDD_GASTOS_FINAL!$AC:$AC,$G16)*-1 -> 7552954.8 | I16: 1 | J16: =L16/$L$15 -> 0.20759624 | K16: NUTRICIÓN | L16: =SUMIFS(BBDD_GASTOS_FINAL!$Z:$Z,BBDD_GASTOS_FINAL!$V:$V,$B$1,BBDD_GASTOS_FINAL!$W:$W,$F$14,BBDD_GASTOS_FINAL!$AC:$AC,$G16)*-1 -> 7552954.8 | M16: 1
A17: =A16+1 -> 2 | B17: =D17/$D$15 -> 0.33888286 | C17: PERSONAL | D17: =SUMIFS(BBDD_GASTOS_FINAL!$Z:$Z,BBDD_GASTOS_FINAL!$V:$V,$B$1,BBDD_GASTOS_FINAL!$W:$W,$B$14,BBDD_GASTOS_FINAL!AC:AC,lote_todos!$C17)*-1 -> 16093922 | E17: 2 | F17: =H17/$H$15 -> 0.42865634 | G17: PERSONAL | H17: =SUMIFS(BBDD_GASTOS_FINAL!$Z:$Z,BBDD_GASTOS_FINAL!$V:$V,$B$1,BBDD_GASTOS_FINAL!$W:$W,$F$14,BBDD_GASTOS_FINAL!$AC:$AC,$G17)*-1 -> 15595764 | I17: =I16+1 -> 2 | J17: =L17/$L$15 -> 0.42865634 | K17: PERSONAL | L17: =SUMIFS(BBDD_GASTOS_FINAL!$Z:$Z,BBDD_GASTOS_FINAL!$V:$V,$B$1,BBDD_GASTOS_FINAL!$W:$W,$F$14,BBDD_GASTOS_FINAL!$AC:$AC,$G17)*-1 -> 15595764 | M17: =M16+1 -> 2
A18: =A17+1 -> 3 | B18: =D18/$D$15 -> 0.0086120867 | C18: SANIDAD | D18: =SUMIFS(BBDD_GASTOS_FINAL!$Z:$Z,BBDD_GASTOS_FINAL!$V:$V,$B$1,BBDD_GASTOS_FINAL!$W:$W,$B$14,BBDD_GASTOS_FINAL!AC:AC,lote_todos!$C18)*-1 -> 408997.54 | E18: 3 | F18: =H18/$H$15 -> 0.013095908 | G18: SANIDAD | H18: =SUMIFS(BBDD_GASTOS_FINAL!$Z:$Z,BBDD_GASTOS_FINAL!$V:$V,$B$1,BBDD_GASTOS_FINAL!$W:$W,$F$14,BBDD_GASTOS_FINAL!$AC:$AC,$G18)*-1 -> 476467.21 | I18: =I17+12 -> 14 | J18: =L18/$L$15 -> 0.013095908 | K18: SANIDAD | L18: =SUMIFS(BBDD_GASTOS_FINAL!$Z:$Z,BBDD_GASTOS_FINAL!$V:$V,$B$1,BBDD_GASTOS_FINAL!$W:$W,$F$14,BBDD_GASTOS_FINAL!$AC:$AC,$G18)*-1 -> 476467.21 | M18: =M17+1 -> 3
A19: =A18+1 -> 4 | B19: =D19/$D$15 -> 0.11752701 | C19: GENÉTICA | D19: =SUMIFS(BBDD_GASTOS_FINAL!$Z:$Z,BBDD_GASTOS_FINAL!$V:$V,$B$1,BBDD_GASTOS_FINAL!$W:$W,$B$14,BBDD_GASTOS_FINAL!AC:AC,lote_todos!$C19)*-1 -> 5581488 | E19: 4 | F19: =H19/$H$15 -> 0 | G19: GENÉTICA | H19: =SUMIFS(BBDD_GASTOS_FINAL!$Z:$Z,BBDD_GASTOS_FINAL!$V:$V,$B$1,BBDD_GASTOS_FINAL!$W:$W,$F$14,BBDD_GASTOS_FINAL!$AC:$AC,$G19)*-1 -> 0 | I19: =I18+1 -> 15 | J19: =L19/$L$15 -> 0 | K19: GENÉTICA | L19: =SUMIFS(BBDD_GASTOS_FINAL!$Z:$Z,BBDD_GASTOS_FINAL!$V:$V,$B$1,BBDD_GASTOS_FINAL!$W:$W,$F$14,BBDD_GASTOS_FINAL!$AC:$AC,$G19)*-1 -> 0 | M19: =M18+1 -> 4
A20: =A19+1 -> 5 | B20: =D20/$D$15 -> 0 | C20: FLETES | D20: =SUMIFS(BBDD_GASTOS_FINAL!$Z:$Z,BBDD_GASTOS_FINAL!$V:$V,$B$1,BBDD_GASTOS_FINAL!$W:$W,$B$14,BBDD_GASTOS_FINAL!AC:AC,lote_todos!$C20)*-1 -> 0 | E20: 5 | F20: =H20/$H$15 -> 0 | G20: FLETES | H20: =SUMIFS(BBDD_GASTOS_FINAL!$Z:$Z,BBDD_GASTOS_FINAL!$V:$V,$B$1,BBDD_GASTOS_FINAL!$W:$W,$F$14,BBDD_GASTOS_FINAL!$AC:$AC,$G20)*-1 -> 0 | I20: =I19+1 -> 16 | J20: =L20/$L$15 -> 0 | K20: FLETES | L20: =SUMIFS(BBDD_GASTOS_FINAL!$Z:$Z,BBDD_GASTOS_FINAL!$V:$V,$B$1,BBDD_GASTOS_FINAL!$W:$W,$F$14,BBDD_GASTOS_FINAL!$AC:$AC,$G20)*-1 -> 0 | M20: =M19+1 -> 5
A21: =A20+1 -> 6 | B21: =D21/$D$15 -> 0.063587202 | C21: ENERGÍA | D21: =SUMIFS(BBDD_GASTOS_FINAL!$Z:$Z,BBDD_GASTOS_FINAL!$V:$V,$B$1,BBDD_GASTOS_FINAL!$W:$W,$B$14,BBDD_GASTOS_FINAL!AC:AC,lote_todos!$C21)*-1 -> 3019826.7 | E21: 6 | F21: =H21/$H$15 -> 0.083001248 | G21: ENERGÍA | H21: =SUMIFS(BBDD_GASTOS_FINAL!$Z:$Z,BBDD_GASTOS_FINAL!$V:$V,$B$1,BBDD_GASTOS_FINAL!$W:$W,$F$14,BBDD_GASTOS_FINAL!$AC:$AC,$G21)*-1 -> 3019826.7 | I21: =I20+1 -> 17 | J21: =L21/$L$15 -> 0.083001248 | K21: ENERGÍA | L21: =SUMIFS(BBDD_GASTOS_FINAL!$Z:$Z,BBDD_GASTOS_FINAL!$V:$V,$B$1,BBDD_GASTOS_FINAL!$W:$W,$F$14,BBDD_GASTOS_FINAL!$AC:$AC,$G21)*-1 -> 3019826.7 | M21: =M20+1 -> 6
A22: =A21+1 -> 7 | B22: =D22/$D$15 -> 0 | C22: MENTENIMIENTO | D22: =SUMIFS(BBDD_GASTOS_FINAL!$Z:$Z,BBDD_GASTOS_FINAL!$V:$V,$B$1,BBDD_GASTOS_FINAL!$W:$W,$B$14,BBDD_GASTOS_FINAL!AC:AC,lote_todos!$C22)*-1 -> 0 | E22: 7 | F22: =H22/$H$15 -> 0 | G22: MENTENIMIENTO | H22: =SUMIFS(BBDD_GASTOS_FINAL!$Z:$Z,BBDD_GASTOS_FINAL!$V:$V,$B$1,BBDD_GASTOS_FINAL!$W:$W,$F$14,BBDD_GASTOS_FINAL!$AC:$AC,$G22)*-1 -> 0 | I22: =I21+1 -> 18 | J22: =L22/$L$15 -> 0 | K22: MENTENIMIENTO | L22: =SUMIFS(BBDD_GASTOS_FINAL!$Z:$Z,BBDD_GASTOS_FINAL!$V:$V,$B$1,BBDD_GASTOS_FINAL!$W:$W,$F$14,BBDD_GASTOS_FINAL!$AC:$AC,$G22)*-1 -> 0 | M22: =M21+1 -> 7
A23: =A22+1 -> 8 | B23: =D23/$D$15 -> 0.11336253 | C23: GASTOS OPERATIVOS | D23: =SUMIFS(BBDD_GASTOS_FINAL!$Z:$Z,BBDD_GASTOS_FINAL!$V:$V,$B$1,BBDD_GASTOS_FINAL!$W:$W,$B$14,BBDD_GASTOS_FINAL!AC:AC,lote_todos!$C23)*-1 -> 5383712.4 | E23: 8 | F23: =H23/$H$15 -> 0.14611924 | G23: GASTOS OPERATIVOS | H23: =SUMIFS(BBDD_GASTOS_FINAL!$Z:$Z,BBDD_GASTOS_FINAL!$V:$V,$B$1,BBDD_GASTOS_FINAL!$W:$W,$F$14,BBDD_GASTOS_FINAL!$AC:$AC,$G23)*-1 -> 5316242.7 | I23: =I22+1 -> 19 | J23: =L23/$L$15 -> 0.14611924 | K23: GASTOS OPERATIVOS | L23: =SUMIFS(BBDD_GASTOS_FINAL!$Z:$Z,BBDD_GASTOS_FINAL!$V:$V,$B$1,BBDD_GASTOS_FINAL!$W:$W,$F$14,BBDD_GASTOS_FINAL!$AC:$AC,$G23)*-1 -> 5316242.7 | M23: =M22+1 -> 8
A24: =A23+1 -> 9 | B24: =D24/$D$15 -> 0.037984074 | C24: IMPUESTOS | D24: =SUMIFS(BBDD_GASTOS_FINAL!$Z:$Z,BBDD_GASTOS_FINAL!$V:$V,$B$1,BBDD_GASTOS_FINAL!$W:$W,$B$14,BBDD_GASTOS_FINAL!AC:AC,lote_todos!$C24)*-1 -> 1803905.8 | E24: 9 | F24: =H24/$H$15 -> 0.10432091 | G24: IMPUESTOS | H24: =SUMIFS(BBDD_GASTOS_FINAL!$Z:$Z,BBDD_GASTOS_FINAL!$V:$V,$B$1,BBDD_GASTOS_FINAL!$W:$W,$F$14,BBDD_GASTOS_FINAL!$AC:$AC,$G24)*-1 -> 3795497.8 | I24: =I23+1 -> 20 | J24: =L24/$L$15 -> 0.10432091 | K24: IMPUESTOS | L24: =SUMIFS(BBDD_GASTOS_FINAL!$Z:$Z,BBDD_GASTOS_FINAL!$V:$V,$B$1,BBDD_GASTOS_FINAL!$W:$W,$F$14,BBDD_GASTOS_FINAL!$AC:$AC,$G24)*-1 -> 3795497.8 | M24: =M23+1 -> 9
A25: =A24+1 -> 10 | B25: =D25/$D$15 -> 0.013184659 | C25: HONORARIOS | D25: =SUMIFS(BBDD_GASTOS_FINAL!$Z:$Z,BBDD_GASTOS_FINAL!$V:$V,$B$1,BBDD_GASTOS_FINAL!$W:$W,$B$14,BBDD_GASTOS_FINAL!AC:AC,lote_todos!$C25)*-1 -> 626154.04 | E25: 10 | F25: =H25/$H$15 -> 0.017210116 | G25: HONORARIOS | H25: =SUMIFS(BBDD_GASTOS_FINAL!$Z:$Z,BBDD_GASTOS_FINAL!$V:$V,$B$1,BBDD_GASTOS_FINAL!$W:$W,$F$14,BBDD_GASTOS_FINAL!$AC:$AC,$G25)*-1 -> 626154.04 | I25: =I24+1 -> 21 | J25: =L25/$L$15 -> 0.017210116 | K25: HONORARIOS | L25: =SUMIFS(BBDD_GASTOS_FINAL!$Z:$Z,BBDD_GASTOS_FINAL!$V:$V,$B$1,BBDD_GASTOS_FINAL!$W:$W,$F$14,BBDD_GASTOS_FINAL!$AC:$AC,$G25)*-1 -> 626154.04 | M25: =M24+1 -> 10
B26: =D26/$D$15 -> 0 | C26: SERVICIOS | D26: =SUMIFS(BBDD_GASTOS_FINAL!$Z:$Z,BBDD_GASTOS_FINAL!$V:$V,$B$1,BBDD_GASTOS_FINAL!$W:$W,$B$14,BBDD_GASTOS_FINAL!AC:AC,lote_todos!$C26)*-1 -> 0 | F26: =H26/$H$15 -> 0 | G26: SERVICIOS | H26: =SUMIFS(BBDD_GASTOS_FINAL!$Z:$Z,BBDD_GASTOS_FINAL!$V:$V,$B$1,BBDD_GASTOS_FINAL!$W:$W,$F$14,BBDD_GASTOS_FINAL!$AC:$AC,$G26)*-1 -> 0 | J26: =L26/$L$15 -> 0 | K26: OTROS | L26: =SUMIFS(BBDD_GASTOS_FINAL!$Z:$Z,BBDD_GASTOS_FINAL!$V:$V,$B$1,BBDD_GASTOS_FINAL!$W:$W,$F$14,BBDD_GASTOS_FINAL!$AC:$AC,$G26)*-1 -> 0
F28: COMPRAS EN GESTACION | H28: =D15 -> 47491108 | J28: COMPRAS EN MATERNIDAD | L28: =H29 -> 48462460
B29: VENTAS | D29: =SUMIFS(produccion!$H:$H,produccion!$A:$A,lote_todos!$B$1,produccion!$B:$B,lote_todos!B14) -> 0 | F29: VENTAS | H29: =SUMIFS(produccion!$H:$H,produccion!$A:$A,lote_todos!$B$1,produccion!$B:$B,lote_todos!F14) -> 48462460 | J29: VENTAS | L29: =SUMIFS(produccion!$H:$H,produccion!$A:$A,lote_todos!$B$1,produccion!$B:$B,lote_todos!J14) -> 94822882
B31: UTILDAD | D31: =D29-D15-D28 -> -47491108 | F31: UTILDAD | H31: =H29-H15-H28 -> -35411555 | J31: UTILDAD | L31: =L29-L15-L28 -> 9977515.2
B33: CAPEX | D33: =SUMIFS(BBDD_GASTOS_FINAL!$Y:$Y,BBDD_GASTOS_FINAL!$J:$J,"Capex",BBDD_GASTOS_FINAL!$Z:$Z,$B$13) -> 0 | F33: CAPEX | H33: =SUMIFS(BBDD_GASTOS_FINAL!$Y:$Y,BBDD_GASTOS_FINAL!$J:$J,"Capex",BBDD_GASTOS_FINAL!$Z:$Z,$F$13) -> 0 | J33: CAPEX | L33: =SUMIFS(BBDD_GASTOS_FINAL!$Y:$Y,BBDD_GASTOS_FINAL!$J:$J,"Capex",BBDD_GASTOS_FINAL!$Z:$Z,$J$13) -> 0
B35: DEUDA | D35: =SUMIFS(BBDD_GASTOS_FINAL!$Y:$Y,BBDD_GASTOS_FINAL!$J:$J,"Deuda",BBDD_GASTOS_FINAL!$V:$V,B14) -> 0 | F35: DEUDA | H35: =SUMIFS(BBDD_GASTOS_FINAL!$Y:$Y,BBDD_GASTOS_FINAL!$J:$J,"Deuda",BBDD_GASTOS_FINAL!$V:$V,F14) -> 0 | J35: DEUDA | L35: =SUMIFS(BBDD_GASTOS_FINAL!$Y:$Y,BBDD_GASTOS_FINAL!$J:$J,"deuda",BBDD_GASTOS_FINAL!$V:$V,J14) -> 0
B37: Flujo de Caja al Accionista | D37: =D31-D35-D33 -> -47491108 | F37: Flujo de Caja al Accionista | H37: =H31-H35-H33 -> -35411555 | J37: Flujo de Caja al Accionista | L37: =L31-L35-L33 -> 9977515.2
F38: Margen de utilidad | H38: =H31/H29 -> -0.73070072 | J38: Margen de utilidad | L38: =L31/L29 -> 0.10522265
A39: id | B39: 1 | M39: id
B40: SITIO 3
B41: OPEX | D41: =SUM(D42:D52) -> 1.1888009e+08
A42: 1 | B42: =D42/$D$41 -> 0.75354893 | C42: NUTRICIÓN | D42: =SUMIFS(BBDD_GASTOS_FINAL!$Z:$Z,BBDD_GASTOS_FINAL!$V:$V,$B$1,BBDD_GASTOS_FINAL!$W:$W,$B$40,BBDD_GASTOS_FINAL!$AC:$AC,lote_todos!$C42)*-1 -> 89581964
A43: =A42+1 -> 2 | B43: =D43/$D$41 -> 0.094630505 | C43: PERSONAL | D43: =SUMIFS(BBDD_GASTOS_FINAL!$Z:$Z,BBDD_GASTOS_FINAL!$V:$V,$B$1,BBDD_GASTOS_FINAL!$W:$W,$B$40,BBDD_GASTOS_FINAL!AC:AC,lote_todos!$C43)*-1 -> 11249683
A44: =A43+1 -> 3 | B44: =D44/$D$41 -> 0.0036378494 | C44: SANIDAD | D44: =SUMIFS(BBDD_GASTOS_FINAL!$Z:$Z,BBDD_GASTOS_FINAL!$V:$V,$B$1,BBDD_GASTOS_FINAL!$W:$W,$B$40,BBDD_GASTOS_FINAL!AC:AC,lote_todos!$C44)*-1 -> 432467.86
A45: =A44+1 -> 4 | B45: =D45/$D$41 -> 0 | C45: GENÉTICA | D45: =SUMIFS(BBDD_GASTOS_FINAL!$Z:$Z,BBDD_GASTOS_FINAL!$V:$V,$B$1,BBDD_GASTOS_FINAL!$W:$W,$B$40,BBDD_GASTOS_FINAL!AC:AC,lote_todos!$C45)*-1 -> 0
A46: =A45+1 -> 5 | B46: =D46/$D$41 -> 0.057249672 | C46: FLETES | D46: =SUMIFS(BBDD_GASTOS_FINAL!$Z:$Z,BBDD_GASTOS_FINAL!$V:$V,$B$1,BBDD_GASTOS_FINAL!$W:$W,$B$40,BBDD_GASTOS_FINAL!AC:AC,lote_todos!$C46)*-1 -> 6805846.2
A47: =A46+1 -> 6 | B47: =D47/$D$41 -> 0.025402291 | C47: ENERGÍA | D47: =SUMIFS(BBDD_GASTOS_FINAL!$Z:$Z,BBDD_GASTOS_FINAL!$V:$V,$B$1,BBDD_GASTOS_FINAL!$W:$W,$B$40,BBDD_GASTOS_FINAL!AC:AC,lote_todos!$C47)*-1 -> 3019826.7
A48: =A47+1 -> 7 | B48: =D48/$D$41 -> 0 | C48: MENTENIMIENTO | D48: =SUMIFS(BBDD_GASTOS_FINAL!$Z:$Z,BBDD_GASTOS_FINAL!$V:$V,$B$1,BBDD_GASTOS_FINAL!$W:$W,$B$40,BBDD_GASTOS_FINAL!AC:AC,lote_todos!$C48)*-1 -> 0
...

Sheet lote_I
A1: LOTE | B1: 3925 | C1: Mortandad-SITIO 2 | G1: CALZIM
C2: Mortandad-SITIO 3 | D2: =SUMIFS(produccion!G:G,produccion!$A:$A,B1) -> -0.053422371
B5: TOTALES | F5: FIJO/VARIABLE | J5: DIRECTO/INDERECTO
B6: VENTAS SITIO 3 | C6: =D55 -> 1.5626228e+08 | F6: VENTAS | G6: =C6 -> 1.5626228e+08 | J6: VENTAS | K6: =G6 -> 1.5626228e+08
B7: OPEX | C7: =SUMIFS(BBDD_GASTOS_FINAL!$Z:$Z,BBDD_GASTOS_FINAL!$V:$V,lote_I!$B$1,BBDD_GASTOS_FINAL!$J:$J,"OPEX")*-1 -> 1.288857e+08 | F7: Fijo | G7: =SUMIFS(BBDD_GASTOS_FINAL!$Z:$Z,BBDD_GASTOS_FINAL!$V:$V,lote_I!$B$1,BBDD_GASTOS_FINAL!$J:$J,"OPEX",BBDD_GASTOS_FINAL!$K:$K,lote_I!F7)*-1 -> 2702743.5 | J7: DIRECTO | K7: =SUMIFS(BBDD_GASTOS_FINAL!$Z:$Z,BBDD_GASTOS_FINAL!$V:$V,lote_I!$B$1,BBDD_GASTOS_FINAL!$J:$J,"OPEX",BBDD_GASTOS_FINAL!$L:$L,lote_I!J7)*-1 -> 12744286
B8: UTILIDAD | C8: =C6-C7 -> 27376584 | F8: Variable | G8: =SUMIFS(BBDD_GASTOS_FINAL!$Z:$Z,BBDD_GASTOS_FINAL!$V:$V,lote_I!$B$1,BBDD_GASTOS_FINAL!$J:$J,"OPEX",BBDD_GASTOS_FINAL!$K:$K,lote_todos!F8)*-1 -> 22292601 | J8: INDIRECTO | K8: =SUMIFS(BBDD_GASTOS_FINAL!$Z:$Z,BBDD_GASTOS_FINAL!$V:$V,lote_I!$B$1,BBDD_GASTOS_FINAL!$J:$J,"OPEX",BBDD_GASTOS_FINAL!$L:$L,lote_I!J8)*-1 -> 12251059
B9: CAPEX | C9: =SUMIFS(BBDD_GASTOS_FINAL!$Y:$Y,BBDD_GASTOS_FINAL!$J:$J,lote_I!B9) -> 0
B10: DEUDA | C10: =SUMIFS(BBDD_GASTOS_FINAL!$Z:$Z,BBDD_GASTOS_FINAL!$J:$J,lote_I!B10,BBDD_GASTOS_FINAL!$V:$V,$B$1)*-1 -> 110979.66
B11: Flujo de Caja al Accionista | C11: =C6-C7-C9-C10 -> 27265604 | F11: Flujo de Caja al Accionista | G11: =G6-G7-G8 -> 1.3126694e+08 | J11: Flujo de Caja al Accionista | K11: =K6-K7-K8 -> 1.3126694e+08
A13: id | B13: 4 | E13: id | F13: 3 | I13: id | J13: 7 | M13: id
B14: GESTACIÓN | F14: MATERNIDAD | J14: SITIO 2
B15: OPEX | D15: =SUM(D16:D26) -> 23745553 | F15: OPEX | H15: =SUM(H16:H26) -> 20889733 | J15: OPEX | L15: =SUM(L16:L26) -> 20889733 | M15: 1
A16: 1 | B16: =D16/$D$15 -> 0.30685959 | C16: NUTRICIÓN | D16: =SUMIFS(BBDD_GASTOS_FINAL!$Z:$Z,BBDD_GASTOS_FINAL!$V:$V,$B$1,BBDD_GASTOS_FINAL!$W:$W,$B$14,BBDD_GASTOS_FINAL!$AC:$AC,lote_I!$C16)*-1 -> 7286550.6 | E16: 1 | F16: =H16/$H$15 -> 0.30994928 | G16: NUTRICIÓN | H16: =SUMIFS(BBDD_GASTOS_FINAL!$Z:$Z,BBDD_GASTOS_FINAL!$V:$V,$B$1,BBDD_GASTOS_FINAL!$W:$W,$F$14,BBDD_GASTOS_FINAL!$AC:$AC,$G16)*-1 -> 6474757.6 | I16: 1 | J16: =L16/$L$15 -> 0.30994928 | K16: NUTRICIÓN | L16: =SUMIFS(BBDD_GASTOS_FINAL!$Z:$Z,BBDD_GASTOS_FINAL!$V:$V,$B$1,BBDD_GASTOS_FINAL!$W:$W,$F$14,BBDD_GASTOS_FINAL!$AC:$AC,$G16)*-1 -> 6474757.6 | M16: 1
A17: =A16+1 -> 2 | B17: =D17/$D$15 -> 0.33888285 | C17: PERSONAL | D17: =SUMIFS(BBDD_GASTOS_FINAL!$Z:$Z,BBDD_GASTOS_FINAL!$V:$V,$B$1,BBDD_GASTOS_FINAL!$W:$W,$B$14,BBDD_GASTOS_FINAL!AC:AC,lote_I!$C17)*-1 -> 8046960.7 | E17: 2 | F17: =H17/$H$15 -> 0.37328775 | G17: PERSONAL | H17: =SUMIFS(BBDD_GASTOS_FINAL!$Z:$Z,BBDD_GASTOS_FINAL!$V:$V,$B$1,BBDD_GASTOS_FINAL!$W:$W,$F$14,BBDD_GASTOS_FINAL!$AC:$AC,$G17)*-1 -> 7797881.3 | I17: =I16+1 -> 2 | J17: =L17/$L$15 -> 0.37328775 | K17: PERSONAL | L17: =SUMIFS(BBDD_GASTOS_FINAL!$Z:$Z,BBDD_GASTOS_FINAL!$V:$V,$B$1,BBDD_GASTOS_FINAL!$W:$W,$F$14,BBDD_GASTOS_FINAL!$AC:$AC,$G17)*-1 -> 7797881.3 | M17: =M16+1 -> 2
A18: =A17+1 -> 3 | B18: =D18/$D$15 -> 0.0085376736 | C18: SANIDAD | D18: =SUMIFS(BBDD_GASTOS_FINAL!$Z:$Z,BBDD_GASTOS_FINAL!$V:$V,$B$1,BBDD_GASTOS_FINAL!$W:$W,$B$14,BBDD_GASTOS_FINAL!AC:AC,lote_I!$C18)*-1 -> 202731.78 | E18: 3 | F18: =H18/$H$15 -> 0.0048034225 | G18: SANIDAD | H18: =SUMIFS(BBDD_GASTOS_FINAL!$Z:$Z,BBDD_GASTOS_FINAL!$V:$V,$B$1,BBDD_GASTOS_FINAL!$W:$W,$F$14,BBDD_GASTOS_FINAL!$AC:$AC,$G18)*-1 -> 100342.21 | I18: =I17+12 -> 14 | J18: =L18/$L$15 -> 0.0048034225 | K18: SANIDAD | L18: =SUMIFS(BBDD_GASTOS_FINAL!$Z:$Z,BBDD_GASTOS_FINAL!$V:$V,$B$1,BBDD_GASTOS_FINAL!$W:$W,$F$14,BBDD_GASTOS_FINAL!$AC:$AC,$G18)*-1 -> 100342.21 | M18: =M17+1 -> 3
A19: =A18+1 -> 4 | B19: =D19/$D$15 -> 0.11752702 | C19: GENÉTICA | D19: =SUMIFS(BBDD_GASTOS_FINAL!$Z:$Z,BBDD_GASTOS_FINAL!$V:$V,$B$1,BBDD_GASTOS_FINAL!$W:$W,$B$14,BBDD_GASTOS_FINAL!AC:AC,lote_I!$C19)*-1 -> 2790744 | E19: 4 | F19: =H19/$H$15 -> 0 | G19: GENÉTICA | H19: =SUMIFS(BBDD_GASTOS_FINAL!$Z:$Z,BBDD_GASTOS_FINAL!$V:$V,$B$1,BBDD_GASTOS_FINAL!$W:$W,$F$14,BBDD_GASTOS_FINAL!$AC:$AC,$G19)*-1 -> 0 | I19: =I18+1 -> 15 | J19: =L19/$L$15 -> 0 | K19: GENÉTICA | L19: =SUMIFS(BBDD_GASTOS_FINAL!$Z:$Z,BBDD_GASTOS_FINAL!$V:$V,$B$1,BBDD_GASTOS_FINAL!$W:$W,$F$14,BBDD_GASTOS_FINAL!$AC:$AC,$G19)*-1 -> 0 | M19: =M18+1 -> 4
A20: =A19+1 -> 5 | B20: =D20/$D$15 -> 0 | C20: FLETES | D20: =SUMIFS(BBDD_GASTOS_FINAL!$Z:$Z,BBDD_GASTOS_FINAL!$V:$V,$B$1,BBDD_GASTOS_FINAL!$W:$W,$B$14,BBDD_GASTOS_FINAL!AC:AC,lote_I!$C20)*-1 -> 0 | E20: 5 | F20: =H20/$H$15 -> 0 | G20: FLETES | H20: =SUMIFS(BBDD_GASTOS_FINAL!$Z:$Z,BBDD_GASTOS_FINAL!$V:$V,$B$1,BBDD_GASTOS_FINAL!$W:$W,$F$14,BBDD_GASTOS_FINAL!$AC:$AC,$G20)*-1 -> 0 | I20: =I19+1 -> 16 | J20: =L20/$L$15 -> 0 | K20: FLETES | L20: =SUMIFS(BBDD_GASTOS_FINAL!$Z:$Z,BBDD_GASTOS_FINAL!$V:$V,$B$1,BBDD_GASTOS_FINAL!$W:$W,$F$14,BBDD_GASTOS_FINAL!$AC:$AC,$G20)*-1 -> 0 | M20: =M19+1 -> 5
A21: =A20+1 -> 6 | B21: =D21/$D$15 -> 0.0635872 | C21: ENERGÍA | D21: =SUMIFS(BBDD_GASTOS_FINAL!$Z:$Z,BBDD_GASTOS_FINAL!$V:$V,$B$1,BBDD_GASTOS_FINAL!$W:$W,$B$14,BBDD_GASTOS_FINAL!AC:AC,lote_I!$C21)*-1 -> 1509913.2 | E21: 6 | F21: =H21/$H$15 -> 0.072280161 | G21: ENERGÍA | H21: =SUMIFS(BBDD_GASTOS_FINAL!$Z:$Z,BBDD_GASTOS_FINAL!$V:$V,$B$1,BBDD_GASTOS_FINAL!$W:$W,$F$14,BBDD_GASTOS_FINAL!$AC:$AC,$G21)*-1 -> 1509913.2 | I21: =I20+1 -> 17 | J21: =L21/$L$15 -> 0.072280161 | K21: ENERGÍA | L21: =SUMIFS(BBDD_GASTOS_FINAL!$Z:$Z,BBDD_GASTOS_FINAL!$V:$V,$B$1,BBDD_GASTOS_FINAL!$W:$W,$F$14,BBDD_GASTOS_FINAL!$AC:$AC,$G21)*-1 -> 1509913.2 | M21: =M20+1 -> 6
A22: =A21+1 -> 7 | B22: =D22/$D$15 -> 0 | C22: MENTENIMIENTO | D22: =SUMIFS(BBDD_GASTOS_FINAL!$Z:$Z,BBDD_GASTOS_FINAL!$V:$V,$B$1,BBDD_GASTOS_FINAL!$W:$W,$B$14,BBDD_GASTOS_FINAL!AC:AC,lote_I!$C22)*-1 -> 0 | E22: 7 | F22: =H22/$H$15 -> 0 | G22: MENTENIMIENTO | H22: =SUMIFS(BBDD_GASTOS_FINAL!$Z:$Z,BBDD_GASTOS_FINAL!$V:$V,$B$1,BBDD_GASTOS_FINAL!$W:$W,$F$14,BBDD_GASTOS_FINAL!$AC:$AC,$G22)*-1 -> 0 | I22: =I21+1 -> 18 | J22: =L22/$L$15 -> 0 | K22: MENTENIMIENTO | L22: =SUMIFS(BBDD_GASTOS_FINAL!$Z:$Z,BBDD_GASTOS_FINAL!$V:$V,$B$1,BBDD_GASTOS_FINAL!$W:$W,$F$14,BBDD_GASTOS_FINAL!$AC:$AC,$G22)*-1 -> 0 | M22: =M21+1 -> 7
A23: =A22+1 -> 8 | B23: =D23/$D$15 -> 0.11356983 | C23: GASTOS OPERATIVOS | D23: =SUMIFS(BBDD_GASTOS_FINAL!$Z:$Z,BBDD_GASTOS_FINAL!$V:$V,$B$1,BBDD_GASTOS_FINAL!$W:$W,$B$14,BBDD_GASTOS_FINAL!AC:AC,lote_I!$C23)*-1 -> 2696778.5 | E23: 8 | F23: =H23/$H$15 -> 0.13399731 | G23: GASTOS OPERATIVOS | H23: =SUMIFS(BBDD_GASTOS_FINAL!$Z:$Z,BBDD_GASTOS_FINAL!$V:$V,$B$1,BBDD_GASTOS_FINAL!$W:$W,$F$14,BBDD_GASTOS_FINAL!$AC:$AC,$G23)*-1 -> 2799168 | I23: =I22+1 -> 19 | J23: =L23/$L$15 -> 0.13399731 | K23: GASTOS OPERATIVOS | L23: =SUMIFS(BBDD_GASTOS_FINAL!$Z:$Z,BBDD_GASTOS_FINAL!$V:$V,$B$1,BBDD_GASTOS_FINAL!$W:$W,$F$14,BBDD_GASTOS_FINAL!$AC:$AC,$G23)*-1 -> 2799168 | M23: =M22+1 -> 8
A24: =A23+1 -> 9 | B24: =D24/$D$15 -> 0.037984074 | C24: IMPUESTOS | D24: =SUMIFS(BBDD_GASTOS_FINAL!$Z:$Z,BBDD_GASTOS_FINAL!$V:$V,$B$1,BBDD_GASTOS_FINAL!$W:$W,$B$14,BBDD_GASTOS_FINAL!AC:AC,lote_I!$C24)*-1 -> 901952.84 | E24: 9 | F24: =H24/$H$15 -> 0.090846007 | G24: IMPUESTOS | H24: =SUMIFS(BBDD_GASTOS_FINAL!$Z:$Z,BBDD_GASTOS_FINAL!$V:$V,$B$1,BBDD_GASTOS_FINAL!$W:$W,$F$14,BBDD_GASTOS_FINAL!$AC:$AC,$G24)*-1 -> 1897748.8 | I24: =I23+1 -> 20 | J24: =L24/$L$15 -> 0.090846007 | K24: IMPUESTOS | L24: =SUMIFS(BBDD_GASTOS_FINAL!$Z:$Z,BBDD_GASTOS_FINAL!$V:$V,$B$1,BBDD_GASTOS_FINAL!$W:$W,$F$14,BBDD_GASTOS_FINAL!$AC:$AC,$G24)*-1 -> 1897748.8 | M24: =M23+1 -> 9
A25: =A24+1 -> 10 | B25: =D25/$D$15 -> 0.013051771 | C25: HONORARIOS | D25: =SUMIFS(BBDD_GASTOS_FINAL!$Z:$Z,BBDD_GASTOS_FINAL!$V:$V,$B$1,BBDD_GASTOS_FINAL!$W:$W,$B$14,BBDD_GASTOS_FINAL!AC:AC,lote_I!$C25)*-1 -> 309921.52 | E25: 10 | F25: =H25/$H$15 -> 0.014836069 | G25: HONORARIOS | H25: =SUMIFS(BBDD_GASTOS_FINAL!$Z:$Z,BBDD_GASTOS_FINAL!$V:$V,$B$1,BBDD_GASTOS_FINAL!$W:$W,$F$14,BBDD_GASTOS_FINAL!$AC:$AC,$G25)*-1 -> 309921.52 | I25: =I24+1 -> 21 | J25: =L25/$L$15 -> 0.014836069 | K25: HONORARIOS | L25: =SUMIFS(BBDD_GASTOS_FINAL!$Z:$Z,BBDD_GASTOS_FINAL!$V:$V,$B$1,BBDD_GASTOS_FINAL!$W:$W,$F$14,BBDD_GASTOS_FINAL!$AC:$AC,$G25)*-1 -> 309921.52 | M25: =M24+1 -> 10
B26: =D26/$D$15 -> 0 | C26: SERVICIOS | D26: =SUMIFS(BBDD_GASTOS_FINAL!$Z:$Z,BBDD_GASTOS_FINAL!$V:$V,$B$1,BBDD_GASTOS_FINAL!$W:$W,$B$14,BBDD_GASTOS_FINAL!AC:AC,lote_I!$C26)*-1 -> 0 | F26: =H26/$H$15 -> 0 | G26: SERVICIOS | H26: =SUMIFS(BBDD_GASTOS_FINAL!$Z:$Z,BBDD_GASTOS_FINAL!$V:$V,$B$1,BBDD_GASTOS_FINAL!$W:$W,$F$14,BBDD_GASTOS_FINAL!$AC:$AC,$G26)*-1 -> 0 | J26: =L26/$L$15 -> 0 | K26: OTROS | L26: =SUMIFS(BBDD_GASTOS_FINAL!$Z:$Z,BBDD_GASTOS_FINAL!$V:$V,$B$1,BBDD_GASTOS_FINAL!$W:$W,$F$14,BBDD_GASTOS_FINAL!$AC:$AC,$G26)*-1 -> 0
F28: COMPRAS EN GESTACION | H28: =D15 -> 23745553 | J28: COMPRAS EN MATERNIDAD | L28: =H29 -> 24295372
B29: VENTAS | D29: =SUMIFS(produccion!$H:$H,produccion!$A:$A,lote_I!$B$1,produccion!$B:$B,lote_I!B14) -> 0 | F29: VENTAS | H29: =SUMIFS(produccion!$H:$H,produccion!$A:$A,lote_I!$B$1,produccion!$B:$B,lote_I!F14) -> 24295372 | J29: VENTAS | L29: =SUMIFS(produccion!$H:$H,produccion!$A:$A,lote_I!$B$1,produccion!$B:$B,lote_I!J14) -> 50061904
B31: UTILDAD | D31: =D29-D15-D28 -> -23745553 | F31: UTILDAD | H31: =H29-H15-H28 -> -20339914 | J31: UTILDAD | L31: =L29-L15-L28 -> 4876799.3
B33: CAPEX | D33: =SUMIFS(BBDD_GASTOS_FINAL!$Y:$Y,BBDD_GASTOS_FINAL!$J:$J,"Capex",BBDD_GASTOS_FINAL!$Z:$Z,$B$13) -> 0 | F33: CAPEX | H33: =SUMIFS(BBDD_GASTOS_FINAL!$Y:$Y,BBDD_GASTOS_FINAL!$J:$J,"Capex",BBDD_GASTOS_FINAL!$Z:$Z,$F$13) -> 0 | J33: CAPEX | L33: =SUMIFS(BBDD_GASTOS_FINAL!$Y:$Y,BBDD_GASTOS_FINAL!$J:$J,"Capex",BBDD_GASTOS_FINAL!$Z:$Z,$J$13) -> 0
B35: DEUDA | D35: =SUMIFS(BBDD_GASTOS_FINAL!$Y:$Y,BBDD_GASTOS_FINAL!$J:$J,"Deuda",BBDD_GASTOS_FINAL!$V:$V,B14) -> 0 | F35: DEUDA | H35: =SUMIFS(BBDD_GASTOS_FINAL!$Y:$Y,BBDD_GASTOS_FINAL!$J:$J,"Deuda",BBDD_GASTOS_FINAL!$V:$V,F14) -> 0 | J35: DEUDA | L35: =SUMIFS(BBDD_GASTOS_FINAL!$Y:$Y,BBDD_GASTOS_FINAL!$J:$J,"deuda",BBDD_GASTOS_FINAL!$V:$V,J14) -> 0
B37: Flujo de Caja al Accionista | D37: =D31-D35-D33 -> -23745553 | F37: Flujo de Caja al Accionista | H37: =H31-H35-H33 -> -20339914 | J37: Flujo de Caja al Accionista | L37: =L31-L35-L33 -> 4876799.3
F38: Margen de utilidad | H38: =H31/H29 -> -0.83719292 | J38: Margen de utilidad | L38: =L31/L29 -> 0.097415377
A39: id | B39: 1 | M39: id
B40: SITIO 3
B41: OPEX | D41: =SUM(D42:D52) -> 59931142
A42: 1 | B42: =D42/$D$41 -> 0.75556845 | C42: NUTRICIÓN | D42: =SUMIFS(BBDD_GASTOS_FINAL!$Z:$Z,BBDD_GASTOS_FINAL!$V:$V,$B$1,BBDD_GASTOS_FINAL!$W:$W,$B$40,BBDD_GASTOS_FINAL!$AC:$AC,lote_I!$C42)*-1 -> 45282080
A43: =A42+1 -> 2 | B43: =D43/$D$41 -> 0.093855064 | C43: PERSONAL | D43: =SUMIFS(BBDD_GASTOS_FINAL!$Z:$Z,BBDD_GASTOS_FINAL!$V:$V,$B$1,BBDD_GASTOS_FINAL!$W:$W,$B$40,BBDD_GASTOS_FINAL!AC:AC,lote_I!$C43)*-1 -> 5624841.1
A44: =A43+1 -> 3 | B44: =D44/$D$41 -> 0.0026403766 | C44: SANIDAD | D44: =SUMIFS(BBDD_GASTOS_FINAL!$Z:$Z,BBDD_GASTOS_FINAL!$V:$V,$B$1,BBDD_GASTOS_FINAL!$W:$W,$B$40,BBDD_GASTOS_FINAL!AC:AC,lote_I!$C44)*-1 -> 158240.78
A45: =A44+1 -> 4 | B45: =D45/$D$41 -> 0 | C45: GENÉTICA | D45: =SUMIFS(BBDD_GASTOS_FINAL!$Z:$Z,BBDD_GASTOS_FINAL!$V:$V,$B$1,BBDD_GASTOS_FINAL!$W:$W,$B$40,BBDD_GASTOS_FINAL!AC:AC,lote_I!$C45)*-1 -> 0
A46: =A45+1 -> 5 | B46: =D46/$D$41 -> 0.056780545 | C46: FLETES | D46: =SUMIFS(BBDD_GASTOS_FINAL!$Z:$Z,BBDD_GASTOS_FINAL!$V:$V,$B$1,BBDD_GASTOS_FINAL!$W:$W,$B$40,BBDD_GASTOS_FINAL!AC:AC,lote_I!$C46)*-1 -> 3402922.9
A47: =A46+1 -> 6 | B47: =D47/$D$41 -> 0.025194134 | C47: ENERGÍA | D47: =SUMIFS(BBDD_GASTOS_FINAL!$Z:$Z,BBDD_GASTOS_FINAL!$V:$V,$B$1,BBDD_GASTOS_FINAL!$W:$W,$B$40,BBDD_GASTOS_FINAL!AC:AC,lote_I!$C47)*-1 -> 1509913.2
A48: =A47+1 -> 7 | B48: =D48/$D$41 -> 0 | C48: MENTENIMIENTO | D48: =SUMIFS(BBDD_GASTOS_FINAL!$Z:$Z,BBDD_GASTOS_FINAL!$V:$V,$B$1,BBDD_GASTOS_FINAL!$W:$W,$B$40,BBDD_GASTOS_FINAL!AC:AC,lote_I!$C48)*-1 -> 0
...

Sheet lote_II
A1: LOTE | B1: 3725 | C1: Mortandad-SITIO 2 | G1: CALZIM
C2: Mortandad-SITIO 3 | D2: =SUMIFS(produccion!G:G,produccion!$A:$A,B1) -> -0.040636042
B5: TOTALES | F5: FIJO/VARIABLE | J5: DIRECTO/INDERECTO
B6: VENTAS SITIO 3 | C6: =D55 -> 1.4756234e+08 | F6: VENTAS | G6: =C6 -> 1.4756234e+08 | J6: VENTAS | K6: =G6 -> 1.4756234e+08
B7: OPEX | C7: =SUMIFS(BBDD_GASTOS_FINAL!$Z:$Z,BBDD_GASTOS_FINAL!$V:$V,lote_II!$B$1,BBDD_GASTOS_FINAL!$J:$J,"OPEX")*-1 -> 1.2164178e+08 | F7: Fijo | G7: =SUMIFS(BBDD_GASTOS_FINAL!$Z:$Z,BBDD_GASTOS_FINAL!$V:$V,lote_II!$B$1,BBDD_GASTOS_FINAL!$J:$J,"OPEX",BBDD_GASTOS_FINAL!$K:$K,lote_II!F7)*-1 -> 2702743.9 | J7: DIRECTO | K7: =SUMIFS(BBDD_GASTOS_FINAL!$Z:$Z,BBDD_GASTOS_FINAL!$V:$V,lote_II!$B$1,BBDD_GASTOS_FINAL!$J:$J,"OPEX",BBDD_GASTOS_FINAL!$L:$L,lote_II!J7)*-1 -> 12744288
B8: UTILIDAD | C8: =C6-C7 -> 25920551 | F8: Variable | G8: =SUMIFS(BBDD_GASTOS_FINAL!$Z:$Z,BBDD_GASTOS_FINAL!$V:$V,lote_II!$B$1,BBDD_GASTOS_FINAL!$J:$J,"OPEX",BBDD_GASTOS_FINAL!$K:$K,lote_II!F8)*-1 -> 22292604 | J8: INDIRECTO | K8: =SUMIFS(BBDD_GASTOS_FINAL!$Z:$Z,BBDD_GASTOS_FINAL!$V:$V,lote_II!$B$1,BBDD_GASTOS_FINAL!$J:$J,"OPEX",BBDD_GASTOS_FINAL!$L:$L,lote_II!J8)*-1 -> 12251060
B9: CAPEX | C9: =SUMIFS(BBDD_GASTOS_FINAL!$Y:$Y,BBDD_GASTOS_FINAL!$J:$J,lote_II!B9) -> 0
B10: DEUDA | C10: =SUMIFS(BBDD_GASTOS_FINAL!$Z:$Z,BBDD_GASTOS_FINAL!$J:$J,lote_II!B10,BBDD_GASTOS_FINAL!$V:$V,lote_II!$B$1)*-1 -> 110979.67
B11: Flujo de Caja al Accionista | C11: =C6-C7-C9-C10 -> 25809571 | F11: Flujo de Caja al Accionista | G11: =G6-G7-G8 -> 1.2256699e+08 | J11: Flujo de Caja al Accionista | K11: =K6-K7-K8 -> 1.2256699e+08
A13: id | B13: 4 | E13: id | F13: 3 | I13: id | J13: 7 | M13: id
B14: GESTACIÓN | F14: MATERNIDAD | J14: SITIO 2
B15: OPEX | D15: =SUM(D16:D26) -> 23745555 | F15: OPEX | H15: =SUM(H16:H26) -> 15493174 | J15: OPEX | L15: =SUM(L16:L26) -> 15493174 | M15: 1
A16: 1 | B16: =D16/$D$15 -> 0.30685956 | C16: NUTRICIÓN | D16: =SUMIFS(BBDD_GASTOS_FINAL!$Z:$Z,BBDD_GASTOS_FINAL!$V:$V,$B$1,BBDD_GASTOS_FINAL!$W:$W,$B$14,BBDD_GASTOS_FINAL!$AC:$AC,lote_II!$C16)*-1 -> 7286550.6 | E16: 1 | F16: =H16/$H$15 -> 0.069591757 | G16: NUTRICIÓN | H16: =SUMIFS(BBDD_GASTOS_FINAL!$Z:$Z,BBDD_GASTOS_FINAL!$V:$V,$B$1,BBDD_GASTOS_FINAL!$W:$W,$F$14,BBDD_GASTOS_FINAL!$AC:$AC,$G16)*-1 -> 1078197.2 | I16: 1 | J16: =L16/$L$15 -> 0.069591757 | K16: NUTRICIÓN | L16: =SUMIFS(BBDD_GASTOS_FINAL!$Z:$Z,BBDD_GASTOS_FINAL!$V:$V,$B$1,BBDD_GASTOS_FINAL!$W:$W,$F$14,BBDD_GASTOS_FINAL!$AC:$AC,$G16)*-1 -> 1078197.2 | M16: 1
A17: =A16+1 -> 2 | B17: =D17/$D$15 -> 0.33888287 | C17: PERSONAL | D17: =SUMIFS(BBDD_GASTOS_FINAL!$Z:$Z,BBDD_GASTOS_FINAL!$V:$V,$B$1,BBDD_GASTOS_FINAL!$W:$W,$B$14,BBDD_GASTOS_FINAL!AC:AC,lote_II!$C17)*-1 -> 8046961.7 | E17: 2 | F17: =H17/$H$15 -> 0.50331083 | G17: PERSONAL | H17: =SUMIFS(BBDD_GASTOS_FINAL!$Z:$Z,BBDD_GASTOS_FINAL!$V:$V,$B$1,BBDD_GASTOS_FINAL!$W:$W,$F$14,BBDD_GASTOS_FINAL!$AC:$AC,$G17)*-1 -> 7797882.3 | I17: =I16+1 -> 2 | J17: =L17/$L$15 -> 0.50331083 | K17: PERSONAL | L17: =SUMIFS(BBDD_GASTOS_FINAL!$Z:$Z,BBDD_GASTOS_FINAL!$V:$V,$B$1,BBDD_GASTOS_FINAL!$W:$W,$F$14,BBDD_GASTOS_FINAL!$AC:$AC,$G17)*-1 -> 7797882.3 | M17: =M16+1 -> 2
A18: =A17+1 -> 3 | B18: =D18/$D$15 -> 0.0086864998 | C18: SANIDAD | D18: =SUMIFS(BBDD_GASTOS_FINAL!$Z:$Z,BBDD_GASTOS_FINAL!$V:$V,$B$1,BBDD_GASTOS_FINAL!$W:$W,$B$14,BBDD_GASTOS_FINAL!AC:AC,lote_II!$C18)*-1 -> 206265.76 | E18: 3 | F18: =H18/$H$15 -> 0.02427682 | G18: SANIDAD | H18: =SUMIFS(BBDD_GASTOS_FINAL!$Z:$Z,BBDD_GASTOS_FINAL!$V:$V,$B$1,BBDD_GASTOS_FINAL!$W:$W,$F$14,BBDD_GASTOS_FINAL!$AC:$AC,$G18)*-1 -> 376124.99 | I18: =I17+12 -> 14 | J18: =L18/$L$15 -> 0.02427682 | K18: SANIDAD | L18: =SUMIFS(BBDD_GASTOS_FINAL!$Z:$Z,BBDD_GASTOS_FINAL!$V:$V,$B$1,BBDD_GASTOS_FINAL!$W:$W,$F$14,BBDD_GASTOS_FINAL!$AC:$AC,$G18)*-1 -> 376124.99 | M18: =M17+1 -> 3
A19: =A18+1 -> 4 | B19: =D19/$D$15 -> 0.11752701 | C19: GENÉTICA | D19: =SUMIFS(BBDD_GASTOS_FINAL!$Z:$Z,BBDD_GASTOS_FINAL!$V:$V,$B$1,BBDD_GASTOS_FINAL!$W:$W,$B$14,BBDD_GASTOS_FINAL!AC:AC,lote_II!$C19)*-1 -> 2790744 | E19: 4 | F19: =H19/$H$15 -> 0 | G19: GENÉTICA | H19: =SUMIFS(BBDD_GASTOS_FINAL!$Z:$Z,BBDD_GASTOS_FINAL!$V:$V,$B$1,BBDD_GASTOS_FINAL!$W:$W,$F$14,BBDD_GASTOS_FINAL!$AC:$AC,$G19)*-1 -> 0 | I19: =I18+1 -> 15 | J19: =L19/$L$15 -> 0 | K19: GENÉTICA | L19: =SUMIFS(BBDD_GASTOS_FINAL!$Z:$Z,BBDD_GASTOS_FINAL!$V:$V,$B$1,BBDD_GASTOS_FINAL!$W:$W,$F$14,BBDD_GASTOS_FINAL!$AC:$AC,$G19)*-1 -> 0 | M19: =M18+1 -> 4
A20: =A19+1 -> 5 | B20: =D20/$D$15 -> 0 | C20: FLETES | D20: =SUMIFS(BBDD_GASTOS_FINAL!$Z:$Z,BBDD_GASTOS_FINAL!$V:$V,$B$1,BBDD_GASTOS_FINAL!$W:$W,$B$14,BBDD_GASTOS_FINAL!AC:AC,lote_II!$C20)*-1 -> 0 | E20: 5 | F20: =H20/$H$15 -> 0 | G20: FLETES | H20: =SUMIFS(BBDD_GASTOS_FINAL!$Z:$Z,BBDD_GASTOS_FINAL!$V:$V,$B$1,BBDD_GASTOS_FINAL!$W:$W,$F$14,BBDD_GASTOS_FINAL!$AC:$AC,$G20)*-1 -> 0 | I20: =I19+1 -> 16 | J20: =L20/$L$15 -> 0 | K20: FLETES | L20: =SUMIFS(BBDD_GASTOS_FINAL!$Z:$Z,BBDD_GASTOS_FINAL!$V:$V,$B$1,BBDD_GASTOS_FINAL!$W:$W,$F$14,BBDD_GASTOS_FINAL!$AC:$AC,$G20)*-1 -> 0 | M20: =M19+1 -> 5
A21: =A20+1 -> 6 | B21: =D21/$D$15 -> 0.063587204 | C21: ENERGÍA | D21: =SUMIFS(BBDD_GASTOS_FINAL!$Z:$Z,BBDD_GASTOS_FINAL!$V:$V,$B$1,BBDD_GASTOS_FINAL!$W:$W,$B$14,BBDD_GASTOS_FINAL!AC:AC,lote_II!$C21)*-1 -> 1509913.4 | E21: 6 | F21: =H21/$H$15 -> 0.097456688 | G21: ENERGÍA | H21: =SUMIFS(BBDD_GASTOS_FINAL!$Z:$Z,BBDD_GASTOS_FINAL!$V:$V,$B$1,BBDD_GASTOS_FINAL!$W:$W,$F$14,BBDD_GASTOS_FINAL!$AC:$AC,$G21)*-1 -> 1509913.4 | I21: =I20+1 -> 17 | J21: =L21/$L$15 -> 0.097456688 | K21: ENERGÍA | L21: =SUMIFS(BBDD_GASTOS_FINAL!$Z:$Z,BBDD_GASTOS_FINAL!$V:$V,$B$1,BBDD_GASTOS_FINAL!$W:$W,$F$14,BBDD_GASTOS_FINAL!$AC:$AC,$G21)*-1 -> 1509913.4 | M21: =M20+1 -> 6
A22: =A21+1 -> 7 | B22: =D22/$D$15 -> 0 | C22: MENTENIMIENTO | D22: =SUMIFS(BBDD_GASTOS_FINAL!$Z:$Z,BBDD_GASTOS_FINAL!$V:$V,$B$1,BBDD_GASTOS_FINAL!$W:$W,$B$14,BBDD_GASTOS_FINAL!AC:AC,lote_II!$C22)*-1 -> 0 | E22: 7 | F22: =H22/$H$15 -> 0 | G22: MENTENIMIENTO | H22: =SUMIFS(BBDD_GASTOS_FINAL!$Z:$Z,BBDD_GASTOS_FINAL!$V:$V,$B$1,BBDD_GASTOS_FINAL!$W:$W,$F$14,BBDD_GASTOS_FINAL!$AC:$AC,$G22)*-1 -> 0 | I22: =I21+1 -> 18 | J22: =L22/$L$15 -> 0 | K22: MENTENIMIENTO | L22: =SUMIFS(BBDD_GASTOS_FINAL!$Z:$Z,BBDD_GASTOS_FINAL!$V:$V,$B$1,BBDD_GASTOS_FINAL!$W:$W,$F$14,BBDD_GASTOS_FINAL!$AC:$AC,$G22)*-1 -> 0 | M22: =M21+1 -> 7
A23: =A22+1 -> 8 | B23: =D23/$D$15 -> 0.11315524 | C23: GASTOS OPERATIVOS | D23: =SUMIFS(BBDD_GASTOS_FINAL!$Z:$Z,BBDD_GASTOS_FINAL!$V:$V,$B$1,BBDD_GASTOS_FINAL!$W:$W,$B$14,BBDD_GASTOS_FINAL!AC:AC,lote_II!$C23)*-1 -> 2686933.9 | E23: 8 | F23: =H23/$H$15 -> 0.16246346 | G23: GASTOS OPERATIVOS | H23: =SUMIFS(BBDD_GASTOS_FINAL!$Z:$Z,BBDD_GASTOS_FINAL!$V:$V,$B$1,BBDD_GASTOS_FINAL!$W:$W,$F$14,BBDD_GASTOS_FINAL!$AC:$AC,$G23)*-1 -> 2517074.6 | I23: =I22+1 -> 19 | J23: =L23/$L$15 -> 0.16246346 | K23: GASTOS OPERATIVOS | L23: =SUMIFS(BBDD_GASTOS_FINAL!$Z:$Z,BBDD_GASTOS_FINAL!$V:$V,$B$1,BBDD_GASTOS_FINAL!$W:$W,$F$14,BBDD_GASTOS_FINAL!$AC:$AC,$G23)*-1 -> 2517074.6 | M23: =M22+1 -> 8
A24: =A23+1 -> 9 | B24: =D24/$D$15 -> 0.037984075 | C24: IMPUESTOS | D24: =SUMIFS(BBDD_GASTOS_FINAL!$Z:$Z,BBDD_GASTOS_FINAL!$V:$V,$B$1,BBDD_GASTOS_FINAL!$W:$W,$B$14,BBDD_GASTOS_FINAL!AC:AC,lote_II!$C24)*-1 -> 901952.95 | E24: 9 | F24: =H24/$H$15 -> 0.12248936 | G24: IMPUESTOS | H24: =SUMIFS(BBDD_GASTOS_FINAL!$Z:$Z,BBDD_GASTOS_FINAL!$V:$V,$B$1,BBDD_GASTOS_FINAL!$W:$W,$F$14,BBDD_GASTOS_FINAL!$AC:$AC,$G24)*-1 -> 1897749 | I24: =I23+1 -> 20 | J24: =L24/$L$15 -> 0.12248936 | K24: IMPUESTOS | L24: =SUMIFS(BBDD_GASTOS_FINAL!$Z:$Z,BBDD_GASTOS_FINAL!$V:$V,$B$1,BBDD_GASTOS_FINAL!$W:$W,$F$14,BBDD_GASTOS_FINAL!$AC:$AC,$G24)*-1 -> 1897749 | M24: =M23+1 -> 9
A25: =A24+1 -> 10 | B25: =D25/$D$15 -> 0.013317546 | C25: HONORARIOS | D25: =SUMIFS(BBDD_GASTOS_FINAL!$Z:$Z,BBDD_GASTOS_FINAL!$V:$V,$B$1,BBDD_GASTOS_FINAL!$W:$W,$B$14,BBDD_GASTOS_FINAL!AC:AC,lote_II!$C25)*-1 -> 316232.53 | E25: 10 | F25: =H25/$H$15 -> 0.020411087 | G25: HONORARIOS | H25: =SUMIFS(BBDD_GASTOS_FINAL!$Z:$Z,BBDD_GASTOS_FINAL!$V:$V,$B$1,BBDD_GASTOS_FINAL!$W:$W,$F$14,BBDD_GASTOS_FINAL!$AC:$AC,$G25)*-1 -> 316232.53 | I25: =I24+1 -> 21 | J25: =L25/$L$15 -> 0.020411087 | K25: HONORARIOS | L25: =SUMIFS(BBDD_GASTOS_FINAL!$Z:$Z,BBDD_GASTOS_FINAL!$V:$V,$B$1,BBDD_GASTOS_FINAL!$W:$W,$F$14,BBDD_GASTOS_FINAL!$AC:$AC,$G25)*-1 -> 316232.53 | M25: =M24+1 -> 10
B26: =D26/$D$15 -> 0 | C26: SERVICIOS | D26: =SUMIFS(BBDD_GASTOS_FINAL!$Z:$Z,BBDD_GASTOS_FINAL!$V:$V,$B$1,BBDD_GASTOS_FINAL!$W:$W,$B$14,BBDD_GASTOS_FINAL!AC:AC,lote_II!$C26)*-1 -> 0 | F26: =H26/$H$15 -> 0 | G26: SERVICIOS | H26: =SUMIFS(BBDD_GASTOS_FINAL!$Z:$Z,BBDD_GASTOS_FINAL!$V:$V,$B$1,BBDD_GASTOS_FINAL!$W:$W,$F$14,BBDD_GASTOS_FINAL!$AC:$AC,$G26)*-1 -> 0 | J26: =L26/$L$15 -> 0 | K26: OTROS | L26: =SUMIFS(BBDD_GASTOS_FINAL!$Z:$Z,BBDD_GASTOS_FINAL!$V:$V,$B$1,BBDD_GASTOS_FINAL!$W:$W,$F$14,BBDD_GASTOS_FINAL!$AC:$AC,$G26)*-1 -> 0
F28: COMPRAS EN GESTACION | H28: =D15 -> 23745555 | J28: COMPRAS EN MATERNIDAD | L28: =H29 -> 24167088
B29: VENTAS | D29: =SUMIFS(produccion!$H:$H,produccion!$A:$A,lote_II!$B$1,produccion!$B:$B,lote_II!B14) -> 0 | F29: VENTAS | H29: =SUMIFS(produccion!$H:$H,produccion!$A:$A,lote_II!$B$1,produccion!$B:$B,lote_II!F14) -> 24167088 | J29: VENTAS | L29: =SUMIFS(produccion!$H:$H,produccion!$A:$A,lote_II!$B$1,produccion!$B:$B,lote_II!J14) -> 44760978
B31: UTILDAD | D31: =D29-D15-D28 -> -23745555 | F31: UTILDAD | H31: =H29-H15-H28 -> -15071641 | J31: UTILDAD | L31: =L29-L15-L28 -> 5100715.9
B33: CAPEX | D33: =SUMIFS(BBDD_GASTOS_FINAL!$Y:$Y,BBDD_GASTOS_FINAL!$J:$J,"Capex",BBDD_GASTOS_FINAL!$Z:$Z,$B$13) -> 0 | F33: CAPEX | H33: =SUMIFS(BBDD_GASTOS_FINAL!$Y:$Y,BBDD_GASTOS_FINAL!$J:$J,"Capex",BBDD_GASTOS_FINAL!$Z:$Z,$F$13) -> 0 | J33: CAPEX | L33: =SUMIFS(BBDD_GASTOS_FINAL!$Y:$Y,BBDD_GASTOS_FINAL!$J:$J,"Capex",BBDD_GASTOS_FINAL!$Z:$Z,$J$13) -> 0
B35: DEUDA | D35: =SUMIFS(BBDD_GASTOS_FINAL!$Y:$Y,BBDD_GASTOS_FINAL!$J:$J,"Deuda",BBDD_GASTOS_FINAL!$V:$V,B14) -> 0 | F35: DEUDA | H35: =SUMIFS(BBDD_GASTOS_FINAL!$Y:$Y,BBDD_GASTOS_FINAL!$J:$J,"Deuda",BBDD_GASTOS_FINAL!$V:$V,F14) -> 0 | J35: DEUDA | L35: =SUMIFS(BBDD_GASTOS_FINAL!$Y:$Y,BBDD_GASTOS_FINAL!$J:$J,"deuda",BBDD_GASTOS_FINAL!$V:$V,J14) -> 0
B37: Flujo de Caja al Accionista | D37: =D31-D35-D33 -> -23745555 | F37: Flujo de Caja al Accionista | H37: =H31-H35-H33 -> -15071641 | J37: Flujo de Caja al Accionista | L37: =L31-L35-L33 -> 5100715.9
F38: Margen de utilidad | H38: =H31/H29 -> -0.62364324 | J38: Margen de utilidad | L38: =L31/L29 -> 0.11395452
A39: id | B39: 1 | M39: id
B40: SITIO 3
B41: OPEX | D41: =SUM(D42:D52) -> 58948948
A42: 1 | B42: =D42/$D$41 -> 0.75149576 | C42: NUTRICIÓN | D42: =SUMIFS(BBDD_GASTOS_FINAL!$Z:$Z,BBDD_GASTOS_FINAL!$V:$V,$B$1,BBDD_GASTOS_FINAL!$W:$W,$B$40,BBDD_GASTOS_FINAL!$AC:$AC,lote_II!$C42)*-1 -> 44299884
A43: =A42+1 -> 2 | B43: =D43/$D$41 -> 0.095418867 | C43: PERSONAL | D43: =SUMIFS(BBDD_GASTOS_FINAL!$Z:$Z,BBDD_GASTOS_FINAL!$V:$V,$B$1,BBDD_GASTOS_FINAL!$W:$W,$B$40,BBDD_GASTOS_FINAL!AC:AC,lote_II!$C43)*-1 -> 5624841.8
A44: =A43+1 -> 3 | B44: =D44/$D$41 -> 0.0046519419 | C44: SANIDAD | D44: =SUMIFS(BBDD_GASTOS_FINAL!$Z:$Z,BBDD_GASTOS_FINAL!$V:$V,$B$1,BBDD_GASTOS_FINAL!$W:$W,$B$40,BBDD_GASTOS_FINAL!AC:AC,lote_II!$C44)*-1 -> 274227.08
A45: =A44+1 -> 4 | B45: =D45/$D$41 -> 0 | C45: GENÉTICA | D45: =SUMIFS(BBDD_GASTOS_FINAL!$Z:$Z,BBDD_GASTOS_FINAL!$V:$V,$B$1,BBDD_GASTOS_FINAL!$W:$W,$B$40,BBDD_GASTOS_FINAL!AC:AC,lote_II!$C45)*-1 -> 0
A46: =A45+1 -> 5 | B46: =D46/$D$41 -> 0.057726616 | C46: FLETES | D46: =SUMIFS(BBDD_GASTOS_FINAL!$Z:$Z,BBDD_GASTOS_FINAL!$V:$V,$B$1,BBDD_GASTOS_FINAL!$W:$W,$B$40,BBDD_GASTOS_FINAL!AC:AC,lote_II!$C46)*-1 -> 3402923.3
A47: =A46+1 -> 6 | B47: =D47/$D$41 -> 0.025613917 | C47: ENERGÍA | D47: =SUMIFS(BBDD_GASTOS_FINAL!$Z:$Z,BBDD_GASTOS_FINAL!$V:$V,$B$1,BBDD_GASTOS_FINAL!$W:$W,$B$40,BBDD_GASTOS_FINAL!AC:AC,lote_II!$C47)*-1 -> 1509913.4
A48: =A47+1 -> 7 | B48: =D48/$D$41 -> 0 | C48: MENTENIMIENTO | D48: =SUMIFS(BBDD_GASTOS_FINAL!$Z:$Z,BBDD_GASTOS_FINAL!$V:$V,$B$1,BBDD_GASTOS_FINAL!$W:$W,$B$40,BBDD_GASTOS_FINAL!AC:AC,lote_II!$C48)*-1 -> 0
...

Sheet RRHH
C1: TOTAL 1+2 | D1: COMPONENTE
A2: ADMINISTRACION | B2: =_xlfn.CONCAT("RRHH-",A2) -> RRHH-ADMINISTRACION | C2: 67124149 | D2: 100% ADMINISTRACION - 100% DIRECTOR | E2: CC1
A3: INTENDENCIA | B3: =_xlfn.CONCAT("RRHH-",A3) -> RRHH-INTENDENCIA | C3: 9375237.7 | D3: 100% INTENDENCIA - 6,67% PRODUCCION | E3: CC1
A4: LABORATORIO | B4: =_xlfn.CONCAT("RRHH-",A4) -> RRHH-LABORATORIO | C4: 12249966 | D4: 100% LABORATORIO - 6,67% PRODUCCION | E4: CC1
A5: LOGISTICA | B5: =_xlfn.CONCAT("RRHH-",A5) -> RRHH-LOGISTICA | C5: 6459899.7 | D5: 75% LOGISTICA - 6,67% PRODUCCION | E5: CC1
A6: MANTENIMIENTO | B6: =_xlfn.CONCAT("RRHH-",A6) -> RRHH-MANTENIMIENTO | C6: 7742399.7 | D6: 100% MANTENIMIENTO - 6,67% PRODUCCION | E6: CC1
A7: NFU | B7: =_xlfn.CONCAT("RRHH-",A7) -> RRHH-NFU | C7: 29572095 | D7: 25% LOGISTICA - 100% CAT - 100% EXTERNO NFU - 6,67% PRODUCCION - 95% NFU | E7: CC7
A8: PORTERIA | B8: =_xlfn.CONCAT("RRHH-",A8) -> RRHH-PORTERIA | C8: 10797311 | D8: 100% PORTERIA - 6,67% PRODUCCION | E8: CC1
A9: COMPOST Y FERTILIZANTES | B9: =_xlfn.CONCAT("RRHH-",A9) -> RRHH-COMPOST Y FERTILIZANTES | C9: 1833599.1 | D9: 60% COMPOST Y FERTILIZANTES - 6,67% PRODUCCION | E9: CC14
A10: CEREAL Y POLVILLO | B10: =_xlfn.CONCAT("RRHH-",A10) -> RRHH-CEREAL Y POLVILLO | C10: 0 | D10: 0% CEREAL Y POLVILLO - 0% PRODUCCION | E10: NO
A11: TALLER MECANICO | B11: =_xlfn.CONCAT("RRHH-",A11) -> RRHH-TALLER MECANICO | C11: 6300478.7 | D11: 100% TALLER MECANICO - 6,67% PRODUCCION | E11: CC1
A12: TIERRAS FILTRANTES | B12: =_xlfn.CONCAT("RRHH-",A12) -> RRHH-TIERRAS FILTRANTES | C12: 0 | D12: 0% TIERRAS FILTRANTES - 0% PRODUCCION | E12: NO
A13: VIGILANCIA | B13: =_xlfn.CONCAT("RRHH-",A13) -> RRHH-VIGILANCIA | C13: 6294101.7 | D13: 100% VIGILANCIA - 6,67% PRODUCCION | E13: CC1
... A21: SALES | B21: =_xlfn.CONCAT("RRHH-",A21) -> RRHH-SALES | C21: 0 | D21: 0% SALES - 0% PRODUCCION | E21: NO

Sheet ref_rrhh
A1: Sector | B1: f/v | C1: d/i
A2: ADMINISTRACION | B2: Fijo | C2: Indirecto
A3: INTENDENCIA | B3: Fijo | C3: Indirecto
A4: REACTOR | B4: Variable | C4: Directo
A5: NFU | B5: Variable | C5: Directo
A6: DISPOSICION FINAL DE R. LIQUIDOS | B6: Variable | C6: Directo
A7: DIRECTOR | B7: Fijo | C7: Indirecto
A8: TALLER MECANICO | B8: Fijo | C8: Indirecto
A9: PRODUCCION | B9: Variable | C9: Directo
A10: CAT | B10: Variable | C10: Directo
A11: MANTENIMIENTO | B11: Fijo | C11: Indirecto
A12: PORTERIA | B12: Fijo | C12: Indirecto
... A17: COMPOST Y FERTILIZANTES | B17: Variable | C17: Directo

Sheet aperturado_por_empresa.p2
A1: {=_xlfn._xlws.PY(0,0,#REF!)} -> #REF!

Sheet bbdd_ape.p3
A1: Fecha de Factura/Recibo | B1: Nombre de la empresa a mostrar en la factura | C1: Número | D1: Total con signo | E1: Líneas de factura/Etiqueta | F1: Líneas de factura/Cantidad | G1: Líneas de factura/Precio unitario | H1: Líneas de factura/Unidad de medida | I1: Líneas de factura/Producto | J1: Concepto | K1: Tipo de Gasto 1 | L1: Tipo de Gasto 2 | M1: CCO EMPRESA | N1: CCO - SECTOR | O1: SECTOR_ODOO | P1: # SECTORES | Q1: LISTA_SECTORES | R1: Column1 | S1: Column2 | T1: Column3 | U1: Column4
A2: 45958 | B2: H.S.E. Ingenieria S R L | C2: FA-A 00003-00027849 | D2: -3315400 | E2: OC 0001-00001756: SERVICIOS Monitoreo | F2: 1 | G2: 2740000 | H2: UN | I2: SERVICIOS | J2: OPEX | K2: VARIABLE | L2: INDIRECTO | M2: 0 | N2: CC1 | O2: #NUM! | P2: 10 | Q2: BACHAS, CEREAL & POLVILLO, COMPOST & FERTILIZANTES, DISPOSICIÓN FINAL RESIDUOS LIQUIDOS, DISPOSICIÓN FINAL RESIDUOS SOLIDOS, EXPORTACION, NFU, PILETAS, REACTORES, TIERRAS FILTRANTES | R2: 1 | S2: -3315400 | T2: 1 | U2: APERTURADO POR EMPRESA
A3: 45933 | B3: Alvarez, Alejandro Dario | C3: FA-C 00002-00000250 | D3: -509644 | E3: OC 0001-00001364: HIGIENE Y SEGURIDAD Servicio de asesoramiento para la gestión ambiental en el cumplimiento de la normativa vigente para la provincia de Santa Fe. Servicio de higiene y seguridad de trabajo con cumplimiento de actividades s/Resol. SRT 905/15- MES 09/2025 | F3: 1 | G3: 509644 | H3: UN | I3: HIGIENE Y SEGURIDAD | J3: OPEX | K3: FIJO | L3: DIRECTO | M3: 0 | N3: CC1 | O3: #NUM! | P3: 10 | Q3: BACHAS, CEREAL & POLVILLO, COMPOST & FERTILIZANTES, DISPOSICIÓN FINAL RESIDUOS LIQUIDOS, DISPOSICIÓN FINAL RESIDUOS SOLIDOS, EXPORTACION, NFU, PILETAS, REACTORES, TIERRAS FILTRANTES | R3: 1 | S3: -509644 | T3: 1 | U3: APERTURADO POR EMPRESA
A4: 45931 | B4: Quiroz, Maria Ines | C4: FA-C 00002-00000031 | D4: -2097200 | E4: OC 0001-00001801: PERSONAL horas soldador | F4: 1 | G4: 2097200 | H4: UN | I4: PERSONAL | J4: OPEX | K4: FIJO | L4: INDIRECTO | M4: 0 | N4: CC1 | O4: #NUM! | P4: 10 | Q4: BACHAS, CEREAL & POLVILLO, COMPOST & FERTILIZANTES, DISPOSICIÓN FINAL RESIDUOS LIQUIDOS, DISPOSICIÓN FINAL RESIDUOS SOLIDOS, EXPORTACION, NFU, PILETAS, REACTORES, TIERRAS FILTRANTES | R4: 1 | S4: -2097200 | T4: 1 | U4: APERTURADO POR EMPRESA
A5: 45947 | B5: Lopez, Jesus Rodrigo | C5: OCOM/2025/0470 | D5: -180000 | E5: OC 0001-00001345: LOGISTICA puerto | F5: 1 | G5: 180000 | H5: UN | I5: LOGISTICA | J5: OPEX | K5: VARIABLE | L5: DIRECTO | M5: 0 | N5: CC9 | O5: #NUM! | P5: 1 | Q5: CEREAL & POLVILLO | R5: 1 | S5: -180000 | T5: 1 | U5: APERTURADO POR EMPRESA
A6: 45938 | B6: Lopez, Jesus Rodrigo | C6: OCOM/2025/0458 | D6: -180000 | E6: OC 0001-00001804: LOGISTICA | F6: 1 | G6: 180000 | H6: UN | I6: LOGISTICA | J6: OPEX | K6: VARIABLE | L6: DIRECTO | M6: 0 | N6: CC9 | O6: #NUM! | P6: 1 | Q6: CEREAL & POLVILLO | R6: 1 | S6: -180000 | T6: 1 | U6: APERTURADO POR EMPRESA
A7: 45931 | B7: Lopez, Jesus Rodrigo | C7: OCOM/2025/0443 | D7: -156000 | E7: OC 0001-00000944: LOGISTICA | F7: 1 | G7: 156000 | H7: UN | I7: LOGISTICA | J7: OPEX | K7: VARIABLE | L7: DIRECTO | M7: 0 | N7: CC9 | O7: #NUM! | P7: 1 | Q7: CEREAL & POLVILLO | R7: 1 | S7: -156000 | T7: 1 | U7: APERTURADO POR EMPRESA
A8: 45950 | B8: Area Abierta S.A. | C8: FA-A 00001-00001146 | D8: -798367.68 | E8: OC 0001-00001924: REPOSICION paño zda luz 6.50 2.50 mm 4 x1,60 metros (NFU) | F8: 1 | G8: 659808 | H8: UN | I8: REPOSICION | J8: OPEX | K8: VARIABLE | L8: DIRECTO | M8: 0 | N8: CC7 | O8: #NUM! | P8: 2 | Q8: NFU | R8: 1 | S8: -798367.68 | T8: 1 | U8: APERTURADO POR EMPRESA
A9: 45958 | B9: Bernis, Carlos Oscar | C9: FA-A 00006-00000175 | D9: -968000 | E9: OC 0001-00002255: LOGISTICA Viaje realizado fecha 28/10 | F9: 1 | G9: 800000 | H9: UN | I9: LOGISTICA | J9: OPEX | K9: VARIABLE | L9: DIRECTO | M9: 0 | N9: CC7 | O9: #NUM! | P9: 2 | Q9: NFU | R9: 1 | S9: -968000 | T9: 1 | U9: APERTURADO POR EMPRESA
A10: 45952 | B10: Bernis, Carlos Oscar | C10: FA-A 00006-00000174 | D10: -968000 | E10: OC 0001-00002218: LOGISTICA Viaje realizado fecha 20-10 worms - Parque industrial guernica | F10: 1 | G10: 800000 | H10: UN | I10: LOGISTICA | J10: OPEX | K10: VARIABLE | L10: DIRECTO | M10: 0 | N10: CC7 | O10: #NUM! | P10: 2 | Q10: NFU | R10: 1 | S10: -968000 | T10: 1 | U10: APERTURADO POR EMPRESA
A11: 45939 | B11: Bernis, Carlos Oscar | C11: FA-A 00006-00000171 | D11: -302500 | E11: OC 0001-00001836: LOGISTICA Viaje: 4 de septiembre origen: lujan worms con cubiertas en desuso . Destino :worms | F11: 1 | G11: 250000 | H11: UN | I11: LOGISTICA | J11: OPEX | K11: VARIABLE | L11: DIRECTO | M11: 0 | N11: CC7 | O11: #NUM! | P11: 2 | Q11: NFU | R11: 1 | S11: -302500 | T11: 1 | U11: APERTURADO POR EMPRESA
A12: 45939 | B12: Bernis, Carlos Oscar | C12: FA-A 00006-00000170 | D12: -968000 | E12: OC 0001-00002228: LOGISTICA Viaje realizado fecha 8/10 neumáticos | F12: 1 | G12: 800000 | H12: UN | I12: LOGISTICA | J12: OPEX | K12: VARIABLE | L12: DIRECTO | M12: 0 | N12: CC7 | O12: #NUM! | P12: 2 | Q12: NFU | R12: 1 | S12: -968000 | T12: 1 | U12: APERTURADO POR EMPRESA
A13: 45958 | B13: Comercial Uritorco S. R. L. (w) | C13: FA-A 00001-00007089 | D13: -66182.16 | E13: OC 0001-00002229: REPOSICION Adaptador 3/4 | F13: 2 | G13: 19578.51 | H13: UN | I13: REPOSICION | J13: OPEX | K13: VARIABLE | L13: INDIRECTO | M13: 0 | N13: CC7 | O13: #NUM! | P13: 2 | Q13: NFU | R13: 1 | S13: -66182.16 | T13: 2 | U13: APERTURADO POR EMPRESA
... A77: 45932 | B77: Acosta, Roberto Maximiliano | C77: FA-C 00001-00000616 | D77: -4632990 | E77: OC 0001-00001709: SERVICIOS de limpieza +ipc julio y agosto 3,8% | F77: 1 | G77: 4632990 | H77: UN | I77: SERVICIOS | J77: OPEX | K77: VARIABLE | L77: INDIRECTO | M77: 0 | N77: CC1 | O77: #NUM! | P77: 10 | Q77: BACHAS, CEREAL & POLVILLO, COMPOST & FERTILIZANTES, DISPOSICIÓN FINAL RESIDUOS LIQUIDOS, DISPOSICIÓN FINAL RESIDUOS SOLIDOS, EXPORTACION, NFU, PILETAS, REACTORES, TIERRAS FILTRANTES | R77: 1 | S77: -4632990 | T77: 1 | U77: APERTURADO POR EMPRESA
A78: 45931 | B78: Adhoc S.A. | C78: FA-A 00003-00019779 | D78: -2004596.6 | E78: OC 0001-00001367: SERVICIOS Sistema contable | F78: 1 | G78: 1656691.4 | H78: UN | I78: SERVICIOS | J78: OPEX | K78: FIJO | L78: INDIRECTO | M78: CC13 | N78: CC1 | O78: #NUM! | P78: 10 | Q78: BACHAS, CEREAL & POLVILLO, COMPOST & FERTILIZANTES, DISPOSICIÓN FINAL RESIDUOS LIQUIDOS, DISPOSICIÓN FINAL RESIDUOS SOLIDOS, EXPORTACION, NFU, PILETAS, REACTORES, TIERRAS FILTRANTES | R78: 0.7 | S78: -1403217.6 | T78: 0.7 | U78: APERTURADO POR EMPRESA
A79: 45950 | B79: American Express Argentina S. A. | C79: OCOM/2025/0472 | D79: -344000.85 | E79: OC 0001-00001936: PERSONAL | F79: 1 | G79: 344000.85 | H79: UN | I79: PERSONAL | J79: OPEX | K79: VARIABLE | L79: INDIRECTO | M79: 0 | N79: CC1 | O79: #NUM! | P79: 10 | Q79: BACHAS, CEREAL & POLVILLO, COMPOST & FERTILIZANTES, DISPOSICIÓN FINAL RESIDUOS LIQUIDOS, DISPOSICIÓN FINAL RESIDUOS SOLIDOS, EXPORTACION, NFU, PILETAS, REACTORES, TIERRAS FILTRANTES | R79: 1 | S79: -344000.85 | T79: 1 | U79: APERTURADO POR EMPRESA
A80: 45949 | B80: Amx Argentina Sociedad Anonima | C80: FA-A 01331-01351660 | D80: -40348.6 | E80: OC 0001-00002225: SERVICIOS Servicio Móvil | F80: 1 | G80: 10605 | H80: UN | I80: SERVICIOS | J80: OPEX | K80: VARIABLE | L80: INDIRECTO | M80: 0 | N80: CC1 | O80: #NUM! | P80: 10 | Q80: BACHAS, CEREAL & POLVILLO, COMPOST & FERTILIZANTES, DISPOSICIÓN FINAL RESIDUOS LIQUIDOS, DISPOSICIÓN FINAL RESIDUOS SOLIDOS, EXPORTACION, NFU, PILETAS, REACTORES, TIERRAS FILTRANTES | R80: 1 | S80: -40348.6 | T80: 1 | U80: APERTURADO POR EMPRESA
A81: 45931 | B81: Aranda, Marisa Isabel | C81: FA-C 00005-00000212 | D81: -720000 | E81: OC 0001-00001711: SERVICIOS servicio de parquización | F81: 9 | G81: 80000 | H81: UN | I81: SERVICIOS | J81: OPEX | K81: VARIABLE | L81: INDIRECTO | M81: 0 | N81: CC1 | O81: #NUM! | P81: 10 | Q81: BACHAS, CEREAL & POLVILLO, COMPOST & FERTILIZANTES, DISPOSICIÓN FINAL RESIDUOS LIQUIDOS, DISPOSICIÓN FINAL RESIDUOS SOLIDOS, EXPORTACION, NFU, PILETAS, REACTORES, TIERRAS FILTRANTES | R81: 1 | S81: -720000 | T81: 9 | U81: APERTURADO POR EMPRESA
A82: 45952 | B82: ARCA | C82: OCOM/2025/0481 | D82: -3840846 | E82: OC 0001-00002049: IMPUESTOS anticipo | F82: 1 | G82: 3840846 | H82: UN | I82: IMPUESTOS | J82: OPEX | K82: VARIABLE | L82: INDIRECTO | M82: 0 | N82: CC1 | O82: #NUM! | P82: 10 | Q82: BACHAS, CEREAL & POLVILLO, COMPOST & FERTILIZANTES, DISPOSICIÓN FINAL RESIDUOS LIQUIDOS, DISPOSICIÓN FINAL RESIDUOS SOLIDOS, EXPORTACION, NFU, PILETAS, REACTORES, TIERRAS FILTRANTES | R82: 1 | S82: -3840846 | T82: 1 | U82: APERTURADO POR EMPRESA
A83: 45952 | B83: ARCA | C83: OCOM/2025/0479 | D83: -1311921.2 | E83: OC 0001-00002043: IMPUESTOS Multa suse | F83: 1 | G83: 1311921.2 | H83: UN | I83: IMPUESTOS | J83: DEUDA | K83: VARIABLE | L83: INDIRECTO | M83: 0 | N83: CC1 | O83: #NUM! | P83: 10 | Q83: BACHAS, CEREAL & POLVILLO, COMPOST & FERTILIZANTES, DISPOSICIÓN FINAL RESIDUOS LIQUIDOS, DISPOSICIÓN FINAL RESIDUOS SOLIDOS, EXPORTACION, NFU, PILETAS, REACTORES, TIERRAS FILTRANTES | R83: 1 | S83: -1311921.2 | T83: 1 | U83: APERTURADO POR EMPRESA
A84: 45946 | B84: ARCA | C84: OCOM/2025/0466 | D84: -552778.24 | E84: OC 0001-00001904: HONORARIOS Didomenico | F84: 1 | G84: 552778.24 | H84: UN | I84: HONORARIOS | J84: DEUDA | K84: VARIABLE | L84: INDIRECTO | M84: 0 | N84: CC1 | O84: #NUM! | P84: 10 | Q84: BACHAS, CEREAL & POLVILLO, COMPOST & FERTILIZANTES, DISPOSICIÓN FINAL RESIDUOS LIQUIDOS, DISPOSICIÓN FINAL RESIDUOS SOLIDOS, EXPORTACION, NFU, PILETAS, REACTORES, TIERRAS FILTRANTES | R84: 1 | S84: -552778.24 | T84: 1 | U84: APERTURADO POR EMPRESA
A85: 45946 | B85: ARCA | C85: OCOM/2025/0464 | D85: -15235035 | E85: OC 0001-00001869: IMPUESTOS Deuda, Planes de pago | F85: 1 | G85: 15235035 | H85: UN | I85: IMPUESTOS | J85: DEUDA | K85: VARIABLE | L85: INDIRECTO | M85: 0 | N85: CC1 | O85: #NUM! | P85: 10 | Q85: BACHAS, CEREAL & POLVILLO, COMPOST & FERTILIZANTES, DISPOSICIÓN FINAL RESIDUOS LIQUIDOS, DISPOSICIÓN FINAL RESIDUOS SOLIDOS, EXPORTACION, NFU, PILETAS, REACTORES, TIERRAS FILTRANTES | R85: 1 | S85: -15235035 | T85: 1 | U85: APERTURADO POR EMPRESA
A86: 45954 | B86: Asociacion Empleados De Comercio De Rosario | C86: OCOM/2025/0504 | D86: -1383181 | E86: OC 0001-00002124: SERVICIOS | F86: 1 | G86: 1383181 | H86: UN | I86: SERVICIOS | J86: DEUDA | K86: VARIABLE | L86: INDIRECTO | M86: 0 | N86: CC1 | O86: #NUM! | P86: 10 | Q86: BACHAS, CEREAL & POLVILLO, COMPOST & FERTILIZANTES, DISPOSICIÓN FINAL RESIDUOS LIQUIDOS, DISPOSICIÓN FINAL RESIDUOS SOLIDOS, EXPORTACION, NFU, PILETAS, REACTORES, TIERRAS FILTRANTES | R86: 1 | S86: -1383181 | T86: 1 | U86: APERTURADO POR EMPRESA
A87: 45951 | B87: Asociacion Mutual 23 De Setiembre | C87: OCOM/2025/0477 | D87: -10000000 | E87: OC 0001-00002032: SERVICIOS mutual | F87: 1 | G87: 10000000 | H87: UN | I87: SERVICIOS | J87: DEUDA | K87: VARIABLE | L87: INDIRECTO | M87: 0 | N87: CC1 | O87: #NUM! | P87: 10 | Q87: BACHAS, CEREAL & POLVILLO, COMPOST & FERTILIZANTES, DISPOSICIÓN FINAL RESIDUOS LIQUIDOS, DISPOSICIÓN FINAL RESIDUOS SOLIDOS, EXPORTACION, NFU, PILETAS, REACTORES, TIERRAS FILTRANTES | R87: 1 | S87: -10000000 | T87: 1 | U87: APERTURADO POR EMPRESA
A88: 45931 | B88: Berardi, Alberto Jose - | C88: FA-C 00005-00000184 | D88: -560000 | E88: OC 0001-00001696: SERVICIOS Abono mensual | F88: 1 | G88: 560000 | H88: UN | I88: SERVICIOS | J88: OPEX | K88: VARIABLE | L88: INDIRECTO | M88: 0 | N88: CC1 | O88: #NUM! | P88: 10 | Q88: BACHAS, CEREAL & POLVILLO, COMPOST & FERTILIZANTES, DISPOSICIÓN FINAL RESIDUOS LIQUIDOS, DISPOSICIÓN FINAL RESIDUOS SOLIDOS, EXPORTACION, NFU, PILETAS, REACTORES, TIERRAS FILTRANTES | R88: 1 | S88: -560000 | T88: 1 | U88: APERTURADO POR EMPRESA
A89: 45943 | B89: Bollini, Tomas Maria | C89: OCOM/2025/0461 | D89: -114000 | E89: OC 0001-00001835: PERSONAL CARTA DOCUMENTO | F89: 1 | G89: 114000 | H89: UN | I89: PERSONAL | J89: OPEX | K89: VARIABLE | L89: INDIRECTO | M89: 0 | N89: CC1 | O89: #NUM! | P89: 10 | Q89: BACHAS, CEREAL & POLVILLO, COMPOST & FERTILIZANTES, DISPOSICIÓN FINAL RESIDUOS LIQUIDOS, DISPOSICIÓN FINAL RESIDUOS SOLIDOS, EXPORTACION, NFU, PILETAS, REACTORES, TIERRAS FILTRANTES | R89: 1 | S89: -114000 | T89: 1 | U89: APERTURADO POR EMPRESA
A90: 45937 | B90: Castelli, Guillermo Alejandro | C90: OCOM/2025/0457 | D90: -1500000 | E90: OC 0001-00001799: PERSONAL personal, acuerdo. | F90: 1 | G90: 1500000 | H90: UN | I90: PERSONAL | J90: DEUDA | K90: VARIABLE | L90: INDIRECTO | M90: 0 | N90: CC1 | O90: #NUM! | P90: 10 | Q90: BACHAS, CEREAL & POLVILLO, COMPOST & FERTILIZANTES, DISPOSICIÓN FINAL RESIDUOS LIQUIDOS, DISPOSICIÓN FINAL RESIDUOS SOLIDOS, EXPORTACION, NFU, PILETAS, REACTORES, TIERRAS FILTRANTES | R90: 1 | S90: -1500000 | T90: 1 | U90: APERTURADO POR EMPRESA
... A152: 45961 | B152: PROVEEDOR | C152: MT-0004 | D152: -3029264148 | E152: AFE (S) | F152: 2236.94 | G152: 925 | H152: TN | I152: MATERIA PRIMA | J152: OPEX | K152: VARIABLE | L152: DIRECTO | M152: 0 | N152: CC11 | O152: #NUM! | P152: 1 | Q152: EXPORTACION | R152: 1 | S152: -3029264148 | T152: 2236.94 | U152: APERTURADO POR EMPRESA
A153: 45961 | B153: PILETAS | C153: MT-0005 | D153: 0 | E153: AG- A | F153: #NUM! | G153: 850 | H153: TN | I153: MATERIA PRIMA | J153: OPEX | K153: VARIABLE | L153: DIRECTO | M153: 0 | N153: CC11 | O153: #NUM! | P153: 1 | Q153: EXPORTACION | R153: 1 | S153: 0 | T153: #NUM! | U153: APERTURADO POR EMPRESA
A154: 45961 | B154: PILETAS | C154: MT-0006 | D154: -24537811 | E154: AG- B | F154: 20.44 | G154: 820 | H154: TN | I154: MATERIA PRIMA | J154: OPEX | K154: VARIABLE | L154: DIRECTO | M154: 0 | N154: CC11 | O154: #NUM! | P154: 1 | Q154: EXPORTACION | R154: 1 | S154: -24537811 | T154: 20.44 | U154: APERTURADO POR EMPRESA
A155: 45961 | B155: PILETAS | C155: MT-0007 | D155: -12127190 | E155: AG- C | F155: 15.34 | G155: 540 | H155: TN | I155: MATERIA PRIMA | J155: OPEX | K155: VARIABLE | L155: DIRECTO | M155: 0 | N155: CC11 | O155: #NUM! | P155: 1 | Q155: EXPORTACION | R155: 1 | S155: -12127190 | T155: 15.34 | U155: APERTURADO POR EMPRESA
A156: 45961 | B156: REACTORES | C156: MT-0008 | D156: 0 | E156: ARE- A | F156: #NUM! | G156: 820 | H156: TN | I156: MATERIA PRIMA | J156: OPEX | K156: VARIABLE | L156: DIRECTO | M156: 0 | N156: CC11 | O156: #NUM! | P156: 1 | Q156: EXPORTACION | R156: 1 | S156: 0 | T156: #NUM! | U156: APERTURADO POR EMPRESA
A157: 45961 | B157: REACTORES | C157: MT-0009 | D157: 0 | E157: ARE- B | F157: #NUM! | G157: 820 | H157: TN | I157: MATERIA PRIMA | J157: OPEX | K157: VARIABLE | L157: DIRECTO | M157: 0 | N157: CC11 | O157: #NUM! | P157: 1 | Q157: EXPORTACION | R157: 1 | S157: 0 | T157: #NUM! | U157: APERTURADO POR EMPRESA
A158: 45961 | B158: REACTORES -PZ | C158: MT-0010 | D158: -246338496 | E158: ARE- A | F158: 205.2 | G158: 820 | H158: TN | I158: MATERIA PRIMA | J158: OPEX | K158: VARIABLE | L158: DIRECTO | M158: 0 | N158: NO | O158: #NUM! | P158: 1 | Q158: ANULADO | R158: 1 | S158: -246338496 | T158: 205.2 | U158: APERTURADO POR EMPRESA
A159: 45961 | B159: REACTORES - PZ | C159: MT-0011 | D159: 0 | E159: ARE- B | F159: #NUM! | G159: 820 | H159: TN | I159: MATERIA PRIMA | J159: OPEX | K159: VARIABLE | L159: DIRECTO | M159: 0 | N159: NO | O159: #NUM! | P159: 1 | Q159: ANULADO | R159: 1 | S159: 0 | T159: #NUM! | U159: APERTURADO POR EMPRESA
A160: 45961 | B160: WORMS 2 | C160: MT-0012 | D160: -154255824 | E160: AG- A | F160: 123.96 | G160: 850 | H160: TN | I160: MATERIA PRIMA | J160: OPEX | K160: VARIABLE | L160: DIRECTO | M160: 0 | N160: NO | O160: #NUM! | P160: 1 | Q160: ANULADO | R160: 1 | S160: -154255824 | T160: 123.96 | U160: APERTURADO POR EMPRESA
A161: 45961 | B161: WORMS 2 | C161: MT-0013 | D161: 0 | E161: AG- B | F161: #NUM! | G161: 820 | H161: TN | I161: MATERIA PRIMA | J161: OPEX | K161: VARIABLE | L161: DIRECTO | M161: 0 | N161: NO | O161: #NUM! | P161: 1 | Q161: ANULADO | R161: 1 | S161: 0 | T161: #NUM! | U161: APERTURADO POR EMPRESA
A162: 45961 | B162: WORMS 2 | C162: MT-0014 | D162: -8300880 | E162: AG- C | F162: 10.5 | G162: 540 | H162: TN | I162: MATERIA PRIMA | J162: OPEX | K162: VARIABLE | L162: DIRECTO | M162: 0 | N162: NO | O162: #NUM! | P162: 1 | Q162: ANULADO | R162: 1 | S162: -8300880 | T162: 10.5 | U162: APERTURADO POR EMPRESA
A163: 45961 | B163: PZ ( BORRA + PROVEEDOR) | C163: MT-0021 | D163: -91072512 | E163: AG- C | F163: 115.2 | G163: 540 | H163: TN | I163: MATERIA PRIMA | J163: OPEX | K163: VARIABLE | L163: DIRECTO | M163: 0 | N163: NO | O163: #NUM! | P163: 1 | Q163: ANULADO | R163: 1 | S163: -91072512 | T163: 115.2 | U163: APERTURADO POR EMPRESA
A164: 45961 | B164: PILETAS | C164: MT-0022 | D164: 0 | E164: AG- C | F164: #NUM! | G164: 540 | H164: TN | I164: MATERIA PRIMA | J164: OPEX | K164: VARIABLE | L164: DIRECTO | M164: 0 | N164: CC5 | O164: #NUM! | P164: 1 | Q164: REACTORES | R164: 1 | S164: 0 | T164: #NUM! | U164: APERTURADO POR EMPRESA
...

Sheet cco_bbdd_asignado.p4 
A1: {=_xlfn._xlws.PY(1,0,bbdd2[#All])} -> 0 | B1: 1 | C1: 2 | D1: 3 | E1: 4 | F1: 5 | G1: 6 | H1: 7 | I1: 8 | J1: 9 | K1: 10 | L1: 11 | M1: 12 | N1: 13 | O1: 14 | P1: 15 | Q1: 16 | R1: 17 | S1: 18 | T1: 19 | U1: 20 | V1: SECTOR APERTURADO
A2: Fecha de Factura/Recibo | B2: Nombre de la empresa a mostrar en la factura | C2: Número | D2: Total con signo | E2: Líneas de factura/Etiqueta | F2: Líneas de factura/Cantidad | G2: Líneas de factura/Precio unitario | H2: Líneas de factura/Unidad de medida | I2: Líneas de factura/Producto | J2: Concepto | K2: Tipo de Gasto 1 | L2: Tipo de Gasto 2 | M2: CCO EMPRESA | N2: CCO - SECTOR | O2: SECTOR_ODOO | P2: # SECTORES | Q2: LISTA_SECTORES | R2: Column1 | S2: Column2 | T2: Column3 | U2: Column4 | V2: LISTA_SECTORES
A3: 45958 | B3: H.S.E. Ingenieria S R L | C3: FA-A 00003-00027849 | D3: -3315400 | E3: OC 0001-00001756: SERVICIOS Monitoreo | F3: 1 | G3: 2740000 | H3: UN | I3: SERVICIOS | J3: OPEX | K3: VARIABLE | L3: INDIRECTO | M3: 0 | N3: CC1 | O3: #NUM! | P3: 10 | Q3: BACHAS, CEREAL & POLVILLO, COMPOST & FERTILIZANTES, DISPOSICIÓN FINAL RESIDUOS LIQUIDOS, DISPOSICIÓN FINAL RESIDUOS SOLIDOS, EXPORTACION, NFU, PILETAS, REACTORES, TIERRAS FILTRANTES | R3: 1 | S3: -3315400 | T3: 1 | U3: APERTURADO POR EMPRESA | V3: BACHAS
A4: 45958 | B4: H.S.E. Ingenieria S R L | C4: FA-A 00003-00027849 | D4: -3315400 | E4: OC 0001-00001756: SERVICIOS Monitoreo | F4: 1 | G4: 2740000 | H4: UN | I4: SERVICIOS | J4: OPEX | K4: VARIABLE | L4: INDIRECTO | M4: 0 | N4: CC1 | O4: #NUM! | P4: 10 | Q4: BACHAS, CEREAL & POLVILLO, COMPOST & FERTILIZANTES, DISPOSICIÓN FINAL RESIDUOS LIQUIDOS, DISPOSICIÓN FINAL RESIDUOS SOLIDOS, EXPORTACION, NFU, PILETAS, REACTORES, TIERRAS FILTRANTES | R4: 1 | S4: -3315400 | T4: 1 | U4: APERTURADO POR EMPRESA | V4: CEREAL & POLVILLO
A5: 45958 | B5: H.S.E. Ingenieria S R L | C5: FA-A 00003-00027849 | D5: -3315400 | E5: OC 0001-00001756: SERVICIOS Monitoreo | F5: 1 | G5: 2740000 | H5: UN | I5: SERVICIOS | J5: OPEX | K5: VARIABLE | L5: INDIRECTO | M5: 0 | N5: CC1 | O5: #NUM! | P5: 10 | Q5: BACHAS, CEREAL & POLVILLO, COMPOST & FERTILIZANTES, DISPOSICIÓN FINAL RESIDUOS LIQUIDOS, DISPOSICIÓN FINAL RESIDUOS SOLIDOS, EXPORTACION, NFU, PILETAS, REACTORES, TIERRAS FILTRANTES | R5: 1 | S5: -3315400 | T5: 1 | U5: APERTURADO POR EMPRESA | V5: COMPOST & FERTILIZANTES
A6: 45958 | B6: H.S.E. Ingenieria S R L | C6: FA-A 00003-00027849 | D6: -3315400 | E6: OC 0001-00001756: SERVICIOS Monitoreo | F6: 1 | G6: 2740000 | H6: UN | I6: SERVICIOS | J6: OPEX | K6: VARIABLE | L6: INDIRECTO | M6: 0 | N6: CC1 | O6: #NUM! | P6: 10 | Q6: BACHAS, CEREAL & POLVILLO, COMPOST & FERTILIZANTES, DISPOSICIÓN FINAL RESIDUOS LIQUIDOS, DISPOSICIÓN FINAL RESIDUOS SOLIDOS, EXPORTACION, NFU, PILETAS, REACTORES, TIERRAS FILTRANTES | R6: 1 | S6: -3315400 | T6: 1 | U6: APERTURADO POR EMPRESA | V6: DISPOSICIÓN FINAL RESIDUOS LIQUIDOS
A7: 45958 | B7: H.S.E. Ingenieria S R L | C7: FA-A 00003-00027849 | D7: -3315400 | E7: OC 0001-00001756: SERVICIOS Monitoreo | F7: 1 | G7: 2740000 | H7: UN | I7: SERVICIOS | J7: OPEX | K7: VARIABLE | L7: INDIRECTO | M7: 0 | N7: CC1 | O7: #NUM! | P7: 10 | Q7: BACHAS, CEREAL & POLVILLO, COMPOST & FERTILIZANTES, DISPOSICIÓN FINAL RESIDUOS LIQUIDOS, DISPOSICIÓN FINAL RESIDUOS SOLIDOS, EXPORTACION, NFU, PILETAS, REACTORES, TIERRAS FILTRANTES | R7: 1 | S7: -3315400 | T7: 1 | U7: APERTURADO POR EMPRESA | V7: DISPOSICIÓN FINAL RESIDUOS SOLIDOS
A8: 45958 | B8: H.S.E. Ingenieria S R L | C8: FA-A 00003-00027849 | D8: -3315400 | E8: OC 0001-00001756: SERVICIOS Monitoreo | F8: 1 | G8: 2740000 | H8: UN | I8: SERVICIOS | J8: OPEX | K8: VARIABLE | L8: INDIRECTO | M8: 0 | N8: CC1 | O8: #NUM! | P8: 10 | Q8: BACHAS, CEREAL & POLVILLO, COMPOST & FERTILIZANTES, DISPOSICIÓN FINAL RESIDUOS LIQUIDOS, DISPOSICIÓN FINAL RESIDUOS SOLIDOS, EXPORTACION, NFU, PILETAS, REACTORES, TIERRAS FILTRANTES | R8: 1 | S8: -3315400 | T8: 1 | U8: APERTURADO POR EMPRESA | V8: EXPORTACION
A9: 45958 | B9: H.S.E. Ingenieria S R L | C9: FA-A 00003-00027849 | D9: -3315400 | E9: OC 0001-00001756: SERVICIOS Monitoreo | F9: 1 | G9: 2740000 | H9: UN | I9: SERVICIOS | J9: OPEX | K9: VARIABLE | L9: INDIRECTO | M9: 0 | N9: CC1 | O9: #NUM! | P9: 10 | Q9: BACHAS, CEREAL & POLVILLO, COMPOST & FERTILIZANTES, DISPOSICIÓN FINAL RESIDUOS LIQUIDOS, DISPOSICIÓN FINAL RESIDUOS SOLIDOS, EXPORTACION, NFU, PILETAS, REACTORES, TIERRAS FILTRANTES | R9: 1 | S9: -3315400 | T9: 1 | U9: APERTURADO POR EMPRESA | V9: NFU
