Workbook

Sheet rubros_id_opex
A1: nombre | B1: id
A2: ENERGIA | B2: 1
A3: HABILITACIONES Y CERT | B3: 2
A4: HIGIENE Y SEGURIDAD | B4: 3
A5: IMPUESTOS | B5: 4
A6: INSUMOS | B6: 5
A7: INVERSION | B7: 6
A8: LOGISTICA | B8: 7
A9: M.PRIMAS | B9: 8
A10: MANTENIMIENTO PREVENTIVO | B10: 9
A11: PERSONAL | B11: 10
A12: REPARACIONES | B12: 11
A13: REPOSICION | B13: 12
A14: SERVICIOS | B14: 12

Sheet fer_gral
C29: DEUDA
C30: FARO | D30: UNI
C31: M23 WORMS | D31: UNI
C32: M23 BROKER WORLD | D32: UNI
C33: SOUTHCROSS | D33: UNI
C34: RAUL BRINGAS | D34: UNI
C35: MOLLINS | D35: UNI
C36: NICOLAS AVELLINO | D36: UNI
C37: JORGE FERNANDEZ | D37: UNI
C38: CARBO | D38: UNI
C39: GARANTIZAR | D39: UNI
C40: CIRCULO CERRADO | D40: UNI
C41: SANTIAGO BORSONE | D41: UNI
... C48: CRISTIAN AMEGHINI | D48: UNI

Sheet fer_expo
B2: RUBRO + GASTO | C2: UM | D2: Q | E2: MONEDA | F2: P | G2: TOTAL
B3: ENERGIA
B4: NAFTA | C4: LTS
B5: ENERGIA ELECTRICA | C5: KW/H
B6: GASOIL G2 | C6: LTS
B7: GASOIL G3 | C7: LTS
B8: FULL OIL | C8: KG
B10: HABILITACION & CERT
B11: ISCC | C11: UNI
B12: AMBIENTAL | C12: UNI
B13: MUNICIPAL | C13: UNI
B15: HIGIENE & SEGURIDAD
B16: EPP | C16: UNI
B17: HONORARIOS SERVICIOS | C17: UNI
B19: INSUMO
B20: PRESINTOS ISO TANUQE | C20: UNI
B21: BOBINA PAPEL | C21: UNI
B23: LOGISTICA
B24: FOB | C24: TN
B25: FSA | C25: TN
B26: CIF | C26: TN
B28: MATERIA PRIMA
B29: AFE (S) | C29: TN
B30: AFE (G) | C30: TN
B31: AFE (SG) | C31: TN
B32: TSO | C32: TN
B33: AFE (AL) | C33: TN
B34: ARE (V) - A | C34: TN
B35: ARE (V) - B | C35: TN
B36: AG - A | C36: TN
B37: AG - B | C37: TN
B38: AG - C | C38: TN
B40: MANTENIMIENTO
B41: LIMPIEZA | C41: UNI
B44: RR.HH
B45: SUPERVISOR | C45: UNI
B46: COORDINADOR | C46: UNI
B47: OPERARIO | C47: UNI
B49: REPARACIONES
B50: BIENES DE USO + PARTES | C50: UNI | D50: 51
...

Sheet Vista
B2: WORMS
B5: TOTALES | F5: FIJO/VARIABLE | J5: DIRECTO/INDERECTO
B6: VENTAS | C6: =SUM(BBDD_INGRESOS_FINAL!$O:$O) -> 3.1786083e+09 | F6: VENTAS | G6: =SUM(BBDD_INGRESOS_FINAL!$O:$O) -> 3.1786083e+09 | J6: VENTAS | K6: =SUM(BBDD_INGRESOS_FINAL!$O:$O) -> 3.1786083e+09
B7: OPEX | C7: =SUMIFS('bbdd.5.final'!$Y:$Y,'bbdd.5.final'!$J:$J,Vista!B7) -> 2.7341314e+09 | F7: Fijo | G7: =SUMIFS(BBDD_GASTOS!$H:$H,BBDD_GASTOS!$J:$J,Vista!F7) -> 6805002.2 | J7: DIRECTO | K7: =SUMIFS('bbdd.5.final'!$Y:$Y,'bbdd.5.final'!$L:$L,$J$7) -> 2.5445771e+09
B8: UTILIDAD | C8: =C6-C7 -> 4.4447693e+08 | F8: Variable | G8: =SUMIFS(BBDD_GASTOS!$H:$H,BBDD_GASTOS!$J:$J,Vista!F8) -> 2.7213994e+09 | J8: INDIRECTO | K8: =SUMIFS('bbdd.5.final'!$Y:$Y,'bbdd.5.final'!$L:$L,$J$8) -> 1.8279075e+08
B9: CAPEX | C9: =SUMIFS('bbdd.5.final'!$Y:$Y,'bbdd.5.final'!$J:$J,Vista!B9) -> 1.8781251e+08
B10: DEUDA | C10: =SUMIFS('bbdd.5.final'!$Y:$Y,'bbdd.5.final'!$J:$J,Vista!B10) -> 1511155.8
B11: Flujo de Caja al Accionista | C11: =C6-C7-C9-C10 -> 2.5515326e+08 | F11: Flujo de Caja al Accionista | G11: =G6-G7-G8 -> 4.5040396e+08 | J11: Flujo de Caja al Accionista | K11: =K6-K7-K8 -> 4.5124053e+08
A13: id | B13: 4 | E13: id | F13: 3 | I13: id | J13: 7 | M13: id | N13: 8
B14: DISPOSICIÓN FINAL RESIDUOS SOLIDOS | F14: DISPOSICIÓN FINAL RESIDUOS LIQUIDOS | J14: PILETAS | N14: REACTORES
B15: OPEX | D15: =SUM(D16:D29) -> 18958267 | F15: OPEX | H15: =SUM(H16:H29) -> 32566130 | J15: OPEX | L15: =SUM(L16:L28) -> 41966910 | M15: 1 | N15: OPEX | P15: =SUM(P16:P29) -> 1.1071668e+08
A16: 1 | B16: =D16/$D$15 -> 0.0020162034 | C16: =_xlfn.XLOOKUP($A16,'rubros_id_opex (2)'!$B:$B,'rubros_id_opex (2)'!$A:$A) -> ENERGIA | D16: =SUMIFS('bbdd.5.final'!$Y:$Y,'bbdd.5.final'!$AA:$AA,Vista!A16,'bbdd.5.final'!$Z:$Z,$B$13,'bbdd.5.final'!$J:$J,"Opex") -> 38223.723 | E16: 1 | F16: =H16/$H$15 -> 0.087681751 | G16: =_xlfn.XLOOKUP($E16,'rubros_id_opex (2)'!$B:$B,'rubros_id_opex (2)'!$A:$A) -> ENERGIA | H16: =SUMIFS('bbdd.5.final'!$Y:$Y,'bbdd.5.final'!$AA:$AA,Vista!E16,'bbdd.5.final'!$Z:$Z,$F$13,'bbdd.5.final'!$J:$J,"Opex") -> 2855455.4 | I16: 1 | J16: =L16/$L$15 -> 0.11080139 | K16: =_xlfn.XLOOKUP($I16,'rubros_id_opex (2)'!$B:$B,'rubros_id_opex (2)'!$A:$A) -> ENERGIA | L16: =SUMIFS('bbdd.5.final'!$Y:$Y,'bbdd.5.final'!$AA:$AA,Vista!I16,'bbdd.5.final'!$Z:$Z,$J$13,'bbdd.5.final'!$J:$J,"Opex") -> 4649992 | M16: 1 | N16: =P16/$P$15 -> 0.22433558 | O16: =_xlfn.XLOOKUP($M16,'rubros_id_opex (2)'!$B:$B,'rubros_id_opex (2)'!$A:$A) -> ENERGIA | P16: =SUMIFS('bbdd.5.final'!$Y:$Y,'bbdd.5.final'!$AA:$AA,Vista!M16,'bbdd.5.final'!$Z:$Z,$N$13,'bbdd.5.final'!$J:$J,"Opex") -> 24837690
A17: =A16+1 -> 2 | B17: =D17/$D$15 -> 0 | C17: =_xlfn.XLOOKUP($A17,'rubros_id_opex (2)'!$B:$B,'rubros_id_opex (2)'!$A:$A) -> HABILITACIONES Y CERT | D17: =SUMIFS('bbdd.5.final'!$Y:$Y,'bbdd.5.final'!$AA:$AA,Vista!A17,'bbdd.5.final'!$Z:$Z,$B$13,'bbdd.5.final'!$J:$J,"Opex") -> 0 | E17: =E16+1 -> 2 | F17: =H17/$H$15 -> 0 | G17: =_xlfn.XLOOKUP($E17,'rubros_id_opex (2)'!$B:$B,'rubros_id_opex (2)'!$A:$A) -> HABILITACIONES Y CERT | H17: =SUMIFS('bbdd.5.final'!$Y:$Y,'bbdd.5.final'!$AA:$AA,Vista!E17,'bbdd.5.final'!$Z:$Z,$F$13,'bbdd.5.final'!$J:$J,"Opex") -> 0 | I17: =I16+1 -> 2 | J17: =L17/$L$15 -> 0 | K17: =_xlfn.XLOOKUP($I17,'rubros_id_opex (2)'!$B:$B,'rubros_id_opex (2)'!$A:$A) -> HABILITACIONES Y CERT | L17: =SUMIFS('bbdd.5.final'!$Y:$Y,'bbdd.5.final'!$AA:$AA,Vista!I17,'bbdd.5.final'!$Z:$Z,$J$13,'bbdd.5.final'!$J:$J,"Opex") -> 0 | M17: =M16+1 -> 2 | N17: =P17/$P$15 -> 0 | O17: =_xlfn.XLOOKUP($M17,'rubros_id_opex (2)'!$B:$B,'rubros_id_opex (2)'!$A:$A) -> HABILITACIONES Y CERT | P17: =SUMIFS('bbdd.5.final'!$Y:$Y,'bbdd.5.final'!$AA:$AA,Vista!M17,'bbdd.5.final'!$Z:$Z,$N$13,'bbdd.5.final'!$J:$J,"Opex") -> 0
A18: =A17+1 -> 3 | B18: =D18/$D$15 -> 0.0011283211 | C18: =_xlfn.XLOOKUP($A18,'rubros_id_opex (2)'!$B:$B,'rubros_id_opex (2)'!$A:$A) -> HIGIENE Y SEGURIDAD | D18: =SUMIFS('bbdd.5.final'!$Y:$Y,'bbdd.5.final'!$AA:$AA,Vista!A18,'bbdd.5.final'!$Z:$Z,$B$13,'bbdd.5.final'!$J:$J,"Opex") -> 21391.014 | E18: =E17+1 -> 3 | F18: =H18/$H$15 -> 0.0080581024 | G18: =_xlfn.XLOOKUP($E18,'rubros_id_opex (2)'!$B:$B,'rubros_id_opex (2)'!$A:$A) -> HIGIENE Y SEGURIDAD | H18: =SUMIFS('bbdd.5.final'!$Y:$Y,'bbdd.5.final'!$AA:$AA,Vista!E18,'bbdd.5.final'!$Z:$Z,$F$13,'bbdd.5.final'!$J:$J,"Opex") -> 262421.21 | I18: =I17+1 -> 3 | J18: =L18/$L$15 -> 0.011253022 | K18: =_xlfn.XLOOKUP($I18,'rubros_id_opex (2)'!$B:$B,'rubros_id_opex (2)'!$A:$A) -> HIGIENE Y SEGURIDAD | L18: =SUMIFS('bbdd.5.final'!$Y:$Y,'bbdd.5.final'!$AA:$AA,Vista!I18,'bbdd.5.final'!$Z:$Z,$J$13,'bbdd.5.final'!$J:$J,"Opex") -> 472254.55 | M18: =M17+1 -> 3 | N18: =P18/$P$15 -> 0.0015727911 | O18: =_xlfn.XLOOKUP($M18,'rubros_id_opex (2)'!$B:$B,'rubros_id_opex (2)'!$A:$A) -> HIGIENE Y SEGURIDAD | P18: =SUMIFS('bbdd.5.final'!$Y:$Y,'bbdd.5.final'!$AA:$AA,Vista!M18,'bbdd.5.final'!$Z:$Z,$N$13,'bbdd.5.final'!$J:$J,"Opex") -> 174134.2
A19: =A18+1 -> 4 | B19: =D19/$D$15 -> 0.001303926 | C19: =_xlfn.XLOOKUP($A19,'rubros_id_opex (2)'!$B:$B,'rubros_id_opex (2)'!$A:$A) -> IMPUESTOS | D19: =SUMIFS('bbdd.5.final'!$Y:$Y,'bbdd.5.final'!$AA:$AA,Vista!A19,'bbdd.5.final'!$Z:$Z,$B$13,'bbdd.5.final'!$J:$J,"Opex") -> 24720.178 | E19: =E18+1 -> 4 | F19: =H19/$H$15 -> 0.030013783 | G19: =_xlfn.XLOOKUP($E19,'rubros_id_opex (2)'!$B:$B,'rubros_id_opex (2)'!$A:$A) -> IMPUESTOS | H19: =SUMIFS('bbdd.5.final'!$Y:$Y,'bbdd.5.final'!$AA:$AA,Vista!E19,'bbdd.5.final'!$Z:$Z,$F$13,'bbdd.5.final'!$J:$J,"Opex") -> 977432.76 | I19: =I18+1 -> 4 | J19: =L19/$L$15 -> 0.019544083 | K19: =_xlfn.XLOOKUP($I19,'rubros_id_opex (2)'!$B:$B,'rubros_id_opex (2)'!$A:$A) -> IMPUESTOS | L19: =SUMIFS('bbdd.5.final'!$Y:$Y,'bbdd.5.final'!$AA:$AA,Vista!I19,'bbdd.5.final'!$Z:$Z,$J$13,'bbdd.5.final'!$J:$J,"Opex") -> 820204.79 | M19: =M18+1 -> 4 | N19: =P19/$P$15 -> 0.0018175705 | O19: =_xlfn.XLOOKUP($M19,'rubros_id_opex (2)'!$B:$B,'rubros_id_opex (2)'!$A:$A) -> IMPUESTOS | P19: =SUMIFS('bbdd.5.final'!$Y:$Y,'bbdd.5.final'!$AA:$AA,Vista!M19,'bbdd.5.final'!$Z:$Z,$N$13,'bbdd.5.final'!$J:$J,"Opex") -> 201235.36
A20: =A19+1 -> 5 | B20: =D20/$D$15 -> 0.00050329615 | C20: =_xlfn.XLOOKUP($A20,'rubros_id_opex (2)'!$B:$B,'rubros_id_opex (2)'!$A:$A) -> INSUMOS | D20: =SUMIFS('bbdd.5.final'!$Y:$Y,'bbdd.5.final'!$AA:$AA,Vista!A20,'bbdd.5.final'!$Z:$Z,$B$13,'bbdd.5.final'!$J:$J,"Opex") -> 9541.6229 | E20: =E19+1 -> 5 | F20: =H20/$H$15 -> 0.0035943773 | G20: =_xlfn.XLOOKUP($E20,'rubros_id_opex (2)'!$B:$B,'rubros_id_opex (2)'!$A:$A) -> INSUMOS | H20: =SUMIFS('bbdd.5.final'!$Y:$Y,'bbdd.5.final'!$AA:$AA,Vista!E20,'bbdd.5.final'!$Z:$Z,$F$13,'bbdd.5.final'!$J:$J,"Opex") -> 117054.96 | I20: =I19+1 -> 5 | J20: =L20/$L$15 -> 0.0050194951 | K20: =_xlfn.XLOOKUP($I20,'rubros_id_opex (2)'!$B:$B,'rubros_id_opex (2)'!$A:$A) -> INSUMOS | L20: =SUMIFS('bbdd.5.final'!$Y:$Y,'bbdd.5.final'!$AA:$AA,Vista!I20,'bbdd.5.final'!$Z:$Z,$J$13,'bbdd.5.final'!$J:$J,"Opex") -> 210652.7 | M20: =M19+1 -> 5 | N20: =P20/$P$15 -> 0.63928482 | O20: =_xlfn.XLOOKUP($M20,'rubros_id_opex (2)'!$B:$B,'rubros_id_opex (2)'!$A:$A) -> INSUMOS | P20: =SUMIFS('bbdd.5.final'!$Y:$Y,'bbdd.5.final'!$AA:$AA,Vista!M20,'bbdd.5.final'!$Z:$Z,$N$13,'bbdd.5.final'!$J:$J,"Opex") -> 70779491
A21: =A20+1 -> 6 | B21: =D21/$D$15 -> 0 | C21: =_xlfn.XLOOKUP($A21,'rubros_id_opex (2)'!$B:$B,'rubros_id_opex (2)'!$A:$A) -> INVERSION | D21: =SUMIFS('bbdd.5.final'!$Y:$Y,'bbdd.5.final'!$AA:$AA,Vista!A21,'bbdd.5.final'!$Z:$Z,$B$13,'bbdd.5.final'!$J:$J,"Opex") -> 0 | E21: =E20+1 -> 6 | F21: =H21/$H$15 -> 0 | G21: =_xlfn.XLOOKUP($E21,'rubros_id_opex (2)'!$B:$B,'rubros_id_opex (2)'!$A:$A) -> INVERSION | H21: =SUMIFS('bbdd.5.final'!$Y:$Y,'bbdd.5.final'!$AA:$AA,Vista!E21,'bbdd.5.final'!$Z:$Z,$F$13,'bbdd.5.final'!$J:$J,"Opex") -> 0 | I21: =I20+1 -> 6 | J21: =L21/$L$15 -> 0 | K21: =_xlfn.XLOOKUP($I21,'rubros_id_opex (2)'!$B:$B,'rubros_id_opex (2)'!$A:$A) -> INVERSION | L21: =SUMIFS('bbdd.5.final'!$Y:$Y,'bbdd.5.final'!$AA:$AA,Vista!I21,'bbdd.5.final'!$Z:$Z,$J$13,'bbdd.5.final'!$J:$J,"Opex") -> 0 | M21: =M20+1 -> 6 | N21: =P21/$P$15 -> 0 | O21: =_xlfn.XLOOKUP($M21,'rubros_id_opex (2)'!$B:$B,'rubros_id_opex (2)'!$A:$A) -> INVERSION | P21: =SUMIFS('bbdd.5.final'!$Y:$Y,'bbdd.5.final'!$AA:$AA,Vista!M21,'bbdd.5.final'!$Z:$Z,$N$13,'bbdd.5.final'!$J:$J,"Opex") -> 0
A22: =A21+1 -> 7 | B22: =D22/$D$15 -> 0 | C22: =_xlfn.XLOOKUP($A22,'rubros_id_opex (2)'!$B:$B,'rubros_id_opex (2)'!$A:$A) -> LOGISTICA | D22: =SUMIFS('bbdd.5.final'!$Y:$Y,'bbdd.5.final'!$AA:$AA,Vista!A22,'bbdd.5.final'!$Z:$Z,$B$13,'bbdd.5.final'!$J:$J,"Opex") -> 0 | E22: =E21+1 -> 7 | F22: =H22/$H$15 -> 0 | G22: =_xlfn.XLOOKUP($E22,'rubros_id_opex (2)'!$B:$B,'rubros_id_opex (2)'!$A:$A) -> LOGISTICA | H22: =SUMIFS('bbdd.5.final'!$Y:$Y,'bbdd.5.final'!$AA:$AA,Vista!E22,'bbdd.5.final'!$Z:$Z,$F$13,'bbdd.5.final'!$J:$J,"Opex") -> 0 | I22: =I21+1 -> 7 | J22: =L22/$L$15 -> 0 | K22: =_xlfn.XLOOKUP($I22,'rubros_id_opex (2)'!$B:$B,'rubros_id_opex (2)'!$A:$A) -> LOGISTICA | L22: =SUMIFS('bbdd.5.final'!$Y:$Y,'bbdd.5.final'!$AA:$AA,Vista!I22,'bbdd.5.final'!$Z:$Z,$J$13,'bbdd.5.final'!$J:$J,"Opex") -> 0 | M22: =M21+1 -> 7 | N22: =P22/$P$15 -> 0 | O22: =_xlfn.XLOOKUP($M22,'rubros_id_opex (2)'!$B:$B,'rubros_id_opex (2)'!$A:$A) -> LOGISTICA | P22: =SUMIFS('bbdd.5.final'!$Y:$Y,'bbdd.5.final'!$AA:$AA,Vista!M22,'bbdd.5.final'!$Z:$Z,$N$13,'bbdd.5.final'!$J:$J,"Opex") -> 0
A23: =A22+1 -> 8 | B23: =D23/$D$15 -> 0.045125088 | C23: =_xlfn.XLOOKUP($A23,'rubros_id_opex (2)'!$B:$B,'rubros_id_opex (2)'!$A:$A) -> M.PRIMAS | D23: =SUMIFS('bbdd.5.final'!$Y:$Y,'bbdd.5.final'!$AA:$AA,Vista!A23,'bbdd.5.final'!$Z:$Z,$B$13,'bbdd.5.final'!$J:$J,"Opex") -> 855493.48 | E23: =E22+1 -> 8 | F23: =H23/$H$15 -> 0 | G23: =_xlfn.XLOOKUP($E23,'rubros_id_opex (2)'!$B:$B,'rubros_id_opex (2)'!$A:$A) -> M.PRIMAS | H23: =SUMIFS('bbdd.5.final'!$Y:$Y,'bbdd.5.final'!$AA:$AA,Vista!E23,'bbdd.5.final'!$Z:$Z,$F$13,'bbdd.5.final'!$J:$J,"Opex") -> 0 | I23: =I22+1 -> 8 | J23: =L23/$L$15 -> 0 | K23: =_xlfn.XLOOKUP($I23,'rubros_id_opex (2)'!$B:$B,'rubros_id_opex (2)'!$A:$A) -> M.PRIMAS | L23: =SUMIFS('bbdd.5.final'!$Y:$Y,'bbdd.5.final'!$AA:$AA,Vista!I23,'bbdd.5.final'!$Z:$Z,$J$13,'bbdd.5.final'!$J:$J,"Opex") -> 0 | M23: =M22+1 -> 8 | N23: =P23/$P$15 -> 0 | O23: =_xlfn.XLOOKUP($M23,'rubros_id_opex (2)'!$B:$B,'rubros_id_opex (2)'!$A:$A) -> M.PRIMAS | P23: =SUMIFS('bbdd.5.final'!$Y:$Y,'bbdd.5.final'!$AA:$AA,Vista!M23,'bbdd.5.final'!$Z:$Z,$N$13,'bbdd.5.final'!$J:$J,"Opex") -> 0
A24: =A23+1 -> 9 | B24: =D24/$D$15 -> 0.00091949148 | C24: =_xlfn.XLOOKUP($A24,'rubros_id_opex (2)'!$B:$B,'rubros_id_opex (2)'!$A:$A) -> MANTENIMIENTO PREVENTIVO | D24: =SUMIFS('bbdd.5.final'!$Y:$Y,'bbdd.5.final'!$AA:$AA,Vista!A24,'bbdd.5.final'!$Z:$Z,$B$13,'bbdd.5.final'!$J:$J,"Opex") -> 17431.965 | E24: =E23+1 -> 9 | F24: =H24/$H$15 -> 0.0065667089 | G24: =_xlfn.XLOOKUP($E24,'rubros_id_opex (2)'!$B:$B,'rubros_id_opex (2)'!$A:$A) -> MANTENIMIENTO PREVENTIVO | H24: =SUMIFS('bbdd.5.final'!$Y:$Y,'bbdd.5.final'!$AA:$AA,Vista!E24,'bbdd.5.final'!$Z:$Z,$F$13,'bbdd.5.final'!$J:$J,"Opex") -> 213852.3 | I24: =I23+1 -> 9 | J24: =L24/$L$15 -> 0.0091703126 | K24: =_xlfn.XLOOKUP($I24,'rubros_id_opex (2)'!$B:$B,'rubros_id_opex (2)'!$A:$A) -> MANTENIMIENTO PREVENTIVO | L24: =SUMIFS('bbdd.5.final'!$Y:$Y,'bbdd.5.final'!$AA:$AA,Vista!I24,'bbdd.5.final'!$Z:$Z,$J$13,'bbdd.5.final'!$J:$J,"Opex") -> 384849.69 | M24: =M23+1 -> 9 | N24: =P24/$P$15 -> 0.0057338924 | O24: =_xlfn.XLOOKUP($M24,'rubros_id_opex (2)'!$B:$B,'rubros_id_opex (2)'!$A:$A) -> MANTENIMIENTO PREVENTIVO | P24: =SUMIFS('bbdd.5.final'!$Y:$Y,'bbdd.5.final'!$AA:$AA,Vista!M24,'bbdd.5.final'!$Z:$Z,$N$13,'bbdd.5.final'!$J:$J,"Opex") -> 634837.51
A25: =A24+1 -> 10 | B25: =D25/$D$15 -> 0.9415857 | C25: =_xlfn.XLOOKUP($A25,'rubros_id_opex (2)'!$B:$B,'rubros_id_opex (2)'!$A:$A) -> PERSONAL | D25: =SUMIFS('bbdd.5.final'!$Y:$Y,'bbdd.5.final'!$AA:$AA,Vista!A25,'bbdd.5.final'!$Z:$Z,$B$13,'bbdd.5.final'!$J:$J,"Opex") -> 17850833 | E25: =E24+1 -> 10 | F25: =H25/$H$15 -> 0.75585347 | G25: =_xlfn.XLOOKUP($E25,'rubros_id_opex (2)'!$B:$B,'rubros_id_opex (2)'!$A:$A) -> PERSONAL | H25: =SUMIFS('bbdd.5.final'!$Y:$Y,'bbdd.5.final'!$AA:$AA,Vista!E25,'bbdd.5.final'!$Z:$Z,$F$13,'bbdd.5.final'!$J:$J,"Opex") -> 24615223 | I25: =I24+1 -> 10 | J25: =L25/$L$15 -> 0.75643576 | K25: =_xlfn.XLOOKUP($I25,'rubros_id_opex (2)'!$B:$B,'rubros_id_opex (2)'!$A:$A) -> PERSONAL | L25: =SUMIFS('bbdd.5.final'!$Y:$Y,'bbdd.5.final'!$AA:$AA,Vista!I25,'bbdd.5.final'!$Z:$Z,$J$13,'bbdd.5.final'!$J:$J,"Opex") -> 31745272 | M25: =M24+1 -> 10 | N25: =P25/$P$15 -> 0.11452515 | O25: =_xlfn.XLOOKUP($M25,'rubros_id_opex (2)'!$B:$B,'rubros_id_opex (2)'!$A:$A) -> PERSONAL | P25: =SUMIFS('bbdd.5.final'!$Y:$Y,'bbdd.5.final'!$AA:$AA,Vista!M25,'bbdd.5.final'!$Z:$Z,$N$13,'bbdd.5.final'!$J:$J,"Opex") -> 12679844
A26: =A25+1 -> 11 | B26: =D26/$D$15 -> 0.00022327495 | C26: =_xlfn.XLOOKUP($A26,'rubros_id_opex (2)'!$B:$B,'rubros_id_opex (2)'!$A:$A) -> REPARACIONES | D26: =SUMIFS('bbdd.5.final'!$Y:$Y,'bbdd.5.final'!$AA:$AA,Vista!A26,'bbdd.5.final'!$Z:$Z,$B$13,'bbdd.5.final'!$J:$J,"Opex") -> 4232.9062 | E26: =E25+1 -> 11 | F26: =H26/$H$15 -> 0.001594557 | G26: =_xlfn.XLOOKUP($E26,'rubros_id_opex (2)'!$B:$B,'rubros_id_opex (2)'!$A:$A) -> REPARACIONES | H26: =SUMIFS('bbdd.5.final'!$Y:$Y,'bbdd.5.final'!$AA:$AA,Vista!E26,'bbdd.5.final'!$Z:$Z,$F$13,'bbdd.5.final'!$J:$J,"Opex") -> 51928.553 | I26: =I25+1 -> 11 | J26: =L26/$L$15 -> 0.0022267755 | K26: =_xlfn.XLOOKUP($I26,'rubros_id_opex (2)'!$B:$B,'rubros_id_opex (2)'!$A:$A) -> REPARACIONES | L26: =SUMIFS('bbdd.5.final'!$Y:$Y,'bbdd.5.final'!$AA:$AA,Vista!I26,'bbdd.5.final'!$Z:$Z,$J$13,'bbdd.5.final'!$J:$J,"Opex") -> 93450.888 | M26: =M25+1 -> 11 | N26: =P26/$P$15 -> 0.0027013463 | O26: =_xlfn.XLOOKUP($M26,'rubros_id_opex (2)'!$B:$B,'rubros_id_opex (2)'!$A:$A) -> REPARACIONES | P26: =SUMIFS('bbdd.5.final'!$Y:$Y,'bbdd.5.final'!$AA:$AA,Vista!M26,'bbdd.5.final'!$Z:$Z,$N$13,'bbdd.5.final'!$J:$J,"Opex") -> 299084.08
A27: =A26+1 -> 12 | B27: =D27/$D$15 -> 0.00037186012 | C27: =_xlfn.XLOOKUP($A27,'rubros_id_opex (2)'!$B:$B,'rubros_id_opex (2)'!$A:$A) -> REPOSICION | D27: =SUMIFS('bbdd.5.final'!$Y:$Y,'bbdd.5.final'!$AA:$AA,Vista!A27,'bbdd.5.final'!$Z:$Z,$B$13,'bbdd.5.final'!$J:$J,"Opex") -> 7049.8235 | E27: =E26+1 -> 12 | F27: =H27/$H$15 -> 0.057910753 | G27: =_xlfn.XLOOKUP($E27,'rubros_id_opex (2)'!$B:$B,'rubros_id_opex (2)'!$A:$A) -> REPOSICION | H27: =SUMIFS('bbdd.5.final'!$Y:$Y,'bbdd.5.final'!$AA:$AA,Vista!E27,'bbdd.5.final'!$Z:$Z,$F$13,'bbdd.5.final'!$J:$J,"Opex") -> 1885929.1 | I27: =I26+1 -> 12 | J27: =L27/$L$15 -> 0.017503327 | K27: =_xlfn.XLOOKUP($I27,'rubros_id_opex (2)'!$B:$B,'rubros_id_opex (2)'!$A:$A) -> REPOSICION | L27: =SUMIFS('bbdd.5.final'!$Y:$Y,'bbdd.5.final'!$AA:$AA,Vista!I27,'bbdd.5.final'!$Z:$Z,$J$13,'bbdd.5.final'!$J:$J,"Opex") -> 734560.57 | M27: =M26+1 -> 12 | N27: =P27/$P$15 -> 0.00051834381 | O27: =_xlfn.XLOOKUP($M27,'rubros_id_opex (2)'!$B:$B,'rubros_id_opex (2)'!$A:$A) -> REPOSICION | P27: =SUMIFS('bbdd.5.final'!$Y:$Y,'bbdd.5.final'!$AA:$AA,Vista!M27,'bbdd.5.final'!$Z:$Z,$N$13,'bbdd.5.final'!$J:$J,"Opex") -> 57389.304
A28: =A27+1 -> 13 | B28: =D28/$D$15 -> 0.0068228391 | C28: =_xlfn.XLOOKUP($A28,'rubros_id_opex (2)'!$B:$B,'rubros_id_opex (2)'!$A:$A) -> SERVICIOS | D28: =SUMIFS('bbdd.5.final'!$Y:$Y,'bbdd.5.final'!$AA:$AA,Vista!A28,'bbdd.5.final'!$Z:$Z,$B$13,'bbdd.5.final'!$J:$J,"Opex") -> 129349.21 | E28: =E27+1 -> 13 | F28: =H28/$H$15 -> 0.048726497 | G28: =_xlfn.XLOOKUP($E28,'rubros_id_opex (2)'!$B:$B,'rubros_id_opex (2)'!$A:$A) -> SERVICIOS | H28: =SUMIFS('bbdd.5.final'!$Y:$Y,'bbdd.5.final'!$AA:$AA,Vista!E28,'bbdd.5.final'!$Z:$Z,$F$13,'bbdd.5.final'!$J:$J,"Opex") -> 1586833.4 | I28: =I27+1 -> 13 | J28: =L28/$L$15 -> 0.068045837 | K28: =_xlfn.XLOOKUP($I28,'rubros_id_opex (2)'!$B:$B,'rubros_id_opex (2)'!$A:$A) -> SERVICIOS | L28: =SUMIFS('bbdd.5.final'!$Y:$Y,'bbdd.5.final'!$AA:$AA,Vista!I28,'bbdd.5.final'!$Z:$Z,$J$13,'bbdd.5.final'!$J:$J,"Opex") -> 2855673.5 | M28: =M27+1 -> 13 | N28: =P28/$P$15 -> 0.0095105022 | O28: =_xlfn.XLOOKUP($M28,'rubros_id_opex (2)'!$B:$B,'rubros_id_opex (2)'!$A:$A) -> SERVICIOS | P28: =SUMIFS('bbdd.5.final'!$Y:$Y,'bbdd.5.final'!$AA:$AA,Vista!M28,'bbdd.5.final'!$Z:$Z,$N$13,'bbdd.5.final'!$J:$J,"Opex") -> 1052971.2
A29: =A28+1 -> 14 | B29: =D29/$D$15 -> 0 | C29: =_xlfn.XLOOKUP($A29,'rubros_id_opex (2)'!$B:$B,'rubros_id_opex (2)'!$A:$A) -> COMERCIAL | D29: =SUMIFS('bbdd.5.final'!$Y:$Y,'bbdd.5.final'!$AA:$AA,Vista!A29,'bbdd.5.final'!$Z:$Z,$B$13,'bbdd.5.final'!$J:$J,"Opex") -> 0 | E29: =E28+1 -> 14 | F29: =H29/$H$15 -> 0 | G29: =_xlfn.XLOOKUP($E29,'rubros_id_opex (2)'!$B:$B,'rubros_id_opex (2)'!$A:$A) -> COMERCIAL | H29: =SUMIFS('bbdd.5.final'!$Y:$Y,'bbdd.5.final'!$AA:$AA,Vista!E29,'bbdd.5.final'!$Z:$Z,$F$13,'bbdd.5.final'!$J:$J,"Opex") -> 0 | I29: =I28+1 -> 14 | J29: =L29/$L$15 -> 0 | K29: =_xlfn.XLOOKUP($I29,'rubros_id_opex (2)'!$B:$B,'rubros_id_opex (2)'!$A:$A) -> COMERCIAL | L29: =SUMIFS('bbdd.5.final'!$Y:$Y,'bbdd.5.final'!$AA:$AA,Vista!I29,'bbdd.5.final'!$Z:$Z,$J$13,'bbdd.5.final'!$J:$J,"Opex") -> 0 | M29: =M28+1 -> 14 | N29: =P29/$P$15 -> 0 | O29: =_xlfn.XLOOKUP($M29,'rubros_id_opex (2)'!$B:$B,'rubros_id_opex (2)'!$A:$A) -> COMERCIAL | P29: =SUMIFS('bbdd.5.final'!$Y:$Y,'bbdd.5.final'!$AA:$AA,Vista!M29,'bbdd.5.final'!$Z:$Z,$N$13,'bbdd.5.final'!$J:$J,"Opex") -> 0
B31: VENTAS | D31: =SUMIFS(BBDD_INGRESOS_FINAL!$O:$O,BBDD_INGRESOS_FINAL!$D:$D,B14) -> 15491941 | F31: VENTAS | H31: =SUMIFS(BBDD_INGRESOS_FINAL!$O:$O,BBDD_INGRESOS_FINAL!$D:$D,F14) -> 1.9005242e+08 | J31: VENTAS | L31: =SUMIFS(BBDD_INGRESOS_FINAL!$O:$O,BBDD_INGRESOS_FINAL!$D:$D,J14) -> 3.420193e+08 | N31: VENTAS | P31: =SUMIFS(BBDD_INGRESOS_FINAL!$O:$O,BBDD_INGRESOS_FINAL!$D:$D,N14) -> 1.2611262e+08
B33: UTILDAD | D33: =D31-D15 -> -3466326.3 | F33: UTILDAD | H33: =H31-H15 -> 1.5748629e+08 | J33: UTILDAD | L33: =L31-L15 -> 3.0005239e+08 | N33: UTILDAD | P33: =P31-P15 -> 15395944
B35: CAPEX | D35: =SUMIFS('bbdd.5.final'!$Y:$Y,'bbdd.5.final'!$J:$J,"Capex",'bbdd.5.final'!$Z:$Z,$B$13) -> 32937.085 | F35: CAPEX | H35: =SUMIFS('bbdd.5.final'!$Y:$Y,'bbdd.5.final'!$J:$J,"Capex",'bbdd.5.final'!$Z:$Z,$F$13) -> 1.5116069e+08 | J35: CAPEX | L35: =SUMIFS('bbdd.5.final'!$Y:$Y,'bbdd.5.final'!$J:$J,"Capex",'bbdd.5.final'!$Z:$Z,$J$13) -> 4670762.8 | N35: CAPEX | P35: =SUMIFS('bbdd.5.final'!$Y:$Y,'bbdd.5.final'!$J:$J,"Capex",'bbdd.5.final'!$Z:$Z,$N$13) -> 996837.73
B37: DEUDA | D37: =SUMIFS('bbdd.5.final'!$Y:$Y,'bbdd.5.final'!$J:$J,"Deuda",'bbdd.5.final'!$V:$V,B14) -> 7365.0902 | F37: DEUDA | H37: =SUMIFS('bbdd.5.final'!$Y:$Y,'bbdd.5.final'!$J:$J,"Deuda",'bbdd.5.final'!$V:$V,F14) -> 90353.638 | J37: DEUDA | L37: =SUMIFS('bbdd.5.final'!$Y:$Y,'bbdd.5.final'!$J:$J,"deuda",'bbdd.5.final'!$V:$V,J14) -> 162600.87 | N37: DEUDA | P37: =SUMIFS('bbdd.5.final'!$Y:$Y,'bbdd.5.final'!$J:$J,"deuda",'bbdd.5.final'!$V:$V,N14) -> 59955.743
B39: Flujo de Caja al Accionista | D39: =D33-D37-D35 -> -3506628.5 | F39: Flujo de Caja al Accionista | H39: =H33-H37-H35 -> 6235251.6 | J39: Flujo de Caja al Accionista | L39: =L33-L37-L35 -> 2.9521903e+08 | N39: Flujo de Caja al Accionista | P39: =P33-P37-P35 -> 14339151
A41: id | B41: 1 | E41: id | F41: 6 | I41: id | J41: 10 | M41: id | N41: 2
B42: BACHAS | F42: NFU | J42: COMPOST & FERTILIZANTES | N42: CEREAL & POLVILLO
B43: OPEX | D43: =SUM(D44:D57) -> 1.4810693e+08 | F43: OPEX | H43: =SUM(H44:H57) -> 51486940 | J43: OPEX | L43: =SUM(L44:L57) -> 9378920.8 | N43: OPEX | P43: =SUM(P44:P57) -> 10563263
A44: 1 | B44: =D44/$D$43 -> 0.051410619 | C44: =_xlfn.XLOOKUP($A44,'rubros_id_opex (2)'!$B:$B,'rubros_id_opex (2)'!$A:$A) -> ENERGIA | D44: =SUMIFS('bbdd.5.final'!$Y:$Y,'bbdd.5.final'!$AA:$AA,Vista!A44,'bbdd.5.final'!$Z:$Z,$B$41,'bbdd.5.final'!$J:$J,"Opex") -> 7614268.9 | E44: 1 | F44: =H44/$H$43 -> 0.3042523 | G44: =_xlfn.XLOOKUP($A44,'rubros_id_opex (2)'!$B:$B,'rubros_id_opex (2)'!$A:$A) -> ENERGIA | H44: =SUMIFS('bbdd.5.final'!$Y:$Y,'bbdd.5.final'!$AA:$AA,Vista!E44,'bbdd.5.final'!$Z:$Z,$F$41,'bbdd.5.final'!$J:$J,"Opex") -> 15665020 | I44: 1 | J44: =L44/$L$43 -> 0.00048472998 | K44: =_xlfn.XLOOKUP($A44,'rubros_id_opex (2)'!$B:$B,'rubros_id_opex (2)'!$A:$A) -> ENERGIA | L44: =SUMIFS('bbdd.5.final'!$Y:$Y,'bbdd.5.final'!$AA:$AA,Vista!I44,'bbdd.5.final'!$Z:$Z,$J$41,'bbdd.5.final'!$J:$J,"Opex") -> 4546.2441 | M44: 1 | N44: =P44/$P$43 -> 0.0071483316 | O44: =_xlfn.XLOOKUP($A44,'rubros_id_opex (2)'!$B:$B,'rubros_id_opex (2)'!$A:$A) -> ENERGIA | P44: =SUMIFS('bbdd.5.final'!$Y:$Y,'bbdd.5.final'!$AA:$AA,Vista!M44,'bbdd.5.final'!$Z:$Z,$N$41,'bbdd.5.final'!$J:$J,"Opex") -> 75509.708
A45: =A44+1 -> 2 | B45: =D45/$D$43 -> 0 | C45: =_xlfn.XLOOKUP($A45,'rubros_id_opex (2)'!$B:$B,'rubros_id_opex (2)'!$A:$A) -> HABILITACIONES Y CERT | D45: =SUMIFS('bbdd.5.final'!$Y:$Y,'bbdd.5.final'!$AA:$AA,Vista!A45,'bbdd.5.final'!$Z:$Z,$B$41,'bbdd.5.final'!$J:$J,"Opex") -> 0 | E45: =E44+1 -> 2 | F45: =H45/$H$43 -> 0 | G45: =_xlfn.XLOOKUP($A45,'rubros_id_opex (2)'!$B:$B,'rubros_id_opex (2)'!$A:$A) -> HABILITACIONES Y CERT | H45: =SUMIFS('bbdd.5.final'!$Y:$Y,'bbdd.5.final'!$AA:$AA,Vista!E45,'bbdd.5.final'!$Z:$Z,$F$41,'bbdd.5.final'!$J:$J,"Opex") -> 0 | I45: =I44+1 -> 2 | J45: =L45/$L$43 -> 0 | K45: =_xlfn.XLOOKUP($A45,'rubros_id_opex (2)'!$B:$B,'rubros_id_opex (2)'!$A:$A) -> HABILITACIONES Y CERT | L45: =SUMIFS('bbdd.5.final'!$Y:$Y,'bbdd.5.final'!$AA:$AA,Vista!I45,'bbdd.5.final'!$Z:$Z,$J$41,'bbdd.5.final'!$J:$J,"Opex") -> 0 | M45: =M44+1 -> 2 | N45: =P45/$P$43 -> 0 | O45: =_xlfn.XLOOKUP($A45,'rubros_id_opex (2)'!$B:$B,'rubros_id_opex (2)'!$A:$A) -> HABILITACIONES Y CERT | P45: =SUMIFS('bbdd.5.final'!$Y:$Y,'bbdd.5.final'!$AA:$AA,Vista!M45,'bbdd.5.final'!$Z:$Z,$N$41,'bbdd.5.final'!$J:$J,"Opex") -> 0
A46: =A45+1 -> 3 | B46: =D46/$D$43 -> 0.00096064554 | C46: =_xlfn.XLOOKUP($A46,'rubros_id_opex (2)'!$B:$B,'rubros_id_opex (2)'!$A:$A) -> HIGIENE Y SEGURIDAD | D46: =SUMIFS('bbdd.5.final'!$Y:$Y,'bbdd.5.final'!$AA:$AA,Vista!A46,'bbdd.5.final'!$Z:$Z,$B$41,'bbdd.5.final'!$J:$J,"Opex") -> 142278.26 | E46: =E45+1 -> 3 | F46: =H46/$H$43 -> 0.0011989944 | G46: =_xlfn.XLOOKUP($A46,'rubros_id_opex (2)'!$B:$B,'rubros_id_opex (2)'!$A:$A) -> HIGIENE Y SEGURIDAD | H46: =SUMIFS('bbdd.5.final'!$Y:$Y,'bbdd.5.final'!$AA:$AA,Vista!E46,'bbdd.5.final'!$Z:$Z,$F$41,'bbdd.5.final'!$J:$J,"Opex") -> 61732.551 | I46: =I45+1 -> 3 | J46: =L46/$L$43 -> 0.00019024136 | K46: =_xlfn.XLOOKUP($A46,'rubros_id_opex (2)'!$B:$B,'rubros_id_opex (2)'!$A:$A) -> HIGIENE Y SEGURIDAD | L46: =SUMIFS('bbdd.5.final'!$Y:$Y,'bbdd.5.final'!$AA:$AA,Vista!I46,'bbdd.5.final'!$Z:$Z,$J$41,'bbdd.5.final'!$J:$J,"Opex") -> 1784.2587 | M46: =M45+1 -> 3 | N46: =P46/$P$43 -> 0.0029332672 | O46: =_xlfn.XLOOKUP($A46,'rubros_id_opex (2)'!$B:$B,'rubros_id_opex (2)'!$A:$A) -> HIGIENE Y SEGURIDAD | P46: =SUMIFS('bbdd.5.final'!$Y:$Y,'bbdd.5.final'!$AA:$AA,Vista!M46,'bbdd.5.final'!$Z:$Z,$N$41,'bbdd.5.final'!$J:$J,"Opex") -> 30984.873
A47: =A46+1 -> 4 | B47: =D47/$D$43 -> 0.0011101544 | C47: =_xlfn.XLOOKUP($A47,'rubros_id_opex (2)'!$B:$B,'rubros_id_opex (2)'!$A:$A) -> IMPUESTOS | D47: =SUMIFS('bbdd.5.final'!$Y:$Y,'bbdd.5.final'!$AA:$AA,Vista!A47,'bbdd.5.final'!$Z:$Z,$B$41,'bbdd.5.final'!$J:$J,"Opex") -> 164421.56 | E47: =E46+1 -> 4 | F47: =H47/$H$43 -> 0.017955747 | G47: =_xlfn.XLOOKUP($A47,'rubros_id_opex (2)'!$B:$B,'rubros_id_opex (2)'!$A:$A) -> IMPUESTOS | H47: =SUMIFS('bbdd.5.final'!$Y:$Y,'bbdd.5.final'!$AA:$AA,Vista!E47,'bbdd.5.final'!$Z:$Z,$F$41,'bbdd.5.final'!$J:$J,"Opex") -> 924486.49 | I47: =I46+1 -> 4 | J47: =L47/$L$43 -> 0.01796493 | K47: =_xlfn.XLOOKUP($A47,'rubros_id_opex (2)'!$B:$B,'rubros_id_opex (2)'!$A:$A) -> IMPUESTOS | L47: =SUMIFS('bbdd.5.final'!$Y:$Y,'bbdd.5.final'!$AA:$AA,Vista!I47,'bbdd.5.final'!$Z:$Z,$J$41,'bbdd.5.final'!$J:$J,"Opex") -> 168491.66 | M47: =M46+1 -> 4 | N47: =P47/$P$43 -> 0.0033897826 | O47: =_xlfn.XLOOKUP($A47,'rubros_id_opex (2)'!$B:$B,'rubros_id_opex (2)'!$A:$A) -> IMPUESTOS | P47: =SUMIFS('bbdd.5.final'!$Y:$Y,'bbdd.5.final'!$AA:$AA,Vista!M47,'bbdd.5.final'!$Z:$Z,$N$41,'bbdd.5.final'!$J:$J,"Opex") -> 35807.165
A48: =A47+1 -> 5 | B48: =D48/$D$43 -> 0.02273382 | C48: =_xlfn.XLOOKUP($A48,'rubros_id_opex (2)'!$B:$B,'rubros_id_opex (2)'!$A:$A) -> INSUMOS | D48: =SUMIFS('bbdd.5.final'!$Y:$Y,'bbdd.5.final'!$AA:$AA,Vista!A48,'bbdd.5.final'!$Z:$Z,$B$41,'bbdd.5.final'!$J:$J,"Opex") -> 3367036.3 | E48: =E47+1 -> 5 | F48: =H48/$H$43 -> 0.00053482048 | G48: =_xlfn.XLOOKUP($A48,'rubros_id_opex (2)'!$B:$B,'rubros_id_opex (2)'!$A:$A) -> INSUMOS | H48: =SUMIFS('bbdd.5.final'!$Y:$Y,'bbdd.5.final'!$AA:$AA,Vista!E48,'bbdd.5.final'!$Z:$Z,$F$41,'bbdd.5.final'!$J:$J,"Opex") -> 27536.27 | I48: =I47+1 -> 5 | J48: =L48/$L$43 -> 8.4858593e-05 | K48: =_xlfn.XLOOKUP($A48,'rubros_id_opex (2)'!$B:$B,'rubros_id_opex (2)'!$A:$A) -> INSUMOS | L48: =SUMIFS('bbdd.5.final'!$Y:$Y,'bbdd.5.final'!$AA:$AA,Vista!I48,'bbdd.5.final'!$Z:$Z,$J$41,'bbdd.5.final'!$J:$J,"Opex") -> 795.88202 | M48: =M47+1 -> 5 | N48: =P48/$P$43 -> 0.0013084059 | O48: =_xlfn.XLOOKUP($A48,'rubros_id_opex (2)'!$B:$B,'rubros_id_opex (2)'!$A:$A) -> INSUMOS | P48: =SUMIFS('bbdd.5.final'!$Y:$Y,'bbdd.5.final'!$AA:$AA,Vista!M48,'bbdd.5.final'!$Z:$Z,$N$41,'bbdd.5.final'!$J:$J,"Opex") -> 13821.036
A49: =A48+1 -> 6 | B49: =D49/$D$43 -> 0 | C49: =_xlfn.XLOOKUP($A49,'rubros_id_opex (2)'!$B:$B,'rubros_id_opex (2)'!$A:$A) -> INVERSION | D49: =SUMIFS('bbdd.5.final'!$Y:$Y,'bbdd.5.final'!$AA:$AA,Vista!A49,'bbdd.5.final'!$Z:$Z,$B$41,'bbdd.5.final'!$J:$J,"Opex") -> 0 | E49: =E48+1 -> 6 | F49: =H49/$H$43 -> 0 | G49: =_xlfn.XLOOKUP($A49,'rubros_id_opex (2)'!$B:$B,'rubros_id_opex (2)'!$A:$A) -> INVERSION | H49: =SUMIFS('bbdd.5.final'!$Y:$Y,'bbdd.5.final'!$AA:$AA,Vista!E49,'bbdd.5.final'!$Z:$Z,$F$41,'bbdd.5.final'!$J:$J,"Opex") -> 0 | I49: =I48+1 -> 6 | J49: =L49/$L$43 -> 0 | K49: =_xlfn.XLOOKUP($A49,'rubros_id_opex (2)'!$B:$B,'rubros_id_opex (2)'!$A:$A) -> INVERSION | L49: =SUMIFS('bbdd.5.final'!$Y:$Y,'bbdd.5.final'!$AA:$AA,Vista!I49,'bbdd.5.final'!$Z:$Z,$J$41,'bbdd.5.final'!$J:$J,"Opex") -> 0 | M49: =M48+1 -> 6 | N49: =P49/$P$43 -> 0 | O49: =_xlfn.XLOOKUP($A49,'rubros_id_opex (2)'!$B:$B,'rubros_id_opex (2)'!$A:$A) -> INVERSION | P49: =SUMIFS('bbdd.5.final'!$Y:$Y,'bbdd.5.final'!$AA:$AA,Vista!M49,'bbdd.5.final'!$Z:$Z,$N$41,'bbdd.5.final'!$J:$J,"Opex") -> 0
A50: =A49+1 -> 7 | B50: =D50/$D$43 -> 0 | C50: =_xlfn.XLOOKUP($A50,'rubros_id_opex (2)'!$B:$B,'rubros_id_opex (2)'!$A:$A) -> LOGISTICA | D50: =SUMIFS('bbdd.5.final'!$Y:$Y,'bbdd.5.final'!$AA:$AA,Vista!A50,'bbdd.5.final'!$Z:$Z,$B$41,'bbdd.5.final'!$J:$J,"Opex") -> 0 | E50: =E49+1 -> 7 | F50: =H50/$H$43 -> 7.5203537e-05 | G50: =_xlfn.XLOOKUP($A50,'rubros_id_opex (2)'!$B:$B,'rubros_id_opex (2)'!$A:$A) -> LOGISTICA | H50: =SUMIFS('bbdd.5.final'!$Y:$Y,'bbdd.5.final'!$AA:$AA,Vista!E50,'bbdd.5.final'!$Z:$Z,$F$41,'bbdd.5.final'!$J:$J,"Opex") -> 3872 | I50: =I49+1 -> 7 | J50: =L50/$L$43 -> 0 | K50: =_xlfn.XLOOKUP($A50,'rubros_id_opex (2)'!$B:$B,'rubros_id_opex (2)'!$A:$A) -> LOGISTICA | L50: =SUMIFS('bbdd.5.final'!$Y:$Y,'bbdd.5.final'!$AA:$AA,Vista!I50,'bbdd.5.final'!$Z:$Z,$J$41,'bbdd.5.final'!$J:$J,"Opex") -> 0 | M50: =M49+1 -> 7 | N50: =P50/$P$43 -> 0.048564538 | O50: =_xlfn.XLOOKUP($A50,'rubros_id_opex (2)'!$B:$B,'rubros_id_opex (2)'!$A:$A) -> LOGISTICA | P50: =SUMIFS('bbdd.5.final'!$Y:$Y,'bbdd.5.final'!$AA:$AA,Vista!M50,'bbdd.5.final'!$Z:$Z,$N$41,'bbdd.5.final'!$J:$J,"Opex") -> 513000
...

Sheet val1
A1: VENTAS
A2: CEREAL & POLVILLO | B2: =Vista!P59 -> 22440069
A3: DISPOSICIÓN FINAL RESIDUOS SOLIDOS | B3: =Vista!D31 -> 15491941 | E3: Row Labels | F3: Sum of TOTAL
A4: DISPOSICIÓN FINAL RESIDUOS LIQUIDOS | B4: =Vista!$H$31 -> 1.9005242e+08 | E4: BACHAS | F4: 1.030417e+08
A5: =Vista!J14 -> PILETAS | B5: =Vista!$L$31 -> 3.420193e+08 | E5: CEREAL & POLVILLO | F5: 22440069
A6: =Vista!N14 -> REACTORES | B6: =Vista!$P$31 -> 1.2611262e+08 | E6: COMPOST & FERTILIZANTES | F6: 1292207.6
A7: =Vista!B42 -> BACHAS | B7: =Vista!D59 -> 1.030417e+08 | E7: DISPOSICIÓN FINAL RESIDUOS LIQUIDOS | F7: 1.9005242e+08
A8: =Vista!F42 -> NFU | B8: =Vista!H59 -> 44708355 | E8: DISPOSICIÓN FINAL RESIDUOS SOLIDOS | F8: 15491941
A9: =Vista!J42 -> COMPOST & FERTILIZANTES | B9: =Vista!L59 -> 1292207.6 | E9: EXPORTACION | F9: 2.3334497e+09
A10: =Vista!#REF! -> #REF! | B10: =Vista!#REF! -> #REF! | E10: NFU | F10: 44708355
A11: =Vista!B70 -> EXPORTACION | B11: =Vista!D88 -> 2.3334497e+09 | E11: PILETAS | F11: 3.420193e+08
A12: SALES | B12: =GETPIVOTDATA("TOTAL",$E$3,"SECTOR","SALES") -> #REF! | E12: REACTORES | F12: 1.2611262e+08
A13: SUB-TOTAL | B13: =SUM(B2:B12) -> #REF! | E13: Grand Total | F13: 3.1786083e+09
A15: TOTAL | B15: =GETPIVOTDATA("TOTAL",$E$3) -> 3.1786083e+09
B18: =B15=B13 -> #REF!

Sheet Vista_R_sin_expo
B2: SIN EXPORTACIÓN
B3: TOTAL
B4: OPEX | D4: =SUM(D5:D18) -> 4.2374404e+08
A5: 1 | B5: =D5/$D$4 -> 0.13154334 | C5: =_xlfn.XLOOKUP($A5,'rubros_id_opex (2)'!$B:$B,'rubros_id_opex (2)'!$A:$A) -> ENERGIA | D5: =SUMIFS('bbdd.5.final'!$Y:$Y,'bbdd.5.final'!$AA:$AA,A5,'bbdd.5.final'!$J:$J,"Opex",'bbdd.5.final'!$Z:$Z,"<>5") -> 55740706
A6: =A5+1 -> 2 | B6: =D6/$D$4 -> 0 | C6: =_xlfn.XLOOKUP($A6,'rubros_id_opex (2)'!$B:$B,'rubros_id_opex (2)'!$A:$A) -> HABILITACIONES Y CERT | D6: =SUMIFS('bbdd.5.final'!$Y:$Y,'bbdd.5.final'!$AA:$AA,A6,'bbdd.5.final'!$J:$J,"Opex",'bbdd.5.final'!$Z:$Z,"<>5") -> 0
A7: =A6+1 -> 3 | B7: =D7/$D$4 -> 0.002753976 | C7: =_xlfn.XLOOKUP($A7,'rubros_id_opex (2)'!$B:$B,'rubros_id_opex (2)'!$A:$A) -> HIGIENE Y SEGURIDAD | D7: =SUMIFS('bbdd.5.final'!$Y:$Y,'bbdd.5.final'!$AA:$AA,A7,'bbdd.5.final'!$J:$J,"Opex",'bbdd.5.final'!$Z:$Z,"<>5") -> 1166980.9
A8: =A7+1 -> 4 | B8: =D8/$D$4 -> 0.0078273667 | C8: =_xlfn.XLOOKUP($A8,'rubros_id_opex (2)'!$B:$B,'rubros_id_opex (2)'!$A:$A) -> IMPUESTOS | D8: =SUMIFS('bbdd.5.final'!$Y:$Y,'bbdd.5.final'!$AA:$AA,A8,'bbdd.5.final'!$J:$J,"Opex",'bbdd.5.final'!$Z:$Z,"<>5") -> 3316800
A9: =A8+1 -> 5 | B9: =D9/$D$4 -> 0.17587487 | C9: =_xlfn.XLOOKUP($A9,'rubros_id_opex (2)'!$B:$B,'rubros_id_opex (2)'!$A:$A) -> INSUMOS | D9: =SUMIFS('bbdd.5.final'!$Y:$Y,'bbdd.5.final'!$AA:$AA,A9,'bbdd.5.final'!$J:$J,"Opex",'bbdd.5.final'!$Z:$Z,"<>5") -> 74525929
A10: =A9+1 -> 6 | B10: =D10/$D$4 -> 0 | C10: =_xlfn.XLOOKUP($A10,'rubros_id_opex (2)'!$B:$B,'rubros_id_opex (2)'!$A:$A) -> INVERSION | D10: =SUMIFS('bbdd.5.final'!$Y:$Y,'bbdd.5.final'!$AA:$AA,A10,'bbdd.5.final'!$J:$J,"Opex",'bbdd.5.final'!$Z:$Z,"<>5") -> 0
A11: =A10+1 -> 7 | B11: =D11/$D$4 -> 0.0012197741 | C11: =_xlfn.XLOOKUP($A11,'rubros_id_opex (2)'!$B:$B,'rubros_id_opex (2)'!$A:$A) -> LOGISTICA | D11: =SUMIFS('bbdd.5.final'!$Y:$Y,'bbdd.5.final'!$AA:$AA,A11,'bbdd.5.final'!$J:$J,"Opex",'bbdd.5.final'!$Z:$Z,"<>5") -> 516872
A12: =A11+1 -> 8 | B12: =D12/$D$4 -> 0.28395129 | C12: =_xlfn.XLOOKUP($A12,'rubros_id_opex (2)'!$B:$B,'rubros_id_opex (2)'!$A:$A) -> M.PRIMAS | D12: =SUMIFS('bbdd.5.final'!$Y:$Y,'bbdd.5.final'!$AA:$AA,A12,'bbdd.5.final'!$J:$J,"Opex",'bbdd.5.final'!$Z:$Z,"<>5") -> 1.2032267e+08
A13: =A12+1 -> 9 | B13: =D13/$D$4 -> 0.0034075481 | C13: =_xlfn.XLOOKUP($A13,'rubros_id_opex (2)'!$B:$B,'rubros_id_opex (2)'!$A:$A) -> MANTENIMIENTO PREVENTIVO | D13: =SUMIFS('bbdd.5.final'!$Y:$Y,'bbdd.5.final'!$AA:$AA,A13,'bbdd.5.final'!$J:$J,"Opex",'bbdd.5.final'!$Z:$Z,"<>5") -> 1443928.2
A14: =A13+1 -> 10 | B14: =D14/$D$4 -> 0.36022486 | C14: =_xlfn.XLOOKUP($A14,'rubros_id_opex (2)'!$B:$B,'rubros_id_opex (2)'!$A:$A) -> PERSONAL | D14: =SUMIFS('bbdd.5.final'!$Y:$Y,'bbdd.5.final'!$AA:$AA,A14,'bbdd.5.final'!$J:$J,"Opex",'bbdd.5.final'!$Z:$Z,"<>5") -> 1.5264314e+08
A15: =A14+1 -> 11 | B15: =D15/$D$4 -> 0.0011694584 | C15: =_xlfn.XLOOKUP($A15,'rubros_id_opex (2)'!$B:$B,'rubros_id_opex (2)'!$A:$A) -> REPARACIONES | D15: =SUMIFS('bbdd.5.final'!$Y:$Y,'bbdd.5.final'!$AA:$AA,A15,'bbdd.5.final'!$J:$J,"Opex",'bbdd.5.final'!$Z:$Z,"<>5") -> 495551.03
A16: =A15+1 -> 12 | B16: =D16/$D$4 -> 0.0095086379 | C16: =_xlfn.XLOOKUP($A16,'rubros_id_opex (2)'!$B:$B,'rubros_id_opex (2)'!$A:$A) -> REPOSICION | D16: =SUMIFS('bbdd.5.final'!$Y:$Y,'bbdd.5.final'!$AA:$AA,A16,'bbdd.5.final'!$J:$J,"Opex",'bbdd.5.final'!$Z:$Z,"<>5") -> 4029228.6
A17: =A16+1 -> 13 | B17: =D17/$D$4 -> 0.02251887 | C17: =_xlfn.XLOOKUP($A17,'rubros_id_opex (2)'!$B:$B,'rubros_id_opex (2)'!$A:$A) -> SERVICIOS | D17: =SUMIFS('bbdd.5.final'!$Y:$Y,'bbdd.5.final'!$AA:$AA,A17,'bbdd.5.final'!$J:$J,"Opex",'bbdd.5.final'!$Z:$Z,"<>5") -> 9542236.8
A18: =A17+1 -> 14 | B18: =D18/$D$4 -> 0 | C18: =_xlfn.XLOOKUP($A18,'rubros_id_opex (2)'!$B:$B,'rubros_id_opex (2)'!$A:$A) -> COMERCIAL | D18: =SUMIFS('bbdd.5.final'!$Y:$Y,'bbdd.5.final'!$AA:$AA,A18,'bbdd.5.final'!$J:$J,"Opex",'bbdd.5.final'!$Z:$Z,"<>5") -> 0
B20: VENTAS | D20: =SUMIFS(BBDD_INGRESOS_FINAL!$O:$O,BBDD_INGRESOS_FINAL!$R:$R,"<>5") -> 8.4515862e+08
B22: UTILDAD | D22: =D20-D4 -> 4.2141458e+08
B24: CAPEX | D24: =SUMIFS('bbdd.5.final'!$Y:$Y,'bbdd.5.final'!$J:$J,"Capex",'bbdd.5.final'!$Z:$Z,"<>5") -> 1.8087214e+08
B26: DEUDA | D26: =SUMIFS('bbdd.5.final'!$Y:$Y,'bbdd.5.final'!$J:$J,"Deuda",'bbdd.5.final'!$Z:$Z,"<>5") -> 401800.49
B28: Flujo de Caja al Accionista | D28: =D22-D24-D26 -> 2.4014064e+08
B31: VENTAS
B32: Row Labels | C32: Sum of TOTAL | D32: prc
B33: PILETAS | C33: 3.420193e+08 | D33: =C33/$C$41 -> 0.40468061
B34: DISPOSICIÓN FINAL RESIDUOS LIQUIDOS | C34: 1.9005242e+08 | D34: =C34/$C$41 -> 0.2248719
B35: REACTORES | C35: 1.2611262e+08 | D35: =C35/$C$41 -> 0.1492177
B36: BACHAS | C36: 1.030417e+08 | D36: =C36/$C$41 -> 0.12191995
B37: NFU | C37: 44708355 | D37: =C37/$C$41 -> 0.052899366
B38: CEREAL & POLVILLO | C38: 22440069 | D38: =C38/$C$41 -> 0.026551311
B39: DISPOSICIÓN FINAL RESIDUOS SOLIDOS | C39: 15491941 | D39: =C39/$C$41 -> 0.018330217
B40: COMPOST & FERTILIZANTES | C40: 1292207.6 | D40: =C40/$C$41 -> 0.0015289527
B41: Grand Total | C41: 8.4515862e+08 | D41: =C41/$C$41 -> 1
B44: COSTOS
B45: Row Labels | C45: Sum of MONTO_FINAL
B46: DISP. FINAL RESIDUOS LÍQUIDOS | C46: 2.3490818e+08 | D46: =C46/$C$54 -> 0.3571559
B47: BACHAS | C47: 1.7240266e+08 | D47: =C47/$C$54 -> 0.26212211
B48: REACTORES | C48: 1.1198631e+08 | D48: =C48/$C$54 -> 0.1702647
B49: NFU | C49: 51768705 | D49: =C49/$C$54 -> 0.07870947
B50: PILETAS | C50: 47505376 | D50: =C50/$C$54 -> 0.072227477
...

Sheet Vista_RUBRO
B2: CON EXPORTACIÓN INCLUÍDA
B3: TOTAL
B4: OPEX | D4: =SUM(D5:D18) -> 2.7341314e+09
A5: 1 | B5: =D5/$D$4 -> 0.023629454 | C5: =_xlfn.XLOOKUP($A5,'rubros_id_opex (2)'!$B:$B,'rubros_id_opex (2)'!$A:$A) -> ENERGIA | D5: =SUMIFS('bbdd.5.final'!$Y:$Y,'bbdd.5.final'!$AA:$AA,A5,'bbdd.5.final'!$J:$J,"Opex") -> 64606033
A6: =A5+1 -> 2 | B6: =D6/$D$4 -> 0.00052886997 | C6: =_xlfn.XLOOKUP($A6,'rubros_id_opex (2)'!$B:$B,'rubros_id_opex (2)'!$A:$A) -> HABILITACIONES Y CERT | D6: =SUMIFS('bbdd.5.final'!$Y:$Y,'bbdd.5.final'!$AA:$AA,A6,'bbdd.5.final'!$J:$J,"Opex") -> 1446000
A7: =A6+1 -> 3 | B7: =D7/$D$4 -> 0.0016052518 | C7: =_xlfn.XLOOKUP($A7,'rubros_id_opex (2)'!$B:$B,'rubros_id_opex (2)'!$A:$A) -> HIGIENE Y SEGURIDAD | D7: =SUMIFS('bbdd.5.final'!$Y:$Y,'bbdd.5.final'!$AA:$AA,A7,'bbdd.5.final'!$J:$J,"Opex") -> 4388969.4
A8: =A7+1 -> 4 | B8: =D8/$D$4 -> 0.0035692244 | C8: =_xlfn.XLOOKUP($A8,'rubros_id_opex (2)'!$B:$B,'rubros_id_opex (2)'!$A:$A) -> IMPUESTOS | D8: =SUMIFS('bbdd.5.final'!$Y:$Y,'bbdd.5.final'!$AA:$AA,A8,'bbdd.5.final'!$J:$J,"Opex") -> 9758728.5
A9: =A8+1 -> 5 | B9: =D9/$D$4 -> 0.027812533 | C9: =_xlfn.XLOOKUP($A9,'rubros_id_opex (2)'!$B:$B,'rubros_id_opex (2)'!$A:$A) -> INSUMOS | D9: =SUMIFS('bbdd.5.final'!$Y:$Y,'bbdd.5.final'!$AA:$AA,A9,'bbdd.5.final'!$J:$J,"Opex") -> 76043122
A10: =A9+1 -> 6 | B10: =D10/$D$4 -> 0 | C10: =_xlfn.XLOOKUP($A10,'rubros_id_opex (2)'!$B:$B,'rubros_id_opex (2)'!$A:$A) -> INVERSION | D10: =SUMIFS('bbdd.5.final'!$Y:$Y,'bbdd.5.final'!$AA:$AA,A10,'bbdd.5.final'!$J:$J,"Opex") -> 0
A11: =A10+1 -> 7 | B11: =D11/$D$4 -> 0.0092388991 | C11: =_xlfn.XLOOKUP($A11,'rubros_id_opex (2)'!$B:$B,'rubros_id_opex (2)'!$A:$A) -> LOGISTICA | D11: =SUMIFS('bbdd.5.final'!$Y:$Y,'bbdd.5.final'!$AA:$AA,A11,'bbdd.5.final'!$J:$J,"Opex") -> 25260364
A12: =A11+1 -> 8 | B12: =D12/$D$4 -> 0.83536567 | C12: =_xlfn.XLOOKUP($A12,'rubros_id_opex (2)'!$B:$B,'rubros_id_opex (2)'!$A:$A) -> M.PRIMAS | D12: =SUMIFS('bbdd.5.final'!$Y:$Y,'bbdd.5.final'!$AA:$AA,A12,'bbdd.5.final'!$J:$J,"Opex") -> 2.2839995e+09
A13: =A12+1 -> 9 | B13: =D13/$D$4 -> 0.0014884402 | C13: =_xlfn.XLOOKUP($A13,'rubros_id_opex (2)'!$B:$B,'rubros_id_opex (2)'!$A:$A) -> MANTENIMIENTO PREVENTIVO | D13: =SUMIFS('bbdd.5.final'!$Y:$Y,'bbdd.5.final'!$AA:$AA,A13,'bbdd.5.final'!$J:$J,"Opex") -> 4069591.1
A14: =A13+1 -> 10 | B14: =D14/$D$4 -> 0.073042215 | C14: =_xlfn.XLOOKUP($A14,'rubros_id_opex (2)'!$B:$B,'rubros_id_opex (2)'!$A:$A) -> PERSONAL | D14: =SUMIFS('bbdd.5.final'!$Y:$Y,'bbdd.5.final'!$AA:$AA,A14,'bbdd.5.final'!$J:$J,"Opex") -> 1.9970702e+08
A15: =A14+1 -> 11 | B15: =D15/$D$4 -> 0.00041443728 | C15: =_xlfn.XLOOKUP($A15,'rubros_id_opex (2)'!$B:$B,'rubros_id_opex (2)'!$A:$A) -> REPARACIONES | D15: =SUMIFS('bbdd.5.final'!$Y:$Y,'bbdd.5.final'!$AA:$AA,A15,'bbdd.5.final'!$J:$J,"Opex") -> 1133126
A16: =A15+1 -> 12 | B16: =D16/$D$4 -> 0.0018620529 | C16: =_xlfn.XLOOKUP($A16,'rubros_id_opex (2)'!$B:$B,'rubros_id_opex (2)'!$A:$A) -> REPOSICION | D16: =SUMIFS('bbdd.5.final'!$Y:$Y,'bbdd.5.final'!$AA:$AA,A16,'bbdd.5.final'!$J:$J,"Opex") -> 5091097.4
A17: =A16+1 -> 13 | B17: =D17/$D$4 -> 0.021442947 | C17: =_xlfn.XLOOKUP($A17,'rubros_id_opex (2)'!$B:$B,'rubros_id_opex (2)'!$A:$A) -> SERVICIOS | D17: =SUMIFS('bbdd.5.final'!$Y:$Y,'bbdd.5.final'!$AA:$AA,A17,'bbdd.5.final'!$J:$J,"Opex") -> 58627836
A18: =A17+1 -> 14 | B18: =D18/$D$4 -> 0 | C18: =_xlfn.XLOOKUP($A18,'rubros_id_opex (2)'!$B:$B,'rubros_id_opex (2)'!$A:$A) -> COMERCIAL | D18: =SUMIFS('bbdd.5.final'!$Y:$Y,'bbdd.5.final'!$AA:$AA,A18,'bbdd.5.final'!$J:$J,"Opex") -> 0
B20: VENTAS | D20: =SUM(BBDD_INGRESOS_FINAL!$O:$O) -> 3.1786083e+09
B22: UTILDAD | D22: =D20-D4 -> 4.4447693e+08
B24: CAPEX | D24: =SUMIFS('bbdd.5.final'!$Y:$Y,'bbdd.5.final'!$J:$J,"Capex") -> 1.8781251e+08
B26: DEUDA | D26: =SUMIFS('bbdd.5.final'!$Y:$Y,'bbdd.5.final'!$J:$J,"Deuda") -> 1511155.8
B28: Flujo de Caja al Accionista | D28: =D22-D24-D26 -> 2.5515326e+08
B31: VENTAS
B32: Row Labels | C32: sectores_id.id_sector_2 | D32: Sum of TOTAL
B33: EXPORTACION | C33: 5 | D33: 2.3334497e+09
B34: PILETAS | C34: 7 | D34: 3.420193e+08
B35: DISPOSICIÓN FINAL RESIDUOS LIQUIDOS | C35: 3 | D35: 1.9005242e+08
B36: REACTORES | C36: 8 | D36: 1.2611262e+08
B37: BACHAS | C37: 1 | D37: 1.030417e+08
B38: NFU | C38: 6 | D38: 44708355
B39: CEREAL & POLVILLO | C39: 2 | D39: 22440069
B40: DISPOSICIÓN FINAL RESIDUOS SOLIDOS | C40: 4 | D40: 15491941
B41: COMPOST & FERTILIZANTES | C41: 10 | D41: 1292207.6
B42: Grand Total | C42: 10 | D42: 3.1786083e+09
B43: Concepto | C43: OPEX
B44: COSTOS_OPEX
B45: Row Labels | C45: Max of id_sector | D45: Sum of monto_final2
B46: EXPORTACION | C46: 5 | D46: 2.3103874e+09
B47: BACHAS | C47: 1 | D47: 1.4810693e+08
B48: REACTORES | C48: 8 | D48: 1.1071668e+08
...

Sheet RRHH
C1: TOTAL 1+2 | D1: COMPONENTE
A2: ADMINISTRACION | B2: =_xlfn.CONCAT("RRHH-",A2) -> RRHH-ADMINISTRACION | C2: 67124149 | D2: 100% ADMINISTRACION - 100% DIRECTOR | E2: CC1
A3: INTENDENCIA | B3: =_xlfn.CONCAT("RRHH-",A3) -> RRHH-INTENDENCIA | C3: 9375237.7 | D3: 100% INTENDENCIA - 6,67% PRODUCCION | E3: CC1
A4: LABORATORIO | B4: =_xlfn.CONCAT("RRHH-",A4) -> RRHH-LABORATORIO | C4: 12249966 | D4: 100% LABORATORIO - 6,67% PRODUCCION | E4: CC1
A5: LOGISTICA | B5: =_xlfn.CONCAT("RRHH-",A5) -> RRHH-LOGISTICA | C5: 6459899.7 | D5: 75% LOGISTICA - 6,67% PRODUCCION | E5: CC1
A6: MANTENIMIENTO | B6: =_xlfn.CONCAT("RRHH-",A6) -> RRHH-MANTENIMIENTO | C6: 7742399.7 | D6: 100% MANTENIMIENTO - 6,67% PRODUCCION | E6: CC1
A7: NFU | B7: =_xlfn.CONCAT("RRHH-",A7) -> RRHH-NFU | C7: 29572095 | D7: 25% LOGISTICA - 100% CAT - 100% EXTERNO NFU - 6,67% PRODUCCION - 95% NFU | E7: CC7
A8: PORTERIA | B8: =_xlfn.CONCAT("RRHH-",A8) -> RRHH-PORTERIA | C8: 10797311 | D8: 100% PORTERIA - 6,67% PRODUCCION | E8: CC1
A9: COMPOST Y FERTILIZANTES | B9: =_xlfn.CONCAT("RRHH-",A9) -> RRHH-COMPOST Y FERTILIZANTES | C9: 1833599.1 | D9: 60% COMPOST Y FERTILIZANTES - 6,67% PRODUCCION | E9: CC14
A10: CEREAL Y POLVILLO | B10: =_xlfn.CONCAT("RRHH-",A10) -> RRHH-CEREAL Y POLVILLO | C10: 0 | D10: 0% CEREAL Y POLVILLO - 0% PRODUCCION | E10: NO
A11: TALLER MECANICO | B11: =_xlfn.CONCAT("RRHH-",A11) -> RRHH-TALLER MECANICO | C11: 6300478.7 | D11: 100% TALLER MECANICO - 6,67% PRODUCCION | E11: CC1
A12: TIERRAS FILTRANTES | B12: =_xlfn.CONCAT("RRHH-",A12) -> RRHH-TIERRAS FILTRANTES | C12: 0 | D12: 0% TIERRAS FILTRANTES - 0% PRODUCCION | E12: NO
A13: VIGILANCIA | B13: =_xlfn.CONCAT("RRHH-",A13) -> RRHH-VIGILANCIA | C13: 6294101.7 | D13: 100% VIGILANCIA - 6,67% PRODUCCION | E13: CC1
... A21: SALES | B21: =_xlfn.CONCAT("RRHH-",A21) -> RRHH-SALES | C21: 0 | D21: 0% SALES - 0% PRODUCCION | E21: NO

Sheet ref_rrhh
A1: Sector | B1: f/v | C1: d/i
A2: ADMINISTRACION | B2: Fijo | C2: Indirecto
A3: INTENDENCIA | B3: Fijo | C3: Indirecto
A4: REACTOR | B4: Variable | C4: Directo
A5: NFU | B5: Variable | C5: Directo
A6: DISPOSICION FINAL DE R. LIQUIDOS | B6: Variable | C6: Directo
A7: DIRECTOR | B7: Fijo | C7: Indirecto
A8: TALLER MECANICO | B8: Fijo | C8: Indirecto
A9: PRODUCCION | B9: Variable | C9: Directo
A10: CAT | B10: Variable | C10: Directo
A11: MANTENIMIENTO | B11: Fijo | C11: Indirecto
A12: PORTERIA | B12: Fijo | C12: Indirecto
... A17: COMPOST Y FERTILIZANTES | B17: Variable | C17: Directo

Sheet gastos_unificado.p0
A1: Fecha de Factura/Recibo | B1: Nombre de la empresa a mostrar en la factura | C1: Número | D1: Total con signo | E1: Líneas de factura/Etiqueta | F1: Líneas de factura/Cantidad | G1: Líneas de factura/Precio unitario | H1: Líneas de factura/Unidad de medida | I1: Líneas de factura/Producto | J1: Concepto | K1: Tipo de Gasto 1 | L1: Tipo de Gasto 2 | M1: CCO EMPRESA | N1: SECTOR | O1: Origen | P1: USD | Q1: SECTOR2 | R1: SUBRUBRO | S1: TC | T1: Total
A2: 46081 | B2: WORMS 2 | C2: prod17 | D2: -1.9004255e+09 | E2: AFE (S) | F2: 1403.96 | G2: 945 | H2: TN | I2: MATERIA PRIMA | J2: OPEX | K2: VARIABLE | L2: DIRECTO | N2: CC11 | O2: gastos_produccion | P2: 1432 | Q2: EXPORTACION | R2: AFE (S)
A3: 46081 | B3: WORMS 2 | C3: prod15 | D3: -1.1459658e+08 | E3: AFE (G) | F3: 86.96 | G3: 920 | H3: TN | I3: MATERIA PRIMA | J3: OPEX | K3: VARIABLE | L3: DIRECTO | N3: CC11 | O3: gastos_produccion | P3: 1432 | Q3: EXPORTACION | R3: AFE (G)
A4: 46081 | B4: WORMS 2 | C4: prod29 | D4: -87594125 | E4: ARE- B | F4: 72.8 | G4: 840 | H4: TN | I4: MATERIA PRIMA | J4: OPEX | K4: VARIABLE | L4: DIRECTO | N4: CC11 | O4: gastos_produccion | P4: 1432 | Q4: EXPORTACION | R4: ARE- B
A5: 46081 | B5: WORMS 1 | C5: prod26 | D5: -78996860 | E5: AG-D | F5: 110.3 | G5: 500 | H5: TN | I5: MATERIA PRIMA | J5: OPEX | K5: VARIABLE | L5: DIRECTO | N5: CC6 | O5: gastos_produccion | P5: 1432 | Q5: BACHAS | R5: AG-D
A6: 46081 | B6: MILO - DENIS LUQUE | C6: prod13 | D6: -67513309 | E6: GLICERINA CRUDA | F6: 130.925 | G6: 360 | H6: TN | I6: INSUMOS | J6: OPEX | K6: VARIABLE | L6: DIRECTO | N6: CC5 | O6: gastos_produccion | P6: 1432 | Q6: REACTORES | R6: GLICERINA CRUDA
A7: 46066 | B7: Construcciones Industriales Y Portuarias S.A. | C7: FA-A 00003-00001286 | D7: -54208000 | E7: INVERSION Planta de efluentes | F7: 1 | G7: 44800000 | H7: UN | I7: INVERSION | J7: CAPEX | K7: VARIABLE | L7: INDIRECTO | N7: CC3 | O7: gastos_produccion | R7: PROYECTO 4
A8: 46056 | B8: Construcciones Industriales Y Portuarias S.A. | C8: FA-A 00003-00001279 | D8: -54208000 | E8: OC 0001-00004263: INVERSION Planta de efluentes | F8: 1 | G8: 44800000 | H8: UN | I8: INVERSION | J8: CAPEX | K8: VARIABLE | L8: INDIRECTO | N8: CC3 | O8: gastos_produccion | R8: PROYECTO 4
A9: 46081 | B9: WORMS 2 | C9: prod19 | D9: -42638251 | E9: AG- A | F9: 35.02 | G9: 850 | H9: TN | I9: MATERIA PRIMA | J9: OPEX | K9: VARIABLE | L9: DIRECTO | N9: CC11 | O9: gastos_produccion | P9: 1432 | Q9: EXPORTACION | R9: AG- A
A10: 46055 | B10: Gmc Valores Sociedad Anonima | C10: OCOM/2026/0113 | D10: -32228280 | E10: OC 0001-00004462: INVERSION NORDIC | F10: 1 | G10: 32228280 | H10: UN | I10: INVERSION | J10: CAPEX | K10: VARIABLE | L10: DIRECTO | N10: CC3 | O10: gastos_produccion | R10: PROYECTO X
A11: 46063 | B11: Empresa Provincial De La Energia De Santa Fe (W) | C11: FA-A 00069-00037349 | D11: -30539110 | E11: OC 0001-00003944: ENERGIA Luz | F11: 1 | G11: 20913570 | H11: UN | I11: ENERGIA | J11: OPEX | K11: VARIABLE | L11: DIRECTO | N11: CC14 | O11: gastos_produccion | R11: ENERGIA
A12: 46081 | B12: LOGISTICA EXPORTACION | C12: FA-C 2-2026-1 | D12: -24743492 | E12: FOB | F12: 692.61 | G12: 35725 | H12: TN | I12: LOGISTICA | J12: OPEX | K12: VARIABLE | L12: DIRECTO | N12: CC11 | O12: gastos_produccion | P12: 1 | Q12: EXPORTACION | R12: FOB
A13: 46081 | B13: WORMS 1 | C13: prod33 | D13: -23997713 | E13: FONDO TK | F13: 33.507 | G13: 500 | H13: TN | I13: MATERIA PRIMA | J13: OPEX | K13: VARIABLE | L13: DIRECTO | N13: CC6 | O13: gastos_produccion | P13: 1432 | Q13: BACHAS
A14: 46081 | B14: COOPERATIVA DE TRABAJO COMERCIO EXTERIOR LIMITADA | C14: FA-C 2-2026-5 | D14: -19676907 | E14: SERVICIO DE DESPACHO | F14: 1616.12 | G14: 8.5 | H14: UN | I14: SERVICIOS | J14: OPEX | K14: VARIABLE | L14: DIRECTO | N14: CC11 | O14: gastos_produccion | P14: 1432 | R14: COMEX
A15: 46081 | B15: WORMS 2 | C15: prod23 | D15: -18422383 | E15: AG- C | F15: 17.38 | G15: 740 | H15: TN | I15: MATERIA PRIMA | J15: OPEX | K15: VARIABLE | L15: DIRECTO | N15: CC11 | O15: gastos_produccion | P15: 1432 | Q15: EXPORTACION | R15: AG- C
A16: 46081 | B16: ULTRAONIX SRL | C16: prod4 | D16: -17799734 | E16: FUEL OIL | F16: 27393.9 | G16: 649.77 | H16: KG | I16: ENERGIA | J16: OPEX | K16: VARIABLE | L16: DIRECTO | N16: CC5 | O16: gastos_produccion | P16: 1 | Q16: REACTORES | R16: FUEL OIL
A17: 46081 | B17: WORMS 1 | C17: prod34 | D17: -16472600 | E17: EMULSION | F17: 23 | G17: 500 | H17: KG | I17: MATERIA PRIMA | J17: OPEX | K17: VARIABLE | L17: DIRECTO | N17: CC6 | O17: gastos_produccion | P17: 1432 | Q17: BACHAS
A18: 46059 | B18: Bca Distribuciones Sa | C18: FA-A 00001-00005780 | D18: -11030401 | E18: OC 0001-00004176: INVERSION Proyecto 35 Bomba a pedido de Fernando T | F18: 1 | G18: 9116034.2 | H18: UN | I18: INVERSION | J18: CAPEX | K18: VARIABLE | L18: DIRECTO | N18: CC6 | O18: gastos_produccion | R18: POYECTO 35
A19: 46081 | B19: WORMS-RRHH | C19: ZIMMERMAN PABLO MAURICIO | D19: -10890280 | E19: DIRECTOR | F19: 1 | G19: 10890280 | H19: #RRHH | I19: PERSONAL | J19: OPEX | N19: CC16 | O19: gastos_rrhh | R19: DIRECTOR | T19: 10890280
A20: 46081 | B20: WORMS-RRHH | C20: FERREYRA GRACES JORGE BENJAMIN | D20: -8861694.3 | E20: DIRECTOR | F20: 1 | G20: 8861694.3 | H20: #RRHH | I20: PERSONAL | J20: OPEX | N20: CC16 | O20: gastos_rrhh | R20: DIRECTOR | T20: 8861694.3
A21: 46072 | B21: Cina, Dario Ruben | C21: FA-A 00002-00000007 | D21: -7763698.8 | E21: INVERSION Nunevo pozo de agua | F21: 1 | G21: 6416280 | H21: UN | I21: INVERSION | J21: CAPEX | K21: VARIABLE | L21: INDIRECTO | N21: CC3 | O21: gastos_produccion | R21: PROYECTO 50
A22: 46081 | B22: MARTINS, JOAQUIN | C22: prod8 | D22: -7070374 | E22: GASOIL G3 | F22: 4031 | G22: 1754 | H22: Lts | I22: ENERGIA | J22: OPEX | K22: VARIABLE | L22: DIRECTO | N22: CC1 | O22: gastos_produccion | P22: 1 | Q22: INTENDENCIA | R22: GASOIL G3
A23: 46081 | B23: WORMS-RRHH | C23: PAGANI, PABLO ALFONSO | D23: -6116414.9 | E23: PRODUCCION | F23: 1 | G23: 6116414.9 | H23: #RRHH | I23: PERSONAL | J23: OPEX | N23: CC28 | O23: gastos_rrhh | R23: PRODUCCION | T23: 6116414.9
A24: 46081 | B24: WORMS-RRHH | C24: MAZZALI CARLA JUDIT | D24: -6032968.4 | E24: ADMINISTRACION | F24: 1 | G24: 6032968.4 | H24: #RRHH | I24: PERSONAL | J24: OPEX | N24: CC15 | O24: gastos_rrhh | R24: ADMINISTRACION | T24: 6032968.4
A25: 46077 | B25: Southcross Logistics S.A real | C25: FA-A 00004-00037163 | D25: -5693050 | E25: SERVICIOS flete terrestre | F25: 5 | G25: 500000 | H25: UN | I25: SERVICIOS | J25: OPEX | K25: VARIABLE | L25: DIRECTO | N25: CC11 | O25: gastos_produccion
A26: 46072 | B26: Mastrangelo Productos Electricos Sa | C26: FA-A 00015-00069801 | D26: -5525708 | E26: INVERSION Proyecto 35 Pedido eléctrico | F26: 1 | G26: 4566700.8 | H26: UN | I26: INVERSION | J26: CAPEX | K26: VARIABLE | L26: DIRECTO | N26: CC6 | O26: gastos_produccion | R26: PROYECTO 35
A27: 46081 | B27: ULTRAONIX SRL | C27: prod5 | D27: -5458221.7 | E27: FUEL OIL | F27: 8410.203 | G27: 649 | H27: KG | I27: ENERGIA | J27: OPEX | K27: VARIABLE | L27: DIRECTO | N27: CC6 | O27: gastos_produccion | P27: 1 | Q27: BACHAS | R27: FUEL OIL
A28: 46081 | B28: IMPUESTOS | C28: imp2 | D28: -5039229.7 | E28: IMPUESTOS | F28: 1 | G28: 5039229.7 | H28: UN | I28: IMPUESTOS | J28: OPEX | K28: VARIABLE | L28: INDIRECTO | N28: CC1 | O28: gastos_impuestos | R28: GASTOS BANCARIOS
A29: 46081 | B29: WORMS-RRHH | C29: DIAZ PABLO EMMANUEL | D29: -4660517 | E29: NFU | F29: 1 | G29: 4660517 | H29: #RRHH | I29: PERSONAL | J29: OPEX | N29: CC7 | O29: gastos_rrhh | R29: NFU | T29: 4660517
A30: 46081 | B30: WORMS-RRHH | C30: CEBALLEZ, MARIA EUGENIA | D30: -4555960.9 | E30: PRODUCCION | F30: 1 | G30: 4555960.9 | H30: #RRHH | I30: PERSONAL | J30: OPEX | N30: CC28 | O30: gastos_rrhh | R30: PRODUCCION | T30: 4555960.9
A31: 46081 | B31: WORMS-RRHH | C31: TISCORNIA FERNANDO | D31: -4207865.4 | E31: DIRECTOR | F31: 1 | G31: 4207865.4 | H31: #RRHH | I31: PERSONAL | J31: OPEX | N31: CC16 | O31: gastos_rrhh | R31: DIRECTOR | T31: 4207865.4
A32: 46081 | B32: WORMS-RRHH | C32: LUQUE, ADRIAN | D32: -4107684.4 | E32: TALLER MECANICO | F32: 1 | G32: 4107684.4 | H32: #RRHH | I32: PERSONAL | J32: OPEX | N32: CC23 | O32: gastos_rrhh | R32: TALLER MECANICO | T32: 4107684.4
A33: 46072 | B33: Bordon, Carlos Roberto | C33: FA-C 00004-00000002 | D33: -4000000 | E33: INVERSION trabajo varios | F33: 1 | G33: 4000000 | H33: UN | I33: INVERSION | J33: CAPEX | K33: VARIABLE | L33: INDIRECTO | N33: CC6 | O33: gastos_produccion | R33: POYECTO X
A34: 46081 | B34: WORMS-RRHH | C34: HONORES ANDRES | D34: -3780940.7 | E34: REACTOR | F34: 1 | G34: 3780940.7 | H34: #RRHH | I34: PERSONAL | J34: OPEX | N34: CC15 | O34: gastos_rrhh | R34: REACTOR | T34: 3780940.7
A35: 46081 | B35: WORMS-RRHH | C35: PEREZ, MATIAS ROMAN | D35: -3671564.8 | E35: INTENDENCIA | F35: 1 | G35: 3671564.8 | H35: #RRHH | I35: PERSONAL | J35: OPEX | N35: CC27 | O35: gastos_rrhh | R35: INTENDENCIA | T35: 3671564.8
A36: 46056 | B36: Exportdeniv Internacional Sa | C36: FA-A 00002-00000604 | D36: -3455620.3 | E36: OC 0001-00004507: SERVICIOS Almacenaje cargas generales 1/26 | F36: 3969.24 | G36: 870.6 | H36: UN | I36: SERVICIOS | J36: OPEX | K36: VARIABLE | L36: DIRECTO | N36: CC11 | O36: gastos_produccion
A37: 46081 | B37: WORMS-RRHH | C37: LOPEZ CAMARGO BERLITZ, BEATRIZ | D37: -3415916.1 | E37: LABORATORIO | F37: 1 | G37: 3415916.1 | H37: #RRHH | I37: PERSONAL | J37: OPEX | N37: CC17 | O37: gastos_rrhh | R37: LABORATORIO | T37: 3415916.1
A38: 46081 | B38: WORMS-RRHH | C38: PELUZZA, CLAUDIA | D38: -3387545.4 | E38: ADMINISTRACION | F38: 1 | G38: 3387545.4 | H38: #RRHH | I38: PERSONAL | J38: OPEX | N38: CC15 | O38: gastos_rrhh | R38: ADMINISTRACION | T38: 3387545.4
A39: 46081 | B39: MARTINS, JOAQUIN | C39: prod10 | D39: -3363750 | E39: NAFTA | F39: 2250 | G39: 1495 | H39: Lts | I39: ENERGIA | J39: OPEX | K39: VARIABLE | L39: DIRECTO | N39: CC4 | O39: gastos_produccion | P39: 1 | Q39: PILETAS | R39: NAFTA
A40: 46081 | B40: WORMS-RRHH | C40: CHIANEA ERWIN | D40: -3349666.3 | E40: PRODUCCION | F40: 1 | G40: 3349666.3 | H40: #RRHH | I40: PERSONAL | J40: OPEX | N40: CC28 | O40: gastos_rrhh | R40: PRODUCCION | T40: 3349666.3
...

Sheet bbdd_total.p1
A1: Fecha de Factura/Recibo | B1: Nombre de la empresa a mostrar en la factura | C1: Número | D1: Total con signo | E1: Líneas de factura/Etiqueta | F1: Líneas de factura/Cantidad | G1: Líneas de factura/Precio unitario | H1: Líneas de factura/Unidad de medida | I1: Líneas de factura/Producto | J1: Concepto | K1: Tipo de Gasto 1 | L1: Tipo de Gasto 2 | M1: CCO EMPRESA | N1: CCO - SECTOR | O1: SECTOR_ODOO | P1: # SECTORES | Q1: LISTA_SECTORES | R1: prc_empresa
A2: 46081 | B2: WORMS 2 | C2: prod17 | D2: -1.9004255e+09 | E2: AFE (S) | F2: 1403.96 | G2: 945 | H2: TN | I2: MATERIA PRIMA | J2: OPEX | K2: VARIABLE | L2: DIRECTO | N2: CC11 | O2: gastos_produccion | P2: =_xlfn.XLOOKUP(bbdd3[[#This Row],[CCO - SECTOR]],'cco '!$A:$A,'cco '!F:F,"CCO NO DEFINIDO") -> 1 | Q2: =_xlfn.XLOOKUP(bbdd3[[#This Row],[CCO - SECTOR]],'cco '!$A:$A,'cco '!I:I,"CCO NO DEFINIDO") -> EXPORTACION | R2: =IF(ISBLANK(bbdd3[[#This Row],[CCO EMPRESA]]),1,_xlfn.XLOOKUP(bbdd3[[#This Row],[CCO EMPRESA]],'cco_worms_empresa'!$A:$A,'cco_worms_empresa'!$G:$G)) -> 1
A3: 46081 | B3: WORMS 2 | C3: prod15 | D3: -1.1459658e+08 | E3: AFE (G) | F3: 86.96 | G3: 920 | H3: TN | I3: MATERIA PRIMA | J3: OPEX | K3: VARIABLE | L3: DIRECTO | N3: CC11 | O3: gastos_produccion | P3: =_xlfn.XLOOKUP(bbdd3[[#This Row],[CCO - SECTOR]],'cco '!$A:$A,'cco '!F:F,"CCO NO DEFINIDO") -> 1 | Q3: =_xlfn.XLOOKUP(bbdd3[[#This Row],[CCO - SECTOR]],'cco '!$A:$A,'cco '!I:I,"CCO NO DEFINIDO") -> EXPORTACION | R3: =IF(ISBLANK(bbdd3[[#This Row],[CCO EMPRESA]]),1,_xlfn.XLOOKUP(bbdd3[[#This Row],[CCO EMPRESA]],'cco_worms_empresa'!$A:$A,'cco_worms_empresa'!$G:$G)) -> 1
A4: 46081 | B4: WORMS 2 | C4: prod29 | D4: -87594125 | E4: ARE- B | F4: 72.8 | G4: 840 | H4: TN | I4: MATERIA PRIMA | J4: OPEX | K4: VARIABLE | L4: DIRECTO | N4: CC11 | O4: gastos_produccion | P4: =_xlfn.XLOOKUP(bbdd3[[#This Row],[CCO - SECTOR]],'cco '!$A:$A,'cco '!F:F,"CCO NO DEFINIDO") -> 1 | Q4: =_xlfn.XLOOKUP(bbdd3[[#This Row],[CCO - SECTOR]],'cco '!$A:$A,'cco '!I:I,"CCO NO DEFINIDO") -> EXPORTACION | R4: =IF(ISBLANK(bbdd3[[#This Row],[CCO EMPRESA]]),1,_xlfn.XLOOKUP(bbdd3[[#This Row],[CCO EMPRESA]],'cco_worms_empresa'!$A:$A,'cco_worms_empresa'!$G:$G)) -> 1
A5: 46081 | B5: WORMS 1 | C5: prod26 | D5: -78996860 | E5: AG-D | F5: 110.3 | G5: 500 | H5: TN | I5: MATERIA PRIMA | J5: OPEX | K5: VARIABLE | L5: DIRECTO | N5: CC6 | O5: gastos_produccion | P5: =_xlfn.XLOOKUP(bbdd3[[#This Row],[CCO - SECTOR]],'cco '!$A:$A,'cco '!F:F,"CCO NO DEFINIDO") -> 1 | Q5: =_xlfn.XLOOKUP(bbdd3[[#This Row],[CCO - SECTOR]],'cco '!$A:$A,'cco '!I:I,"CCO NO DEFINIDO") -> BACHAS | R5: =IF(ISBLANK(bbdd3[[#This Row],[CCO EMPRESA]]),1,_xlfn.XLOOKUP(bbdd3[[#This Row],[CCO EMPRESA]],'cco_worms_empresa'!$A:$A,'cco_worms_empresa'!$G:$G)) -> 1
A6: 46081 | B6: MILO - DENIS LUQUE | C6: prod13 | D6: -67513309 | E6: GLICERINA CRUDA | F6: 130.925 | G6: 360 | H6: TN | I6: INSUMOS | J6: OPEX | K6: VARIABLE | L6: DIRECTO | N6: CC5 | O6: gastos_produccion | P6: =_xlfn.XLOOKUP(bbdd3[[#This Row],[CCO - SECTOR]],'cco '!$A:$A,'cco '!F:F,"CCO NO DEFINIDO") -> 1 | Q6: =_xlfn.XLOOKUP(bbdd3[[#This Row],[CCO - SECTOR]],'cco '!$A:$A,'cco '!I:I,"CCO NO DEFINIDO") -> REACTORES | R6: =IF(ISBLANK(bbdd3[[#This Row],[CCO EMPRESA]]),1,_xlfn.XLOOKUP(bbdd3[[#This Row],[CCO EMPRESA]],'cco_worms_empresa'!$A:$A,'cco_worms_empresa'!$G:$G)) -> 1
A7: 46066 | B7: Construcciones Industriales Y Portuarias S.A. | C7: FA-A 00003-00001286 | D7: -54208000 | E7: INVERSION Planta de efluentes | F7: 1 | G7: 44800000 | H7: UN | I7: INVERSION | J7: CAPEX | K7: VARIABLE | L7: INDIRECTO | N7: CC3 | O7: gastos_produccion | P7: =_xlfn.XLOOKUP(bbdd3[[#This Row],[CCO - SECTOR]],'cco '!$A:$A,'cco '!F:F,"CCO NO DEFINIDO") -> 1 | Q7: =_xlfn.XLOOKUP(bbdd3[[#This Row],[CCO - SECTOR]],'cco '!$A:$A,'cco '!I:I,"CCO NO DEFINIDO") -> DISPOSICIÓN FINAL RESIDUOS LIQUIDOS | R7: =IF(ISBLANK(bbdd3[[#This Row],[CCO EMPRESA]]),1,_xlfn.XLOOKUP(bbdd3[[#This Row],[CCO EMPRESA]],'cco_worms_empresa'!$A:$A,'cco_worms_empresa'!$G:$G)) -> 1
A8: 46056 | B8: Construcciones Industriales Y Portuarias S.A. | C8: FA-A 00003-00001279 | D8: -54208000 | E8: OC 0001-00004263: INVERSION Planta de efluentes | F8: 1 | G8: 44800000 | H8: UN | I8: INVERSION | J8: CAPEX | K8: VARIABLE | L8: INDIRECTO | N8: CC3 | O8: gastos_produccion | P8: =_xlfn.XLOOKUP(bbdd3[[#This Row],[CCO - SECTOR]],'cco '!$A:$A,'cco '!F:F,"CCO NO DEFINIDO") -> 1 | Q8: =_xlfn.XLOOKUP(bbdd3[[#This Row],[CCO - SECTOR]],'cco '!$A:$A,'cco '!I:I,"CCO NO DEFINIDO") -> DISPOSICIÓN FINAL RESIDUOS LIQUIDOS | R8: =IF(ISBLANK(bbdd3[[#This Row],[CCO EMPRESA]]),1,_xlfn.XLOOKUP(bbdd3[[#This Row],[CCO EMPRESA]],'cco_worms_empresa'!$A:$A,'cco_worms_empresa'!$G:$G)) -> 1
A9: 46081 | B9: WORMS 2 | C9: prod19 | D9: -42638251 | E9: AG- A | F9: 35.02 | G9: 850 | H9: TN | I9: MATERIA PRIMA | J9: OPEX | K9: VARIABLE | L9: DIRECTO | N9: CC11 | O9: gastos_produccion | P9: =_xlfn.XLOOKUP(bbdd3[[#This Row],[CCO - SECTOR]],'cco '!$A:$A,'cco '!F:F,"CCO NO DEFINIDO") -> 1 | Q9: =_xlfn.XLOOKUP(bbdd3[[#This Row],[CCO - SECTOR]],'cco '!$A:$A,'cco '!I:I,"CCO NO DEFINIDO") -> EXPORTACION | R9: =IF(ISBLANK(bbdd3[[#This Row],[CCO EMPRESA]]),1,_xlfn.XLOOKUP(bbdd3[[#This Row],[CCO EMPRESA]],'cco_worms_empresa'!$A:$A,'cco_worms_empresa'!$G:$G)) -> 1
A10: 46055 | B10: Gmc Valores Sociedad Anonima | C10: OCOM/2026/0113 | D10: -32228280 | E10: OC 0001-00004462: INVERSION NORDIC | F10: 1 | G10: 32228280 | H10: UN | I10: INVERSION | J10: CAPEX | K10: VARIABLE | L10: DIRECTO | N10: CC3 | O10: gastos_produccion | P10: =_xlfn.XLOOKUP(bbdd3[[#This Row],[CCO - SECTOR]],'cco '!$A:$A,'cco '!F:F,"CCO NO DEFINIDO") -> 1 | Q10: =_xlfn.XLOOKUP(bbdd3[[#This Row],[CCO - SECTOR]],'cco '!$A:$A,'cco '!I:I,"CCO NO DEFINIDO") -> DISPOSICIÓN FINAL RESIDUOS LIQUIDOS | R10: =IF(ISBLANK(bbdd3[[#This Row],[CCO EMPRESA]]),1,_xlfn.XLOOKUP(bbdd3[[#This Row],[CCO EMPRESA]],'cco_worms_empresa'!$A:$A,'cco_worms_empresa'!$G:$G)) -> 1
A11: 46063 | B11: Empresa Provincial De La Energia De Santa Fe (W) | C11: FA-A 00069-00037349 | D11: -30539110 | E11: OC 0001-00003944: ENERGIA Luz | F11: 1 | G11: 20913570 | H11: UN | I11: ENERGIA | J11: OPEX | K11: VARIABLE | L11: DIRECTO | N11: CC14 | O11: gastos_produccion | P11: =_xlfn.XLOOKUP(bbdd3[[#This Row],[CCO - SECTOR]],'cco '!$A:$A,'cco '!F:F,"CCO NO DEFINIDO") -> 10 | Q11: =_xlfn.XLOOKUP(bbdd3[[#This Row],[CCO - SECTOR]],'cco '!$A:$A,'cco '!I:I,"CCO NO DEFINIDO") -> BACHAS, CEREAL & POLVILLO, COMPOST & FERTILIZANTES, DISPOSICIÓN FINAL RESIDUOS LIQUIDOS, DISPOSICIÓN FINAL RESIDUOS SOLIDOS, EXPORTACION, NFU, PILETAS, REACTORES, TIERRAS FILTRANTES | R11: =IF(ISBLANK(bbdd3[[#This Row],[CCO EMPRESA]]),1,_xlfn.XLOOKUP(bbdd3[[#This Row],[CCO EMPRESA]],'cco_worms_empresa'!$A:$A,'cco_worms_empresa'!$G:$G)) -> 1
